<?xml version="1.0"?>
<robot xmlns:xacro="http://ros.org/wiki/xacro">

<!-- car frame virtual joints -->
<joint name="car_frame_tx" type="prismatic">
    <parent link="pelvis"/>
    <origin xyz="0.0 0.0 0.0"/>
    <child link="car_frame_intermediate_1"/>
    <axis xyz="1 0 0"/>
    <limit effort="1000" lower="-1e9" upper="1e9" velocity="10.0"/>
</joint>
<link name="car_frame_intermediate_1">
    <inertial>
    <mass value="0.0"/>
    <inertia ixx="0.0" ixy="0.0" ixz="0.0" iyy="0.0" iyz="0.0" izz="0.0"/>
    </inertial>
</link>

<joint name="car_frame_ty" type="prismatic">
    <parent link="car_frame_intermediate_1"/>
    <origin xyz="0.0 0.0 0.0"/>
    <child link="car_frame_intermediate_2"/>
    <axis xyz="0 1 0"/>
    <limit effort="1000" lower="-1e9" upper="1e9" velocity="10.0"/>
</joint>
<link name="car_frame_intermediate_2">
    <inertial>
    <mass value="0.0"/>
    <inertia ixx="0.0" ixy="0.0" ixz="0.0" iyy="0.0" iyz="0.0" izz="0.0"/>
    </inertial>
</link>

<joint name="car_frame_tz" type="prismatic">
    <parent link="car_frame_intermediate_2"/>
    <origin xyz="0.0 0.0 0.0"/>
    <child link="car_frame_intermediate_3"/>
    <axis xyz="0 0 1"/>
    <limit effort="1000" lower="-1e9" upper="1e9" velocity="10.0"/>
</joint>
<link name="car_frame_intermediate_3">
    <inertial>
    <mass value="0.0"/>
    <inertia ixx="0.0" ixy="0.0" ixz="0.0" iyy="0.0" iyz="0.0" izz="0.0"/>
    </inertial>
</link>

<joint name="car_frame_rx" type="revolute">
    <parent link="car_frame_intermediate_3"/>
    <origin xyz="0.0 0.0 0.0"/>
    <child link="car_frame_intermediate_4"/>
    <axis xyz="1 0 0"/>
    <limit effort="1000" lower="-1e9" upper="1e9" velocity="10.0"/>
</joint>
<link name="car_frame_intermediate_4">
    <inertial>
    <mass value="0.0"/>
    <inertia ixx="0.0" ixy="0.0" ixz="0.0" iyy="0.0" iyz="0.0" izz="0.0"/>
    </inertial>
</link>

<joint name="car_frame_ry" type="revolute">
    <parent link="car_frame_intermediate_4"/>
    <origin xyz="0.0 0.0 0.0"/>
    <child link="car_frame_intermediate_5"/>
    <axis xyz="0 1 0"/>
    <limit effort="1000" lower="-1e9" upper="1e9" velocity="10.0"/>
</joint>
<link name="car_frame_intermediate_5">
    <inertial>
    <mass value="0.0"/>
    <inertia ixx="0.0" ixy="0.0" ixz="0.0" iyy="0.0" iyz="0.0" izz="0.0"/>
    </inertial>
</link>

<joint name="car_frame_rz" type="revolute">
    <parent link="car_frame_intermediate_5"/>
    <origin xyz="0.0 0.0 0.0"/>
    <child link="car_frame"/>
    <axis xyz="0 0 1"/>
    <limit effort="1000" lower="-1e9" upper="1e9" velocity="10.0"/>
</joint>
<link name="car_frame">
    <inertial>
    <mass value="0.0"/>
    <inertia ixx="0.0" ixy="0.0" ixz="0.0" iyy="0.0" iyz="0.0" izz="0.0"/>
    </inertial>
</link>

</robot>