<sdf version='1.6'>
  <world name='default'>
    <plugin name='xbot2_clock' filename='libxbot2_gz_clock.so'/>
    <gravity>0 0 -9.81</gravity>
    <model name='ground_plane'>
      <static>1</static>
      <link name='link'>
        <collision name='collision'>
          <geometry>
            <plane>
              <normal>0 0 1</normal>
              <size>100 100</size>
            </plane>
          </geometry>
          <surface>
            <friction>
              <ode>
                <mu>1</mu>
                <mu2>1</mu2>
              </ode>
              <torsional>
                <ode/>
              </torsional>
            </friction>
            <contact>
              <ode/>
            </contact>
            <bounce/>
          </surface>
          <max_contacts>10</max_contacts>
        </collision>
        <visual name='visual'>
          <cast_shadows>0</cast_shadows>
          <geometry>
            <plane>
              <normal>0 0 1</normal>
              <size>100 100</size>
            </plane>
          </geometry>
          <material>
            <script>
              <uri>file://media/materials/scripts/gazebo.material</uri>
              <name>Gazebo/Grey</name>
            </script>
          </material>
        </visual>
        <self_collide>0</self_collide>
        <enable_wind>0</enable_wind>
        <kinematic>0</kinematic>
      </link>
    </model>
    <model name='unit_box'>
      <pose frame=''>2 -0.5 0.1 0 -0 0</pose>
      <link name='link'>
        <inertial>
          <mass>1000</mass>
          <inertia>
            <ixx>100</ixx>
            <ixy>0</ixy>
            <ixz>0</ixz>
            <iyy>100</iyy>
            <iyz>0</iyz>
            <izz>166</izz>
          </inertia>
        </inertial>
        <collision name='collision'>
          <geometry>
            <box>
              <size>2 1 0.2</size>
            </box>
          </geometry>
          <max_contacts>10</max_contacts>
          <surface>
            <contact>
              <ode/>
            </contact>
            <bounce/>
            <friction>
              <torsional>
                <ode/>
              </torsional>
              <ode/>
            </friction>
          </surface>
        </collision>
        <visual name='visual'>
          <geometry>
            <box>
              <size>2 1 0.2</size>
            </box>
          </geometry>
          <material>
            <script>
              <name>Gazebo/Grey</name>
              <uri>file://media/materials/scripts/gazebo.material</uri>
            </script>
          </material>
        </visual>
        <self_collide>0</self_collide>
        <enable_wind>0</enable_wind>
        <kinematic>1</kinematic>
      </link>
    </model>
    <light name='sun' type='directional'>
      <cast_shadows>1</cast_shadows>
      <pose frame=''>0 0 10 0 -0 0</pose>
      <diffuse>0.8 0.8 0.8 1</diffuse>
      <specular>0.2 0.2 0.2 1</specular>
      <attenuation>
        <range>1000</range>
        <constant>0.9</constant>
        <linear>0.01</linear>
        <quadratic>0.001</quadratic>
      </attenuation>
      <direction>-0.5 0.1 -0.9</direction>
    </light>
    <gui fullscreen='0'>
      <camera name='user_camera'>
        <pose frame=''>3.47139 -6.99822 1.86634 0 0.107643 1.8722</pose>
        <view_controller>orbit</view_controller>
        <projection_type>perspective</projection_type>
      </camera>
    </gui>
    <physics name='update_rate' default='0' type='ode'>
      <real_time_update_rate>4000</real_time_update_rate>
      <max_step_size>0.00025</max_step_size>
      <max_contacts>5</max_contacts>
      <bullet>
        <solver>
          <iters>100</iters>
          <sor>1.55</sor>
          <type>sequential_impulse</type>
        </solver>
        <constraints>
          <contact_surface_layer>0.2</contact_surface_layer>
          <cfm>0.005</cfm>
          <erp>0.2</erp>
          <split_impulse>1</split_impulse>
          <split_impulse_penetration_threshold>-0.01</split_impulse_penetration_threshold>
        </constraints>
      </bullet>
      <ode>
        <solver>
          <iters>50</iters>
          <sor>1.2</sor>
          <type>quick</type>
          <use_dynamic_moi_rescaling>0</use_dynamic_moi_rescaling>
        </solver>
        <constraints>
          <contact_surface_layer>0.0002</contact_surface_layer>
          <contact_max_correcting_vel>500</contact_max_correcting_vel>
          <cfm>1e-06</cfm>
          <erp>0.3</erp>
        </constraints>
      </ode>
      <real_time_factor>1</real_time_factor>
    </physics>
    <magnetic_field>6e-06 2.3e-05 -4.2e-05</magnetic_field>
    <atmosphere type='adiabatic'/>
    <scene>
      <ambient>0.4 0.4 0.4 1</ambient>
      <background>0.7 0.7 0.7 1</background>
      <shadows>1</shadows>
    </scene>
    <audio>
      <device>default</device>
    </audio>
    <wind/>
    <spherical_coordinates>
      <surface_model>EARTH_WGS84</surface_model>
      <latitude_deg>0</latitude_deg>
      <longitude_deg>0</longitude_deg>
      <elevation>0</elevation>
      <heading_deg>0</heading_deg>
    </spherical_coordinates>
    <model name='centauro'>
      <link name='pelvis'>
        <pose frame=''>0 0 0 0 -0 0</pose>
        <inertial>
          <pose frame=''>0.001389 -0.001599 0.063101 0 -0 0</pose>
          <mass>16.0976</mass>
          <inertia>
            <ixx>0.239126</ixx>
            <ixy>-0.00505413</ixy>
            <ixz>-0.0197461</ixz>
            <iyy>0.714301</iyy>
            <iyz>0.00021312</iyz>
            <izz>0.818704</izz>
          </inertia>
        </inertial>
        <collision name='pelvis_collision'>
          <pose frame=''>0 0 0 0 -0 0</pose>
          <geometry>
            <mesh>
              <scale>0.001 0.001 0.001</scale>
              <uri>/home/ioannis/centauro_ws/src/iit-centauro-ros-pkg/centauro_urdf/meshes/simple/pelvis.stl</uri>
            </mesh>
          </geometry>
          <surface>
            <contact>
              <ode/>
            </contact>
            <friction>
              <ode/>
              <torsional>
                <ode/>
              </torsional>
            </friction>
            <bounce/>
          </surface>
          <max_contacts>10</max_contacts>
        </collision>
        <visual name='pelvis_visual'>
          <pose frame=''>0 0 0 0 -0 0</pose>
          <geometry>
            <mesh>
              <scale>0.001 0.001 0.001</scale>
              <uri>/home/ioannis/centauro_ws/src/iit-centauro-ros-pkg/centauro_urdf/meshes/pelvis.stl</uri>
            </mesh>
          </geometry>
          <material>
            <script>
              <name>Gazebo/LightBlueLaser</name>
              <uri>file://media/materials/scripts/gazebo.material</uri>
            </script>
          </material>
        </visual>
        <velocity_decay/>
        <gravity>1</gravity>
        <velocity_decay/>
        <sensor name='imu_link' type='imu'>
          <always_on>1</always_on>
          <update_rate>500</update_rate>
          <visualize>1</visualize>
          <topic>__default_topic__</topic>
          <imu>
            <angular_velocity/>
            <linear_acceleration/>
          </imu>
          <pose frame=''>0.248316 0 0.015 0 -0 0</pose>
        </sensor>
        <self_collide>0</self_collide>
        <enable_wind>0</enable_wind>
        <kinematic>0</kinematic>
      </link>
      <link name='hip1_1'>
        <pose frame=''>0.25 0.125 -0.0566 -3.14159 -0 0.461416</pose>
        <inertial>
          <pose frame=''>0.010214 -0.018348 0.038091 0 -0 0</pose>
          <mass>1.91944</mass>
          <inertia>
            <ixx>0.00474396</ixx>
            <ixy>0.000574705</ixy>
            <ixz>-0.000378414</ixz>
            <iyy>0.00405519</iyy>
            <iyz>0.000740751</iyz>
            <izz>0.00341462</izz>
          </inertia>
        </inertial>
        <collision name='hip1_1_collision'>
          <pose frame=''>0 0 0 0 -0 -2.21876</pose>
          <geometry>
            <mesh>
              <scale>0.001 0.001 0.001</scale>
              <uri>/home/ioannis/centauro_ws/src/iit-centauro-ros-pkg/centauro_urdf/meshes/simple/hip-yaw.stl</uri>
            </mesh>
          </geometry>
          <surface>
            <contact>
              <ode/>
            </contact>
            <friction>
              <ode/>
              <torsional>
                <ode/>
              </torsional>
            </friction>
            <bounce/>
          </surface>
          <max_contacts>10</max_contacts>
        </collision>
        <visual name='hip1_1_visual'>
          <pose frame=''>0 0 0 0 -0 -2.21876</pose>
          <geometry>
            <mesh>
              <scale>0.001 0.001 0.001</scale>
              <uri>/home/ioannis/centauro_ws/src/iit-centauro-ros-pkg/centauro_urdf/meshes/hip-yaw.stl</uri>
            </mesh>
          </geometry>
          <material>
            <script>
              <name>Gazebo/LightBlueLaser</name>
              <uri>file://media/materials/scripts/gazebo.material</uri>
            </script>
          </material>
        </visual>
        <gravity>1</gravity>
        <velocity_decay/>
        <self_collide>0</self_collide>
        <enable_wind>0</enable_wind>
        <kinematic>0</kinematic>
      </link>
      <joint name='hip_yaw_1' type='revolute'>
        <child>hip1_1</child>
        <parent>pelvis</parent>
        <axis>
          <xyz>-0 0 -1</xyz>
          <limit>
            <lower>-2.03</lower>
            <upper>2.51</upper>
            <effort>304</effort>
            <velocity>8.8</velocity>
          </limit>
          <dynamics>
            <spring_reference>0</spring_reference>
            <spring_stiffness>0</spring_stiffness>
          </dynamics>
          <use_parent_model_frame>1</use_parent_model_frame>
        </axis>
        <physics>
          <provide_feedback>1</provide_feedback>
          <ode>
            <provide_feedback>1</provide_feedback>
            <implicit_spring_damper>1</implicit_spring_damper>
            <cfm_damping>1</cfm_damping>
            <limit>
              <cfm>0</cfm>
              <erp>0.2</erp>
            </limit>
          </ode>
        </physics>
      </joint>
      <link name='hip2_1'>
        <pose frame=''>0.25 0.125 -0.1191 -1.5708 0 0</pose>
        <inertial>
          <pose frame=''>2.6e-05 0.181027 0.08567 0 -0 0</pose>
          <mass>2.72645</mass>
          <inertia>
            <ixx>0.0485187</ixx>
            <ixy>-4.11894e-05</ixy>
            <ixz>-1.68778e-05</ixz>
            <iyy>0.00424205</iyy>
            <iyz>0.00322432</iyz>
            <izz>0.0482558</izz>
          </inertia>
        </inertial>
        <collision name='hip2_1_collision'>
          <pose frame=''>0 0 0 0 -0 0</pose>
          <geometry>
            <mesh>
              <scale>0.001 0.001 0.001</scale>
              <uri>/home/ioannis/centauro_ws/src/iit-centauro-ros-pkg/centauro_urdf/meshes/simple/hip-pitch.stl</uri>
            </mesh>
          </geometry>
          <surface>
            <contact>
              <ode/>
            </contact>
            <friction>
              <ode/>
              <torsional>
                <ode/>
              </torsional>
            </friction>
            <bounce/>
          </surface>
          <max_contacts>10</max_contacts>
        </collision>
        <visual name='hip2_1_visual'>
          <pose frame=''>0 0 0 0 -0 0</pose>
          <geometry>
            <mesh>
              <scale>0.001 0.001 0.001</scale>
              <uri>/home/ioannis/centauro_ws/src/iit-centauro-ros-pkg/centauro_urdf/meshes/hip-pitch.stl</uri>
            </mesh>
          </geometry>
          <material>
            <script>
              <name>Gazebo/BlackTransparent</name>
              <uri>file://media/materials/scripts/gazebo.material</uri>
            </script>
          </material>
        </visual>
        <gravity>1</gravity>
        <velocity_decay/>
        <self_collide>0</self_collide>
        <enable_wind>0</enable_wind>
        <kinematic>0</kinematic>
      </link>
      <joint name='hip_pitch_1' type='revolute'>
        <child>hip2_1</child>
        <parent>hip1_1</parent>
        <axis>
          <xyz>0 1 -0</xyz>
          <limit>
            <lower>-2.0226</lower>
            <upper>2.02748</upper>
            <effort>304</effort>
            <velocity>8.8</velocity>
          </limit>
          <dynamics>
            <spring_reference>0</spring_reference>
            <spring_stiffness>0</spring_stiffness>
          </dynamics>
          <use_parent_model_frame>1</use_parent_model_frame>
        </axis>
        <physics>
          <provide_feedback>1</provide_feedback>
          <ode>
            <provide_feedback>1</provide_feedback>
            <implicit_spring_damper>1</implicit_spring_damper>
            <cfm_damping>1</cfm_damping>
            <limit>
              <cfm>0</cfm>
              <erp>0.2</erp>
            </limit>
          </ode>
        </physics>
      </joint>
      <link name='knee_1'>
        <pose frame=''>0.25 0.1214 -0.4191 -1.57079 1.57079 3.14159</pose>
        <inertial>
          <pose frame=''>0.108817 0.000109 -0.022639 0 -0 0</pose>
          <mass>1.93568</mass>
          <inertia>
            <ixx>0.00305342</ixx>
            <ixy>-4.22079e-05</ixy>
            <ixz>0.00136793</ixz>
            <iyy>0.0196033</iyy>
            <iyz>6.9941e-06</iyz>
            <izz>0.0198498</izz>
          </inertia>
        </inertial>
        <collision name='knee_1_collision'>
          <pose frame=''>0 0 0 0 -0 0</pose>
          <geometry>
            <mesh>
              <scale>0.001 0.001 0.001</scale>
              <uri>/home/ioannis/centauro_ws/src/iit-centauro-ros-pkg/centauro_urdf/meshes/simple/knee.stl</uri>
            </mesh>
          </geometry>
          <surface>
            <contact>
              <ode/>
            </contact>
            <friction>
              <ode/>
              <torsional>
                <ode/>
              </torsional>
            </friction>
            <bounce/>
          </surface>
          <max_contacts>10</max_contacts>
        </collision>
        <visual name='knee_1_visual'>
          <pose frame=''>0 0 0 0 -0 0</pose>
          <geometry>
            <mesh>
              <scale>0.001 0.001 0.001</scale>
              <uri>/home/ioannis/centauro_ws/src/iit-centauro-ros-pkg/centauro_urdf/meshes/knee.stl</uri>
            </mesh>
          </geometry>
          <material>
            <script>
              <name>Gazebo/LightBlueLaser</name>
              <uri>file://media/materials/scripts/gazebo.material</uri>
            </script>
          </material>
        </visual>
        <gravity>1</gravity>
        <velocity_decay/>
        <self_collide>0</self_collide>
        <enable_wind>0</enable_wind>
        <kinematic>0</kinematic>
      </link>
      <joint name='knee_pitch_1' type='revolute'>
        <child>knee_1</child>
        <parent>hip2_1</parent>
        <axis>
          <xyz>-0 -1 0</xyz>
          <limit>
            <lower>-2.4056</lower>
            <upper>2.3994</upper>
            <effort>304</effort>
            <velocity>8.8</velocity>
          </limit>
          <dynamics>
            <spring_reference>0</spring_reference>
            <spring_stiffness>0</spring_stiffness>
          </dynamics>
          <use_parent_model_frame>1</use_parent_model_frame>
        </axis>
        <physics>
          <provide_feedback>1</provide_feedback>
          <ode>
            <provide_feedback>1</provide_feedback>
            <implicit_spring_damper>1</implicit_spring_damper>
            <cfm_damping>1</cfm_damping>
            <limit>
              <cfm>0</cfm>
              <erp>0.2</erp>
            </limit>
          </ode>
        </physics>
      </joint>
      <link name='ankle1_1'>
        <pose frame=''>0.25 0.22155 -0.6191 1.57079 1.57079 3.14159</pose>
        <inertial>
          <pose frame=''>0.032137 9.7e-05 -0.004422 0 -0 0</pose>
          <mass>1.23807</mass>
          <inertia>
            <ixx>0.00156105</ixx>
            <ixy>3.30597e-05</ixy>
            <ixz>-0.000131417</ixz>
            <iyy>0.00374232</iyy>
            <iyz>-2.12589e-05</iyz>
            <izz>0.00383124</izz>
          </inertia>
        </inertial>
        <collision name='ankle1_1_collision'>
          <pose frame=''>0 0 0 0 -0 0</pose>
          <geometry>
            <mesh>
              <scale>0.001 0.001 0.001</scale>
              <uri>/home/ioannis/centauro_ws/src/iit-centauro-ros-pkg/centauro_urdf/meshes/simple/ankle-pitch.stl</uri>
            </mesh>
          </geometry>
          <surface>
            <contact>
              <ode/>
            </contact>
            <friction>
              <ode/>
              <torsional>
                <ode/>
              </torsional>
            </friction>
            <bounce/>
          </surface>
          <max_contacts>10</max_contacts>
        </collision>
        <visual name='ankle1_1_visual'>
          <pose frame=''>0 0 0 0 -0 0</pose>
          <geometry>
            <mesh>
              <scale>0.001 0.001 0.001</scale>
              <uri>/home/ioannis/centauro_ws/src/iit-centauro-ros-pkg/centauro_urdf/meshes/ankle-pitch.stl</uri>
            </mesh>
          </geometry>
          <material>
            <script>
              <name>Gazebo/LightBlueLaser</name>
              <uri>file://media/materials/scripts/gazebo.material</uri>
            </script>
          </material>
        </visual>
        <gravity>1</gravity>
        <velocity_decay/>
        <self_collide>0</self_collide>
        <enable_wind>0</enable_wind>
        <kinematic>0</kinematic>
      </link>
      <joint name='ankle_pitch_1' type='revolute'>
        <child>ankle1_1</child>
        <parent>knee_1</parent>
        <axis>
          <xyz>0 1 -0</xyz>
          <limit>
            <lower>-2.4056</lower>
            <upper>2.3184</upper>
            <effort>147</effort>
            <velocity>8.1</velocity>
          </limit>
          <dynamics>
            <spring_reference>0</spring_reference>
            <spring_stiffness>0</spring_stiffness>
          </dynamics>
          <use_parent_model_frame>1</use_parent_model_frame>
        </axis>
        <physics>
          <provide_feedback>1</provide_feedback>
          <ode>
            <provide_feedback>1</provide_feedback>
            <implicit_spring_damper>1</implicit_spring_damper>
            <cfm_damping>1</cfm_damping>
            <limit>
              <cfm>0</cfm>
              <erp>0.2</erp>
            </limit>
          </ode>
        </physics>
      </joint>
      <link name='ankle2_1'>
        <pose frame=''>0.25 0.22155 -0.6191 3.14159 -0 3.14159</pose>
        <inertial>
          <pose frame=''>0.000444 0.000439 0.193921 0 -0 0</pose>
          <mass>1.15659</mass>
          <inertia>
            <ixx>0.00490195</ixx>
            <ixy>4.3032e-06</ixy>
            <ixz>3.46491e-05</ixz>
            <iyy>0.00387242</iyy>
            <iyz>1.7099e-05</iyz>
            <izz>0.00217832</izz>
          </inertia>
        </inertial>
        <collision name='ankle2_1_collision'>
          <pose frame=''>0 0 0 0 -0 0</pose>
          <geometry>
            <mesh>
              <scale>0.001 0.001 0.001</scale>
              <uri>/home/ioannis/centauro_ws/src/iit-centauro-ros-pkg/centauro_urdf/meshes/simple/ankle-yaw.stl</uri>
            </mesh>
          </geometry>
          <surface>
            <contact>
              <ode/>
            </contact>
            <friction>
              <ode/>
              <torsional>
                <ode/>
              </torsional>
            </friction>
            <bounce/>
          </surface>
          <max_contacts>10</max_contacts>
        </collision>
        <visual name='ankle2_1_visual'>
          <pose frame=''>0 0 0 0 -0 0</pose>
          <geometry>
            <mesh>
              <scale>0.001 0.001 0.001</scale>
              <uri>/home/ioannis/centauro_ws/src/iit-centauro-ros-pkg/centauro_urdf/meshes/ankle-yaw.stl</uri>
            </mesh>
          </geometry>
          <material>
            <script>
              <name>Gazebo/LightBlueLaser</name>
              <uri>file://media/materials/scripts/gazebo.material</uri>
            </script>
          </material>
        </visual>
        <gravity>1</gravity>
        <velocity_decay/>
        <self_collide>0</self_collide>
        <enable_wind>0</enable_wind>
        <kinematic>0</kinematic>
      </link>
      <joint name='ankle_yaw_1' type='revolute'>
        <child>ankle2_1</child>
        <parent>ankle1_1</parent>
        <axis>
          <xyz>0 0 -1</xyz>
          <limit>
            <lower>-2.5626</lower>
            <upper>2.5384</upper>
            <effort>35</effort>
            <velocity>20</velocity>
          </limit>
          <dynamics>
            <spring_reference>0</spring_reference>
            <spring_stiffness>0</spring_stiffness>
          </dynamics>
          <use_parent_model_frame>1</use_parent_model_frame>
        </axis>
        <physics>
          <provide_feedback>1</provide_feedback>
          <ode>
            <provide_feedback>1</provide_feedback>
            <implicit_spring_damper>1</implicit_spring_damper>
            <cfm_damping>1</cfm_damping>
            <limit>
              <cfm>0</cfm>
              <erp>0.2</erp>
            </limit>
          </ode>
        </physics>
      </joint>
      <link name='wheel_1'>
        <pose frame=''>0.25 0.2224 -0.85645 -1.5708 -0 -0</pose>
        <inertial>
          <pose frame=''>0 0 0.002427 0 -0 0</pose>
          <mass>1.7289</mass>
          <inertia>
            <ixx>0.00468643</ixx>
            <ixy>0</ixy>
            <ixz>0</ixz>
            <iyy>0.00467135</iyy>
            <iyz>0</iyz>
            <izz>0.0053126</izz>
          </inertia>
        </inertial>
        <collision name='wheel_1_collision'>
          <pose frame=''>0 0 0 0 -0 0</pose>
          <geometry>
            <cylinder>
              <length>0.06</length>
              <radius>0.078</radius>
            </cylinder>
          </geometry>
          <surface>
            <friction>
              <ode>
                <mu>0.5</mu>
                <mu2>0.5</mu2>
              </ode>
              <bullet>
                <friction>0.5</friction>
                <friction2>0.5</friction2>
              </bullet>
              <torsional>
                <ode/>
              </torsional>
            </friction>
            <contact>
              <ode>
                <kp>2.1e+06</kp>
                <kd>1</kd>
                <max_vel>100</max_vel>
              </ode>
              <bullet>
                <soft_cfm>0.007</soft_cfm>
                <soft_erp>0.25</soft_erp>
                <kp>1e+06</kp>
                <kd>5</kd>
                <split_impulse>1</split_impulse>
                <split_impulse_penetration_threshold>-0.01</split_impulse_penetration_threshold>
              </bullet>
            </contact>
            <bounce/>
          </surface>
          <max_contacts>10</max_contacts>
        </collision>
        <visual name='wheel_1_visual'>
          <pose frame=''>0 0 0 0 -0 0</pose>
          <geometry>
            <mesh>
              <scale>0.001 0.001 0.001</scale>
              <uri>/home/ioannis/centauro_ws/src/iit-centauro-ros-pkg/centauro_urdf/meshes/wheel.stl</uri>
            </mesh>
          </geometry>
          <material>
            <script>
              <name>Gazebo/BlackTransparent</name>
              <uri>file://media/materials/scripts/gazebo.material</uri>
            </script>
          </material>
        </visual>
        <velocity_decay/>
        <gravity>1</gravity>
        <velocity_decay/>
        <self_collide>0</self_collide>
        <enable_wind>0</enable_wind>
        <kinematic>0</kinematic>
      </link>
      <joint name='j_wheel_1' type='revolute'>
        <child>wheel_1</child>
        <parent>ankle2_1</parent>
        <axis>
          <xyz>0 1 -0</xyz>
          <limit>
            <lower>-1e+16</lower>
            <upper>1e+16</upper>
          </limit>
          <dynamics>
            <spring_reference>0</spring_reference>
            <spring_stiffness>0</spring_stiffness>
          </dynamics>
          <use_parent_model_frame>1</use_parent_model_frame>
        </axis>
        <physics>
          <provide_feedback>1</provide_feedback>
          <ode>
            <provide_feedback>1</provide_feedback>
            <implicit_spring_damper>1</implicit_spring_damper>
            <cfm_damping>1</cfm_damping>
            <limit>
              <cfm>0</cfm>
              <erp>0.2</erp>
            </limit>
          </ode>
        </physics>
      </joint>
      <link name='hip1_2'>
        <pose frame=''>0.25 -0.125 -0.0566 -3.14159 -0 -0.461416</pose>
        <inertial>
          <pose frame=''>0.010214 0.018348 0.038091 0 -0 0</pose>
          <mass>1.91944</mass>
          <inertia>
            <ixx>0.00474396</ixx>
            <ixy>-0.000574705</ixy>
            <ixz>-0.000378414</ixz>
            <iyy>0.00405519</iyy>
            <iyz>-0.000740751</iyz>
            <izz>0.00341462</izz>
          </inertia>
        </inertial>
        <collision name='hip1_2_collision'>
          <pose frame=''>0 0 0 0 -0 0</pose>
          <geometry>
            <mesh>
              <scale>0.001 0.001 0.001</scale>
              <uri>/home/ioannis/centauro_ws/src/iit-centauro-ros-pkg/centauro_urdf/meshes/simple/hip-yaw.stl</uri>
            </mesh>
          </geometry>
          <surface>
            <contact>
              <ode/>
            </contact>
            <friction>
              <ode/>
              <torsional>
                <ode/>
              </torsional>
            </friction>
            <bounce/>
          </surface>
          <max_contacts>10</max_contacts>
        </collision>
        <visual name='hip1_2_visual'>
          <pose frame=''>0 0 0 0 -0 0</pose>
          <geometry>
            <mesh>
              <scale>0.001 0.001 0.001</scale>
              <uri>/home/ioannis/centauro_ws/src/iit-centauro-ros-pkg/centauro_urdf/meshes/hip-yaw.stl</uri>
            </mesh>
          </geometry>
          <material>
            <script>
              <name>Gazebo/LightBlueLaser</name>
              <uri>file://media/materials/scripts/gazebo.material</uri>
            </script>
          </material>
        </visual>
        <gravity>1</gravity>
        <velocity_decay/>
        <self_collide>0</self_collide>
        <enable_wind>0</enable_wind>
        <kinematic>0</kinematic>
      </link>
      <joint name='hip_yaw_2' type='revolute'>
        <child>hip1_2</child>
        <parent>pelvis</parent>
        <axis>
          <xyz>0 0 -1</xyz>
          <limit>
            <lower>-2.51</lower>
            <upper>2.03</upper>
            <effort>304</effort>
            <velocity>8.8</velocity>
          </limit>
          <dynamics>
            <spring_reference>0</spring_reference>
            <spring_stiffness>0</spring_stiffness>
          </dynamics>
          <use_parent_model_frame>1</use_parent_model_frame>
        </axis>
        <physics>
          <provide_feedback>1</provide_feedback>
          <ode>
            <provide_feedback>1</provide_feedback>
            <implicit_spring_damper>1</implicit_spring_damper>
            <cfm_damping>1</cfm_damping>
            <limit>
              <cfm>0</cfm>
              <erp>0.2</erp>
            </limit>
          </ode>
        </physics>
      </joint>
      <link name='hip2_2'>
        <pose frame=''>0.25 -0.125 -0.1191 -1.5708 -0 -3.14159</pose>
        <inertial>
          <pose frame=''>2.6e-05 0.181027 0.08567 0 -0 0</pose>
          <mass>2.72645</mass>
          <inertia>
            <ixx>0.0485187</ixx>
            <ixy>-4.11894e-05</ixy>
            <ixz>-1.68778e-05</ixz>
            <iyy>0.00424205</iyy>
            <iyz>0.00322432</iyz>
            <izz>0.0482558</izz>
          </inertia>
        </inertial>
        <collision name='hip2_2_collision'>
          <pose frame=''>0 0 0 0 -0 0</pose>
          <geometry>
            <mesh>
              <scale>0.001 0.001 0.001</scale>
              <uri>/home/ioannis/centauro_ws/src/iit-centauro-ros-pkg/centauro_urdf/meshes/simple/hip-pitch.stl</uri>
            </mesh>
          </geometry>
          <surface>
            <contact>
              <ode/>
            </contact>
            <friction>
              <ode/>
              <torsional>
                <ode/>
              </torsional>
            </friction>
            <bounce/>
          </surface>
          <max_contacts>10</max_contacts>
        </collision>
        <visual name='hip2_2_visual'>
          <pose frame=''>0 0 0 0 -0 0</pose>
          <geometry>
            <mesh>
              <scale>0.001 0.001 0.001</scale>
              <uri>/home/ioannis/centauro_ws/src/iit-centauro-ros-pkg/centauro_urdf/meshes/hip-pitch.stl</uri>
            </mesh>
          </geometry>
          <material>
            <script>
              <name>Gazebo/BlackTransparent</name>
              <uri>file://media/materials/scripts/gazebo.material</uri>
            </script>
          </material>
        </visual>
        <gravity>1</gravity>
        <velocity_decay/>
        <self_collide>0</self_collide>
        <enable_wind>0</enable_wind>
        <kinematic>0</kinematic>
      </link>
      <joint name='hip_pitch_2' type='revolute'>
        <child>hip2_2</child>
        <parent>hip1_2</parent>
        <axis>
          <xyz>0 -1 -0</xyz>
          <limit>
            <lower>-2.0156</lower>
            <upper>2.0354</upper>
            <effort>304</effort>
            <velocity>8.8</velocity>
          </limit>
          <dynamics>
            <spring_reference>0</spring_reference>
            <spring_stiffness>0</spring_stiffness>
          </dynamics>
          <use_parent_model_frame>1</use_parent_model_frame>
        </axis>
        <physics>
          <provide_feedback>1</provide_feedback>
          <ode>
            <provide_feedback>1</provide_feedback>
            <implicit_spring_damper>1</implicit_spring_damper>
            <cfm_damping>1</cfm_damping>
            <limit>
              <cfm>0</cfm>
              <erp>0.2</erp>
            </limit>
          </ode>
        </physics>
      </joint>
      <link name='knee_2'>
        <pose frame=''>0.25 -0.1214 -0.4191 1.57079 1.57079 3.14159</pose>
        <inertial>
          <pose frame=''>0.108817 0.000109 -0.022639 0 -0 0</pose>
          <mass>1.93568</mass>
          <inertia>
            <ixx>0.00305342</ixx>
            <ixy>-4.22079e-05</ixy>
            <ixz>0.00136793</ixz>
            <iyy>0.0196033</iyy>
            <iyz>6.9941e-06</iyz>
            <izz>0.0198498</izz>
          </inertia>
        </inertial>
        <collision name='knee_2_collision'>
          <pose frame=''>0 0 0 0 -0 0</pose>
          <geometry>
            <mesh>
              <scale>0.001 0.001 0.001</scale>
              <uri>/home/ioannis/centauro_ws/src/iit-centauro-ros-pkg/centauro_urdf/meshes/simple/knee.stl</uri>
            </mesh>
          </geometry>
          <surface>
            <contact>
              <ode/>
            </contact>
            <friction>
              <ode/>
              <torsional>
                <ode/>
              </torsional>
            </friction>
            <bounce/>
          </surface>
          <max_contacts>10</max_contacts>
        </collision>
        <visual name='knee_2_visual'>
          <pose frame=''>0 0 0 0 -0 0</pose>
          <geometry>
            <mesh>
              <scale>0.001 0.001 0.001</scale>
              <uri>/home/ioannis/centauro_ws/src/iit-centauro-ros-pkg/centauro_urdf/meshes/knee.stl</uri>
            </mesh>
          </geometry>
          <material>
            <script>
              <name>Gazebo/LightBlueLaser</name>
              <uri>file://media/materials/scripts/gazebo.material</uri>
            </script>
          </material>
        </visual>
        <gravity>1</gravity>
        <velocity_decay/>
        <self_collide>0</self_collide>
        <enable_wind>0</enable_wind>
        <kinematic>0</kinematic>
      </link>
      <joint name='knee_pitch_2' type='revolute'>
        <child>knee_2</child>
        <parent>hip2_2</parent>
        <axis>
          <xyz>-0 1 0</xyz>
          <limit>
            <lower>-2.4006</lower>
            <upper>2.4034</upper>
            <effort>304</effort>
            <velocity>8.8</velocity>
          </limit>
          <dynamics>
            <spring_reference>0</spring_reference>
            <spring_stiffness>0</spring_stiffness>
          </dynamics>
          <use_parent_model_frame>1</use_parent_model_frame>
        </axis>
        <physics>
          <provide_feedback>1</provide_feedback>
          <ode>
            <provide_feedback>1</provide_feedback>
            <implicit_spring_damper>1</implicit_spring_damper>
            <cfm_damping>1</cfm_damping>
            <limit>
              <cfm>0</cfm>
              <erp>0.2</erp>
            </limit>
          </ode>
        </physics>
      </joint>
      <link name='ankle1_2'>
        <pose frame=''>0.25 -0.22155 -0.6191 -1.57079 1.57079 3.14159</pose>
        <inertial>
          <pose frame=''>0.032137 9.7e-05 -0.004422 0 -0 0</pose>
          <mass>1.23807</mass>
          <inertia>
            <ixx>0.00156105</ixx>
            <ixy>3.30597e-05</ixy>
            <ixz>-0.000131417</ixz>
            <iyy>0.00374232</iyy>
            <iyz>-2.12589e-05</iyz>
            <izz>0.00383124</izz>
          </inertia>
        </inertial>
        <collision name='ankle1_2_collision'>
          <pose frame=''>0 0 0 0 -0 0</pose>
          <geometry>
            <mesh>
              <scale>0.001 0.001 0.001</scale>
              <uri>/home/ioannis/centauro_ws/src/iit-centauro-ros-pkg/centauro_urdf/meshes/simple/ankle-pitch.stl</uri>
            </mesh>
          </geometry>
          <surface>
            <contact>
              <ode/>
            </contact>
            <friction>
              <ode/>
              <torsional>
                <ode/>
              </torsional>
            </friction>
            <bounce/>
          </surface>
          <max_contacts>10</max_contacts>
        </collision>
        <visual name='ankle1_2_visual'>
          <pose frame=''>0 0 0 0 -0 0</pose>
          <geometry>
            <mesh>
              <scale>0.001 0.001 0.001</scale>
              <uri>/home/ioannis/centauro_ws/src/iit-centauro-ros-pkg/centauro_urdf/meshes/ankle-pitch.stl</uri>
            </mesh>
          </geometry>
          <material>
            <script>
              <name>Gazebo/LightBlueLaser</name>
              <uri>file://media/materials/scripts/gazebo.material</uri>
            </script>
          </material>
        </visual>
        <gravity>1</gravity>
        <velocity_decay/>
        <self_collide>0</self_collide>
        <enable_wind>0</enable_wind>
        <kinematic>0</kinematic>
      </link>
      <joint name='ankle_pitch_2' type='revolute'>
        <child>ankle1_2</child>
        <parent>knee_2</parent>
        <axis>
          <xyz>0 -1 -0</xyz>
          <limit>
            <lower>-2.3266</lower>
            <upper>2.3914</upper>
            <effort>147</effort>
            <velocity>8.1</velocity>
          </limit>
          <dynamics>
            <spring_reference>0</spring_reference>
            <spring_stiffness>0</spring_stiffness>
          </dynamics>
          <use_parent_model_frame>1</use_parent_model_frame>
        </axis>
        <physics>
          <provide_feedback>1</provide_feedback>
          <ode>
            <provide_feedback>1</provide_feedback>
            <implicit_spring_damper>1</implicit_spring_damper>
            <cfm_damping>1</cfm_damping>
            <limit>
              <cfm>0</cfm>
              <erp>0.2</erp>
            </limit>
          </ode>
        </physics>
      </joint>
      <link name='ankle2_2'>
        <pose frame=''>0.25 -0.22155 -0.6191 -3.14159 0 0</pose>
        <inertial>
          <pose frame=''>0.000444 0.000439 0.193921 0 -0 0</pose>
          <mass>1.15659</mass>
          <inertia>
            <ixx>0.00490195</ixx>
            <ixy>4.3032e-06</ixy>
            <ixz>3.46491e-05</ixz>
            <iyy>0.00387242</iyy>
            <iyz>1.7099e-05</iyz>
            <izz>0.00217832</izz>
          </inertia>
        </inertial>
        <collision name='ankle2_2_collision'>
          <pose frame=''>0 0 0 0 -0 0</pose>
          <geometry>
            <mesh>
              <scale>0.001 0.001 0.001</scale>
              <uri>/home/ioannis/centauro_ws/src/iit-centauro-ros-pkg/centauro_urdf/meshes/simple/ankle-yaw.stl</uri>
            </mesh>
          </geometry>
          <surface>
            <contact>
              <ode/>
            </contact>
            <friction>
              <ode/>
              <torsional>
                <ode/>
              </torsional>
            </friction>
            <bounce/>
          </surface>
          <max_contacts>10</max_contacts>
        </collision>
        <visual name='ankle2_2_visual'>
          <pose frame=''>0 0 0 0 -0 0</pose>
          <geometry>
            <mesh>
              <scale>0.001 0.001 0.001</scale>
              <uri>/home/ioannis/centauro_ws/src/iit-centauro-ros-pkg/centauro_urdf/meshes/ankle-yaw.stl</uri>
            </mesh>
          </geometry>
          <material>
            <script>
              <name>Gazebo/LightBlueLaser</name>
              <uri>file://media/materials/scripts/gazebo.material</uri>
            </script>
          </material>
        </visual>
        <gravity>1</gravity>
        <velocity_decay/>
        <self_collide>0</self_collide>
        <enable_wind>0</enable_wind>
        <kinematic>0</kinematic>
      </link>
      <joint name='ankle_yaw_2' type='revolute'>
        <child>ankle2_2</child>
        <parent>ankle1_2</parent>
        <axis>
          <xyz>-0 0 -1</xyz>
          <limit>
            <lower>-2.5546</lower>
            <upper>2.5484</upper>
            <effort>35</effort>
            <velocity>20</velocity>
          </limit>
          <dynamics>
            <spring_reference>0</spring_reference>
            <spring_stiffness>0</spring_stiffness>
          </dynamics>
          <use_parent_model_frame>1</use_parent_model_frame>
        </axis>
        <physics>
          <provide_feedback>1</provide_feedback>
          <ode>
            <provide_feedback>1</provide_feedback>
            <implicit_spring_damper>1</implicit_spring_damper>
            <cfm_damping>1</cfm_damping>
            <limit>
              <cfm>0</cfm>
              <erp>0.2</erp>
            </limit>
          </ode>
        </physics>
      </joint>
      <link name='wheel_2'>
        <pose frame=''>0.25 -0.2224 -0.85645 -1.5708 -0 -3.14159</pose>
        <inertial>
          <pose frame=''>0 0 0.002427 0 -0 0</pose>
          <mass>1.7289</mass>
          <inertia>
            <ixx>0.00468643</ixx>
            <ixy>0</ixy>
            <ixz>0</ixz>
            <iyy>0.00467135</iyy>
            <iyz>0</iyz>
            <izz>0.0053126</izz>
          </inertia>
        </inertial>
        <collision name='wheel_2_collision'>
          <pose frame=''>0 0 0 0 -0 0</pose>
          <geometry>
            <cylinder>
              <length>0.06</length>
              <radius>0.078</radius>
            </cylinder>
          </geometry>
          <surface>
            <friction>
              <ode>
                <mu>0.5</mu>
                <mu2>0.5</mu2>
              </ode>
              <bullet>
                <friction>0.5</friction>
                <friction2>0.5</friction2>
              </bullet>
              <torsional>
                <ode/>
              </torsional>
            </friction>
            <contact>
              <ode>
                <kp>2.1e+06</kp>
                <kd>1</kd>
                <max_vel>100</max_vel>
              </ode>
              <bullet>
                <soft_cfm>0.007</soft_cfm>
                <soft_erp>0.25</soft_erp>
                <kp>1e+06</kp>
                <kd>5</kd>
                <split_impulse>1</split_impulse>
                <split_impulse_penetration_threshold>-0.01</split_impulse_penetration_threshold>
              </bullet>
            </contact>
            <bounce/>
          </surface>
          <max_contacts>10</max_contacts>
        </collision>
        <visual name='wheel_2_visual'>
          <pose frame=''>0 0 0 0 -0 0</pose>
          <geometry>
            <mesh>
              <scale>0.001 0.001 0.001</scale>
              <uri>/home/ioannis/centauro_ws/src/iit-centauro-ros-pkg/centauro_urdf/meshes/wheel.stl</uri>
            </mesh>
          </geometry>
          <material>
            <script>
              <name>Gazebo/BlackTransparent</name>
              <uri>file://media/materials/scripts/gazebo.material</uri>
            </script>
          </material>
        </visual>
        <velocity_decay/>
        <gravity>1</gravity>
        <velocity_decay/>
        <self_collide>0</self_collide>
        <enable_wind>0</enable_wind>
        <kinematic>0</kinematic>
      </link>
      <joint name='j_wheel_2' type='revolute'>
        <child>wheel_2</child>
        <parent>ankle2_2</parent>
        <axis>
          <xyz>0 -1 -0</xyz>
          <limit>
            <lower>-1e+16</lower>
            <upper>1e+16</upper>
          </limit>
          <dynamics>
            <spring_reference>0</spring_reference>
            <spring_stiffness>0</spring_stiffness>
          </dynamics>
          <use_parent_model_frame>1</use_parent_model_frame>
        </axis>
        <physics>
          <provide_feedback>1</provide_feedback>
          <ode>
            <provide_feedback>1</provide_feedback>
            <implicit_spring_damper>1</implicit_spring_damper>
            <cfm_damping>1</cfm_damping>
            <limit>
              <cfm>0</cfm>
              <erp>0.2</erp>
            </limit>
          </ode>
        </physics>
      </joint>
      <link name='hip1_3'>
        <pose frame=''>-0.25 0.125 -0.0566 -3.14159 -0 2.68018</pose>
        <inertial>
          <pose frame=''>0.010214 0.018348 0.038091 0 -0 0</pose>
          <mass>1.91944</mass>
          <inertia>
            <ixx>0.00474396</ixx>
            <ixy>-0.000574705</ixy>
            <ixz>-0.000378414</ixz>
            <iyy>0.00405519</iyy>
            <iyz>-0.000740751</iyz>
            <izz>0.00341462</izz>
          </inertia>
        </inertial>
        <collision name='hip1_3_collision'>
          <pose frame=''>0 0 0 0 -0 0</pose>
          <geometry>
            <mesh>
              <scale>0.001 0.001 0.001</scale>
              <uri>/home/ioannis/centauro_ws/src/iit-centauro-ros-pkg/centauro_urdf/meshes/simple/hip-yaw.stl</uri>
            </mesh>
          </geometry>
          <surface>
            <contact>
              <ode/>
            </contact>
            <friction>
              <ode/>
              <torsional>
                <ode/>
              </torsional>
            </friction>
            <bounce/>
          </surface>
          <max_contacts>10</max_contacts>
        </collision>
        <visual name='hip1_3_visual'>
          <pose frame=''>0 0 0 0 -0 0</pose>
          <geometry>
            <mesh>
              <scale>0.001 0.001 0.001</scale>
              <uri>/home/ioannis/centauro_ws/src/iit-centauro-ros-pkg/centauro_urdf/meshes/hip-yaw.stl</uri>
            </mesh>
          </geometry>
          <material>
            <script>
              <name>Gazebo/LightBlueLaser</name>
              <uri>file://media/materials/scripts/gazebo.material</uri>
            </script>
          </material>
        </visual>
        <gravity>1</gravity>
        <velocity_decay/>
        <self_collide>0</self_collide>
        <enable_wind>0</enable_wind>
        <kinematic>0</kinematic>
      </link>
      <joint name='hip_yaw_3' type='revolute'>
        <child>hip1_3</child>
        <parent>pelvis</parent>
        <axis>
          <xyz>-0 -0 -1</xyz>
          <limit>
            <lower>-2.51</lower>
            <upper>2.03</upper>
            <effort>304</effort>
            <velocity>8.8</velocity>
          </limit>
          <dynamics>
            <spring_reference>0</spring_reference>
            <spring_stiffness>0</spring_stiffness>
          </dynamics>
          <use_parent_model_frame>1</use_parent_model_frame>
        </axis>
        <physics>
          <provide_feedback>1</provide_feedback>
          <ode>
            <provide_feedback>1</provide_feedback>
            <implicit_spring_damper>1</implicit_spring_damper>
            <cfm_damping>1</cfm_damping>
            <limit>
              <cfm>0</cfm>
              <erp>0.2</erp>
            </limit>
          </ode>
        </physics>
      </joint>
      <link name='hip2_3'>
        <pose frame=''>-0.25 0.125 -0.1191 -1.5708 0 0</pose>
        <inertial>
          <pose frame=''>2.6e-05 0.181027 0.08567 0 -0 0</pose>
          <mass>2.72645</mass>
          <inertia>
            <ixx>0.0485187</ixx>
            <ixy>-4.11894e-05</ixy>
            <ixz>-1.68778e-05</ixz>
            <iyy>0.00424205</iyy>
            <iyz>0.00322432</iyz>
            <izz>0.0482558</izz>
          </inertia>
        </inertial>
        <collision name='hip2_3_collision'>
          <pose frame=''>0 0 0 0 -0 0</pose>
          <geometry>
            <mesh>
              <scale>0.001 0.001 0.001</scale>
              <uri>/home/ioannis/centauro_ws/src/iit-centauro-ros-pkg/centauro_urdf/meshes/simple/hip-pitch.stl</uri>
            </mesh>
          </geometry>
          <surface>
            <contact>
              <ode/>
            </contact>
            <friction>
              <ode/>
              <torsional>
                <ode/>
              </torsional>
            </friction>
            <bounce/>
          </surface>
          <max_contacts>10</max_contacts>
        </collision>
        <visual name='hip2_3_visual'>
          <pose frame=''>0 0 0 0 -0 0</pose>
          <geometry>
            <mesh>
              <scale>0.001 0.001 0.001</scale>
              <uri>/home/ioannis/centauro_ws/src/iit-centauro-ros-pkg/centauro_urdf/meshes/hip-pitch.stl</uri>
            </mesh>
          </geometry>
          <material>
            <script>
              <name>Gazebo/BlackTransparent</name>
              <uri>file://media/materials/scripts/gazebo.material</uri>
            </script>
          </material>
        </visual>
        <gravity>1</gravity>
        <velocity_decay/>
        <self_collide>0</self_collide>
        <enable_wind>0</enable_wind>
        <kinematic>0</kinematic>
      </link>
      <joint name='hip_pitch_3' type='revolute'>
        <child>hip2_3</child>
        <parent>hip1_3</parent>
        <axis>
          <xyz>-0 1 -0</xyz>
          <limit>
            <lower>-2.0126</lower>
            <upper>2.0384</upper>
            <effort>304</effort>
            <velocity>8.8</velocity>
          </limit>
          <dynamics>
            <spring_reference>0</spring_reference>
            <spring_stiffness>0</spring_stiffness>
          </dynamics>
          <use_parent_model_frame>1</use_parent_model_frame>
        </axis>
        <physics>
          <provide_feedback>1</provide_feedback>
          <ode>
            <provide_feedback>1</provide_feedback>
            <implicit_spring_damper>1</implicit_spring_damper>
            <cfm_damping>1</cfm_damping>
            <limit>
              <cfm>0</cfm>
              <erp>0.2</erp>
            </limit>
          </ode>
        </physics>
      </joint>
      <link name='knee_3'>
        <pose frame=''>-0.25 0.1214 -0.4191 -1.57079 1.57079 3.14159</pose>
        <inertial>
          <pose frame=''>0.108817 0.000109 -0.022639 0 -0 0</pose>
          <mass>1.93568</mass>
          <inertia>
            <ixx>0.00305342</ixx>
            <ixy>-4.22079e-05</ixy>
            <ixz>0.00136793</ixz>
            <iyy>0.0196033</iyy>
            <iyz>6.9941e-06</iyz>
            <izz>0.0198498</izz>
          </inertia>
        </inertial>
        <collision name='knee_3_collision'>
          <pose frame=''>0 0 0 0 -0 0</pose>
          <geometry>
            <mesh>
              <scale>0.001 0.001 0.001</scale>
              <uri>/home/ioannis/centauro_ws/src/iit-centauro-ros-pkg/centauro_urdf/meshes/simple/knee.stl</uri>
            </mesh>
          </geometry>
          <surface>
            <contact>
              <ode/>
            </contact>
            <friction>
              <ode/>
              <torsional>
                <ode/>
              </torsional>
            </friction>
            <bounce/>
          </surface>
          <max_contacts>10</max_contacts>
        </collision>
        <visual name='knee_3_visual'>
          <pose frame=''>0 0 0 0 -0 0</pose>
          <geometry>
            <mesh>
              <scale>0.001 0.001 0.001</scale>
              <uri>/home/ioannis/centauro_ws/src/iit-centauro-ros-pkg/centauro_urdf/meshes/knee.stl</uri>
            </mesh>
          </geometry>
          <material>
            <script>
              <name>Gazebo/LightBlueLaser</name>
              <uri>file://media/materials/scripts/gazebo.material</uri>
            </script>
          </material>
        </visual>
        <gravity>1</gravity>
        <velocity_decay/>
        <self_collide>0</self_collide>
        <enable_wind>0</enable_wind>
        <kinematic>0</kinematic>
      </link>
      <joint name='knee_pitch_3' type='revolute'>
        <child>knee_3</child>
        <parent>hip2_3</parent>
        <axis>
          <xyz>-0 -1 0</xyz>
          <limit>
            <lower>-2.4056</lower>
            <upper>2.4064</upper>
            <effort>304</effort>
            <velocity>8.8</velocity>
          </limit>
          <dynamics>
            <spring_reference>0</spring_reference>
            <spring_stiffness>0</spring_stiffness>
          </dynamics>
          <use_parent_model_frame>1</use_parent_model_frame>
        </axis>
        <physics>
          <provide_feedback>1</provide_feedback>
          <ode>
            <provide_feedback>1</provide_feedback>
            <implicit_spring_damper>1</implicit_spring_damper>
            <cfm_damping>1</cfm_damping>
            <limit>
              <cfm>0</cfm>
              <erp>0.2</erp>
            </limit>
          </ode>
        </physics>
      </joint>
      <link name='ankle1_3'>
        <pose frame=''>-0.25 0.22155 -0.6191 1.57079 1.57079 3.14159</pose>
        <inertial>
          <pose frame=''>0.032137 9.7e-05 -0.004422 0 -0 0</pose>
          <mass>1.23807</mass>
          <inertia>
            <ixx>0.00156105</ixx>
            <ixy>3.30597e-05</ixy>
            <ixz>-0.000131417</ixz>
            <iyy>0.00374232</iyy>
            <iyz>-2.12589e-05</iyz>
            <izz>0.00383124</izz>
          </inertia>
        </inertial>
        <collision name='ankle1_3_collision'>
          <pose frame=''>0 0 0 0 -0 0</pose>
          <geometry>
            <mesh>
              <scale>0.001 0.001 0.001</scale>
              <uri>/home/ioannis/centauro_ws/src/iit-centauro-ros-pkg/centauro_urdf/meshes/simple/ankle-pitch.stl</uri>
            </mesh>
          </geometry>
          <surface>
            <contact>
              <ode/>
            </contact>
            <friction>
              <ode/>
              <torsional>
                <ode/>
              </torsional>
            </friction>
            <bounce/>
          </surface>
          <max_contacts>10</max_contacts>
        </collision>
        <visual name='ankle1_3_visual'>
          <pose frame=''>0 0 0 0 -0 0</pose>
          <geometry>
            <mesh>
              <scale>0.001 0.001 0.001</scale>
              <uri>/home/ioannis/centauro_ws/src/iit-centauro-ros-pkg/centauro_urdf/meshes/ankle-pitch.stl</uri>
            </mesh>
          </geometry>
          <material>
            <script>
              <name>Gazebo/LightBlueLaser</name>
              <uri>file://media/materials/scripts/gazebo.material</uri>
            </script>
          </material>
        </visual>
        <gravity>1</gravity>
        <velocity_decay/>
        <self_collide>0</self_collide>
        <enable_wind>0</enable_wind>
        <kinematic>0</kinematic>
      </link>
      <joint name='ankle_pitch_3' type='revolute'>
        <child>ankle1_3</child>
        <parent>knee_3</parent>
        <axis>
          <xyz>0 1 -0</xyz>
          <limit>
            <lower>-2.4696</lower>
            <upper>2.4464</upper>
            <effort>147</effort>
            <velocity>8.1</velocity>
          </limit>
          <dynamics>
            <spring_reference>0</spring_reference>
            <spring_stiffness>0</spring_stiffness>
          </dynamics>
          <use_parent_model_frame>1</use_parent_model_frame>
        </axis>
        <physics>
          <provide_feedback>1</provide_feedback>
          <ode>
            <provide_feedback>1</provide_feedback>
            <implicit_spring_damper>1</implicit_spring_damper>
            <cfm_damping>1</cfm_damping>
            <limit>
              <cfm>0</cfm>
              <erp>0.2</erp>
            </limit>
          </ode>
        </physics>
      </joint>
      <link name='ankle2_3'>
        <pose frame=''>-0.25 0.22155 -0.6191 -3.14159 -0 3.14159</pose>
        <inertial>
          <pose frame=''>0.000444 0.000439 0.193921 0 -0 0</pose>
          <mass>1.15659</mass>
          <inertia>
            <ixx>0.00490195</ixx>
            <ixy>4.3032e-06</ixy>
            <ixz>3.46491e-05</ixz>
            <iyy>0.00387242</iyy>
            <iyz>1.7099e-05</iyz>
            <izz>0.00217832</izz>
          </inertia>
        </inertial>
        <collision name='ankle2_3_collision'>
          <pose frame=''>0 0 0 0 -0 0</pose>
          <geometry>
            <mesh>
              <scale>0.001 0.001 0.001</scale>
              <uri>/home/ioannis/centauro_ws/src/iit-centauro-ros-pkg/centauro_urdf/meshes/simple/ankle-yaw.stl</uri>
            </mesh>
          </geometry>
          <surface>
            <contact>
              <ode/>
            </contact>
            <friction>
              <ode/>
              <torsional>
                <ode/>
              </torsional>
            </friction>
            <bounce/>
          </surface>
          <max_contacts>10</max_contacts>
        </collision>
        <visual name='ankle2_3_visual'>
          <pose frame=''>0 0 0 0 -0 0</pose>
          <geometry>
            <mesh>
              <scale>0.001 0.001 0.001</scale>
              <uri>/home/ioannis/centauro_ws/src/iit-centauro-ros-pkg/centauro_urdf/meshes/ankle-yaw.stl</uri>
            </mesh>
          </geometry>
          <material>
            <script>
              <name>Gazebo/LightBlueLaser</name>
              <uri>file://media/materials/scripts/gazebo.material</uri>
            </script>
          </material>
        </visual>
        <gravity>1</gravity>
        <velocity_decay/>
        <self_collide>0</self_collide>
        <enable_wind>0</enable_wind>
        <kinematic>0</kinematic>
      </link>
      <joint name='ankle_yaw_3' type='revolute'>
        <child>ankle2_3</child>
        <parent>ankle1_3</parent>
        <axis>
          <xyz>0 -0 -1</xyz>
          <limit>
            <lower>-2.5606</lower>
            <upper>2.5454</upper>
            <effort>35</effort>
            <velocity>20</velocity>
          </limit>
          <dynamics>
            <spring_reference>0</spring_reference>
            <spring_stiffness>0</spring_stiffness>
          </dynamics>
          <use_parent_model_frame>1</use_parent_model_frame>
        </axis>
        <physics>
          <provide_feedback>1</provide_feedback>
          <ode>
            <provide_feedback>1</provide_feedback>
            <implicit_spring_damper>1</implicit_spring_damper>
            <cfm_damping>1</cfm_damping>
            <limit>
              <cfm>0</cfm>
              <erp>0.2</erp>
            </limit>
          </ode>
        </physics>
      </joint>
      <link name='wheel_3'>
        <pose frame=''>-0.25 0.2224 -0.85645 -1.5708 -0 -0</pose>
        <inertial>
          <pose frame=''>0 0 0.002427 0 -0 0</pose>
          <mass>1.7289</mass>
          <inertia>
            <ixx>0.00468643</ixx>
            <ixy>0</ixy>
            <ixz>0</ixz>
            <iyy>0.00467135</iyy>
            <iyz>0</iyz>
            <izz>0.0053126</izz>
          </inertia>
        </inertial>
        <collision name='wheel_3_collision'>
          <pose frame=''>0 0 0 0 -0 0</pose>
          <geometry>
            <cylinder>
              <length>0.06</length>
              <radius>0.078</radius>
            </cylinder>
          </geometry>
          <surface>
            <friction>
              <ode>
                <mu>0.5</mu>
                <mu2>0.5</mu2>
              </ode>
              <bullet>
                <friction>0.5</friction>
                <friction2>0.5</friction2>
              </bullet>
              <torsional>
                <ode/>
              </torsional>
            </friction>
            <contact>
              <ode>
                <kp>2.1e+06</kp>
                <kd>1</kd>
                <max_vel>100</max_vel>
              </ode>
              <bullet>
                <soft_cfm>0.007</soft_cfm>
                <soft_erp>0.25</soft_erp>
                <kp>1e+06</kp>
                <kd>5</kd>
                <split_impulse>1</split_impulse>
                <split_impulse_penetration_threshold>-0.01</split_impulse_penetration_threshold>
              </bullet>
            </contact>
            <bounce/>
          </surface>
          <max_contacts>10</max_contacts>
        </collision>
        <visual name='wheel_3_visual'>
          <pose frame=''>0 0 0 0 -0 0</pose>
          <geometry>
            <mesh>
              <scale>0.001 0.001 0.001</scale>
              <uri>/home/ioannis/centauro_ws/src/iit-centauro-ros-pkg/centauro_urdf/meshes/wheel.stl</uri>
            </mesh>
          </geometry>
          <material>
            <script>
              <name>Gazebo/BlackTransparent</name>
              <uri>file://media/materials/scripts/gazebo.material</uri>
            </script>
          </material>
        </visual>
        <velocity_decay/>
        <gravity>1</gravity>
        <velocity_decay/>
        <self_collide>0</self_collide>
        <enable_wind>0</enable_wind>
        <kinematic>0</kinematic>
      </link>
      <joint name='j_wheel_3' type='revolute'>
        <child>wheel_3</child>
        <parent>ankle2_3</parent>
        <axis>
          <xyz>0 1 -0</xyz>
          <limit>
            <lower>-1e+16</lower>
            <upper>1e+16</upper>
          </limit>
          <dynamics>
            <spring_reference>0</spring_reference>
            <spring_stiffness>0</spring_stiffness>
          </dynamics>
          <use_parent_model_frame>1</use_parent_model_frame>
        </axis>
        <physics>
          <provide_feedback>1</provide_feedback>
          <ode>
            <provide_feedback>1</provide_feedback>
            <implicit_spring_damper>1</implicit_spring_damper>
            <cfm_damping>1</cfm_damping>
            <limit>
              <cfm>0</cfm>
              <erp>0.2</erp>
            </limit>
          </ode>
        </physics>
      </joint>
      <link name='hip1_4'>
        <pose frame=''>-0.25 -0.125 -0.0566 -3.14159 -0 -2.68018</pose>
        <inertial>
          <pose frame=''>0.010214 -0.018348 0.038091 0 -0 0</pose>
          <mass>1.91944</mass>
          <inertia>
            <ixx>0.00474396</ixx>
            <ixy>0.000574705</ixy>
            <ixz>-0.000378414</ixz>
            <iyy>0.00405519</iyy>
            <iyz>0.000740751</iyz>
            <izz>0.00341462</izz>
          </inertia>
        </inertial>
        <collision name='hip1_4_collision'>
          <pose frame=''>0 0 0 0 -0 -2.21876</pose>
          <geometry>
            <mesh>
              <scale>0.001 0.001 0.001</scale>
              <uri>/home/ioannis/centauro_ws/src/iit-centauro-ros-pkg/centauro_urdf/meshes/simple/hip-yaw.stl</uri>
            </mesh>
          </geometry>
          <surface>
            <contact>
              <ode/>
            </contact>
            <friction>
              <ode/>
              <torsional>
                <ode/>
              </torsional>
            </friction>
            <bounce/>
          </surface>
          <max_contacts>10</max_contacts>
        </collision>
        <visual name='hip1_4_visual'>
          <pose frame=''>0 0 0 0 -0 -2.21876</pose>
          <geometry>
            <mesh>
              <scale>0.001 0.001 0.001</scale>
              <uri>/home/ioannis/centauro_ws/src/iit-centauro-ros-pkg/centauro_urdf/meshes/hip-yaw.stl</uri>
            </mesh>
          </geometry>
          <material>
            <script>
              <name>Gazebo/LightBlueLaser</name>
              <uri>file://media/materials/scripts/gazebo.material</uri>
            </script>
          </material>
        </visual>
        <gravity>1</gravity>
        <velocity_decay/>
        <self_collide>0</self_collide>
        <enable_wind>0</enable_wind>
        <kinematic>0</kinematic>
      </link>
      <joint name='hip_yaw_4' type='revolute'>
        <child>hip1_4</child>
        <parent>pelvis</parent>
        <axis>
          <xyz>0 -0 -1</xyz>
          <limit>
            <lower>-2.03</lower>
            <upper>2.51</upper>
            <effort>304</effort>
            <velocity>8.8</velocity>
          </limit>
          <dynamics>
            <spring_reference>0</spring_reference>
            <spring_stiffness>0</spring_stiffness>
          </dynamics>
          <use_parent_model_frame>1</use_parent_model_frame>
        </axis>
        <physics>
          <provide_feedback>1</provide_feedback>
          <ode>
            <provide_feedback>1</provide_feedback>
            <implicit_spring_damper>1</implicit_spring_damper>
            <cfm_damping>1</cfm_damping>
            <limit>
              <cfm>0</cfm>
              <erp>0.2</erp>
            </limit>
          </ode>
        </physics>
      </joint>
      <link name='hip2_4'>
        <pose frame=''>-0.25 -0.125 -0.1191 -1.5708 -0 -3.14159</pose>
        <inertial>
          <pose frame=''>2.6e-05 0.181027 0.08567 0 -0 0</pose>
          <mass>2.72645</mass>
          <inertia>
            <ixx>0.0485187</ixx>
            <ixy>-4.11894e-05</ixy>
            <ixz>-1.68778e-05</ixz>
            <iyy>0.00424205</iyy>
            <iyz>0.00322432</iyz>
            <izz>0.0482558</izz>
          </inertia>
        </inertial>
        <collision name='hip2_4_collision'>
          <pose frame=''>0 0 0 0 -0 0</pose>
          <geometry>
            <mesh>
              <scale>0.001 0.001 0.001</scale>
              <uri>/home/ioannis/centauro_ws/src/iit-centauro-ros-pkg/centauro_urdf/meshes/simple/hip-pitch.stl</uri>
            </mesh>
          </geometry>
          <surface>
            <contact>
              <ode/>
            </contact>
            <friction>
              <ode/>
              <torsional>
                <ode/>
              </torsional>
            </friction>
            <bounce/>
          </surface>
          <max_contacts>10</max_contacts>
        </collision>
        <visual name='hip2_4_visual'>
          <pose frame=''>0 0 0 0 -0 0</pose>
          <geometry>
            <mesh>
              <scale>0.001 0.001 0.001</scale>
              <uri>/home/ioannis/centauro_ws/src/iit-centauro-ros-pkg/centauro_urdf/meshes/hip-pitch.stl</uri>
            </mesh>
          </geometry>
          <material>
            <script>
              <name>Gazebo/BlackTransparent</name>
              <uri>file://media/materials/scripts/gazebo.material</uri>
            </script>
          </material>
        </visual>
        <gravity>1</gravity>
        <velocity_decay/>
        <self_collide>0</self_collide>
        <enable_wind>0</enable_wind>
        <kinematic>0</kinematic>
      </link>
      <joint name='hip_pitch_4' type='revolute'>
        <child>hip2_4</child>
        <parent>hip1_4</parent>
        <axis>
          <xyz>0 -1 -0</xyz>
          <limit>
            <lower>-2.0326</lower>
            <upper>2.0524</upper>
            <effort>304</effort>
            <velocity>8.8</velocity>
          </limit>
          <dynamics>
            <spring_reference>0</spring_reference>
            <spring_stiffness>0</spring_stiffness>
          </dynamics>
          <use_parent_model_frame>1</use_parent_model_frame>
        </axis>
        <physics>
          <provide_feedback>1</provide_feedback>
          <ode>
            <provide_feedback>1</provide_feedback>
            <implicit_spring_damper>1</implicit_spring_damper>
            <cfm_damping>1</cfm_damping>
            <limit>
              <cfm>0</cfm>
              <erp>0.2</erp>
            </limit>
          </ode>
        </physics>
      </joint>
      <link name='knee_4'>
        <pose frame=''>-0.25 -0.1214 -0.4191 1.57079 1.57079 3.14159</pose>
        <inertial>
          <pose frame=''>0.108817 0.000109 -0.022639 0 -0 0</pose>
          <mass>1.93568</mass>
          <inertia>
            <ixx>0.00305342</ixx>
            <ixy>-4.22079e-05</ixy>
            <ixz>0.00136793</ixz>
            <iyy>0.0196033</iyy>
            <iyz>6.9941e-06</iyz>
            <izz>0.0198498</izz>
          </inertia>
        </inertial>
        <collision name='knee_4_collision'>
          <pose frame=''>0 0 0 0 -0 0</pose>
          <geometry>
            <mesh>
              <scale>0.001 0.001 0.001</scale>
              <uri>/home/ioannis/centauro_ws/src/iit-centauro-ros-pkg/centauro_urdf/meshes/simple/knee.stl</uri>
            </mesh>
          </geometry>
          <surface>
            <contact>
              <ode/>
            </contact>
            <friction>
              <ode/>
              <torsional>
                <ode/>
              </torsional>
            </friction>
            <bounce/>
          </surface>
          <max_contacts>10</max_contacts>
        </collision>
        <visual name='knee_4_visual'>
          <pose frame=''>0 0 0 0 -0 0</pose>
          <geometry>
            <mesh>
              <scale>0.001 0.001 0.001</scale>
              <uri>/home/ioannis/centauro_ws/src/iit-centauro-ros-pkg/centauro_urdf/meshes/knee.stl</uri>
            </mesh>
          </geometry>
          <material>
            <script>
              <name>Gazebo/LightBlueLaser</name>
              <uri>file://media/materials/scripts/gazebo.material</uri>
            </script>
          </material>
        </visual>
        <gravity>1</gravity>
        <velocity_decay/>
        <self_collide>0</self_collide>
        <enable_wind>0</enable_wind>
        <kinematic>0</kinematic>
      </link>
      <joint name='knee_pitch_4' type='revolute'>
        <child>knee_4</child>
        <parent>hip2_4</parent>
        <axis>
          <xyz>0 1 0</xyz>
          <limit>
            <lower>-2.4176</lower>
            <upper>2.3884</upper>
            <effort>304</effort>
            <velocity>8.8</velocity>
          </limit>
          <dynamics>
            <spring_reference>0</spring_reference>
            <spring_stiffness>0</spring_stiffness>
          </dynamics>
          <use_parent_model_frame>1</use_parent_model_frame>
        </axis>
        <physics>
          <provide_feedback>1</provide_feedback>
          <ode>
            <provide_feedback>1</provide_feedback>
            <implicit_spring_damper>1</implicit_spring_damper>
            <cfm_damping>1</cfm_damping>
            <limit>
              <cfm>0</cfm>
              <erp>0.2</erp>
            </limit>
          </ode>
        </physics>
      </joint>
      <link name='ankle1_4'>
        <pose frame=''>-0.25 -0.22155 -0.6191 -1.57079 1.57079 3.14159</pose>
        <inertial>
          <pose frame=''>0.032137 9.7e-05 -0.004422 0 -0 0</pose>
          <mass>1.23807</mass>
          <inertia>
            <ixx>0.00156105</ixx>
            <ixy>3.30597e-05</ixy>
            <ixz>-0.000131417</ixz>
            <iyy>0.00374232</iyy>
            <iyz>-2.12589e-05</iyz>
            <izz>0.00383124</izz>
          </inertia>
        </inertial>
        <collision name='ankle1_4_collision'>
          <pose frame=''>0 0 0 0 -0 0</pose>
          <geometry>
            <mesh>
              <scale>0.001 0.001 0.001</scale>
              <uri>/home/ioannis/centauro_ws/src/iit-centauro-ros-pkg/centauro_urdf/meshes/simple/ankle-pitch.stl</uri>
            </mesh>
          </geometry>
          <surface>
            <contact>
              <ode/>
            </contact>
            <friction>
              <ode/>
              <torsional>
                <ode/>
              </torsional>
            </friction>
            <bounce/>
          </surface>
          <max_contacts>10</max_contacts>
        </collision>
        <visual name='ankle1_4_visual'>
          <pose frame=''>0 0 0 0 -0 0</pose>
          <geometry>
            <mesh>
              <scale>0.001 0.001 0.001</scale>
              <uri>/home/ioannis/centauro_ws/src/iit-centauro-ros-pkg/centauro_urdf/meshes/ankle-pitch.stl</uri>
            </mesh>
          </geometry>
          <material>
            <script>
              <name>Gazebo/LightBlueLaser</name>
              <uri>file://media/materials/scripts/gazebo.material</uri>
            </script>
          </material>
        </visual>
        <gravity>1</gravity>
        <velocity_decay/>
        <self_collide>0</self_collide>
        <enable_wind>0</enable_wind>
        <kinematic>0</kinematic>
      </link>
      <joint name='ankle_pitch_4' type='revolute'>
        <child>ankle1_4</child>
        <parent>knee_4</parent>
        <axis>
          <xyz>-0 -1 -0</xyz>
          <limit>
            <lower>-2.3426</lower>
            <upper>2.3934</upper>
            <effort>147</effort>
            <velocity>8.1</velocity>
          </limit>
          <dynamics>
            <spring_reference>0</spring_reference>
            <spring_stiffness>0</spring_stiffness>
          </dynamics>
          <use_parent_model_frame>1</use_parent_model_frame>
        </axis>
        <physics>
          <provide_feedback>1</provide_feedback>
          <ode>
            <provide_feedback>1</provide_feedback>
            <implicit_spring_damper>1</implicit_spring_damper>
            <cfm_damping>1</cfm_damping>
            <limit>
              <cfm>0</cfm>
              <erp>0.2</erp>
            </limit>
          </ode>
        </physics>
      </joint>
      <link name='ankle2_4'>
        <pose frame=''>-0.25 -0.22155 -0.6191 3.14159 -0 0</pose>
        <inertial>
          <pose frame=''>0.000444 0.000439 0.193921 0 -0 0</pose>
          <mass>1.15659</mass>
          <inertia>
            <ixx>0.00490195</ixx>
            <ixy>4.3032e-06</ixy>
            <ixz>3.46491e-05</ixz>
            <iyy>0.00387242</iyy>
            <iyz>1.7099e-05</iyz>
            <izz>0.00217832</izz>
          </inertia>
        </inertial>
        <collision name='ankle2_4_collision'>
          <pose frame=''>0 0 0 0 -0 0</pose>
          <geometry>
            <mesh>
              <scale>0.001 0.001 0.001</scale>
              <uri>/home/ioannis/centauro_ws/src/iit-centauro-ros-pkg/centauro_urdf/meshes/simple/ankle-yaw.stl</uri>
            </mesh>
          </geometry>
          <surface>
            <contact>
              <ode/>
            </contact>
            <friction>
              <ode/>
              <torsional>
                <ode/>
              </torsional>
            </friction>
            <bounce/>
          </surface>
          <max_contacts>10</max_contacts>
        </collision>
        <visual name='ankle2_4_visual'>
          <pose frame=''>0 0 0 0 -0 0</pose>
          <geometry>
            <mesh>
              <scale>0.001 0.001 0.001</scale>
              <uri>/home/ioannis/centauro_ws/src/iit-centauro-ros-pkg/centauro_urdf/meshes/ankle-yaw.stl</uri>
            </mesh>
          </geometry>
          <material>
            <script>
              <name>Gazebo/LightBlueLaser</name>
              <uri>file://media/materials/scripts/gazebo.material</uri>
            </script>
          </material>
        </visual>
        <gravity>1</gravity>
        <velocity_decay/>
        <self_collide>0</self_collide>
        <enable_wind>0</enable_wind>
        <kinematic>0</kinematic>
      </link>
      <joint name='ankle_yaw_4' type='revolute'>
        <child>ankle2_4</child>
        <parent>ankle1_4</parent>
        <axis>
          <xyz>-0 -0 -1</xyz>
          <limit>
            <lower>-2.6046</lower>
            <upper>2.5514</upper>
            <effort>35</effort>
            <velocity>20</velocity>
          </limit>
          <dynamics>
            <spring_reference>0</spring_reference>
            <spring_stiffness>0</spring_stiffness>
          </dynamics>
          <use_parent_model_frame>1</use_parent_model_frame>
        </axis>
        <physics>
          <provide_feedback>1</provide_feedback>
          <ode>
            <provide_feedback>1</provide_feedback>
            <implicit_spring_damper>1</implicit_spring_damper>
            <cfm_damping>1</cfm_damping>
            <limit>
              <cfm>0</cfm>
              <erp>0.2</erp>
            </limit>
          </ode>
        </physics>
      </joint>
      <link name='wheel_4'>
        <pose frame=''>-0.25 -0.2224 -0.85645 -1.5708 -0 3.14159</pose>
        <inertial>
          <pose frame=''>0 0 0.002427 0 -0 0</pose>
          <mass>1.7289</mass>
          <inertia>
            <ixx>0.00468643</ixx>
            <ixy>0</ixy>
            <ixz>0</ixz>
            <iyy>0.00467135</iyy>
            <iyz>0</iyz>
            <izz>0.0053126</izz>
          </inertia>
        </inertial>
        <collision name='wheel_4_collision'>
          <pose frame=''>0 0 0 0 -0 0</pose>
          <geometry>
            <cylinder>
              <length>0.06</length>
              <radius>0.078</radius>
            </cylinder>
          </geometry>
          <surface>
            <friction>
              <ode>
                <mu>0.5</mu>
                <mu2>0.5</mu2>
              </ode>
              <bullet>
                <friction>0.5</friction>
                <friction2>0.5</friction2>
              </bullet>
              <torsional>
                <ode/>
              </torsional>
            </friction>
            <contact>
              <ode>
                <kp>2.1e+06</kp>
                <kd>1</kd>
                <max_vel>100</max_vel>
              </ode>
              <bullet>
                <soft_cfm>0.007</soft_cfm>
                <soft_erp>0.25</soft_erp>
                <kp>1e+06</kp>
                <kd>5</kd>
                <split_impulse>1</split_impulse>
                <split_impulse_penetration_threshold>-0.01</split_impulse_penetration_threshold>
              </bullet>
            </contact>
            <bounce/>
          </surface>
          <max_contacts>10</max_contacts>
        </collision>
        <visual name='wheel_4_visual'>
          <pose frame=''>0 0 0 0 -0 0</pose>
          <geometry>
            <mesh>
              <scale>0.001 0.001 0.001</scale>
              <uri>/home/ioannis/centauro_ws/src/iit-centauro-ros-pkg/centauro_urdf/meshes/wheel.stl</uri>
            </mesh>
          </geometry>
          <material>
            <script>
              <name>Gazebo/BlackTransparent</name>
              <uri>file://media/materials/scripts/gazebo.material</uri>
            </script>
          </material>
        </visual>
        <velocity_decay/>
        <gravity>1</gravity>
        <velocity_decay/>
        <self_collide>0</self_collide>
        <enable_wind>0</enable_wind>
        <kinematic>0</kinematic>
      </link>
      <joint name='j_wheel_4' type='revolute'>
        <child>wheel_4</child>
        <parent>ankle2_4</parent>
        <axis>
          <xyz>-0 -1 -0</xyz>
          <limit>
            <lower>-1e+16</lower>
            <upper>1e+16</upper>
          </limit>
          <dynamics>
            <spring_reference>0</spring_reference>
            <spring_stiffness>0</spring_stiffness>
          </dynamics>
          <use_parent_model_frame>1</use_parent_model_frame>
        </axis>
        <physics>
          <provide_feedback>1</provide_feedback>
          <ode>
            <provide_feedback>1</provide_feedback>
            <implicit_spring_damper>1</implicit_spring_damper>
            <cfm_damping>1</cfm_damping>
            <limit>
              <cfm>0</cfm>
              <erp>0.2</erp>
            </limit>
          </ode>
        </physics>
      </joint>
      <link name='torso_2'>
        <pose frame=''>0.2 0 0.256 0 -0 0</pose>
        <inertial>
          <pose frame=''>-0.019498 0.004532 0.137683 0 -0 0</pose>
          <mass>11.4927</mass>
          <inertia>
            <ixx>0.0636434</ixx>
            <ixy>8.939e-05</ixy>
            <ixz>-0.00086873</ixz>
            <iyy>0.0268023</iyy>
            <iyz>-4.657e-05</iyz>
            <izz>0.0474301</izz>
          </inertia>
        </inertial>
        <collision name='torso_2_collision'>
          <pose frame=''>0 0 0 0 -0 0</pose>
          <geometry>
            <mesh>
              <scale>0.001 0.001 0.001</scale>
              <uri>/home/ioannis/centauro_ws/src/iit-centauro-ros-pkg/centauro_urdf/meshes/simple/link1.stl</uri>
            </mesh>
          </geometry>
          <surface>
            <contact>
              <ode/>
            </contact>
            <friction>
              <ode/>
              <torsional>
                <ode/>
              </torsional>
            </friction>
            <bounce/>
          </surface>
          <max_contacts>10</max_contacts>
        </collision>
        <visual name='torso_2_visual'>
          <pose frame=''>0 0 0 0 -0 0</pose>
          <geometry>
            <mesh>
              <scale>0.001 0.001 0.001</scale>
              <uri>/home/ioannis/centauro_ws/src/iit-centauro-ros-pkg/centauro_urdf/meshes/link1.stl</uri>
            </mesh>
          </geometry>
          <material>
            <script>
              <name>Gazebo/BlackTransparent</name>
              <uri>file://media/materials/scripts/gazebo.material</uri>
            </script>
          </material>
        </visual>
        <gravity>1</gravity>
        <velocity_decay/>
        <self_collide>0</self_collide>
        <enable_wind>0</enable_wind>
        <kinematic>0</kinematic>
      </link>
      <joint name='torso_yaw' type='revolute'>
        <child>torso_2</child>
        <parent>pelvis</parent>
        <axis>
          <xyz>0 0 1</xyz>
          <limit>
            <lower>-2.618</lower>
            <upper>2.618</upper>
            <effort>147</effort>
            <velocity>5.7</velocity>
          </limit>
          <dynamics>
            <spring_reference>0</spring_reference>
            <spring_stiffness>0</spring_stiffness>
          </dynamics>
          <use_parent_model_frame>1</use_parent_model_frame>
        </axis>
        <physics>
          <provide_feedback>1</provide_feedback>
          <ode>
            <provide_feedback>1</provide_feedback>
            <implicit_spring_damper>1</implicit_spring_damper>
            <cfm_damping>1</cfm_damping>
            <limit>
              <cfm>0</cfm>
              <erp>0.2</erp>
            </limit>
          </ode>
        </physics>
      </joint>
      <link name='arm1_1'>
        <pose frame=''>0.245748 0.169137 0.372626 0.174533 -0 -0.523599</pose>
        <inertial>
          <pose frame=''>-0.007446 0.034108 0.00011 0 -0 0</pose>
          <mass>1.96287</mass>
          <inertia>
            <ixx>0.00535477</ixx>
            <ixy>0.000364289</ixy>
            <ixz>1.50896e-05</ixz>
            <iyy>0.00339233</iyy>
            <iyz>5.56923e-05</iyz>
            <izz>0.00689214</izz>
          </inertia>
        </inertial>
        <collision name='arm1_1_collision'>
          <pose frame=''>0 0 0 0 -0 0</pose>
          <geometry>
            <mesh>
              <scale>0.001 -0.001 0.001</scale>
              <uri>/home/ioannis/centauro_ws/src/iit-centauro-ros-pkg/centauro_urdf/meshes/simple/ShoulderPitch.STL</uri>
            </mesh>
          </geometry>
          <surface>
            <contact>
              <ode/>
            </contact>
            <friction>
              <ode/>
              <torsional>
                <ode/>
              </torsional>
            </friction>
            <bounce/>
          </surface>
          <max_contacts>10</max_contacts>
        </collision>
        <visual name='arm1_1_visual'>
          <pose frame=''>0 0 0 0 -0 0</pose>
          <geometry>
            <mesh>
              <scale>0.001 -0.001 0.001</scale>
              <uri>/home/ioannis/centauro_ws/src/iit-centauro-ros-pkg/centauro_urdf/meshes/ShoulderPitch.STL</uri>
            </mesh>
          </geometry>
          <material>
            <script>
              <name>Gazebo/BlackTransparent</name>
              <uri>file://media/materials/scripts/gazebo.material</uri>
            </script>
          </material>
        </visual>
        <gravity>1</gravity>
        <velocity_decay/>
        <self_collide>0</self_collide>
        <enable_wind>0</enable_wind>
        <kinematic>0</kinematic>
      </link>
      <joint name='j_arm1_1' type='revolute'>
        <child>arm1_1</child>
        <parent>torso_2</parent>
        <axis>
          <xyz>0.492404 0.852869 0.173648</xyz>
          <limit>
            <lower>-3.312</lower>
            <upper>1.615</upper>
            <effort>147</effort>
            <velocity>3.86</velocity>
          </limit>
          <dynamics>
            <spring_reference>0</spring_reference>
            <spring_stiffness>0</spring_stiffness>
          </dynamics>
          <use_parent_model_frame>1</use_parent_model_frame>
        </axis>
        <physics>
          <provide_feedback>1</provide_feedback>
          <ode>
            <provide_feedback>1</provide_feedback>
            <implicit_spring_damper>1</implicit_spring_damper>
            <cfm_damping>1</cfm_damping>
            <limit>
              <cfm>0</cfm>
              <erp>0.2</erp>
            </limit>
          </ode>
        </physics>
      </joint>
      <link name='arm1_2'>
        <pose frame=''>0.198204 0.26709 0.383392 0 0 -0.523599</pose>
        <inertial>
          <pose frame=''>0.058142 5.7e-05 -0.077478 0 -0 0</pose>
          <mass>1.85958</mass>
          <inertia>
            <ixx>0.0137766</ixx>
            <ixy>3.77887e-05</ixy>
            <ixz>0.00376902</ixz>
            <iyy>0.0156775</iyy>
            <iyz>-9.48935e-06</iyz>
            <izz>0.00463177</izz>
          </inertia>
        </inertial>
        <collision name='arm1_2_collision'>
          <pose frame=''>0 0 0 0 -0 0</pose>
          <geometry>
            <mesh>
              <scale>0.001 -0.001 0.001</scale>
              <uri>/home/ioannis/centauro_ws/src/iit-centauro-ros-pkg/centauro_urdf/meshes/simple/ShoulderRoll.STL</uri>
            </mesh>
          </geometry>
          <surface>
            <contact>
              <ode/>
            </contact>
            <friction>
              <ode/>
              <torsional>
                <ode/>
              </torsional>
            </friction>
            <bounce/>
          </surface>
          <max_contacts>10</max_contacts>
        </collision>
        <visual name='arm1_2_visual'>
          <pose frame=''>0 0 0 0 -0 0</pose>
          <geometry>
            <mesh>
              <scale>0.001 -0.001 0.001</scale>
              <uri>/home/ioannis/centauro_ws/src/iit-centauro-ros-pkg/centauro_urdf/meshes/ShoulderRoll.STL</uri>
            </mesh>
          </geometry>
          <material>
            <script>
              <name>Gazebo/LightBlueLaser</name>
              <uri>file://media/materials/scripts/gazebo.material</uri>
            </script>
          </material>
        </visual>
        <gravity>1</gravity>
        <velocity_decay/>
        <self_collide>0</self_collide>
        <enable_wind>0</enable_wind>
        <kinematic>0</kinematic>
      </link>
      <joint name='j_arm1_2' type='revolute'>
        <child>arm1_2</child>
        <parent>arm1_1</parent>
        <axis>
          <xyz>0.866025 -0.5 -0</xyz>
          <limit>
            <lower>0.02</lower>
            <upper>3.431</upper>
            <effort>147</effort>
            <velocity>3.86</velocity>
          </limit>
          <dynamics>
            <spring_reference>0</spring_reference>
            <spring_stiffness>0</spring_stiffness>
          </dynamics>
          <use_parent_model_frame>1</use_parent_model_frame>
        </axis>
        <physics>
          <provide_feedback>1</provide_feedback>
          <ode>
            <provide_feedback>1</provide_feedback>
            <implicit_spring_damper>1</implicit_spring_damper>
            <cfm_damping>1</cfm_damping>
            <limit>
              <cfm>0</cfm>
              <erp>0.2</erp>
            </limit>
          </ode>
        </physics>
      </joint>
      <link name='arm1_3'>
        <pose frame=''>0.276277 0.222015 0.165242 0 0 -0.523599</pose>
        <inertial>
          <pose frame=''>0.014625 0.000817 -0.028334 0 -0 0</pose>
          <mass>1.66781</mass>
          <inertia>
            <ixx>0.00644804</ixx>
            <ixy>-0.000156391</ixy>
            <ixz>0.00122054</ixz>
            <iyy>0.00733721</iyy>
            <iyz>8.99415e-05</iyz>
            <izz>0.00367384</izz>
          </inertia>
        </inertial>
        <collision name='arm1_3_collision'>
          <pose frame=''>0 0 0 0 -0 0</pose>
          <geometry>
            <mesh>
              <scale>0.001 -0.001 0.001</scale>
              <uri>/home/ioannis/centauro_ws/src/iit-centauro-ros-pkg/centauro_urdf/meshes/simple/ShoulderYaw.STL</uri>
            </mesh>
          </geometry>
          <surface>
            <contact>
              <ode/>
            </contact>
            <friction>
              <ode/>
              <torsional>
                <ode/>
              </torsional>
            </friction>
            <bounce/>
          </surface>
          <max_contacts>10</max_contacts>
        </collision>
        <visual name='arm1_3_visual'>
          <pose frame=''>0 0 0 0 -0 0</pose>
          <geometry>
            <mesh>
              <scale>0.001 -0.001 0.001</scale>
              <uri>/home/ioannis/centauro_ws/src/iit-centauro-ros-pkg/centauro_urdf/meshes/ShoulderYaw.STL</uri>
            </mesh>
          </geometry>
          <material>
            <script>
              <name>Gazebo/LightBlueLaser</name>
              <uri>file://media/materials/scripts/gazebo.material</uri>
            </script>
          </material>
        </visual>
        <gravity>1</gravity>
        <velocity_decay/>
        <self_collide>0</self_collide>
        <enable_wind>0</enable_wind>
        <kinematic>0</kinematic>
      </link>
      <joint name='j_arm1_3' type='revolute'>
        <child>arm1_3</child>
        <parent>arm1_2</parent>
        <axis>
          <xyz>-0 -0 1</xyz>
          <limit>
            <lower>-2.552</lower>
            <upper>2.566</upper>
            <effort>147</effort>
            <velocity>6.06</velocity>
          </limit>
          <dynamics>
            <spring_reference>0</spring_reference>
            <spring_stiffness>0</spring_stiffness>
          </dynamics>
          <use_parent_model_frame>1</use_parent_model_frame>
        </axis>
        <physics>
          <provide_feedback>1</provide_feedback>
          <ode>
            <provide_feedback>1</provide_feedback>
            <implicit_spring_damper>1</implicit_spring_damper>
            <cfm_damping>1</cfm_damping>
            <limit>
              <cfm>0</cfm>
              <erp>0.2</erp>
            </limit>
          </ode>
        </physics>
      </joint>
      <link name='arm1_4'>
        <pose frame=''>0.342823 0.247276 0.091242 0 0 -0.523599</pose>
        <inertial>
          <pose frame=''>-0.007683 -0.040302 -0.043493 0 -0 0</pose>
          <mass>1.31573</mass>
          <inertia>
            <ixx>0.00433039</ixx>
            <ixy>-0.000117374</ixy>
            <ixz>-0.000419232</ixz>
            <iyy>0.00385399</iyy>
            <iyz>-0.00079573</iyz>
            <izz>0.00175947</izz>
          </inertia>
        </inertial>
        <collision name='arm1_4_collision'>
          <pose frame=''>0 0 0 0 -0 0</pose>
          <geometry>
            <mesh>
              <scale>0.001 -0.001 0.001</scale>
              <uri>/home/ioannis/centauro_ws/src/iit-centauro-ros-pkg/centauro_urdf/meshes/simple/Elbow.STL</uri>
            </mesh>
          </geometry>
          <surface>
            <contact>
              <ode/>
            </contact>
            <friction>
              <ode/>
              <torsional>
                <ode/>
              </torsional>
            </friction>
            <bounce/>
          </surface>
          <max_contacts>10</max_contacts>
        </collision>
        <visual name='arm1_4_visual'>
          <pose frame=''>0 0 0 0 -0 0</pose>
          <geometry>
            <mesh>
              <scale>0.001 -0.001 0.001</scale>
              <uri>/home/ioannis/centauro_ws/src/iit-centauro-ros-pkg/centauro_urdf/meshes/Elbow.STL</uri>
            </mesh>
          </geometry>
          <material>
            <script>
              <name>Gazebo/LightBlueLaser</name>
              <uri>file://media/materials/scripts/gazebo.material</uri>
            </script>
          </material>
        </visual>
        <gravity>1</gravity>
        <velocity_decay/>
        <self_collide>0</self_collide>
        <enable_wind>0</enable_wind>
        <kinematic>0</kinematic>
      </link>
      <joint name='j_arm1_4' type='revolute'>
        <child>arm1_4</child>
        <parent>arm1_3</parent>
        <axis>
          <xyz>0.5 0.866025 0</xyz>
          <limit>
            <lower>-2.465</lower>
            <upper>0.28</upper>
            <effort>147</effort>
            <velocity>6.06</velocity>
          </limit>
          <dynamics>
            <spring_reference>0</spring_reference>
            <spring_stiffness>0</spring_stiffness>
          </dynamics>
          <use_parent_model_frame>1</use_parent_model_frame>
        </axis>
        <physics>
          <provide_feedback>1</provide_feedback>
          <ode>
            <provide_feedback>1</provide_feedback>
            <implicit_spring_damper>1</implicit_spring_damper>
            <cfm_damping>1</cfm_damping>
            <limit>
              <cfm>0</cfm>
              <erp>0.2</erp>
            </limit>
          </ode>
        </physics>
      </joint>
      <link name='arm1_5'>
        <pose frame=''>0.302257 0.207015 -0.003758 0 0 -0.523599</pose>
        <inertial>
          <pose frame=''>-0.000111 0.011591 -0.07816 0 -0 0</pose>
          <mass>1.49085</mass>
          <inertia>
            <ixx>0.00856921</ixx>
            <ixy>1.78563e-05</ixy>
            <ixz>1.93794e-05</ixz>
            <iyy>0.00774542</iyy>
            <iyz>-0.000328601</iyz>
            <izz>0.00274419</izz>
          </inertia>
        </inertial>
        <collision name='arm1_5_collision'>
          <pose frame=''>0 0 0 0 -0 0</pose>
          <geometry>
            <mesh>
              <scale>0.001 -0.001 0.001</scale>
              <uri>/home/ioannis/centauro_ws/src/iit-centauro-ros-pkg/centauro_urdf/meshes/simple/Forearm.STL</uri>
            </mesh>
          </geometry>
          <surface>
            <contact>
              <ode/>
            </contact>
            <friction>
              <ode/>
              <torsional>
                <ode/>
              </torsional>
            </friction>
            <bounce/>
          </surface>
          <max_contacts>10</max_contacts>
        </collision>
        <visual name='arm1_5_visual'>
          <pose frame=''>0 0 0 0 -0 0</pose>
          <geometry>
            <mesh>
              <scale>0.001 -0.001 0.001</scale>
              <uri>/home/ioannis/centauro_ws/src/iit-centauro-ros-pkg/centauro_urdf/meshes/Forearm.STL</uri>
            </mesh>
          </geometry>
          <material>
            <script>
              <name>Gazebo/BlackTransparent</name>
              <uri>file://media/materials/scripts/gazebo.material</uri>
            </script>
          </material>
        </visual>
        <gravity>1</gravity>
        <velocity_decay/>
        <self_collide>0</self_collide>
        <enable_wind>0</enable_wind>
        <kinematic>0</kinematic>
      </link>
      <joint name='j_arm1_5' type='revolute'>
        <child>arm1_5</child>
        <parent>arm1_4</parent>
        <axis>
          <xyz>-0 -0 1</xyz>
          <limit>
            <lower>-2.569</lower>
            <upper>2.562</upper>
            <effort>55</effort>
            <velocity>11.72</velocity>
          </limit>
          <dynamics>
            <spring_reference>0</spring_reference>
            <spring_stiffness>0</spring_stiffness>
          </dynamics>
          <use_parent_model_frame>1</use_parent_model_frame>
        </axis>
        <physics>
          <provide_feedback>1</provide_feedback>
          <ode>
            <provide_feedback>1</provide_feedback>
            <implicit_spring_damper>1</implicit_spring_damper>
            <cfm_damping>1</cfm_damping>
            <limit>
              <cfm>0</cfm>
              <erp>0.2</erp>
            </limit>
          </ode>
        </physics>
      </joint>
      <link name='arm1_6'>
        <pose frame=''>0.326757 0.24945 -0.159758 0 0 -0.523599</pose>
        <inertial>
          <pose frame=''>-5e-06 -0.038014 -0.069927 0 -0 0</pose>
          <mass>1.12636</mass>
          <inertia>
            <ixx>0.00518718</ixx>
            <ixy>2.72444e-05</ixy>
            <ixz>2.28335e-06</ixz>
            <iyy>0.00480378</iyy>
            <iyz>-0.000721657</iyz>
            <izz>0.00127714</izz>
          </inertia>
        </inertial>
        <collision name='arm1_6_collision'>
          <pose frame=''>0 0 0 0 -0 0</pose>
          <geometry>
            <mesh>
              <scale>0.001 -0.001 0.001</scale>
              <uri>/home/ioannis/centauro_ws/src/iit-centauro-ros-pkg/centauro_urdf/meshes/simple/ForearmPitch.STL</uri>
            </mesh>
          </geometry>
          <surface>
            <contact>
              <ode/>
            </contact>
            <friction>
              <ode/>
              <torsional>
                <ode/>
              </torsional>
            </friction>
            <bounce/>
          </surface>
          <max_contacts>10</max_contacts>
        </collision>
        <visual name='arm1_6_visual'>
          <pose frame=''>0 0 0 0 -0 0</pose>
          <geometry>
            <mesh>
              <scale>0.001 -0.001 0.001</scale>
              <uri>/home/ioannis/centauro_ws/src/iit-centauro-ros-pkg/centauro_urdf/meshes/ForearmPitch.STL</uri>
            </mesh>
          </geometry>
          <material>
            <script>
              <name>Gazebo/LightBlueLaser</name>
              <uri>file://media/materials/scripts/gazebo.material</uri>
            </script>
          </material>
        </visual>
        <gravity>1</gravity>
        <velocity_decay/>
        <self_collide>0</self_collide>
        <enable_wind>0</enable_wind>
        <kinematic>0</kinematic>
      </link>
      <joint name='j_arm1_6' type='revolute'>
        <child>arm1_6</child>
        <parent>arm1_5</parent>
        <axis>
          <xyz>0.5 0.866025 0</xyz>
          <limit>
            <lower>-1.529</lower>
            <upper>1.509</upper>
            <effort>55</effort>
            <velocity>11.72</velocity>
          </limit>
          <dynamics>
            <spring_reference>0</spring_reference>
            <spring_stiffness>0</spring_stiffness>
          </dynamics>
          <use_parent_model_frame>1</use_parent_model_frame>
        </axis>
        <physics>
          <provide_feedback>1</provide_feedback>
          <ode>
            <provide_feedback>1</provide_feedback>
            <implicit_spring_damper>1</implicit_spring_damper>
            <cfm_damping>1</cfm_damping>
            <limit>
              <cfm>0</cfm>
              <erp>0.2</erp>
            </limit>
          </ode>
        </physics>
      </joint>
      <link name='arm1_7'>
        <pose frame=''>0.302257 0.207015 -0.333758 0 0 -0.523599</pose>
        <inertial>
          <pose frame=''>9e-06 0.000541 0.01433 0 -0 0</pose>
          <mass>1.92794</mass>
          <inertia>
            <ixx>0.00316217</ixx>
            <ixy>2.68715e-06</ixy>
            <ixz>-9.8962e-07</ixz>
            <iyy>0.00313238</iyy>
            <iyz>6.27992e-05</iyz>
            <izz>0.00340412</izz>
          </inertia>
        </inertial>
        <collision name='arm1_7_collision'>
          <pose frame=''>0 0 0 0 -0 0</pose>
          <geometry>
            <mesh>
              <scale>0.001 -0.001 0.001</scale>
              <uri>/home/ioannis/centauro_ws/src/iit-centauro-ros-pkg/centauro_urdf/meshes/simple/ForearmYaw.STL</uri>
            </mesh>
          </geometry>
          <surface>
            <contact>
              <ode/>
            </contact>
            <friction>
              <ode/>
              <torsional>
                <ode/>
              </torsional>
            </friction>
            <bounce/>
          </surface>
          <max_contacts>10</max_contacts>
        </collision>
        <collision name='arm1_7_fixed_joint_lump__ball1_collision_1'>
          <pose frame=''>0 0 0 0 -0 0</pose>
          <geometry>
            <mesh>
              <scale>0.001 0.001 0.001</scale>
              <uri>/home/ioannis/centauro_ws/src/iit-centauro-ros-pkg/centauro_urdf/meshes/simple/BallHand.stl</uri>
            </mesh>
          </geometry>
          <surface>
            <contact>
              <ode/>
            </contact>
            <friction>
              <ode/>
              <torsional>
                <ode/>
              </torsional>
            </friction>
            <bounce/>
          </surface>
          <max_contacts>10</max_contacts>
        </collision>
        <visual name='arm1_7_visual'>
          <pose frame=''>0 0 0 0 -0 0</pose>
          <geometry>
            <mesh>
              <scale>0.001 -0.001 0.001</scale>
              <uri>/home/ioannis/centauro_ws/src/iit-centauro-ros-pkg/centauro_urdf/meshes/ForearmYaw.STL</uri>
            </mesh>
          </geometry>
          <material>
            <script>
              <name>Gazebo/LightBlueLaser</name>
              <uri>file://media/materials/scripts/gazebo.material</uri>
            </script>
          </material>
        </visual>
        <visual name='arm1_7_fixed_joint_lump__ball1_visual_1'>
          <pose frame=''>0 0 0 0 -0 0</pose>
          <geometry>
            <mesh>
              <scale>0.001 0.001 0.001</scale>
              <uri>/home/ioannis/centauro_ws/src/iit-centauro-ros-pkg/centauro_urdf/meshes/BallHand.stl</uri>
            </mesh>
          </geometry>
          <material>
            <script>
              <name>Gazebo/BlackTransparent</name>
              <uri>file://media/materials/scripts/gazebo.material</uri>
            </script>
          </material>
        </visual>
        <velocity_decay/>
        <gravity>1</gravity>
        <velocity_decay/>
        <self_collide>0</self_collide>
        <enable_wind>0</enable_wind>
        <kinematic>0</kinematic>
      </link>
      <joint name='j_arm1_7' type='revolute'>
        <child>arm1_7</child>
        <parent>arm1_6</parent>
        <axis>
          <xyz>-0 -0 1</xyz>
          <limit>
            <lower>-2.565</lower>
            <upper>2.569</upper>
            <effort>28.32</effort>
            <velocity>20.35</velocity>
          </limit>
          <dynamics>
            <spring_reference>0</spring_reference>
            <spring_stiffness>0</spring_stiffness>
          </dynamics>
          <use_parent_model_frame>1</use_parent_model_frame>
        </axis>
        <physics>
          <provide_feedback>1</provide_feedback>
          <ode>
            <provide_feedback>1</provide_feedback>
            <implicit_spring_damper>1</implicit_spring_damper>
            <cfm_damping>1</cfm_damping>
            <limit>
              <cfm>0</cfm>
              <erp>0.2</erp>
            </limit>
          </ode>
        </physics>
      </joint>
      <link name='arm2_1'>
        <pose frame=''>0.245748 -0.169137 0.372626 -0.174533 -0 0.523599</pose>
        <inertial>
          <pose frame=''>-0.007446 -0.034108 0.00011 0 -0 0</pose>
          <mass>1.96287</mass>
          <inertia>
            <ixx>0.00535477</ixx>
            <ixy>-0.000364289</ixy>
            <ixz>1.50896e-05</ixz>
            <iyy>0.00339233</iyy>
            <iyz>-5.56923e-05</iyz>
            <izz>0.00689214</izz>
          </inertia>
        </inertial>
        <collision name='arm2_1_collision'>
          <pose frame=''>0 0 0 0 -0 0</pose>
          <geometry>
            <mesh>
              <scale>0.001 0.001 0.001</scale>
              <uri>/home/ioannis/centauro_ws/src/iit-centauro-ros-pkg/centauro_urdf/meshes/simple/ShoulderPitch.STL</uri>
            </mesh>
          </geometry>
          <surface>
            <contact>
              <ode/>
            </contact>
            <friction>
              <ode/>
              <torsional>
                <ode/>
              </torsional>
            </friction>
            <bounce/>
          </surface>
          <max_contacts>10</max_contacts>
        </collision>
        <visual name='arm2_1_visual'>
          <pose frame=''>0 0 0 0 -0 0</pose>
          <geometry>
            <mesh>
              <scale>0.001 0.001 0.001</scale>
              <uri>/home/ioannis/centauro_ws/src/iit-centauro-ros-pkg/centauro_urdf/meshes/ShoulderPitch.STL</uri>
            </mesh>
          </geometry>
          <material>
            <script>
              <name>Gazebo/BlackTransparent</name>
              <uri>file://media/materials/scripts/gazebo.material</uri>
            </script>
          </material>
        </visual>
        <gravity>1</gravity>
        <velocity_decay/>
        <self_collide>0</self_collide>
        <enable_wind>0</enable_wind>
        <kinematic>0</kinematic>
      </link>
      <joint name='j_arm2_1' type='revolute'>
        <child>arm2_1</child>
        <parent>torso_2</parent>
        <axis>
          <xyz>-0.492404 0.852869 -0.173648</xyz>
          <limit>
            <lower>-3.3458</lower>
            <upper>1.6012</upper>
            <effort>147</effort>
            <velocity>3.86</velocity>
          </limit>
          <dynamics>
            <spring_reference>0</spring_reference>
            <spring_stiffness>0</spring_stiffness>
          </dynamics>
          <use_parent_model_frame>1</use_parent_model_frame>
        </axis>
        <physics>
          <provide_feedback>1</provide_feedback>
          <ode>
            <provide_feedback>1</provide_feedback>
            <implicit_spring_damper>1</implicit_spring_damper>
            <cfm_damping>1</cfm_damping>
            <limit>
              <cfm>0</cfm>
              <erp>0.2</erp>
            </limit>
          </ode>
        </physics>
      </joint>
      <link name='arm2_2'>
        <pose frame=''>0.198204 -0.26709 0.383392 0 -0 0.523599</pose>
        <inertial>
          <pose frame=''>0.058142 -5.7e-05 -0.077478 0 -0 0</pose>
          <mass>1.85958</mass>
          <inertia>
            <ixx>0.0137766</ixx>
            <ixy>-3.77887e-05</ixy>
            <ixz>0.00376902</ixz>
            <iyy>0.0156775</iyy>
            <iyz>9.48935e-06</iyz>
            <izz>0.00463177</izz>
          </inertia>
        </inertial>
        <collision name='arm2_2_collision'>
          <pose frame=''>0 0 0 0 -0 0</pose>
          <geometry>
            <mesh>
              <scale>0.001 0.001 0.001</scale>
              <uri>/home/ioannis/centauro_ws/src/iit-centauro-ros-pkg/centauro_urdf/meshes/simple/ShoulderRoll.STL</uri>
            </mesh>
          </geometry>
          <surface>
            <contact>
              <ode/>
            </contact>
            <friction>
              <ode/>
              <torsional>
                <ode/>
              </torsional>
            </friction>
            <bounce/>
          </surface>
          <max_contacts>10</max_contacts>
        </collision>
        <visual name='arm2_2_visual'>
          <pose frame=''>0 0 0 0 -0 0</pose>
          <geometry>
            <mesh>
              <scale>0.001 0.001 0.001</scale>
              <uri>/home/ioannis/centauro_ws/src/iit-centauro-ros-pkg/centauro_urdf/meshes/ShoulderRoll.STL</uri>
            </mesh>
          </geometry>
          <material>
            <script>
              <name>Gazebo/LightBlueLaser</name>
              <uri>file://media/materials/scripts/gazebo.material</uri>
            </script>
          </material>
        </visual>
        <gravity>1</gravity>
        <velocity_decay/>
        <self_collide>0</self_collide>
        <enable_wind>0</enable_wind>
        <kinematic>0</kinematic>
      </link>
      <joint name='j_arm2_2' type='revolute'>
        <child>arm2_2</child>
        <parent>arm2_1</parent>
        <axis>
          <xyz>0.866025 0.5 -0</xyz>
          <limit>
            <lower>-3.4258</lower>
            <upper>-0.0138</upper>
            <effort>147</effort>
            <velocity>3.86</velocity>
          </limit>
          <dynamics>
            <spring_reference>0</spring_reference>
            <spring_stiffness>0</spring_stiffness>
          </dynamics>
          <use_parent_model_frame>1</use_parent_model_frame>
        </axis>
        <physics>
          <provide_feedback>1</provide_feedback>
          <ode>
            <provide_feedback>1</provide_feedback>
            <implicit_spring_damper>1</implicit_spring_damper>
            <cfm_damping>1</cfm_damping>
            <limit>
              <cfm>0</cfm>
              <erp>0.2</erp>
            </limit>
          </ode>
        </physics>
      </joint>
      <link name='arm2_3'>
        <pose frame=''>0.276277 -0.222015 0.165242 0 -0 0.523599</pose>
        <inertial>
          <pose frame=''>0.014625 -0.000817 -0.028334 0 -0 0</pose>
          <mass>1.66781</mass>
          <inertia>
            <ixx>0.00644804</ixx>
            <ixy>0.000156391</ixy>
            <ixz>0.00122054</ixz>
            <iyy>0.00733721</iyy>
            <iyz>-8.99415e-05</iyz>
            <izz>0.00367384</izz>
          </inertia>
        </inertial>
        <collision name='arm2_3_collision'>
          <pose frame=''>0 0 0 0 -0 0</pose>
          <geometry>
            <mesh>
              <scale>0.001 0.001 0.001</scale>
              <uri>/home/ioannis/centauro_ws/src/iit-centauro-ros-pkg/centauro_urdf/meshes/simple/ShoulderYaw.STL</uri>
            </mesh>
          </geometry>
          <surface>
            <contact>
              <ode/>
            </contact>
            <friction>
              <ode/>
              <torsional>
                <ode/>
              </torsional>
            </friction>
            <bounce/>
          </surface>
          <max_contacts>10</max_contacts>
        </collision>
        <visual name='arm2_3_visual'>
          <pose frame=''>0 0 0 0 -0 0</pose>
          <geometry>
            <mesh>
              <scale>0.001 0.001 0.001</scale>
              <uri>/home/ioannis/centauro_ws/src/iit-centauro-ros-pkg/centauro_urdf/meshes/ShoulderYaw.STL</uri>
            </mesh>
          </geometry>
          <material>
            <script>
              <name>Gazebo/LightBlueLaser</name>
              <uri>file://media/materials/scripts/gazebo.material</uri>
            </script>
          </material>
        </visual>
        <gravity>1</gravity>
        <velocity_decay/>
        <self_collide>0</self_collide>
        <enable_wind>0</enable_wind>
        <kinematic>0</kinematic>
      </link>
      <joint name='j_arm2_3' type='revolute'>
        <child>arm2_3</child>
        <parent>arm2_2</parent>
        <axis>
          <xyz>-0 0 1</xyz>
          <limit>
            <lower>-2.5614</lower>
            <upper>2.5606</upper>
            <effort>147</effort>
            <velocity>6.06</velocity>
          </limit>
          <dynamics>
            <spring_reference>0</spring_reference>
            <spring_stiffness>0</spring_stiffness>
          </dynamics>
          <use_parent_model_frame>1</use_parent_model_frame>
        </axis>
        <physics>
          <provide_feedback>1</provide_feedback>
          <ode>
            <provide_feedback>1</provide_feedback>
            <implicit_spring_damper>1</implicit_spring_damper>
            <cfm_damping>1</cfm_damping>
            <limit>
              <cfm>0</cfm>
              <erp>0.2</erp>
            </limit>
          </ode>
        </physics>
      </joint>
      <link name='arm2_4'>
        <pose frame=''>0.342823 -0.247276 0.091242 0 -0 0.523599</pose>
        <inertial>
          <pose frame=''>-0.007683 0.040302 -0.043493 0 -0 0</pose>
          <mass>1.31573</mass>
          <inertia>
            <ixx>0.00433039</ixx>
            <ixy>0.000117374</ixy>
            <ixz>-0.000419232</ixz>
            <iyy>0.00385399</iyy>
            <iyz>0.00079573</iyz>
            <izz>0.00175947</izz>
          </inertia>
        </inertial>
        <collision name='arm2_4_collision'>
          <pose frame=''>0 0 0 0 -0 0</pose>
          <geometry>
            <mesh>
              <scale>0.001 0.001 0.001</scale>
              <uri>/home/ioannis/centauro_ws/src/iit-centauro-ros-pkg/centauro_urdf/meshes/simple/Elbow.STL</uri>
            </mesh>
          </geometry>
          <surface>
            <contact>
              <ode/>
            </contact>
            <friction>
              <ode/>
              <torsional>
                <ode/>
              </torsional>
            </friction>
            <bounce/>
          </surface>
          <max_contacts>10</max_contacts>
        </collision>
        <visual name='arm2_4_visual'>
          <pose frame=''>0 0 0 0 -0 0</pose>
          <geometry>
            <mesh>
              <scale>0.001 0.001 0.001</scale>
              <uri>/home/ioannis/centauro_ws/src/iit-centauro-ros-pkg/centauro_urdf/meshes/Elbow.STL</uri>
            </mesh>
          </geometry>
          <material>
            <script>
              <name>Gazebo/LightBlueLaser</name>
              <uri>file://media/materials/scripts/gazebo.material</uri>
            </script>
          </material>
        </visual>
        <gravity>1</gravity>
        <velocity_decay/>
        <self_collide>0</self_collide>
        <enable_wind>0</enable_wind>
        <kinematic>0</kinematic>
      </link>
      <joint name='j_arm2_4' type='revolute'>
        <child>arm2_4</child>
        <parent>arm2_3</parent>
        <axis>
          <xyz>-0.5 0.866025 -0</xyz>
          <limit>
            <lower>-2.4794</lower>
            <upper>0.2886</upper>
            <effort>147</effort>
            <velocity>6.06</velocity>
          </limit>
          <dynamics>
            <spring_reference>0</spring_reference>
            <spring_stiffness>0</spring_stiffness>
          </dynamics>
          <use_parent_model_frame>1</use_parent_model_frame>
        </axis>
        <physics>
          <provide_feedback>1</provide_feedback>
          <ode>
            <provide_feedback>1</provide_feedback>
            <implicit_spring_damper>1</implicit_spring_damper>
            <cfm_damping>1</cfm_damping>
            <limit>
              <cfm>0</cfm>
              <erp>0.2</erp>
            </limit>
          </ode>
        </physics>
      </joint>
      <link name='arm2_5'>
        <pose frame=''>0.302257 -0.207015 -0.003758 0 -0 0.523599</pose>
        <inertial>
          <pose frame=''>-0.000111 -0.011591 -0.07816 0 -0 0</pose>
          <mass>1.49085</mass>
          <inertia>
            <ixx>0.00856921</ixx>
            <ixy>-1.78563e-05</ixy>
            <ixz>1.93794e-05</ixz>
            <iyy>0.00774542</iyy>
            <iyz>0.000328601</iyz>
            <izz>0.00274419</izz>
          </inertia>
        </inertial>
        <collision name='arm2_5_collision'>
          <pose frame=''>0 0 0 0 -0 0</pose>
          <geometry>
            <mesh>
              <scale>0.001 0.001 0.001</scale>
              <uri>/home/ioannis/centauro_ws/src/iit-centauro-ros-pkg/centauro_urdf/meshes/simple/Forearm.STL</uri>
            </mesh>
          </geometry>
          <surface>
            <contact>
              <ode/>
            </contact>
            <friction>
              <ode/>
              <torsional>
                <ode/>
              </torsional>
            </friction>
            <bounce/>
          </surface>
          <max_contacts>10</max_contacts>
        </collision>
        <visual name='arm2_5_visual'>
          <pose frame=''>0 0 0 0 -0 0</pose>
          <geometry>
            <mesh>
              <scale>0.001 0.001 0.001</scale>
              <uri>/home/ioannis/centauro_ws/src/iit-centauro-ros-pkg/centauro_urdf/meshes/Forearm.STL</uri>
            </mesh>
          </geometry>
          <material>
            <script>
              <name>Gazebo/BlackTransparent</name>
              <uri>file://media/materials/scripts/gazebo.material</uri>
            </script>
          </material>
        </visual>
        <gravity>1</gravity>
        <velocity_decay/>
        <self_collide>0</self_collide>
        <enable_wind>0</enable_wind>
        <kinematic>0</kinematic>
      </link>
      <joint name='j_arm2_5' type='revolute'>
        <child>arm2_5</child>
        <parent>arm2_4</parent>
        <axis>
          <xyz>-0 0 1</xyz>
          <limit>
            <lower>-2.5394</lower>
            <upper>2.5546</upper>
            <effort>55</effort>
            <velocity>11.72</velocity>
          </limit>
          <dynamics>
            <spring_reference>0</spring_reference>
            <spring_stiffness>0</spring_stiffness>
          </dynamics>
          <use_parent_model_frame>1</use_parent_model_frame>
        </axis>
        <physics>
          <provide_feedback>1</provide_feedback>
          <ode>
            <provide_feedback>1</provide_feedback>
            <implicit_spring_damper>1</implicit_spring_damper>
            <cfm_damping>1</cfm_damping>
            <limit>
              <cfm>0</cfm>
              <erp>0.2</erp>
            </limit>
          </ode>
        </physics>
      </joint>
      <link name='arm2_6'>
        <pose frame=''>0.326757 -0.24945 -0.159758 0 -0 0.523599</pose>
        <inertial>
          <pose frame=''>-5e-06 0.038014 -0.069927 0 -0 0</pose>
          <mass>1.12636</mass>
          <inertia>
            <ixx>0.00518718</ixx>
            <ixy>-2.72444e-05</ixy>
            <ixz>2.28335e-06</ixz>
            <iyy>0.00480378</iyy>
            <iyz>0.000721657</iyz>
            <izz>0.00127714</izz>
          </inertia>
        </inertial>
        <collision name='arm2_6_collision'>
          <pose frame=''>0 0 0 0 -0 0</pose>
          <geometry>
            <mesh>
              <scale>0.001 0.001 0.001</scale>
              <uri>/home/ioannis/centauro_ws/src/iit-centauro-ros-pkg/centauro_urdf/meshes/simple/ForearmPitch.STL</uri>
            </mesh>
          </geometry>
          <surface>
            <contact>
              <ode/>
            </contact>
            <friction>
              <ode/>
              <torsional>
                <ode/>
              </torsional>
            </friction>
            <bounce/>
          </surface>
          <max_contacts>10</max_contacts>
        </collision>
        <visual name='arm2_6_visual'>
          <pose frame=''>0 0 0 0 -0 0</pose>
          <geometry>
            <mesh>
              <scale>0.001 0.001 0.001</scale>
              <uri>/home/ioannis/centauro_ws/src/iit-centauro-ros-pkg/centauro_urdf/meshes/ForearmPitch.STL</uri>
            </mesh>
          </geometry>
          <material>
            <script>
              <name>Gazebo/LightBlueLaser</name>
              <uri>file://media/materials/scripts/gazebo.material</uri>
            </script>
          </material>
        </visual>
        <gravity>1</gravity>
        <velocity_decay/>
        <self_collide>0</self_collide>
        <enable_wind>0</enable_wind>
        <kinematic>0</kinematic>
      </link>
      <joint name='j_arm2_6' type='revolute'>
        <child>arm2_6</child>
        <parent>arm2_5</parent>
        <axis>
          <xyz>-0.5 0.866025 -0</xyz>
          <limit>
            <lower>-1.5154</lower>
            <upper>1.5156</upper>
            <effort>55</effort>
            <velocity>11.72</velocity>
          </limit>
          <dynamics>
            <spring_reference>0</spring_reference>
            <spring_stiffness>0</spring_stiffness>
          </dynamics>
          <use_parent_model_frame>1</use_parent_model_frame>
        </axis>
        <physics>
          <provide_feedback>1</provide_feedback>
          <ode>
            <provide_feedback>1</provide_feedback>
            <implicit_spring_damper>1</implicit_spring_damper>
            <cfm_damping>1</cfm_damping>
            <limit>
              <cfm>0</cfm>
              <erp>0.2</erp>
            </limit>
          </ode>
        </physics>
      </joint>
      <link name='arm2_7'>
        <pose frame=''>0.302257 -0.207015 -0.333758 0 -0 0.523599</pose>
        <inertial>
          <pose frame=''>9e-06 -0.000492 0.01433 0 -0 0</pose>
          <mass>1.92794</mass>
          <inertia>
            <ixx>0.00316227</ixx>
            <ixy>-2.10165e-06</ixy>
            <ixz>-9.8962e-07</ixz>
            <iyy>0.00313238</iyy>
            <iyz>-6.1733e-05</iyz>
            <izz>0.00340422</izz>
          </inertia>
        </inertial>
        <collision name='arm2_7_collision'>
          <pose frame=''>0 0 0 0 -0 0</pose>
          <geometry>
            <mesh>
              <scale>0.001 0.001 0.001</scale>
              <uri>/home/ioannis/centauro_ws/src/iit-centauro-ros-pkg/centauro_urdf/meshes/simple/ForearmYaw.STL</uri>
            </mesh>
          </geometry>
          <surface>
            <contact>
              <ode/>
            </contact>
            <friction>
              <ode/>
              <torsional>
                <ode/>
              </torsional>
            </friction>
            <bounce/>
          </surface>
          <max_contacts>10</max_contacts>
        </collision>
        <collision name='arm2_7_fixed_joint_lump__ball2_collision_1'>
          <pose frame=''>0 0 0 0 -0 0</pose>
          <geometry>
            <mesh>
              <scale>0.001 0.001 0.001</scale>
              <uri>/home/ioannis/centauro_ws/src/iit-centauro-ros-pkg/centauro_urdf/meshes/simple/BallHand.stl</uri>
            </mesh>
          </geometry>
          <surface>
            <contact>
              <ode/>
            </contact>
            <friction>
              <ode/>
              <torsional>
                <ode/>
              </torsional>
            </friction>
            <bounce/>
          </surface>
          <max_contacts>10</max_contacts>
        </collision>
        <visual name='arm2_7_visual'>
          <pose frame=''>0 0 0 0 -0 0</pose>
          <geometry>
            <mesh>
              <scale>0.001 0.001 0.001</scale>
              <uri>/home/ioannis/centauro_ws/src/iit-centauro-ros-pkg/centauro_urdf/meshes/ForearmYaw.STL</uri>
            </mesh>
          </geometry>
          <material>
            <script>
              <name>Gazebo/LightBlueLaser</name>
              <uri>file://media/materials/scripts/gazebo.material</uri>
            </script>
          </material>
        </visual>
        <visual name='arm2_7_fixed_joint_lump__ball2_visual_1'>
          <pose frame=''>0 0 0 0 -0 0</pose>
          <geometry>
            <mesh>
              <scale>0.001 0.001 0.001</scale>
              <uri>/home/ioannis/centauro_ws/src/iit-centauro-ros-pkg/centauro_urdf/meshes/BallHand.stl</uri>
            </mesh>
          </geometry>
          <material>
            <script>
              <name>Gazebo/BlackTransparent</name>
              <uri>file://media/materials/scripts/gazebo.material</uri>
            </script>
          </material>
        </visual>
        <velocity_decay/>
        <gravity>1</gravity>
        <velocity_decay/>
        <self_collide>0</self_collide>
        <enable_wind>0</enable_wind>
        <kinematic>0</kinematic>
      </link>
      <joint name='j_arm2_7' type='revolute'>
        <child>arm2_7</child>
        <parent>arm2_6</parent>
        <axis>
          <xyz>-0 0 1</xyz>
          <limit>
            <lower>-2.5554</lower>
            <upper>2.5686</upper>
            <effort>28.32</effort>
            <velocity>20.35</velocity>
          </limit>
          <dynamics>
            <spring_reference>0</spring_reference>
            <spring_stiffness>0</spring_stiffness>
          </dynamics>
          <use_parent_model_frame>1</use_parent_model_frame>
        </axis>
        <physics>
          <provide_feedback>1</provide_feedback>
          <ode>
            <provide_feedback>1</provide_feedback>
            <implicit_spring_damper>1</implicit_spring_damper>
            <cfm_damping>1</cfm_damping>
            <limit>
              <cfm>0</cfm>
              <erp>0.2</erp>
            </limit>
          </ode>
        </physics>
      </joint>
      <link name='neck_3'>
        <pose frame=''>0.255 0 0.729262 0 0 -1.828</pose>
        <inertial>
          <pose frame=''>0.048467 -0.059852 -0.008531 0 -0 0</pose>
          <mass>0.785269</mass>
          <inertia>
            <ixx>0.000468234</ixx>
            <ixy>-1.05438e-05</ixy>
            <ixz>7.24398e-05</ixz>
            <iyy>0.000263525</iyy>
            <iyz>1.6904e-06</iyz>
            <izz>0.000376335</izz>
          </inertia>
        </inertial>
        <collision name='neck_3_collision'>
          <pose frame=''>0 0 0 0 -0 0</pose>
          <geometry>
            <mesh>
              <scale>0.001 0.001 0.001</scale>
              <uri>/home/ioannis/centauro_ws/src/iit-centauro-ros-pkg/centauro_urdf/meshes/simple/lidar.stl</uri>
            </mesh>
          </geometry>
          <max_contacts>10</max_contacts>
          <surface>
            <contact>
              <ode/>
            </contact>
            <bounce/>
            <friction>
              <torsional>
                <ode/>
              </torsional>
              <ode/>
            </friction>
          </surface>
        </collision>
        <visual name='neck_3_visual'>
          <pose frame=''>0 0 0 0 -0 0</pose>
          <geometry>
            <mesh>
              <scale>0.001 0.001 0.001</scale>
              <uri>/home/ioannis/centauro_ws/src/iit-centauro-ros-pkg/centauro_urdf/meshes/lidar.stl</uri>
            </mesh>
          </geometry>
        </visual>
        <self_collide>0</self_collide>
        <enable_wind>0</enable_wind>
        <kinematic>0</kinematic>
      </link>
      <joint name='neck_velodyne' type='revolute'>
        <child>neck_3</child>
        <parent>torso_2</parent>
        <axis>
          <xyz>0 0 1</xyz>
          <limit>
            <lower>-1e+16</lower>
            <upper>1e+16</upper>
          </limit>
          <dynamics>
            <damping>0.2</damping>
            <friction>10</friction>
            <spring_reference>0</spring_reference>
            <spring_stiffness>0</spring_stiffness>
          </dynamics>
          <use_parent_model_frame>1</use_parent_model_frame>
        </axis>
      </joint>
      <link name='neck_1'>
        <pose frame=''>0.2 0 0.5355 0 -0 0</pose>
        <inertial>
          <pose frame=''>0.04048 0.021378 -0.014595 0 -0 0</pose>
          <mass>0.338787</mass>
          <inertia>
            <ixx>0.000371857</ixx>
            <ixy>-9.42983e-05</ixy>
            <ixz>-2.80644e-05</ixz>
            <iyy>0.000188688</iyy>
            <iyz>-1.54534e-05</iyz>
            <izz>0.000502344</izz>
          </inertia>
        </inertial>
        <collision name='neck_1_collision'>
          <pose frame=''>0 0 0 0 -0 0</pose>
          <geometry>
            <mesh>
              <scale>0.001 0.001 0.001</scale>
              <uri>/home/ioannis/centauro_ws/src/iit-centauro-ros-pkg/centauro_urdf/meshes/simple/neck_yaw.stl</uri>
            </mesh>
          </geometry>
          <max_contacts>10</max_contacts>
          <surface>
            <contact>
              <ode/>
            </contact>
            <bounce/>
            <friction>
              <torsional>
                <ode/>
              </torsional>
              <ode/>
            </friction>
          </surface>
        </collision>
        <visual name='neck_1_visual'>
          <pose frame=''>0 0 0 0 -0 0</pose>
          <geometry>
            <mesh>
              <scale>0.001 0.001 0.001</scale>
              <uri>/home/ioannis/centauro_ws/src/iit-centauro-ros-pkg/centauro_urdf/meshes/neck_yaw.stl</uri>
            </mesh>
          </geometry>
        </visual>
        <self_collide>0</self_collide>
        <enable_wind>0</enable_wind>
        <kinematic>0</kinematic>
      </link>
      <joint name='neck_yaw' type='revolute'>
        <child>neck_1</child>
        <parent>torso_2</parent>
        <axis>
          <xyz>0 0 1</xyz>
          <limit>
            <lower>-0.785398</lower>
            <upper>0.785398</upper>
            <effort>35</effort>
            <velocity>5.7</velocity>
          </limit>
          <dynamics>
            <damping>0</damping>
            <friction>10</friction>
            <spring_reference>0</spring_reference>
            <spring_stiffness>0</spring_stiffness>
          </dynamics>
          <use_parent_model_frame>1</use_parent_model_frame>
        </axis>
      </joint>
      <link name='neck_2'>
        <pose frame=''>0.254 0.0596 0.523003 0 -0 0</pose>
        <inertial>
          <pose frame=''>0.048467 -0.059852 -0.008531 0 -0 0</pose>
          <mass>0.785269</mass>
          <inertia>
            <ixx>0.000468234</ixx>
            <ixy>-1.05438e-05</ixy>
            <ixz>7.24398e-05</ixz>
            <iyy>0.000263525</iyy>
            <iyz>1.6904e-06</iyz>
            <izz>0.000376335</izz>
          </inertia>
        </inertial>
        <collision name='neck_2_collision'>
          <pose frame=''>0 0 0 0 -0 0</pose>
          <geometry>
            <mesh>
              <scale>0.001 0.001 0.001</scale>
              <uri>/home/ioannis/centauro_ws/src/iit-centauro-ros-pkg/centauro_urdf/meshes/simple/neck_pitch.stl</uri>
            </mesh>
          </geometry>
          <max_contacts>10</max_contacts>
          <surface>
            <contact>
              <ode/>
            </contact>
            <bounce/>
            <friction>
              <torsional>
                <ode/>
              </torsional>
              <ode/>
            </friction>
          </surface>
        </collision>
        <visual name='neck_2_visual'>
          <pose frame=''>0 0 0 0 -0 0</pose>
          <geometry>
            <mesh>
              <scale>0.001 0.001 0.001</scale>
              <uri>/home/ioannis/centauro_ws/src/iit-centauro-ros-pkg/centauro_urdf/meshes/neck_pitch.stl</uri>
            </mesh>
          </geometry>
        </visual>
        <self_collide>0</self_collide>
        <enable_wind>0</enable_wind>
        <kinematic>0</kinematic>
      </link>
      <joint name='neck_pitch' type='revolute'>
        <child>neck_2</child>
        <parent>neck_1</parent>
        <axis>
          <xyz>0 1 0</xyz>
          <limit>
            <lower>-0.349066</lower>
            <upper>0.785398</upper>
            <effort>35</effort>
            <velocity>5.7</velocity>
          </limit>
          <dynamics>
            <damping>0</damping>
            <friction>10</friction>
            <spring_reference>0</spring_reference>
            <spring_stiffness>0</spring_stiffness>
          </dynamics>
          <use_parent_model_frame>1</use_parent_model_frame>
        </axis>
      </joint>
      <static>0</static>
      <plugin name='xbot2_link_state_sensor' filename='libxbot2_gz_link_state_sensor.so'>
        <links>
          <link name='pelvis'/>
          <link name='wheel_1'/>
        </links>
        <robotNamespace>/</robotNamespace>
      </plugin>
      <plugin name='xbot2_ft_driver' filename='libxbot2_gz_ft_server.so'>
        <robotNamespace>/</robotNamespace>
      </plugin>
      <plugin name='xbot2_imu_driver' filename='libxbot2_gz_imu_server.so'>
        <robotNamespace>/</robotNamespace>
      </plugin>
      <plugin name='xbot2_joint_driver' filename='libxbot2_gz_joint_server.so'>
        <pid>
          <gain d='5' name='lowpwr_mot' p='50'/>
          <gain d='5' name='small_mot' p='250'/>
          <gain d='10' name='medium_mot' p='1000'/>
          <gain d='10' name='big_mot' p='3000'/>
          <gain d='10' name='wheel_mot' p='0'/>
          <pid name='neck_yaw' profile='lowpwr_mot'/>
          <pid name='neck_pitch' profile='lowpwr_mot'/>
          <pid d='20' name='neck_velodyne' p='0'/>
          <pid name='j_arm1_1' profile='medium_mot'/>
          <pid name='j_arm1_2' profile='medium_mot'/>
          <pid name='j_arm1_3' profile='medium_mot'/>
          <pid name='j_arm1_4' profile='medium_mot'/>
          <pid name='j_arm1_5' profile='small_mot'/>
          <pid name='j_arm1_6' profile='small_mot'/>
          <pid name='j_arm1_7' profile='small_mot'/>
          <pid name='j_arm2_1' profile='medium_mot'/>
          <pid name='j_arm2_2' profile='medium_mot'/>
          <pid name='j_arm2_3' profile='medium_mot'/>
          <pid name='j_arm2_4' profile='medium_mot'/>
          <pid name='j_arm2_5' profile='small_mot'/>
          <pid name='j_arm2_6' profile='small_mot'/>
          <pid name='j_arm2_7' profile='small_mot'/>
          <pid name='torso_yaw' profile='big_mot'/>
          <pid name='hip_yaw_1' profile='big_mot'/>
          <pid name='hip_pitch_1' profile='big_mot'/>
          <pid name='knee_pitch_1' profile='big_mot'/>
          <pid name='ankle_pitch_1' profile='medium_mot'/>
          <pid name='ankle_yaw_1' profile='small_mot'/>
          <pid name='j_wheel_1' profile='wheel_mot'/>
          <pid name='hip_yaw_2' profile='big_mot'/>
          <pid name='hip_pitch_2' profile='big_mot'/>
          <pid name='knee_pitch_2' profile='big_mot'/>
          <pid name='ankle_pitch_2' profile='medium_mot'/>
          <pid name='ankle_yaw_2' profile='small_mot'/>
          <pid name='j_wheel_2' profile='wheel_mot'/>
          <pid name='hip_yaw_3' profile='big_mot'/>
          <pid name='hip_pitch_3' profile='big_mot'/>
          <pid name='knee_pitch_3' profile='big_mot'/>
          <pid name='ankle_pitch_3' profile='medium_mot'/>
          <pid name='ankle_yaw_3' profile='small_mot'/>
          <pid name='j_wheel_3' profile='wheel_mot'/>
          <pid name='hip_yaw_4' profile='big_mot'/>
          <pid name='hip_pitch_4' profile='big_mot'/>
          <pid name='knee_pitch_4' profile='big_mot'/>
          <pid name='ankle_pitch_4' profile='medium_mot'/>
          <pid name='ankle_yaw_4' profile='small_mot'/>
          <pid name='j_wheel_4' profile='wheel_mot'/>
        </pid>
        <robotNamespace>/</robotNamespace>
      </plugin>
      <pose frame=''>0 0 1.2 0 -0 0</pose>
    </model>
    <state world_name='default'>
      <sim_time>76 834000000</sim_time>
      <real_time>509 734952306</real_time>
      <wall_time>1615382052 556427444</wall_time>
      <iterations>307336</iterations>
      <model name='centauro'>
        <pose frame=''>0.434307 -0.043857 0.723997 0.01815 -0.117582 0.030329</pose>
        <scale>1 1 1</scale>
        <link name='ankle1_1'>
          <pose frame=''>0.734695 0.337303 0.314088 -2.52401 1.45179 0.18476</pose>
          <velocity>0.021418 0.002663 -0.001074 0.001082 0.001422 -0.038651</velocity>
          <acceleration>-0.004204 0.006772 0.000431 0.61477 0.382288 2.22726</acceleration>
          <wrench>-0.005204 0.008384 0.000533 0 -0 0</wrench>
        </link>
        <link name='ankle1_2'>
          <pose frame=''>0.830448 -0.365451 0.508834 2.07873 1.38832 -0.149084</pose>
          <velocity>0.16151 -0.113496 -0.319931 0.467661 0.768291 -0.112634</velocity>
          <acceleration>-0.011213 -0.002513 -0.020804 -0.459384 -0.136259 0.574296</acceleration>
          <wrench>-0.013882 -0.003112 -0.025757 0 -0 0</wrench>
        </link>
        <link name='ankle1_3'>
          <pose frame=''>0.238368 0.320032 0.315243 0.285258 1.44895 0.659316</pose>
          <velocity>0.023667 -0.00294 0.000394 0.014366 0.009559 -0.010628</velocity>
          <acceleration>-0.006148 0.024421 -0.002927 0.327469 -1.50731 2.35218</acceleration>
          <wrench>-0.007612 0.030236 -0.003624 0 -0 0</wrench>
        </link>
        <link name='ankle1_4'>
          <pose frame=''>0.199114 -0.394629 0.513119 0.940361 1.41439 0.440817</pose>
          <velocity>0.042074 -0.012471 -0.056314 -0.398932 0.195398 0.056052</velocity>
          <acceleration>-0.017288 0.04581 -0.011236 -0.245444 -0.26984 -0.004774</acceleration>
          <wrench>-0.021404 0.056716 -0.01391 0 -0 0</wrench>
        </link>
        <link name='ankle2_1'>
          <pose frame=''>0.734694 0.337304 0.314088 3.12561 0.117943 -3.09174</pose>
          <velocity>0.022498 0.002305 -0.000904 -0.003861 0.001767 0.005326</velocity>
          <acceleration>-0.00237 0.002662 0.000455 -2.91716 0.14466 0.757659</acceleration>
          <wrench>-0.002741 0.003079 0.000526 0 -0 0</wrench>
        </link>
        <link name='ankle2_2'>
          <pose frame=''>0.830451 -0.365447 0.50884 3.11212 -0.180105 0.013998</pose>
          <velocity>0.157142 -0.118422 -0.327003 0.197769 0.802664 1.36419</velocity>
          <acceleration>-0.007071 -0.001443 -0.02064 -0.788545 0.793914 2.73942</acceleration>
          <wrench>-0.008178 -0.001669 -0.023872 0 -0 0</wrench>
        </link>
        <link name='ankle2_3'>
          <pose frame=''>0.238369 0.320032 0.315244 3.07195 0.100063 -3.09192</pose>
          <velocity>0.023501 -0.002988 0.000377 0.01281 0.008117 0.005979</velocity>
          <acceleration>0.006266 0.010622 -0.002572 0.498268 -0.83168 2.57769</acceleration>
          <wrench>0.007248 0.012285 -0.002975 0 -0 0</wrench>
        </link>
        <link name='ankle2_4'>
          <pose frame=''>0.199111 -0.394628 0.51312 -3.08156 -0.14451 0.04549</pose>
          <velocity>0.045848 -0.013806 -0.057219 -0.426363 0.175147 0.203951</velocity>
          <acceleration>-0.000138 0.048229 -0.009409 3.0778 -0.559911 -1.32839</acceleration>
          <wrench>-0.000159 0.055782 -0.010883 0 -0 0</wrench>
        </link>
        <link name='arm1_1'>
          <pose frame=''>0.629882 0.124333 1.12593 0.271826 0.413325 -0.364237</pose>
          <velocity>0.023317 0.000336 0.001556 0.009982 -0.020226 0.006069</velocity>
          <acceleration>-0.00236 -0.002139 0.005923 -2.71963 -0.810905 0.340724</acceleration>
          <wrench>-0.004632 -0.004198 0.011626 0 -0 0</wrench>
        </link>
        <link name='arm1_2'>
          <pose frame=''>0.580262 0.207167 1.17739 0.384981 0.413325 -0.364237</pose>
          <velocity>0.021807 -0.000532 0.001457 -0.006214 -0.013944 0.013768</velocity>
          <acceleration>0.007939 0.000546 0.00459 -1.77226 1.19235 2.4761</acceleration>
          <wrench>0.014763 0.001016 0.008536 0 -0 0</wrench>
        </link>
        <link name='arm1_3'>
          <pose frame=''>0.610709 0.283236 0.956021 0.481329 0.292393 -0.087511</pose>
          <velocity>0.023834 -0.001498 0.001394 -0.009316 -0.006877 0.001271</velocity>
          <acceleration>0.026451 0.000411 0.005041 -1.96339 0.052528 -0.81907</acceleration>
          <wrench>0.044114 0.000686 0.008407 0 -0 0</wrench>
        </link>
        <link name='arm1_4'>
          <pose frame=''>0.649398 0.363303 0.90469 2.15072 -1.01225 -2.46545</pose>
          <velocity>0.024084 -0.001922 0.000917 -0.00527 0.009791 0.009675</velocity>
          <acceleration>0.030037 -0.010222 0.01037 -2.43084 0.997301 -0.482256</acceleration>
          <wrench>0.039521 -0.013449 0.013645 0 -0 0</wrench>
        </link>
        <link name='arm1_5'>
          <pose frame=''>0.728158 0.285865 0.895108 2.15997 -1.0209 -2.47632</pose>
          <velocity>0.024738 -0.001208 0.000554 0.003603 0.006155 0.012583</velocity>
          <acceleration>0.018625 -0.030204 0.023512 -1.96268 1.07716 0.30241</acceleration>
          <wrench>0.027767 -0.04503 0.035052 0 -0 0</wrench>
        </link>
        <link name='arm1_6'>
          <pose frame=''>0.876881 0.272305 0.9617 2.64614 -0.418004 3.11688</pose>
          <velocity>0.025316 0.000424 -0.000412 0.00123 -0.003459 0.007806</velocity>
          <acceleration>-0.000727 -0.045791 0.033854 -0.368455 0.048808 -0.465083</acceleration>
          <wrench>-0.000819 -0.051577 0.038131 0 -0 0</wrench>
        </link>
        <link name='arm1_7'>
          <pose frame=''>0.926439 0.145209 1.08031 2.63854 -0.408542 3.13582</pose>
          <velocity>0.0259 0.000664 -0.000399 0.000207 -0.002017 0.005422</velocity>
          <acceleration>-0.01724 -0.050564 0.037148 0.038286 -0.221873 -0.150203</acceleration>
          <wrench>-0.033237 -0.097484 0.071619 0 -0 0</wrench>
        </link>
        <link name='arm2_1'>
          <pose frame=''>0.639658 -0.213742 1.1197 -0.234748 0.397925 0.43693</pose>
          <velocity>0.028235 0.000711 -0.006895 0.01605 0.025513 0.011107</velocity>
          <acceleration>-0.034831 -0.002698 -0.007444 0.112297 1.55665 -0.856851</acceleration>
          <wrench>-0.068368 -0.005295 -0.014612 0 -0 0</wrench>
        </link>
        <link name='arm2_2'>
          <pose frame=''>0.594938 -0.30118 1.16792 -0.377056 0.397925 0.43693</pose>
          <velocity>0.030445 -0.000489 -0.00692 -0.016716 0.010325 0.026244</velocity>
          <acceleration>-0.045069 0.000154 -0.006535 -1.0607 0.713122 -1.70042</acceleration>
          <wrench>-0.083809 0.000287 -0.012152 0 -0 0</wrench>
        </link>
        <link name='arm2_3'>
          <pose frame=''>0.633013 -0.372045 0.94601 -0.464082 0.289157 0.180195</pose>
          <velocity>0.030014 -0.003144 -0.006062 -0.021142 -0.002454 0.003935</velocity>
          <acceleration>-0.060963 1.7e-05 -0.007637 -2.58715 0.814596 -2.40686</acceleration>
          <wrench>-0.101675 2.8e-05 -0.012736 0 -0 0</wrench>
        </link>
        <link name='arm2_4'>
          <pose frame=''>0.678583 -0.44754 0.893413 -2.17206 -1.02364 2.56949</pose>
          <velocity>0.030473 -0.004046 -0.004302 -0.01131 -0.031676 0.018586</velocity>
          <acceleration>-0.063955 -0.008819 -0.010264 -0.878512 -0.930962 -0.922467</acceleration>
          <wrench>-0.084148 -0.011604 -0.013505 0 -0 0</wrench>
        </link>
        <link name='arm2_5'>
          <pose frame=''>0.75038 -0.36349 0.884901 -2.22126 -1.06327 2.6264</pose>
          <velocity>0.029198 -0.002798 -0.002971 0.014085 -0.018877 0.027344</velocity>
          <acceleration>-0.054758 -0.024654 -0.015078 -1.95331 0.554547 -1.46031</acceleration>
          <wrench>-0.081636 -0.036755 -0.02248 0 -0 0</wrench>
        </link>
        <link name='arm2_6'>
          <pose frame=''>0.898425 -0.338747 0.949765 -2.70169 -0.431751 -2.99683</pose>
          <velocity>0.02731 0.00034 0.000174 0.000667 0.01945 0.010335</velocity>
          <acceleration>-0.0412 -0.038876 -0.017727 0.605395 -1.15422 0.314839</acceleration>
          <wrench>-0.046406 -0.043789 -0.019967 0 -0 0</wrench>
        </link>
        <link name='arm2_7'>
          <pose frame=''>0.937891 -0.213308 1.0738 -2.67805 -0.405995 -3.05492</pose>
          <velocity>0.028433 0.000668 -0.00051 -0.0033 0.013442 -6.9e-05</velocity>
          <acceleration>-0.030097 -0.044745 -0.017322 0.014653 -0.017792 -0.144494</acceleration>
          <wrench>-0.058025 -0.086265 -0.033396 0 -0 0</wrench>
        </link>
        <link name='hip1_1'>
          <pose frame=''>0.685015 0.089814 0.699378 3.02406 -0.018359 1.60047</pose>
          <velocity>0.018811 0.011964 -0.000261 0.027545 0.002308 -0.038964</velocity>
          <acceleration>-0.008687 0.015905 0.003655 1.57566 -0.690215 0.274542</acceleration>
          <wrench>-0.016674 0.03053 0.007016 0 -0 0</wrench>
        </link>
        <link name='hip1_2'>
          <pose frame=''>0.693128 -0.160015 0.694872 -3.02693 -0.031888 -1.11674</pose>
          <velocity>0.022689 0.013468 -0.006643 0.01382 0.045682 -0.147452</velocity>
          <acceleration>-0.005089 0.018098 -0.002946 -1.69778 -1.47697 -0.981708</acceleration>
          <wrench>-0.009768 0.034738 -0.005655 0 -0 0</wrench>
        </link>
        <link name='hip1_3'>
          <pose frame=''>0.188696 0.074756 0.640722 3.02704 -0.032182 1.48197</pose>
          <velocity>0.018502 0.003878 0.004482 0.027572 0.012252 -0.008973</velocity>
          <acceleration>-0.00696 0.006025 -0.009534 2.30068 0.633172 1.72471</acceleration>
          <wrench>-0.013359 0.011565 -0.018301 0 -0 0</wrench>
        </link>
        <link name='hip1_4'>
          <pose frame=''>0.196808 -0.175072 0.636216 -3.02559 0.026409 -1.60973</pose>
          <velocity>0.023506 0.004707 -0.001915 0.010069 -0.008963 0.082261</velocity>
          <acceleration>-0.00233 0.003465 -0.016545 -0.626513 0.586763 0.431736</acceleration>
          <wrench>-0.004473 0.006651 -0.031757 0 -0 0</wrench>
        </link>
        <link name='hip2_1'>
          <pose frame=''>0.692308 0.09117 0.63732 -1.81244 -1.15432 1.35629</pose>
          <velocity>0.018548 0.013298 -0.000486 -0.003802 0.008259 -0.03743</velocity>
          <acceleration>-0.006342 0.015047 0.000629 2.85215 -0.056151 -0.539016</acceleration>
          <wrench>-0.017292 0.041026 0.001716 0 -0 0</wrench>
        </link>
        <link name='hip2_2'>
          <pose frame=''>0.700423 -0.158659 0.632814 1.91457 1.30595 -0.317276</pose>
          <velocity>0.019755 0.015015 -0.006077 0.519473 0.776835 -0.081889</velocity>
          <acceleration>-0.025076 0.003829 -0.012762 1.45677 -0.463082 1.51502</acceleration>
          <wrench>-0.068368 0.010439 -0.034795 0 -0 0</wrench>
        </link>
        <link name='hip2_3'>
          <pose frame=''>0.195989 0.076112 0.578664 -1.2007 1.24248 -0.846789</pose>
          <velocity>0.01782 0.005401 0.004422 -0.020515 -0.004835 -0.01559</velocity>
          <acceleration>-0.009702 0.008694 -0.00165 -2.81382 -1.05103 -1.9787</acceleration>
          <wrench>-0.026451 0.023704 -0.004498 0 -0 0</wrench>
        </link>
        <link name='hip2_4'>
          <pose frame=''>0.2041 -0.173717 0.574155 1.32845 -1.17805 1.28997</pose>
          <velocity>0.023652 0.007421 0.000596 0.191019 -0.101437 0.101477</velocity>
          <acceleration>-0.033173 0.006215 -0.024631 2.03323 -0.799311 -1.7186</acceleration>
          <wrench>-0.090445 0.016946 -0.067155 0 -0 0</wrench>
        </link>
        <link name='knee_1'>
          <pose frame=''>0.8224 0.334657 0.519832 -1.05932 1.37171 -1.50398</pose>
          <velocity>0.026719 0.007531 -0.003396 -0.041683 0.026161 -0.043377</velocity>
          <acceleration>-0.005079 0.010311 0.001119 -0.835624 0.101287 -2.6385</acceleration>
          <wrench>-0.009831 0.019959 0.002167 0 -0 0</wrench>
        </link>
        <link name='knee_2'>
          <pose frame=''>0.930041 -0.336918 0.707064 1.29257 1.24374 2.22749</pose>
          <velocity>0.060567 -0.041587 -0.274456 -0.486957 -0.539987 -0.252423</velocity>
          <acceleration>-0.014906 -0.011696 -0.015719 1.96131 -0.498583 -0.457162</acceleration>
          <wrench>-0.028853 -0.022639 -0.030427 0 -0 0</wrench>
        </link>
        <link name='knee_3'>
          <pose frame=''>0.098585 0.345029 0.488061 1.87775 1.17449 -0.914288</pose>
          <velocity>0.022466 0.004967 -0.001743 -0.032207 -0.009316 -0.01657</velocity>
          <acceleration>-0.009068 0.017768 -0.003289 0.399444 1.51263 -2.58891</acceleration>
          <wrench>-0.017552 0.034392 -0.006367 0 -0 0</wrench>
        </link>
        <link name='knee_4'>
          <pose frame=''>0.057219 -0.410548 0.685287 -1.79043 1.1357 0.8657</pose>
          <velocity>0.037245 -0.028592 -0.059911 0.017591 -0.030345 0.093575</velocity>
          <acceleration>-0.027599 0.04154 -0.019753 2.61222 0.381829 2.54021</acceleration>
          <wrench>-0.053424 0.080408 -0.038235 0 -0 0</wrench>
        </link>
        <link name='neck_1'>
          <pose frame=''>0.570348 -0.049453 1.27917 0.019075 -0.117441 0.022424</pose>
          <velocity>0.027621 -0.004638 -0.001797 0.026161 0.01431 0.014662</velocity>
          <acceleration>-0.020676 -0.004867 -0.001099 2.1691 1.48905 1.97387</acceleration>
          <wrench>-0.007005 -0.001649 -0.000372 0 -0 0</wrench>
        </link>
        <link name='neck_2'>
          <pose frame=''>0.623952 0.011592 1.27422 0.019261 0.181406 0.028138</pose>
          <velocity>0.026744 -0.003882 -0.00058 0.024909 0.017669 0.012569</velocity>
          <acceleration>-0.021954 -0.009186 -0.000423 0.963178 0.465493 0.232073</acceleration>
          <wrench>-0.01724 -0.007214 -0.000332 0 -0 0</wrench>
        </link>
        <link name='neck_3'>
          <pose frame=''>0.60234 -0.052197 1.47801 0.109513 0.046571 -1.78747</pose>
          <velocity>0.029589 -0.009349 -0.002543 0.025348 0.009392 0.015038</velocity>
          <acceleration>-0.030379 -0.005498 -0.005146 2.57918 0.787598 0.420994</acceleration>
          <wrench>-0.023856 -0.004317 -0.004041 0 -0 0</wrench>
        </link>
        <link name='pelvis'>
          <pose frame=''>0.434307 -0.043857 0.723997 0.01815 -0.117582 0.030329</pose>
          <velocity>0.021563 0.006772 -0.000924 0.024073 0.010316 0.019409</velocity>
          <acceleration>-0.009067 0.006845 -0.006759 -1.01112 -0.391073 -1.09274</acceleration>
          <wrench>-0.145964 0.11018 -0.108805 0 -0 0</wrench>
        </link>
        <link name='torso_2'>
          <pose frame=''>0.602963 -0.043389 1.00165 0.018572 -0.117517 0.026732</pose>
          <velocity>0.024461 0.003114 -0.002429 0.025044 0.010487 0.014827</velocity>
          <acceleration>-0.018505 0.003615 -0.002734 -0.583451 -0.466662 -2.95921</acceleration>
          <wrench>-0.212676 0.041552 -0.031425 0 -0 0</wrench>
        </link>
        <link name='wheel_1'>
          <pose frame=''>0.762351 0.343331 0.07843 -1.53672 -1.08655 0.021564</pose>
          <velocity>0.022013 0.001517 -0.000964 -0.019541 0.283979 0.009457</velocity>
          <acceleration>-0.001804 0.001548 0.000423 -3.0823 -1.13019 0.076799</acceleration>
          <wrench>-0.003119 0.002677 0.000731 0 -0 0</wrench>
        </link>
        <link name='wheel_2'>
          <pose frame=''>0.873051 -0.372695 0.275462 1.54181 -0.018138 0.009233</pose>
          <velocity>-0.020009 -0.014752 -0.3702 0.188395 0.320493 1.38679</velocity>
          <acceleration>-0.005929 -0.00122 -0.020874 2.2794 0.277529 -2.77873</acceleration>
          <wrench>-0.010251 -0.002109 -0.036088 0 -0 0</wrench>
        </link>
        <link name='wheel_3'>
          <pose frame=''>0.261124 0.33855 0.079713 1.35623 1.23958 2.99501</pose>
          <velocity>0.021475 0.000163 0.000434 -0.002483 0.276361 0.024553</velocity>
          <acceleration>0.009852 0.006901 -0.002699 0.127249 1.05455 -2.70617</acceleration>
          <wrench>0.017033 0.011931 -0.004666 0 -0 0</wrench>
        </link>
        <link name='wheel_4'>
          <pose frame=''>0.232592 -0.379697 0.278618 -1.6309 -0.15181 -3.07835</pose>
          <velocity>0.002504 -0.107446 -0.071072 -0.423781 0.095069 0.200477</velocity>
          <acceleration>0.002968 0.049546 -0.009821 -0.920154 -0.390287 -0.292605</acceleration>
          <wrench>0.005132 0.085661 -0.01698 0 -0 0</wrench>
        </link>
      </model>
      <model name='ground_plane'>
        <pose frame=''>0 0 0 0 -0 0</pose>
        <scale>1 1 1</scale>
        <link name='link'>
          <pose frame=''>0 0 0 0 -0 0</pose>
          <velocity>0 0 0 0 -0 0</velocity>
          <acceleration>0 0 0 0 -0 0</acceleration>
          <wrench>0 0 0 0 -0 0</wrench>
        </link>
      </model>
      <model name='unit_box'>
        <pose frame=''>0.657282 -0.49391 0.1 0 -0 0</pose>
        <scale>1 1 1</scale>
        <link name='link'>
          <pose frame=''>0.657282 -0.49391 0.1 0 -0 0</pose>
          <velocity>0 0 0 0 -0 0</velocity>
          <acceleration>0 0 -0.00981 0 -0 0</acceleration>
          <wrench>0 0 -9.81 0 -0 0</wrench>
        </link>
      </model>
      <light name='sun'>
        <pose frame=''>0 0 10 0 -0 0</pose>
      </light>
    </state>
  </world>
</sdf>
