<sdf version='1.6'>
  <world name='default'>
    <plugin name='xbot2_clock' filename='libxbot2_gz_clock.so'/>
    <gravity>0 0 -9.81</gravity>
    <model name='ground_plane'>
      <static>1</static>
      <link name='link'>
        <collision name='collision'>
          <geometry>
            <plane>
              <normal>0 0 1</normal>
              <size>100 100</size>
            </plane>
          </geometry>
          <surface>
            <friction>
              <ode>
                <mu>1</mu>
                <mu2>1</mu2>
              </ode>
              <torsional>
                <ode/>
              </torsional>
            </friction>
            <contact>
              <ode/>
            </contact>
            <bounce/>
          </surface>
          <max_contacts>10</max_contacts>
        </collision>
        <visual name='visual'>
          <cast_shadows>0</cast_shadows>
          <geometry>
            <plane>
              <normal>0 0 1</normal>
              <size>100 100</size>
            </plane>
          </geometry>
          <material>
            <script>
              <uri>file://media/materials/scripts/gazebo.material</uri>
              <name>Gazebo/Grey</name>
            </script>
          </material>
        </visual>
        <self_collide>0</self_collide>
        <enable_wind>0</enable_wind>
        <kinematic>0</kinematic>
      </link>
    </model>
    <model name='unit_box'>
      <pose frame=''>2 -0.5 0.1 0 -0 0</pose>
      <link name='link'>
        <inertial>
          <mass>1000</mass>
          <inertia>
            <ixx>100</ixx>
            <ixy>0</ixy>
            <ixz>0</ixz>
            <iyy>100</iyy>
            <iyz>0</iyz>
            <izz>166</izz>
          </inertia>
        </inertial>
        <collision name='collision'>
          <geometry>
            <box>
              <size>2 1 0.2</size>
            </box>
          </geometry>
          <max_contacts>10</max_contacts>
          <surface>
            <contact>
              <ode/>
            </contact>
            <bounce/>
            <friction>
              <torsional>
                <ode/>
              </torsional>
              <ode/>
            </friction>
          </surface>
        </collision>
        <visual name='visual'>
          <geometry>
            <box>
              <size>2 1 0.2</size>
            </box>
          </geometry>
          <material>
            <script>
              <name>Gazebo/Grey</name>
              <uri>file://media/materials/scripts/gazebo.material</uri>
            </script>
          </material>
        </visual>
        <self_collide>0</self_collide>
        <enable_wind>0</enable_wind>
        <kinematic>1</kinematic>
      </link>
    </model>
    <light name='sun' type='directional'>
      <cast_shadows>1</cast_shadows>
      <pose frame=''>0 0 10 0 -0 0</pose>
      <diffuse>0.8 0.8 0.8 1</diffuse>
      <specular>0.2 0.2 0.2 1</specular>
      <attenuation>
        <range>1000</range>
        <constant>0.9</constant>
        <linear>0.01</linear>
        <quadratic>0.001</quadratic>
      </attenuation>
      <direction>-0.5 0.1 -0.9</direction>
    </light>
    <gui fullscreen='0'>
      <camera name='user_camera'>
        <pose frame=''>3.49897 0.797796 1.40922 0 0.283643 -2.763</pose>
        <view_controller>orbit</view_controller>
        <projection_type>perspective</projection_type>
      </camera>
    </gui>
    <physics name='update_rate' default='0' type='ode'>
      <real_time_update_rate>4000</real_time_update_rate>
      <max_step_size>0.00025</max_step_size>
      <max_contacts>5</max_contacts>
      <bullet>
        <solver>
          <iters>100</iters>
          <sor>1.55</sor>
          <type>sequential_impulse</type>
        </solver>
        <constraints>
          <contact_surface_layer>0.2</contact_surface_layer>
          <cfm>0.005</cfm>
          <erp>0.2</erp>
          <split_impulse>1</split_impulse>
          <split_impulse_penetration_threshold>-0.01</split_impulse_penetration_threshold>
        </constraints>
      </bullet>
      <ode>
        <solver>
          <iters>50</iters>
          <sor>1.2</sor>
          <type>quick</type>
          <use_dynamic_moi_rescaling>0</use_dynamic_moi_rescaling>
        </solver>
        <constraints>
          <contact_surface_layer>0.0002</contact_surface_layer>
          <contact_max_correcting_vel>500</contact_max_correcting_vel>
          <cfm>1e-06</cfm>
          <erp>0.3</erp>
        </constraints>
      </ode>
      <real_time_factor>1</real_time_factor>
    </physics>
    <magnetic_field>6e-06 2.3e-05 -4.2e-05</magnetic_field>
    <atmosphere type='adiabatic'/>
    <scene>
      <ambient>0.4 0.4 0.4 1</ambient>
      <background>0.7 0.7 0.7 1</background>
      <shadows>1</shadows>
    </scene>
    <audio>
      <device>default</device>
    </audio>
    <wind/>
    <spherical_coordinates>
      <surface_model>EARTH_WGS84</surface_model>
      <latitude_deg>0</latitude_deg>
      <longitude_deg>0</longitude_deg>
      <elevation>0</elevation>
      <heading_deg>0</heading_deg>
    </spherical_coordinates>
    <model name='centauro'>
      <link name='pelvis'>
        <pose frame=''>0 0 0 0 -0 0</pose>
        <inertial>
          <pose frame=''>0.001389 -0.001599 0.063101 0 -0 0</pose>
          <mass>16.0976</mass>
          <inertia>
            <ixx>0.239126</ixx>
            <ixy>-0.00505413</ixy>
            <ixz>-0.0197461</ixz>
            <iyy>0.714301</iyy>
            <iyz>0.00021312</iyz>
            <izz>0.818704</izz>
          </inertia>
        </inertial>
        <collision name='pelvis_collision'>
          <pose frame=''>0 0 0 0 -0 0</pose>
          <geometry>
            <mesh>
              <scale>0.001 0.001 0.001</scale>
              <uri>/home/ioannis/centauro_ws/src/iit-centauro-ros-pkg/centauro_urdf/meshes/simple/pelvis.stl</uri>
            </mesh>
          </geometry>
          <surface>
            <contact>
              <ode/>
            </contact>
            <friction>
              <ode/>
              <torsional>
                <ode/>
              </torsional>
            </friction>
            <bounce/>
          </surface>
          <max_contacts>10</max_contacts>
        </collision>
        <visual name='pelvis_visual'>
          <pose frame=''>0 0 0 0 -0 0</pose>
          <geometry>
            <mesh>
              <scale>0.001 0.001 0.001</scale>
              <uri>/home/ioannis/centauro_ws/src/iit-centauro-ros-pkg/centauro_urdf/meshes/pelvis.stl</uri>
            </mesh>
          </geometry>
          <material>
            <script>
              <name>Gazebo/LightBlueLaser</name>
              <uri>file://media/materials/scripts/gazebo.material</uri>
            </script>
          </material>
        </visual>
        <velocity_decay/>
        <gravity>1</gravity>
        <velocity_decay/>
        <sensor name='imu_link' type='imu'>
          <always_on>1</always_on>
          <update_rate>500</update_rate>
          <visualize>1</visualize>
          <topic>__default_topic__</topic>
          <imu>
            <angular_velocity/>
            <linear_acceleration/>
          </imu>
          <pose frame=''>0.248316 0 0.015 0 -0 0</pose>
        </sensor>
        <self_collide>0</self_collide>
        <enable_wind>0</enable_wind>
        <kinematic>0</kinematic>
      </link>
      <link name='hip1_1'>
        <pose frame=''>0.25 0.125 -0.0566 -3.14159 -0 0.461416</pose>
        <inertial>
          <pose frame=''>0.010214 -0.018348 0.038091 0 -0 0</pose>
          <mass>1.91944</mass>
          <inertia>
            <ixx>0.00474396</ixx>
            <ixy>0.000574705</ixy>
            <ixz>-0.000378414</ixz>
            <iyy>0.00405519</iyy>
            <iyz>0.000740751</iyz>
            <izz>0.00341462</izz>
          </inertia>
        </inertial>
        <collision name='hip1_1_collision'>
          <pose frame=''>0 0 0 0 -0 -2.21876</pose>
          <geometry>
            <mesh>
              <scale>0.001 0.001 0.001</scale>
              <uri>/home/ioannis/centauro_ws/src/iit-centauro-ros-pkg/centauro_urdf/meshes/simple/hip-yaw.stl</uri>
            </mesh>
          </geometry>
          <surface>
            <contact>
              <ode/>
            </contact>
            <friction>
              <ode/>
              <torsional>
                <ode/>
              </torsional>
            </friction>
            <bounce/>
          </surface>
          <max_contacts>10</max_contacts>
        </collision>
        <visual name='hip1_1_visual'>
          <pose frame=''>0 0 0 0 -0 -2.21876</pose>
          <geometry>
            <mesh>
              <scale>0.001 0.001 0.001</scale>
              <uri>/home/ioannis/centauro_ws/src/iit-centauro-ros-pkg/centauro_urdf/meshes/hip-yaw.stl</uri>
            </mesh>
          </geometry>
          <material>
            <script>
              <name>Gazebo/LightBlueLaser</name>
              <uri>file://media/materials/scripts/gazebo.material</uri>
            </script>
          </material>
        </visual>
        <gravity>1</gravity>
        <velocity_decay/>
        <self_collide>0</self_collide>
        <enable_wind>0</enable_wind>
        <kinematic>0</kinematic>
      </link>
      <joint name='hip_yaw_1' type='revolute'>
        <child>hip1_1</child>
        <parent>pelvis</parent>
        <axis>
          <xyz>-0 0 -1</xyz>
          <limit>
            <lower>-2.03</lower>
            <upper>2.51</upper>
            <effort>304</effort>
            <velocity>8.8</velocity>
          </limit>
          <dynamics>
            <spring_reference>0</spring_reference>
            <spring_stiffness>0</spring_stiffness>
          </dynamics>
          <use_parent_model_frame>1</use_parent_model_frame>
        </axis>
        <physics>
          <provide_feedback>1</provide_feedback>
          <ode>
            <provide_feedback>1</provide_feedback>
            <implicit_spring_damper>1</implicit_spring_damper>
            <cfm_damping>1</cfm_damping>
            <limit>
              <cfm>0</cfm>
              <erp>0.2</erp>
            </limit>
          </ode>
        </physics>
      </joint>
      <link name='hip2_1'>
        <pose frame=''>0.25 0.125 -0.1191 -1.5708 0 0</pose>
        <inertial>
          <pose frame=''>2.6e-05 0.181027 0.08567 0 -0 0</pose>
          <mass>2.72645</mass>
          <inertia>
            <ixx>0.0485187</ixx>
            <ixy>-4.11894e-05</ixy>
            <ixz>-1.68778e-05</ixz>
            <iyy>0.00424205</iyy>
            <iyz>0.00322432</iyz>
            <izz>0.0482558</izz>
          </inertia>
        </inertial>
        <collision name='hip2_1_collision'>
          <pose frame=''>0 0 0 0 -0 0</pose>
          <geometry>
            <mesh>
              <scale>0.001 0.001 0.001</scale>
              <uri>/home/ioannis/centauro_ws/src/iit-centauro-ros-pkg/centauro_urdf/meshes/simple/hip-pitch.stl</uri>
            </mesh>
          </geometry>
          <surface>
            <contact>
              <ode/>
            </contact>
            <friction>
              <ode/>
              <torsional>
                <ode/>
              </torsional>
            </friction>
            <bounce/>
          </surface>
          <max_contacts>10</max_contacts>
        </collision>
        <visual name='hip2_1_visual'>
          <pose frame=''>0 0 0 0 -0 0</pose>
          <geometry>
            <mesh>
              <scale>0.001 0.001 0.001</scale>
              <uri>/home/ioannis/centauro_ws/src/iit-centauro-ros-pkg/centauro_urdf/meshes/hip-pitch.stl</uri>
            </mesh>
          </geometry>
          <material>
            <script>
              <name>Gazebo/BlackTransparent</name>
              <uri>file://media/materials/scripts/gazebo.material</uri>
            </script>
          </material>
        </visual>
        <gravity>1</gravity>
        <velocity_decay/>
        <self_collide>0</self_collide>
        <enable_wind>0</enable_wind>
        <kinematic>0</kinematic>
      </link>
      <joint name='hip_pitch_1' type='revolute'>
        <child>hip2_1</child>
        <parent>hip1_1</parent>
        <axis>
          <xyz>0 1 -0</xyz>
          <limit>
            <lower>-2.0226</lower>
            <upper>2.02748</upper>
            <effort>304</effort>
            <velocity>8.8</velocity>
          </limit>
          <dynamics>
            <spring_reference>0</spring_reference>
            <spring_stiffness>0</spring_stiffness>
          </dynamics>
          <use_parent_model_frame>1</use_parent_model_frame>
        </axis>
        <physics>
          <provide_feedback>1</provide_feedback>
          <ode>
            <provide_feedback>1</provide_feedback>
            <implicit_spring_damper>1</implicit_spring_damper>
            <cfm_damping>1</cfm_damping>
            <limit>
              <cfm>0</cfm>
              <erp>0.2</erp>
            </limit>
          </ode>
        </physics>
      </joint>
      <link name='knee_1'>
        <pose frame=''>0.25 0.1214 -0.4191 -1.57079 1.57079 3.14159</pose>
        <inertial>
          <pose frame=''>0.108817 0.000109 -0.022639 0 -0 0</pose>
          <mass>1.93568</mass>
          <inertia>
            <ixx>0.00305342</ixx>
            <ixy>-4.22079e-05</ixy>
            <ixz>0.00136793</ixz>
            <iyy>0.0196033</iyy>
            <iyz>6.9941e-06</iyz>
            <izz>0.0198498</izz>
          </inertia>
        </inertial>
        <collision name='knee_1_collision'>
          <pose frame=''>0 0 0 0 -0 0</pose>
          <geometry>
            <mesh>
              <scale>0.001 0.001 0.001</scale>
              <uri>/home/ioannis/centauro_ws/src/iit-centauro-ros-pkg/centauro_urdf/meshes/simple/knee.stl</uri>
            </mesh>
          </geometry>
          <surface>
            <contact>
              <ode/>
            </contact>
            <friction>
              <ode/>
              <torsional>
                <ode/>
              </torsional>
            </friction>
            <bounce/>
          </surface>
          <max_contacts>10</max_contacts>
        </collision>
        <visual name='knee_1_visual'>
          <pose frame=''>0 0 0 0 -0 0</pose>
          <geometry>
            <mesh>
              <scale>0.001 0.001 0.001</scale>
              <uri>/home/ioannis/centauro_ws/src/iit-centauro-ros-pkg/centauro_urdf/meshes/knee.stl</uri>
            </mesh>
          </geometry>
          <material>
            <script>
              <name>Gazebo/LightBlueLaser</name>
              <uri>file://media/materials/scripts/gazebo.material</uri>
            </script>
          </material>
        </visual>
        <gravity>1</gravity>
        <velocity_decay/>
        <self_collide>0</self_collide>
        <enable_wind>0</enable_wind>
        <kinematic>0</kinematic>
      </link>
      <joint name='knee_pitch_1' type='revolute'>
        <child>knee_1</child>
        <parent>hip2_1</parent>
        <axis>
          <xyz>-0 -1 0</xyz>
          <limit>
            <lower>-2.4056</lower>
            <upper>2.3994</upper>
            <effort>304</effort>
            <velocity>8.8</velocity>
          </limit>
          <dynamics>
            <spring_reference>0</spring_reference>
            <spring_stiffness>0</spring_stiffness>
          </dynamics>
          <use_parent_model_frame>1</use_parent_model_frame>
        </axis>
        <physics>
          <provide_feedback>1</provide_feedback>
          <ode>
            <provide_feedback>1</provide_feedback>
            <implicit_spring_damper>1</implicit_spring_damper>
            <cfm_damping>1</cfm_damping>
            <limit>
              <cfm>0</cfm>
              <erp>0.2</erp>
            </limit>
          </ode>
        </physics>
      </joint>
      <link name='ankle1_1'>
        <pose frame=''>0.25 0.22155 -0.6191 1.57079 1.57079 3.14159</pose>
        <inertial>
          <pose frame=''>0.032137 9.7e-05 -0.004422 0 -0 0</pose>
          <mass>1.23807</mass>
          <inertia>
            <ixx>0.00156105</ixx>
            <ixy>3.30597e-05</ixy>
            <ixz>-0.000131417</ixz>
            <iyy>0.00374232</iyy>
            <iyz>-2.12589e-05</iyz>
            <izz>0.00383124</izz>
          </inertia>
        </inertial>
        <collision name='ankle1_1_collision'>
          <pose frame=''>0 0 0 0 -0 0</pose>
          <geometry>
            <mesh>
              <scale>0.001 0.001 0.001</scale>
              <uri>/home/ioannis/centauro_ws/src/iit-centauro-ros-pkg/centauro_urdf/meshes/simple/ankle-pitch.stl</uri>
            </mesh>
          </geometry>
          <surface>
            <contact>
              <ode/>
            </contact>
            <friction>
              <ode/>
              <torsional>
                <ode/>
              </torsional>
            </friction>
            <bounce/>
          </surface>
          <max_contacts>10</max_contacts>
        </collision>
        <visual name='ankle1_1_visual'>
          <pose frame=''>0 0 0 0 -0 0</pose>
          <geometry>
            <mesh>
              <scale>0.001 0.001 0.001</scale>
              <uri>/home/ioannis/centauro_ws/src/iit-centauro-ros-pkg/centauro_urdf/meshes/ankle-pitch.stl</uri>
            </mesh>
          </geometry>
          <material>
            <script>
              <name>Gazebo/LightBlueLaser</name>
              <uri>file://media/materials/scripts/gazebo.material</uri>
            </script>
          </material>
        </visual>
        <gravity>1</gravity>
        <velocity_decay/>
        <self_collide>0</self_collide>
        <enable_wind>0</enable_wind>
        <kinematic>0</kinematic>
      </link>
      <joint name='ankle_pitch_1' type='revolute'>
        <child>ankle1_1</child>
        <parent>knee_1</parent>
        <axis>
          <xyz>0 1 -0</xyz>
          <limit>
            <lower>-2.4056</lower>
            <upper>2.3184</upper>
            <effort>147</effort>
            <velocity>8.1</velocity>
          </limit>
          <dynamics>
            <spring_reference>0</spring_reference>
            <spring_stiffness>0</spring_stiffness>
          </dynamics>
          <use_parent_model_frame>1</use_parent_model_frame>
        </axis>
        <physics>
          <provide_feedback>1</provide_feedback>
          <ode>
            <provide_feedback>1</provide_feedback>
            <implicit_spring_damper>1</implicit_spring_damper>
            <cfm_damping>1</cfm_damping>
            <limit>
              <cfm>0</cfm>
              <erp>0.2</erp>
            </limit>
          </ode>
        </physics>
      </joint>
      <link name='ankle2_1'>
        <pose frame=''>0.25 0.22155 -0.6191 3.14159 -0 3.14159</pose>
        <inertial>
          <pose frame=''>0.000444 0.000439 0.193921 0 -0 0</pose>
          <mass>1.15659</mass>
          <inertia>
            <ixx>0.00490195</ixx>
            <ixy>4.3032e-06</ixy>
            <ixz>3.46491e-05</ixz>
            <iyy>0.00387242</iyy>
            <iyz>1.7099e-05</iyz>
            <izz>0.00217832</izz>
          </inertia>
        </inertial>
        <collision name='ankle2_1_collision'>
          <pose frame=''>0 0 0 0 -0 0</pose>
          <geometry>
            <mesh>
              <scale>0.001 0.001 0.001</scale>
              <uri>/home/ioannis/centauro_ws/src/iit-centauro-ros-pkg/centauro_urdf/meshes/simple/ankle-yaw.stl</uri>
            </mesh>
          </geometry>
          <surface>
            <contact>
              <ode/>
            </contact>
            <friction>
              <ode/>
              <torsional>
                <ode/>
              </torsional>
            </friction>
            <bounce/>
          </surface>
          <max_contacts>10</max_contacts>
        </collision>
        <visual name='ankle2_1_visual'>
          <pose frame=''>0 0 0 0 -0 0</pose>
          <geometry>
            <mesh>
              <scale>0.001 0.001 0.001</scale>
              <uri>/home/ioannis/centauro_ws/src/iit-centauro-ros-pkg/centauro_urdf/meshes/ankle-yaw.stl</uri>
            </mesh>
          </geometry>
          <material>
            <script>
              <name>Gazebo/LightBlueLaser</name>
              <uri>file://media/materials/scripts/gazebo.material</uri>
            </script>
          </material>
        </visual>
        <gravity>1</gravity>
        <velocity_decay/>
        <self_collide>0</self_collide>
        <enable_wind>0</enable_wind>
        <kinematic>0</kinematic>
      </link>
      <joint name='ankle_yaw_1' type='revolute'>
        <child>ankle2_1</child>
        <parent>ankle1_1</parent>
        <axis>
          <xyz>0 0 -1</xyz>
          <limit>
            <lower>-2.5626</lower>
            <upper>2.5384</upper>
            <effort>35</effort>
            <velocity>20</velocity>
          </limit>
          <dynamics>
            <spring_reference>0</spring_reference>
            <spring_stiffness>0</spring_stiffness>
          </dynamics>
          <use_parent_model_frame>1</use_parent_model_frame>
        </axis>
        <physics>
          <provide_feedback>1</provide_feedback>
          <ode>
            <provide_feedback>1</provide_feedback>
            <implicit_spring_damper>1</implicit_spring_damper>
            <cfm_damping>1</cfm_damping>
            <limit>
              <cfm>0</cfm>
              <erp>0.2</erp>
            </limit>
          </ode>
        </physics>
      </joint>
      <link name='wheel_1'>
        <pose frame=''>0.25 0.2224 -0.85645 -1.5708 -0 -0</pose>
        <inertial>
          <pose frame=''>0 0 0.002427 0 -0 0</pose>
          <mass>1.7289</mass>
          <inertia>
            <ixx>0.00468643</ixx>
            <ixy>0</ixy>
            <ixz>0</ixz>
            <iyy>0.00467135</iyy>
            <iyz>0</iyz>
            <izz>0.0053126</izz>
          </inertia>
        </inertial>
        <collision name='wheel_1_collision'>
          <pose frame=''>0 0 0 0 -0 0</pose>
          <geometry>
            <cylinder>
              <length>0.06</length>
              <radius>0.078</radius>
            </cylinder>
          </geometry>
          <surface>
            <friction>
              <torsional>
                <coefficient>1</coefficient>
                <use_patch_radius>1</use_patch_radius>
                <patch_radius>0.2</patch_radius>
                <ode/>
              </torsional>
              <ode>
                <mu>1</mu>
                <mu2>1</mu2>
              </ode>
              <bullet>
                <friction>1</friction>
                <friction2>1</friction2>
              </bullet>
            </friction>
            <contact>
              <ode>
                <kp>2.1e+06</kp>
                <kd>1</kd>
                <max_vel>100</max_vel>
              </ode>
              <bullet>
                <soft_cfm>0.007</soft_cfm>
                <soft_erp>0.25</soft_erp>
                <kp>1e+06</kp>
                <kd>5</kd>
                <split_impulse>1</split_impulse>
                <split_impulse_penetration_threshold>-0.01</split_impulse_penetration_threshold>
              </bullet>
            </contact>
            <bounce/>
          </surface>
          <max_contacts>10</max_contacts>
        </collision>
        <visual name='wheel_1_visual'>
          <pose frame=''>0 0 0 0 -0 0</pose>
          <geometry>
            <mesh>
              <scale>0.001 0.001 0.001</scale>
              <uri>/home/ioannis/centauro_ws/src/iit-centauro-ros-pkg/centauro_urdf/meshes/wheel.stl</uri>
            </mesh>
          </geometry>
          <material>
            <script>
              <name>Gazebo/BlackTransparent</name>
              <uri>file://media/materials/scripts/gazebo.material</uri>
            </script>
          </material>
        </visual>
        <velocity_decay/>
        <gravity>1</gravity>
        <velocity_decay/>
        <self_collide>0</self_collide>
        <enable_wind>0</enable_wind>
        <kinematic>0</kinematic>
      </link>
      <joint name='j_wheel_1' type='revolute'>
        <child>wheel_1</child>
        <parent>ankle2_1</parent>
        <axis>
          <xyz>0 1 -0</xyz>
          <limit>
            <lower>-1e+16</lower>
            <upper>1e+16</upper>
          </limit>
          <dynamics>
            <spring_reference>0</spring_reference>
            <spring_stiffness>0</spring_stiffness>
          </dynamics>
          <use_parent_model_frame>1</use_parent_model_frame>
        </axis>
        <physics>
          <provide_feedback>1</provide_feedback>
          <ode>
            <provide_feedback>1</provide_feedback>
            <implicit_spring_damper>1</implicit_spring_damper>
            <cfm_damping>1</cfm_damping>
            <limit>
              <cfm>0</cfm>
              <erp>0.2</erp>
            </limit>
          </ode>
        </physics>
      </joint>
      <link name='hip1_2'>
        <pose frame=''>0.25 -0.125 -0.0566 -3.14159 -0 -0.461416</pose>
        <inertial>
          <pose frame=''>0.010214 0.018348 0.038091 0 -0 0</pose>
          <mass>1.91944</mass>
          <inertia>
            <ixx>0.00474396</ixx>
            <ixy>-0.000574705</ixy>
            <ixz>-0.000378414</ixz>
            <iyy>0.00405519</iyy>
            <iyz>-0.000740751</iyz>
            <izz>0.00341462</izz>
          </inertia>
        </inertial>
        <collision name='hip1_2_collision'>
          <pose frame=''>0 0 0 0 -0 0</pose>
          <geometry>
            <mesh>
              <scale>0.001 0.001 0.001</scale>
              <uri>/home/ioannis/centauro_ws/src/iit-centauro-ros-pkg/centauro_urdf/meshes/simple/hip-yaw.stl</uri>
            </mesh>
          </geometry>
          <surface>
            <contact>
              <ode/>
            </contact>
            <friction>
              <ode/>
              <torsional>
                <ode/>
              </torsional>
            </friction>
            <bounce/>
          </surface>
          <max_contacts>10</max_contacts>
        </collision>
        <visual name='hip1_2_visual'>
          <pose frame=''>0 0 0 0 -0 0</pose>
          <geometry>
            <mesh>
              <scale>0.001 0.001 0.001</scale>
              <uri>/home/ioannis/centauro_ws/src/iit-centauro-ros-pkg/centauro_urdf/meshes/hip-yaw.stl</uri>
            </mesh>
          </geometry>
          <material>
            <script>
              <name>Gazebo/LightBlueLaser</name>
              <uri>file://media/materials/scripts/gazebo.material</uri>
            </script>
          </material>
        </visual>
        <gravity>1</gravity>
        <velocity_decay/>
        <self_collide>0</self_collide>
        <enable_wind>0</enable_wind>
        <kinematic>0</kinematic>
      </link>
      <joint name='hip_yaw_2' type='revolute'>
        <child>hip1_2</child>
        <parent>pelvis</parent>
        <axis>
          <xyz>0 0 -1</xyz>
          <limit>
            <lower>-2.51</lower>
            <upper>2.03</upper>
            <effort>304</effort>
            <velocity>8.8</velocity>
          </limit>
          <dynamics>
            <spring_reference>0</spring_reference>
            <spring_stiffness>0</spring_stiffness>
          </dynamics>
          <use_parent_model_frame>1</use_parent_model_frame>
        </axis>
        <physics>
          <provide_feedback>1</provide_feedback>
          <ode>
            <provide_feedback>1</provide_feedback>
            <implicit_spring_damper>1</implicit_spring_damper>
            <cfm_damping>1</cfm_damping>
            <limit>
              <cfm>0</cfm>
              <erp>0.2</erp>
            </limit>
          </ode>
        </physics>
      </joint>
      <link name='hip2_2'>
        <pose frame=''>0.25 -0.125 -0.1191 -1.5708 -0 -3.14159</pose>
        <inertial>
          <pose frame=''>2.6e-05 0.181027 0.08567 0 -0 0</pose>
          <mass>2.72645</mass>
          <inertia>
            <ixx>0.0485187</ixx>
            <ixy>-4.11894e-05</ixy>
            <ixz>-1.68778e-05</ixz>
            <iyy>0.00424205</iyy>
            <iyz>0.00322432</iyz>
            <izz>0.0482558</izz>
          </inertia>
        </inertial>
        <collision name='hip2_2_collision'>
          <pose frame=''>0 0 0 0 -0 0</pose>
          <geometry>
            <mesh>
              <scale>0.001 0.001 0.001</scale>
              <uri>/home/ioannis/centauro_ws/src/iit-centauro-ros-pkg/centauro_urdf/meshes/simple/hip-pitch.stl</uri>
            </mesh>
          </geometry>
          <surface>
            <contact>
              <ode/>
            </contact>
            <friction>
              <ode/>
              <torsional>
                <ode/>
              </torsional>
            </friction>
            <bounce/>
          </surface>
          <max_contacts>10</max_contacts>
        </collision>
        <visual name='hip2_2_visual'>
          <pose frame=''>0 0 0 0 -0 0</pose>
          <geometry>
            <mesh>
              <scale>0.001 0.001 0.001</scale>
              <uri>/home/ioannis/centauro_ws/src/iit-centauro-ros-pkg/centauro_urdf/meshes/hip-pitch.stl</uri>
            </mesh>
          </geometry>
          <material>
            <script>
              <name>Gazebo/BlackTransparent</name>
              <uri>file://media/materials/scripts/gazebo.material</uri>
            </script>
          </material>
        </visual>
        <gravity>1</gravity>
        <velocity_decay/>
        <self_collide>0</self_collide>
        <enable_wind>0</enable_wind>
        <kinematic>0</kinematic>
      </link>
      <joint name='hip_pitch_2' type='revolute'>
        <child>hip2_2</child>
        <parent>hip1_2</parent>
        <axis>
          <xyz>0 -1 -0</xyz>
          <limit>
            <lower>-2.0156</lower>
            <upper>2.0354</upper>
            <effort>304</effort>
            <velocity>8.8</velocity>
          </limit>
          <dynamics>
            <spring_reference>0</spring_reference>
            <spring_stiffness>0</spring_stiffness>
          </dynamics>
          <use_parent_model_frame>1</use_parent_model_frame>
        </axis>
        <physics>
          <provide_feedback>1</provide_feedback>
          <ode>
            <provide_feedback>1</provide_feedback>
            <implicit_spring_damper>1</implicit_spring_damper>
            <cfm_damping>1</cfm_damping>
            <limit>
              <cfm>0</cfm>
              <erp>0.2</erp>
            </limit>
          </ode>
        </physics>
      </joint>
      <link name='knee_2'>
        <pose frame=''>0.25 -0.1214 -0.4191 1.57079 1.57079 3.14159</pose>
        <inertial>
          <pose frame=''>0.108817 0.000109 -0.022639 0 -0 0</pose>
          <mass>1.93568</mass>
          <inertia>
            <ixx>0.00305342</ixx>
            <ixy>-4.22079e-05</ixy>
            <ixz>0.00136793</ixz>
            <iyy>0.0196033</iyy>
            <iyz>6.9941e-06</iyz>
            <izz>0.0198498</izz>
          </inertia>
        </inertial>
        <collision name='knee_2_collision'>
          <pose frame=''>0 0 0 0 -0 0</pose>
          <geometry>
            <mesh>
              <scale>0.001 0.001 0.001</scale>
              <uri>/home/ioannis/centauro_ws/src/iit-centauro-ros-pkg/centauro_urdf/meshes/simple/knee.stl</uri>
            </mesh>
          </geometry>
          <surface>
            <contact>
              <ode/>
            </contact>
            <friction>
              <ode/>
              <torsional>
                <ode/>
              </torsional>
            </friction>
            <bounce/>
          </surface>
          <max_contacts>10</max_contacts>
        </collision>
        <visual name='knee_2_visual'>
          <pose frame=''>0 0 0 0 -0 0</pose>
          <geometry>
            <mesh>
              <scale>0.001 0.001 0.001</scale>
              <uri>/home/ioannis/centauro_ws/src/iit-centauro-ros-pkg/centauro_urdf/meshes/knee.stl</uri>
            </mesh>
          </geometry>
          <material>
            <script>
              <name>Gazebo/LightBlueLaser</name>
              <uri>file://media/materials/scripts/gazebo.material</uri>
            </script>
          </material>
        </visual>
        <gravity>1</gravity>
        <velocity_decay/>
        <self_collide>0</self_collide>
        <enable_wind>0</enable_wind>
        <kinematic>0</kinematic>
      </link>
      <joint name='knee_pitch_2' type='revolute'>
        <child>knee_2</child>
        <parent>hip2_2</parent>
        <axis>
          <xyz>-0 1 0</xyz>
          <limit>
            <lower>-2.4006</lower>
            <upper>2.4034</upper>
            <effort>304</effort>
            <velocity>8.8</velocity>
          </limit>
          <dynamics>
            <spring_reference>0</spring_reference>
            <spring_stiffness>0</spring_stiffness>
          </dynamics>
          <use_parent_model_frame>1</use_parent_model_frame>
        </axis>
        <physics>
          <provide_feedback>1</provide_feedback>
          <ode>
            <provide_feedback>1</provide_feedback>
            <implicit_spring_damper>1</implicit_spring_damper>
            <cfm_damping>1</cfm_damping>
            <limit>
              <cfm>0</cfm>
              <erp>0.2</erp>
            </limit>
          </ode>
        </physics>
      </joint>
      <link name='ankle1_2'>
        <pose frame=''>0.25 -0.22155 -0.6191 -1.57079 1.57079 3.14159</pose>
        <inertial>
          <pose frame=''>0.032137 9.7e-05 -0.004422 0 -0 0</pose>
          <mass>1.23807</mass>
          <inertia>
            <ixx>0.00156105</ixx>
            <ixy>3.30597e-05</ixy>
            <ixz>-0.000131417</ixz>
            <iyy>0.00374232</iyy>
            <iyz>-2.12589e-05</iyz>
            <izz>0.00383124</izz>
          </inertia>
        </inertial>
        <collision name='ankle1_2_collision'>
          <pose frame=''>0 0 0 0 -0 0</pose>
          <geometry>
            <mesh>
              <scale>0.001 0.001 0.001</scale>
              <uri>/home/ioannis/centauro_ws/src/iit-centauro-ros-pkg/centauro_urdf/meshes/simple/ankle-pitch.stl</uri>
            </mesh>
          </geometry>
          <surface>
            <contact>
              <ode/>
            </contact>
            <friction>
              <ode/>
              <torsional>
                <ode/>
              </torsional>
            </friction>
            <bounce/>
          </surface>
          <max_contacts>10</max_contacts>
        </collision>
        <visual name='ankle1_2_visual'>
          <pose frame=''>0 0 0 0 -0 0</pose>
          <geometry>
            <mesh>
              <scale>0.001 0.001 0.001</scale>
              <uri>/home/ioannis/centauro_ws/src/iit-centauro-ros-pkg/centauro_urdf/meshes/ankle-pitch.stl</uri>
            </mesh>
          </geometry>
          <material>
            <script>
              <name>Gazebo/LightBlueLaser</name>
              <uri>file://media/materials/scripts/gazebo.material</uri>
            </script>
          </material>
        </visual>
        <gravity>1</gravity>
        <velocity_decay/>
        <self_collide>0</self_collide>
        <enable_wind>0</enable_wind>
        <kinematic>0</kinematic>
      </link>
      <joint name='ankle_pitch_2' type='revolute'>
        <child>ankle1_2</child>
        <parent>knee_2</parent>
        <axis>
          <xyz>0 -1 -0</xyz>
          <limit>
            <lower>-2.3266</lower>
            <upper>2.3914</upper>
            <effort>147</effort>
            <velocity>8.1</velocity>
          </limit>
          <dynamics>
            <spring_reference>0</spring_reference>
            <spring_stiffness>0</spring_stiffness>
          </dynamics>
          <use_parent_model_frame>1</use_parent_model_frame>
        </axis>
        <physics>
          <provide_feedback>1</provide_feedback>
          <ode>
            <provide_feedback>1</provide_feedback>
            <implicit_spring_damper>1</implicit_spring_damper>
            <cfm_damping>1</cfm_damping>
            <limit>
              <cfm>0</cfm>
              <erp>0.2</erp>
            </limit>
          </ode>
        </physics>
      </joint>
      <link name='ankle2_2'>
        <pose frame=''>0.25 -0.22155 -0.6191 -3.14159 0 0</pose>
        <inertial>
          <pose frame=''>0.000444 0.000439 0.193921 0 -0 0</pose>
          <mass>1.15659</mass>
          <inertia>
            <ixx>0.00490195</ixx>
            <ixy>4.3032e-06</ixy>
            <ixz>3.46491e-05</ixz>
            <iyy>0.00387242</iyy>
            <iyz>1.7099e-05</iyz>
            <izz>0.00217832</izz>
          </inertia>
        </inertial>
        <collision name='ankle2_2_collision'>
          <pose frame=''>0 0 0 0 -0 0</pose>
          <geometry>
            <mesh>
              <scale>0.001 0.001 0.001</scale>
              <uri>/home/ioannis/centauro_ws/src/iit-centauro-ros-pkg/centauro_urdf/meshes/simple/ankle-yaw.stl</uri>
            </mesh>
          </geometry>
          <surface>
            <contact>
              <ode/>
            </contact>
            <friction>
              <ode/>
              <torsional>
                <ode/>
              </torsional>
            </friction>
            <bounce/>
          </surface>
          <max_contacts>10</max_contacts>
        </collision>
        <visual name='ankle2_2_visual'>
          <pose frame=''>0 0 0 0 -0 0</pose>
          <geometry>
            <mesh>
              <scale>0.001 0.001 0.001</scale>
              <uri>/home/ioannis/centauro_ws/src/iit-centauro-ros-pkg/centauro_urdf/meshes/ankle-yaw.stl</uri>
            </mesh>
          </geometry>
          <material>
            <script>
              <name>Gazebo/LightBlueLaser</name>
              <uri>file://media/materials/scripts/gazebo.material</uri>
            </script>
          </material>
        </visual>
        <gravity>1</gravity>
        <velocity_decay/>
        <self_collide>0</self_collide>
        <enable_wind>0</enable_wind>
        <kinematic>0</kinematic>
      </link>
      <joint name='ankle_yaw_2' type='revolute'>
        <child>ankle2_2</child>
        <parent>ankle1_2</parent>
        <axis>
          <xyz>-0 0 -1</xyz>
          <limit>
            <lower>-2.5546</lower>
            <upper>2.5484</upper>
            <effort>35</effort>
            <velocity>20</velocity>
          </limit>
          <dynamics>
            <spring_reference>0</spring_reference>
            <spring_stiffness>0</spring_stiffness>
          </dynamics>
          <use_parent_model_frame>1</use_parent_model_frame>
        </axis>
        <physics>
          <provide_feedback>1</provide_feedback>
          <ode>
            <provide_feedback>1</provide_feedback>
            <implicit_spring_damper>1</implicit_spring_damper>
            <cfm_damping>1</cfm_damping>
            <limit>
              <cfm>0</cfm>
              <erp>0.2</erp>
            </limit>
          </ode>
        </physics>
      </joint>
      <link name='wheel_2'>
        <pose frame=''>0.25 -0.2224 -0.85645 -1.5708 -0 -3.14159</pose>
        <inertial>
          <pose frame=''>0 0 0.002427 0 -0 0</pose>
          <mass>1.7289</mass>
          <inertia>
            <ixx>0.00468643</ixx>
            <ixy>0</ixy>
            <ixz>0</ixz>
            <iyy>0.00467135</iyy>
            <iyz>0</iyz>
            <izz>0.0053126</izz>
          </inertia>
        </inertial>
        <collision name='wheel_2_collision'>
          <pose frame=''>0 0 0 0 -0 0</pose>
          <geometry>
            <cylinder>
              <length>0.06</length>
              <radius>0.078</radius>
            </cylinder>
          </geometry>
          <surface>
            <friction>
              <torsional>
                <coefficient>1</coefficient>
                <use_patch_radius>1</use_patch_radius>
                <patch_radius>0.2</patch_radius>
                <ode/>
              </torsional>
              <ode>
                <mu>1</mu>
                <mu2>1</mu2>
              </ode>
              <bullet>
                <friction>1</friction>
                <friction2>1</friction2>
              </bullet>
            </friction>
            <contact>
              <ode>
                <kp>2.1e+06</kp>
                <kd>1</kd>
                <max_vel>100</max_vel>
              </ode>
              <bullet>
                <soft_cfm>0.007</soft_cfm>
                <soft_erp>0.25</soft_erp>
                <kp>1e+06</kp>
                <kd>5</kd>
                <split_impulse>1</split_impulse>
                <split_impulse_penetration_threshold>-0.01</split_impulse_penetration_threshold>
              </bullet>
            </contact>
            <bounce/>
          </surface>
          <max_contacts>10</max_contacts>
        </collision>
        <visual name='wheel_2_visual'>
          <pose frame=''>0 0 0 0 -0 0</pose>
          <geometry>
            <mesh>
              <scale>0.001 0.001 0.001</scale>
              <uri>/home/ioannis/centauro_ws/src/iit-centauro-ros-pkg/centauro_urdf/meshes/wheel.stl</uri>
            </mesh>
          </geometry>
          <material>
            <script>
              <name>Gazebo/BlackTransparent</name>
              <uri>file://media/materials/scripts/gazebo.material</uri>
            </script>
          </material>
        </visual>
        <velocity_decay/>
        <gravity>1</gravity>
        <velocity_decay/>
        <self_collide>0</self_collide>
        <enable_wind>0</enable_wind>
        <kinematic>0</kinematic>
      </link>
      <joint name='j_wheel_2' type='revolute'>
        <child>wheel_2</child>
        <parent>ankle2_2</parent>
        <axis>
          <xyz>0 -1 -0</xyz>
          <limit>
            <lower>-1e+16</lower>
            <upper>1e+16</upper>
          </limit>
          <dynamics>
            <spring_reference>0</spring_reference>
            <spring_stiffness>0</spring_stiffness>
          </dynamics>
          <use_parent_model_frame>1</use_parent_model_frame>
        </axis>
        <physics>
          <provide_feedback>1</provide_feedback>
          <ode>
            <provide_feedback>1</provide_feedback>
            <implicit_spring_damper>1</implicit_spring_damper>
            <cfm_damping>1</cfm_damping>
            <limit>
              <cfm>0</cfm>
              <erp>0.2</erp>
            </limit>
          </ode>
        </physics>
      </joint>
      <link name='hip1_3'>
        <pose frame=''>-0.25 0.125 -0.0566 -3.14159 -0 2.68018</pose>
        <inertial>
          <pose frame=''>0.010214 0.018348 0.038091 0 -0 0</pose>
          <mass>1.91944</mass>
          <inertia>
            <ixx>0.00474396</ixx>
            <ixy>-0.000574705</ixy>
            <ixz>-0.000378414</ixz>
            <iyy>0.00405519</iyy>
            <iyz>-0.000740751</iyz>
            <izz>0.00341462</izz>
          </inertia>
        </inertial>
        <collision name='hip1_3_collision'>
          <pose frame=''>0 0 0 0 -0 0</pose>
          <geometry>
            <mesh>
              <scale>0.001 0.001 0.001</scale>
              <uri>/home/ioannis/centauro_ws/src/iit-centauro-ros-pkg/centauro_urdf/meshes/simple/hip-yaw.stl</uri>
            </mesh>
          </geometry>
          <surface>
            <contact>
              <ode/>
            </contact>
            <friction>
              <ode/>
              <torsional>
                <ode/>
              </torsional>
            </friction>
            <bounce/>
          </surface>
          <max_contacts>10</max_contacts>
        </collision>
        <visual name='hip1_3_visual'>
          <pose frame=''>0 0 0 0 -0 0</pose>
          <geometry>
            <mesh>
              <scale>0.001 0.001 0.001</scale>
              <uri>/home/ioannis/centauro_ws/src/iit-centauro-ros-pkg/centauro_urdf/meshes/hip-yaw.stl</uri>
            </mesh>
          </geometry>
          <material>
            <script>
              <name>Gazebo/LightBlueLaser</name>
              <uri>file://media/materials/scripts/gazebo.material</uri>
            </script>
          </material>
        </visual>
        <gravity>1</gravity>
        <velocity_decay/>
        <self_collide>0</self_collide>
        <enable_wind>0</enable_wind>
        <kinematic>0</kinematic>
      </link>
      <joint name='hip_yaw_3' type='revolute'>
        <child>hip1_3</child>
        <parent>pelvis</parent>
        <axis>
          <xyz>-0 -0 -1</xyz>
          <limit>
            <lower>-2.51</lower>
            <upper>2.03</upper>
            <effort>304</effort>
            <velocity>8.8</velocity>
          </limit>
          <dynamics>
            <spring_reference>0</spring_reference>
            <spring_stiffness>0</spring_stiffness>
          </dynamics>
          <use_parent_model_frame>1</use_parent_model_frame>
        </axis>
        <physics>
          <provide_feedback>1</provide_feedback>
          <ode>
            <provide_feedback>1</provide_feedback>
            <implicit_spring_damper>1</implicit_spring_damper>
            <cfm_damping>1</cfm_damping>
            <limit>
              <cfm>0</cfm>
              <erp>0.2</erp>
            </limit>
          </ode>
        </physics>
      </joint>
      <link name='hip2_3'>
        <pose frame=''>-0.25 0.125 -0.1191 -1.5708 0 0</pose>
        <inertial>
          <pose frame=''>2.6e-05 0.181027 0.08567 0 -0 0</pose>
          <mass>2.72645</mass>
          <inertia>
            <ixx>0.0485187</ixx>
            <ixy>-4.11894e-05</ixy>
            <ixz>-1.68778e-05</ixz>
            <iyy>0.00424205</iyy>
            <iyz>0.00322432</iyz>
            <izz>0.0482558</izz>
          </inertia>
        </inertial>
        <collision name='hip2_3_collision'>
          <pose frame=''>0 0 0 0 -0 0</pose>
          <geometry>
            <mesh>
              <scale>0.001 0.001 0.001</scale>
              <uri>/home/ioannis/centauro_ws/src/iit-centauro-ros-pkg/centauro_urdf/meshes/simple/hip-pitch.stl</uri>
            </mesh>
          </geometry>
          <surface>
            <contact>
              <ode/>
            </contact>
            <friction>
              <ode/>
              <torsional>
                <ode/>
              </torsional>
            </friction>
            <bounce/>
          </surface>
          <max_contacts>10</max_contacts>
        </collision>
        <visual name='hip2_3_visual'>
          <pose frame=''>0 0 0 0 -0 0</pose>
          <geometry>
            <mesh>
              <scale>0.001 0.001 0.001</scale>
              <uri>/home/ioannis/centauro_ws/src/iit-centauro-ros-pkg/centauro_urdf/meshes/hip-pitch.stl</uri>
            </mesh>
          </geometry>
          <material>
            <script>
              <name>Gazebo/BlackTransparent</name>
              <uri>file://media/materials/scripts/gazebo.material</uri>
            </script>
          </material>
        </visual>
        <gravity>1</gravity>
        <velocity_decay/>
        <self_collide>0</self_collide>
        <enable_wind>0</enable_wind>
        <kinematic>0</kinematic>
      </link>
      <joint name='hip_pitch_3' type='revolute'>
        <child>hip2_3</child>
        <parent>hip1_3</parent>
        <axis>
          <xyz>-0 1 -0</xyz>
          <limit>
            <lower>-2.0126</lower>
            <upper>2.0384</upper>
            <effort>304</effort>
            <velocity>8.8</velocity>
          </limit>
          <dynamics>
            <spring_reference>0</spring_reference>
            <spring_stiffness>0</spring_stiffness>
          </dynamics>
          <use_parent_model_frame>1</use_parent_model_frame>
        </axis>
        <physics>
          <provide_feedback>1</provide_feedback>
          <ode>
            <provide_feedback>1</provide_feedback>
            <implicit_spring_damper>1</implicit_spring_damper>
            <cfm_damping>1</cfm_damping>
            <limit>
              <cfm>0</cfm>
              <erp>0.2</erp>
            </limit>
          </ode>
        </physics>
      </joint>
      <link name='knee_3'>
        <pose frame=''>-0.25 0.1214 -0.4191 -1.57079 1.57079 3.14159</pose>
        <inertial>
          <pose frame=''>0.108817 0.000109 -0.022639 0 -0 0</pose>
          <mass>1.93568</mass>
          <inertia>
            <ixx>0.00305342</ixx>
            <ixy>-4.22079e-05</ixy>
            <ixz>0.00136793</ixz>
            <iyy>0.0196033</iyy>
            <iyz>6.9941e-06</iyz>
            <izz>0.0198498</izz>
          </inertia>
        </inertial>
        <collision name='knee_3_collision'>
          <pose frame=''>0 0 0 0 -0 0</pose>
          <geometry>
            <mesh>
              <scale>0.001 0.001 0.001</scale>
              <uri>/home/ioannis/centauro_ws/src/iit-centauro-ros-pkg/centauro_urdf/meshes/simple/knee.stl</uri>
            </mesh>
          </geometry>
          <surface>
            <contact>
              <ode/>
            </contact>
            <friction>
              <ode/>
              <torsional>
                <ode/>
              </torsional>
            </friction>
            <bounce/>
          </surface>
          <max_contacts>10</max_contacts>
        </collision>
        <visual name='knee_3_visual'>
          <pose frame=''>0 0 0 0 -0 0</pose>
          <geometry>
            <mesh>
              <scale>0.001 0.001 0.001</scale>
              <uri>/home/ioannis/centauro_ws/src/iit-centauro-ros-pkg/centauro_urdf/meshes/knee.stl</uri>
            </mesh>
          </geometry>
          <material>
            <script>
              <name>Gazebo/LightBlueLaser</name>
              <uri>file://media/materials/scripts/gazebo.material</uri>
            </script>
          </material>
        </visual>
        <gravity>1</gravity>
        <velocity_decay/>
        <self_collide>0</self_collide>
        <enable_wind>0</enable_wind>
        <kinematic>0</kinematic>
      </link>
      <joint name='knee_pitch_3' type='revolute'>
        <child>knee_3</child>
        <parent>hip2_3</parent>
        <axis>
          <xyz>-0 -1 0</xyz>
          <limit>
            <lower>-2.4056</lower>
            <upper>2.4064</upper>
            <effort>304</effort>
            <velocity>8.8</velocity>
          </limit>
          <dynamics>
            <spring_reference>0</spring_reference>
            <spring_stiffness>0</spring_stiffness>
          </dynamics>
          <use_parent_model_frame>1</use_parent_model_frame>
        </axis>
        <physics>
          <provide_feedback>1</provide_feedback>
          <ode>
            <provide_feedback>1</provide_feedback>
            <implicit_spring_damper>1</implicit_spring_damper>
            <cfm_damping>1</cfm_damping>
            <limit>
              <cfm>0</cfm>
              <erp>0.2</erp>
            </limit>
          </ode>
        </physics>
      </joint>
      <link name='ankle1_3'>
        <pose frame=''>-0.25 0.22155 -0.6191 1.57079 1.57079 3.14159</pose>
        <inertial>
          <pose frame=''>0.032137 9.7e-05 -0.004422 0 -0 0</pose>
          <mass>1.23807</mass>
          <inertia>
            <ixx>0.00156105</ixx>
            <ixy>3.30597e-05</ixy>
            <ixz>-0.000131417</ixz>
            <iyy>0.00374232</iyy>
            <iyz>-2.12589e-05</iyz>
            <izz>0.00383124</izz>
          </inertia>
        </inertial>
        <collision name='ankle1_3_collision'>
          <pose frame=''>0 0 0 0 -0 0</pose>
          <geometry>
            <mesh>
              <scale>0.001 0.001 0.001</scale>
              <uri>/home/ioannis/centauro_ws/src/iit-centauro-ros-pkg/centauro_urdf/meshes/simple/ankle-pitch.stl</uri>
            </mesh>
          </geometry>
          <surface>
            <contact>
              <ode/>
            </contact>
            <friction>
              <ode/>
              <torsional>
                <ode/>
              </torsional>
            </friction>
            <bounce/>
          </surface>
          <max_contacts>10</max_contacts>
        </collision>
        <visual name='ankle1_3_visual'>
          <pose frame=''>0 0 0 0 -0 0</pose>
          <geometry>
            <mesh>
              <scale>0.001 0.001 0.001</scale>
              <uri>/home/ioannis/centauro_ws/src/iit-centauro-ros-pkg/centauro_urdf/meshes/ankle-pitch.stl</uri>
            </mesh>
          </geometry>
          <material>
            <script>
              <name>Gazebo/LightBlueLaser</name>
              <uri>file://media/materials/scripts/gazebo.material</uri>
            </script>
          </material>
        </visual>
        <gravity>1</gravity>
        <velocity_decay/>
        <self_collide>0</self_collide>
        <enable_wind>0</enable_wind>
        <kinematic>0</kinematic>
      </link>
      <joint name='ankle_pitch_3' type='revolute'>
        <child>ankle1_3</child>
        <parent>knee_3</parent>
        <axis>
          <xyz>0 1 -0</xyz>
          <limit>
            <lower>-2.4696</lower>
            <upper>2.4464</upper>
            <effort>147</effort>
            <velocity>8.1</velocity>
          </limit>
          <dynamics>
            <spring_reference>0</spring_reference>
            <spring_stiffness>0</spring_stiffness>
          </dynamics>
          <use_parent_model_frame>1</use_parent_model_frame>
        </axis>
        <physics>
          <provide_feedback>1</provide_feedback>
          <ode>
            <provide_feedback>1</provide_feedback>
            <implicit_spring_damper>1</implicit_spring_damper>
            <cfm_damping>1</cfm_damping>
            <limit>
              <cfm>0</cfm>
              <erp>0.2</erp>
            </limit>
          </ode>
        </physics>
      </joint>
      <link name='ankle2_3'>
        <pose frame=''>-0.25 0.22155 -0.6191 -3.14159 -0 3.14159</pose>
        <inertial>
          <pose frame=''>0.000444 0.000439 0.193921 0 -0 0</pose>
          <mass>1.15659</mass>
          <inertia>
            <ixx>0.00490195</ixx>
            <ixy>4.3032e-06</ixy>
            <ixz>3.46491e-05</ixz>
            <iyy>0.00387242</iyy>
            <iyz>1.7099e-05</iyz>
            <izz>0.00217832</izz>
          </inertia>
        </inertial>
        <collision name='ankle2_3_collision'>
          <pose frame=''>0 0 0 0 -0 0</pose>
          <geometry>
            <mesh>
              <scale>0.001 0.001 0.001</scale>
              <uri>/home/ioannis/centauro_ws/src/iit-centauro-ros-pkg/centauro_urdf/meshes/simple/ankle-yaw.stl</uri>
            </mesh>
          </geometry>
          <surface>
            <contact>
              <ode/>
            </contact>
            <friction>
              <ode/>
              <torsional>
                <ode/>
              </torsional>
            </friction>
            <bounce/>
          </surface>
          <max_contacts>10</max_contacts>
        </collision>
        <visual name='ankle2_3_visual'>
          <pose frame=''>0 0 0 0 -0 0</pose>
          <geometry>
            <mesh>
              <scale>0.001 0.001 0.001</scale>
              <uri>/home/ioannis/centauro_ws/src/iit-centauro-ros-pkg/centauro_urdf/meshes/ankle-yaw.stl</uri>
            </mesh>
          </geometry>
          <material>
            <script>
              <name>Gazebo/LightBlueLaser</name>
              <uri>file://media/materials/scripts/gazebo.material</uri>
            </script>
          </material>
        </visual>
        <gravity>1</gravity>
        <velocity_decay/>
        <self_collide>0</self_collide>
        <enable_wind>0</enable_wind>
        <kinematic>0</kinematic>
      </link>
      <joint name='ankle_yaw_3' type='revolute'>
        <child>ankle2_3</child>
        <parent>ankle1_3</parent>
        <axis>
          <xyz>0 -0 -1</xyz>
          <limit>
            <lower>-2.5606</lower>
            <upper>2.5454</upper>
            <effort>35</effort>
            <velocity>20</velocity>
          </limit>
          <dynamics>
            <spring_reference>0</spring_reference>
            <spring_stiffness>0</spring_stiffness>
          </dynamics>
          <use_parent_model_frame>1</use_parent_model_frame>
        </axis>
        <physics>
          <provide_feedback>1</provide_feedback>
          <ode>
            <provide_feedback>1</provide_feedback>
            <implicit_spring_damper>1</implicit_spring_damper>
            <cfm_damping>1</cfm_damping>
            <limit>
              <cfm>0</cfm>
              <erp>0.2</erp>
            </limit>
          </ode>
        </physics>
      </joint>
      <link name='wheel_3'>
        <pose frame=''>-0.25 0.2224 -0.85645 -1.5708 -0 -0</pose>
        <inertial>
          <pose frame=''>0 0 0.002427 0 -0 0</pose>
          <mass>1.7289</mass>
          <inertia>
            <ixx>0.00468643</ixx>
            <ixy>0</ixy>
            <ixz>0</ixz>
            <iyy>0.00467135</iyy>
            <iyz>0</iyz>
            <izz>0.0053126</izz>
          </inertia>
        </inertial>
        <collision name='wheel_3_collision'>
          <pose frame=''>0 0 0 0 -0 0</pose>
          <geometry>
            <cylinder>
              <length>0.06</length>
              <radius>0.078</radius>
            </cylinder>
          </geometry>
          <surface>
            <friction>
              <torsional>
                <coefficient>1</coefficient>
                <use_patch_radius>1</use_patch_radius>
                <patch_radius>0.2</patch_radius>
                <ode/>
              </torsional>
              <ode>
                <mu>1</mu>
                <mu2>1</mu2>
              </ode>
              <bullet>
                <friction>1</friction>
                <friction2>1</friction2>
              </bullet>
            </friction>
            <contact>
              <ode>
                <kp>2.1e+06</kp>
                <kd>1</kd>
                <max_vel>100</max_vel>
              </ode>
              <bullet>
                <soft_cfm>0.007</soft_cfm>
                <soft_erp>0.25</soft_erp>
                <kp>1e+06</kp>
                <kd>5</kd>
                <split_impulse>1</split_impulse>
                <split_impulse_penetration_threshold>-0.01</split_impulse_penetration_threshold>
              </bullet>
            </contact>
            <bounce/>
          </surface>
          <max_contacts>10</max_contacts>
        </collision>
        <visual name='wheel_3_visual'>
          <pose frame=''>0 0 0 0 -0 0</pose>
          <geometry>
            <mesh>
              <scale>0.001 0.001 0.001</scale>
              <uri>/home/ioannis/centauro_ws/src/iit-centauro-ros-pkg/centauro_urdf/meshes/wheel.stl</uri>
            </mesh>
          </geometry>
          <material>
            <script>
              <name>Gazebo/BlackTransparent</name>
              <uri>file://media/materials/scripts/gazebo.material</uri>
            </script>
          </material>
        </visual>
        <velocity_decay/>
        <gravity>1</gravity>
        <velocity_decay/>
        <self_collide>0</self_collide>
        <enable_wind>0</enable_wind>
        <kinematic>0</kinematic>
      </link>
      <joint name='j_wheel_3' type='revolute'>
        <child>wheel_3</child>
        <parent>ankle2_3</parent>
        <axis>
          <xyz>0 1 -0</xyz>
          <limit>
            <lower>-1e+16</lower>
            <upper>1e+16</upper>
          </limit>
          <dynamics>
            <spring_reference>0</spring_reference>
            <spring_stiffness>0</spring_stiffness>
          </dynamics>
          <use_parent_model_frame>1</use_parent_model_frame>
        </axis>
        <physics>
          <provide_feedback>1</provide_feedback>
          <ode>
            <provide_feedback>1</provide_feedback>
            <implicit_spring_damper>1</implicit_spring_damper>
            <cfm_damping>1</cfm_damping>
            <limit>
              <cfm>0</cfm>
              <erp>0.2</erp>
            </limit>
          </ode>
        </physics>
      </joint>
      <link name='hip1_4'>
        <pose frame=''>-0.25 -0.125 -0.0566 -3.14159 -0 -2.68018</pose>
        <inertial>
          <pose frame=''>0.010214 -0.018348 0.038091 0 -0 0</pose>
          <mass>1.91944</mass>
          <inertia>
            <ixx>0.00474396</ixx>
            <ixy>0.000574705</ixy>
            <ixz>-0.000378414</ixz>
            <iyy>0.00405519</iyy>
            <iyz>0.000740751</iyz>
            <izz>0.00341462</izz>
          </inertia>
        </inertial>
        <collision name='hip1_4_collision'>
          <pose frame=''>0 0 0 0 -0 -2.21876</pose>
          <geometry>
            <mesh>
              <scale>0.001 0.001 0.001</scale>
              <uri>/home/ioannis/centauro_ws/src/iit-centauro-ros-pkg/centauro_urdf/meshes/simple/hip-yaw.stl</uri>
            </mesh>
          </geometry>
          <surface>
            <contact>
              <ode/>
            </contact>
            <friction>
              <ode/>
              <torsional>
                <ode/>
              </torsional>
            </friction>
            <bounce/>
          </surface>
          <max_contacts>10</max_contacts>
        </collision>
        <visual name='hip1_4_visual'>
          <pose frame=''>0 0 0 0 -0 -2.21876</pose>
          <geometry>
            <mesh>
              <scale>0.001 0.001 0.001</scale>
              <uri>/home/ioannis/centauro_ws/src/iit-centauro-ros-pkg/centauro_urdf/meshes/hip-yaw.stl</uri>
            </mesh>
          </geometry>
          <material>
            <script>
              <name>Gazebo/LightBlueLaser</name>
              <uri>file://media/materials/scripts/gazebo.material</uri>
            </script>
          </material>
        </visual>
        <gravity>1</gravity>
        <velocity_decay/>
        <self_collide>0</self_collide>
        <enable_wind>0</enable_wind>
        <kinematic>0</kinematic>
      </link>
      <joint name='hip_yaw_4' type='revolute'>
        <child>hip1_4</child>
        <parent>pelvis</parent>
        <axis>
          <xyz>0 -0 -1</xyz>
          <limit>
            <lower>-2.03</lower>
            <upper>2.51</upper>
            <effort>304</effort>
            <velocity>8.8</velocity>
          </limit>
          <dynamics>
            <spring_reference>0</spring_reference>
            <spring_stiffness>0</spring_stiffness>
          </dynamics>
          <use_parent_model_frame>1</use_parent_model_frame>
        </axis>
        <physics>
          <provide_feedback>1</provide_feedback>
          <ode>
            <provide_feedback>1</provide_feedback>
            <implicit_spring_damper>1</implicit_spring_damper>
            <cfm_damping>1</cfm_damping>
            <limit>
              <cfm>0</cfm>
              <erp>0.2</erp>
            </limit>
          </ode>
        </physics>
      </joint>
      <link name='hip2_4'>
        <pose frame=''>-0.25 -0.125 -0.1191 -1.5708 -0 -3.14159</pose>
        <inertial>
          <pose frame=''>2.6e-05 0.181027 0.08567 0 -0 0</pose>
          <mass>2.72645</mass>
          <inertia>
            <ixx>0.0485187</ixx>
            <ixy>-4.11894e-05</ixy>
            <ixz>-1.68778e-05</ixz>
            <iyy>0.00424205</iyy>
            <iyz>0.00322432</iyz>
            <izz>0.0482558</izz>
          </inertia>
        </inertial>
        <collision name='hip2_4_collision'>
          <pose frame=''>0 0 0 0 -0 0</pose>
          <geometry>
            <mesh>
              <scale>0.001 0.001 0.001</scale>
              <uri>/home/ioannis/centauro_ws/src/iit-centauro-ros-pkg/centauro_urdf/meshes/simple/hip-pitch.stl</uri>
            </mesh>
          </geometry>
          <surface>
            <contact>
              <ode/>
            </contact>
            <friction>
              <ode/>
              <torsional>
                <ode/>
              </torsional>
            </friction>
            <bounce/>
          </surface>
          <max_contacts>10</max_contacts>
        </collision>
        <visual name='hip2_4_visual'>
          <pose frame=''>0 0 0 0 -0 0</pose>
          <geometry>
            <mesh>
              <scale>0.001 0.001 0.001</scale>
              <uri>/home/ioannis/centauro_ws/src/iit-centauro-ros-pkg/centauro_urdf/meshes/hip-pitch.stl</uri>
            </mesh>
          </geometry>
          <material>
            <script>
              <name>Gazebo/BlackTransparent</name>
              <uri>file://media/materials/scripts/gazebo.material</uri>
            </script>
          </material>
        </visual>
        <gravity>1</gravity>
        <velocity_decay/>
        <self_collide>0</self_collide>
        <enable_wind>0</enable_wind>
        <kinematic>0</kinematic>
      </link>
      <joint name='hip_pitch_4' type='revolute'>
        <child>hip2_4</child>
        <parent>hip1_4</parent>
        <axis>
          <xyz>0 -1 -0</xyz>
          <limit>
            <lower>-2.0326</lower>
            <upper>2.0524</upper>
            <effort>304</effort>
            <velocity>8.8</velocity>
          </limit>
          <dynamics>
            <spring_reference>0</spring_reference>
            <spring_stiffness>0</spring_stiffness>
          </dynamics>
          <use_parent_model_frame>1</use_parent_model_frame>
        </axis>
        <physics>
          <provide_feedback>1</provide_feedback>
          <ode>
            <provide_feedback>1</provide_feedback>
            <implicit_spring_damper>1</implicit_spring_damper>
            <cfm_damping>1</cfm_damping>
            <limit>
              <cfm>0</cfm>
              <erp>0.2</erp>
            </limit>
          </ode>
        </physics>
      </joint>
      <link name='knee_4'>
        <pose frame=''>-0.25 -0.1214 -0.4191 1.57079 1.57079 3.14159</pose>
        <inertial>
          <pose frame=''>0.108817 0.000109 -0.022639 0 -0 0</pose>
          <mass>1.93568</mass>
          <inertia>
            <ixx>0.00305342</ixx>
            <ixy>-4.22079e-05</ixy>
            <ixz>0.00136793</ixz>
            <iyy>0.0196033</iyy>
            <iyz>6.9941e-06</iyz>
            <izz>0.0198498</izz>
          </inertia>
        </inertial>
        <collision name='knee_4_collision'>
          <pose frame=''>0 0 0 0 -0 0</pose>
          <geometry>
            <mesh>
              <scale>0.001 0.001 0.001</scale>
              <uri>/home/ioannis/centauro_ws/src/iit-centauro-ros-pkg/centauro_urdf/meshes/simple/knee.stl</uri>
            </mesh>
          </geometry>
          <surface>
            <contact>
              <ode/>
            </contact>
            <friction>
              <ode/>
              <torsional>
                <ode/>
              </torsional>
            </friction>
            <bounce/>
          </surface>
          <max_contacts>10</max_contacts>
        </collision>
        <visual name='knee_4_visual'>
          <pose frame=''>0 0 0 0 -0 0</pose>
          <geometry>
            <mesh>
              <scale>0.001 0.001 0.001</scale>
              <uri>/home/ioannis/centauro_ws/src/iit-centauro-ros-pkg/centauro_urdf/meshes/knee.stl</uri>
            </mesh>
          </geometry>
          <material>
            <script>
              <name>Gazebo/LightBlueLaser</name>
              <uri>file://media/materials/scripts/gazebo.material</uri>
            </script>
          </material>
        </visual>
        <gravity>1</gravity>
        <velocity_decay/>
        <self_collide>0</self_collide>
        <enable_wind>0</enable_wind>
        <kinematic>0</kinematic>
      </link>
      <joint name='knee_pitch_4' type='revolute'>
        <child>knee_4</child>
        <parent>hip2_4</parent>
        <axis>
          <xyz>0 1 0</xyz>
          <limit>
            <lower>-2.4176</lower>
            <upper>2.3884</upper>
            <effort>304</effort>
            <velocity>8.8</velocity>
          </limit>
          <dynamics>
            <spring_reference>0</spring_reference>
            <spring_stiffness>0</spring_stiffness>
          </dynamics>
          <use_parent_model_frame>1</use_parent_model_frame>
        </axis>
        <physics>
          <provide_feedback>1</provide_feedback>
          <ode>
            <provide_feedback>1</provide_feedback>
            <implicit_spring_damper>1</implicit_spring_damper>
            <cfm_damping>1</cfm_damping>
            <limit>
              <cfm>0</cfm>
              <erp>0.2</erp>
            </limit>
          </ode>
        </physics>
      </joint>
      <link name='ankle1_4'>
        <pose frame=''>-0.25 -0.22155 -0.6191 -1.57079 1.57079 3.14159</pose>
        <inertial>
          <pose frame=''>0.032137 9.7e-05 -0.004422 0 -0 0</pose>
          <mass>1.23807</mass>
          <inertia>
            <ixx>0.00156105</ixx>
            <ixy>3.30597e-05</ixy>
            <ixz>-0.000131417</ixz>
            <iyy>0.00374232</iyy>
            <iyz>-2.12589e-05</iyz>
            <izz>0.00383124</izz>
          </inertia>
        </inertial>
        <collision name='ankle1_4_collision'>
          <pose frame=''>0 0 0 0 -0 0</pose>
          <geometry>
            <mesh>
              <scale>0.001 0.001 0.001</scale>
              <uri>/home/ioannis/centauro_ws/src/iit-centauro-ros-pkg/centauro_urdf/meshes/simple/ankle-pitch.stl</uri>
            </mesh>
          </geometry>
          <surface>
            <contact>
              <ode/>
            </contact>
            <friction>
              <ode/>
              <torsional>
                <ode/>
              </torsional>
            </friction>
            <bounce/>
          </surface>
          <max_contacts>10</max_contacts>
        </collision>
        <visual name='ankle1_4_visual'>
          <pose frame=''>0 0 0 0 -0 0</pose>
          <geometry>
            <mesh>
              <scale>0.001 0.001 0.001</scale>
              <uri>/home/ioannis/centauro_ws/src/iit-centauro-ros-pkg/centauro_urdf/meshes/ankle-pitch.stl</uri>
            </mesh>
          </geometry>
          <material>
            <script>
              <name>Gazebo/LightBlueLaser</name>
              <uri>file://media/materials/scripts/gazebo.material</uri>
            </script>
          </material>
        </visual>
        <gravity>1</gravity>
        <velocity_decay/>
        <self_collide>0</self_collide>
        <enable_wind>0</enable_wind>
        <kinematic>0</kinematic>
      </link>
      <joint name='ankle_pitch_4' type='revolute'>
        <child>ankle1_4</child>
        <parent>knee_4</parent>
        <axis>
          <xyz>-0 -1 -0</xyz>
          <limit>
            <lower>-2.3426</lower>
            <upper>2.3934</upper>
            <effort>147</effort>
            <velocity>8.1</velocity>
          </limit>
          <dynamics>
            <spring_reference>0</spring_reference>
            <spring_stiffness>0</spring_stiffness>
          </dynamics>
          <use_parent_model_frame>1</use_parent_model_frame>
        </axis>
        <physics>
          <provide_feedback>1</provide_feedback>
          <ode>
            <provide_feedback>1</provide_feedback>
            <implicit_spring_damper>1</implicit_spring_damper>
            <cfm_damping>1</cfm_damping>
            <limit>
              <cfm>0</cfm>
              <erp>0.2</erp>
            </limit>
          </ode>
        </physics>
      </joint>
      <link name='ankle2_4'>
        <pose frame=''>-0.25 -0.22155 -0.6191 3.14159 -0 0</pose>
        <inertial>
          <pose frame=''>0.000444 0.000439 0.193921 0 -0 0</pose>
          <mass>1.15659</mass>
          <inertia>
            <ixx>0.00490195</ixx>
            <ixy>4.3032e-06</ixy>
            <ixz>3.46491e-05</ixz>
            <iyy>0.00387242</iyy>
            <iyz>1.7099e-05</iyz>
            <izz>0.00217832</izz>
          </inertia>
        </inertial>
        <collision name='ankle2_4_collision'>
          <pose frame=''>0 0 0 0 -0 0</pose>
          <geometry>
            <mesh>
              <scale>0.001 0.001 0.001</scale>
              <uri>/home/ioannis/centauro_ws/src/iit-centauro-ros-pkg/centauro_urdf/meshes/simple/ankle-yaw.stl</uri>
            </mesh>
          </geometry>
          <surface>
            <contact>
              <ode/>
            </contact>
            <friction>
              <ode/>
              <torsional>
                <ode/>
              </torsional>
            </friction>
            <bounce/>
          </surface>
          <max_contacts>10</max_contacts>
        </collision>
        <visual name='ankle2_4_visual'>
          <pose frame=''>0 0 0 0 -0 0</pose>
          <geometry>
            <mesh>
              <scale>0.001 0.001 0.001</scale>
              <uri>/home/ioannis/centauro_ws/src/iit-centauro-ros-pkg/centauro_urdf/meshes/ankle-yaw.stl</uri>
            </mesh>
          </geometry>
          <material>
            <script>
              <name>Gazebo/LightBlueLaser</name>
              <uri>file://media/materials/scripts/gazebo.material</uri>
            </script>
          </material>
        </visual>
        <gravity>1</gravity>
        <velocity_decay/>
        <self_collide>0</self_collide>
        <enable_wind>0</enable_wind>
        <kinematic>0</kinematic>
      </link>
      <joint name='ankle_yaw_4' type='revolute'>
        <child>ankle2_4</child>
        <parent>ankle1_4</parent>
        <axis>
          <xyz>-0 -0 -1</xyz>
          <limit>
            <lower>-2.6046</lower>
            <upper>2.5514</upper>
            <effort>35</effort>
            <velocity>20</velocity>
          </limit>
          <dynamics>
            <spring_reference>0</spring_reference>
            <spring_stiffness>0</spring_stiffness>
          </dynamics>
          <use_parent_model_frame>1</use_parent_model_frame>
        </axis>
        <physics>
          <provide_feedback>1</provide_feedback>
          <ode>
            <provide_feedback>1</provide_feedback>
            <implicit_spring_damper>1</implicit_spring_damper>
            <cfm_damping>1</cfm_damping>
            <limit>
              <cfm>0</cfm>
              <erp>0.2</erp>
            </limit>
          </ode>
        </physics>
      </joint>
      <link name='wheel_4'>
        <pose frame=''>-0.25 -0.2224 -0.85645 -1.5708 -0 3.14159</pose>
        <inertial>
          <pose frame=''>0 0 0.002427 0 -0 0</pose>
          <mass>1.7289</mass>
          <inertia>
            <ixx>0.00468643</ixx>
            <ixy>0</ixy>
            <ixz>0</ixz>
            <iyy>0.00467135</iyy>
            <iyz>0</iyz>
            <izz>0.0053126</izz>
          </inertia>
        </inertial>
        <collision name='wheel_4_collision'>
          <pose frame=''>0 0 0 0 -0 0</pose>
          <geometry>
            <cylinder>
              <length>0.06</length>
              <radius>0.078</radius>
            </cylinder>
          </geometry>
          <surface>
            <friction>
              <torsional>
                <coefficient>1</coefficient>
                <use_patch_radius>1</use_patch_radius>
                <patch_radius>0.2</patch_radius>
                <ode/>
              </torsional>
              <ode>
                <mu>1</mu>
                <mu2>1</mu2>
              </ode>
              <bullet>
                <friction>1</friction>
                <friction2>1</friction2>
              </bullet>
            </friction>
            <contact>
              <ode>
                <kp>2.1e+06</kp>
                <kd>1</kd>
                <max_vel>100</max_vel>
              </ode>
              <bullet>
                <soft_cfm>0.007</soft_cfm>
                <soft_erp>0.25</soft_erp>
                <kp>1e+06</kp>
                <kd>5</kd>
                <split_impulse>1</split_impulse>
                <split_impulse_penetration_threshold>-0.01</split_impulse_penetration_threshold>
              </bullet>
            </contact>
            <bounce/>
          </surface>
          <max_contacts>10</max_contacts>
        </collision>
        <visual name='wheel_4_visual'>
          <pose frame=''>0 0 0 0 -0 0</pose>
          <geometry>
            <mesh>
              <scale>0.001 0.001 0.001</scale>
              <uri>/home/ioannis/centauro_ws/src/iit-centauro-ros-pkg/centauro_urdf/meshes/wheel.stl</uri>
            </mesh>
          </geometry>
          <material>
            <script>
              <name>Gazebo/BlackTransparent</name>
              <uri>file://media/materials/scripts/gazebo.material</uri>
            </script>
          </material>
        </visual>
        <velocity_decay/>
        <gravity>1</gravity>
        <velocity_decay/>
        <self_collide>0</self_collide>
        <enable_wind>0</enable_wind>
        <kinematic>0</kinematic>
      </link>
      <joint name='j_wheel_4' type='revolute'>
        <child>wheel_4</child>
        <parent>ankle2_4</parent>
        <axis>
          <xyz>-0 -1 -0</xyz>
          <limit>
            <lower>-1e+16</lower>
            <upper>1e+16</upper>
          </limit>
          <dynamics>
            <spring_reference>0</spring_reference>
            <spring_stiffness>0</spring_stiffness>
          </dynamics>
          <use_parent_model_frame>1</use_parent_model_frame>
        </axis>
        <physics>
          <provide_feedback>1</provide_feedback>
          <ode>
            <provide_feedback>1</provide_feedback>
            <implicit_spring_damper>1</implicit_spring_damper>
            <cfm_damping>1</cfm_damping>
            <limit>
              <cfm>0</cfm>
              <erp>0.2</erp>
            </limit>
          </ode>
        </physics>
      </joint>
      <link name='torso_2'>
        <pose frame=''>0.2 0 0.256 0 -0 0</pose>
        <inertial>
          <pose frame=''>-0.019498 0.004532 0.137683 0 -0 0</pose>
          <mass>11.4927</mass>
          <inertia>
            <ixx>0.0636434</ixx>
            <ixy>8.939e-05</ixy>
            <ixz>-0.00086873</ixz>
            <iyy>0.0268023</iyy>
            <iyz>-4.657e-05</iyz>
            <izz>0.0474301</izz>
          </inertia>
        </inertial>
        <collision name='torso_2_collision'>
          <pose frame=''>0 0 0 0 -0 0</pose>
          <geometry>
            <mesh>
              <scale>0.001 0.001 0.001</scale>
              <uri>/home/ioannis/centauro_ws/src/iit-centauro-ros-pkg/centauro_urdf/meshes/simple/link1.stl</uri>
            </mesh>
          </geometry>
          <surface>
            <contact>
              <ode/>
            </contact>
            <friction>
              <ode/>
              <torsional>
                <ode/>
              </torsional>
            </friction>
            <bounce/>
          </surface>
          <max_contacts>10</max_contacts>
        </collision>
        <visual name='torso_2_visual'>
          <pose frame=''>0 0 0 0 -0 0</pose>
          <geometry>
            <mesh>
              <scale>0.001 0.001 0.001</scale>
              <uri>/home/ioannis/centauro_ws/src/iit-centauro-ros-pkg/centauro_urdf/meshes/link1.stl</uri>
            </mesh>
          </geometry>
          <material>
            <script>
              <name>Gazebo/BlackTransparent</name>
              <uri>file://media/materials/scripts/gazebo.material</uri>
            </script>
          </material>
        </visual>
        <gravity>1</gravity>
        <velocity_decay/>
        <self_collide>0</self_collide>
        <enable_wind>0</enable_wind>
        <kinematic>0</kinematic>
      </link>
      <joint name='torso_yaw' type='revolute'>
        <child>torso_2</child>
        <parent>pelvis</parent>
        <axis>
          <xyz>0 0 1</xyz>
          <limit>
            <lower>-2.618</lower>
            <upper>2.618</upper>
            <effort>147</effort>
            <velocity>5.7</velocity>
          </limit>
          <dynamics>
            <spring_reference>0</spring_reference>
            <spring_stiffness>0</spring_stiffness>
          </dynamics>
          <use_parent_model_frame>1</use_parent_model_frame>
        </axis>
        <physics>
          <provide_feedback>1</provide_feedback>
          <ode>
            <provide_feedback>1</provide_feedback>
            <implicit_spring_damper>1</implicit_spring_damper>
            <cfm_damping>1</cfm_damping>
            <limit>
              <cfm>0</cfm>
              <erp>0.2</erp>
            </limit>
          </ode>
        </physics>
      </joint>
      <link name='arm1_1'>
        <pose frame=''>0.245748 0.169137 0.372626 0.174533 -0 -0.523599</pose>
        <inertial>
          <pose frame=''>-0.007446 0.034108 0.00011 0 -0 0</pose>
          <mass>1.96287</mass>
          <inertia>
            <ixx>0.00535477</ixx>
            <ixy>0.000364289</ixy>
            <ixz>1.50896e-05</ixz>
            <iyy>0.00339233</iyy>
            <iyz>5.56923e-05</iyz>
            <izz>0.00689214</izz>
          </inertia>
        </inertial>
        <collision name='arm1_1_collision'>
          <pose frame=''>0 0 0 0 -0 0</pose>
          <geometry>
            <mesh>
              <scale>0.001 -0.001 0.001</scale>
              <uri>/home/ioannis/centauro_ws/src/iit-centauro-ros-pkg/centauro_urdf/meshes/simple/ShoulderPitch.STL</uri>
            </mesh>
          </geometry>
          <surface>
            <contact>
              <ode/>
            </contact>
            <friction>
              <ode/>
              <torsional>
                <ode/>
              </torsional>
            </friction>
            <bounce/>
          </surface>
          <max_contacts>10</max_contacts>
        </collision>
        <visual name='arm1_1_visual'>
          <pose frame=''>0 0 0 0 -0 0</pose>
          <geometry>
            <mesh>
              <scale>0.001 -0.001 0.001</scale>
              <uri>/home/ioannis/centauro_ws/src/iit-centauro-ros-pkg/centauro_urdf/meshes/ShoulderPitch.STL</uri>
            </mesh>
          </geometry>
          <material>
            <script>
              <name>Gazebo/BlackTransparent</name>
              <uri>file://media/materials/scripts/gazebo.material</uri>
            </script>
          </material>
        </visual>
        <gravity>1</gravity>
        <velocity_decay/>
        <self_collide>0</self_collide>
        <enable_wind>0</enable_wind>
        <kinematic>0</kinematic>
      </link>
      <joint name='j_arm1_1' type='revolute'>
        <child>arm1_1</child>
        <parent>torso_2</parent>
        <axis>
          <xyz>0.492404 0.852869 0.173648</xyz>
          <limit>
            <lower>-3.312</lower>
            <upper>1.615</upper>
            <effort>147</effort>
            <velocity>3.86</velocity>
          </limit>
          <dynamics>
            <spring_reference>0</spring_reference>
            <spring_stiffness>0</spring_stiffness>
          </dynamics>
          <use_parent_model_frame>1</use_parent_model_frame>
        </axis>
        <physics>
          <provide_feedback>1</provide_feedback>
          <ode>
            <provide_feedback>1</provide_feedback>
            <implicit_spring_damper>1</implicit_spring_damper>
            <cfm_damping>1</cfm_damping>
            <limit>
              <cfm>0</cfm>
              <erp>0.2</erp>
            </limit>
          </ode>
        </physics>
      </joint>
      <link name='arm1_2'>
        <pose frame=''>0.198204 0.26709 0.383392 0 0 -0.523599</pose>
        <inertial>
          <pose frame=''>0.058142 5.7e-05 -0.077478 0 -0 0</pose>
          <mass>1.85958</mass>
          <inertia>
            <ixx>0.0137766</ixx>
            <ixy>3.77887e-05</ixy>
            <ixz>0.00376902</ixz>
            <iyy>0.0156775</iyy>
            <iyz>-9.48935e-06</iyz>
            <izz>0.00463177</izz>
          </inertia>
        </inertial>
        <collision name='arm1_2_collision'>
          <pose frame=''>0 0 0 0 -0 0</pose>
          <geometry>
            <mesh>
              <scale>0.001 -0.001 0.001</scale>
              <uri>/home/ioannis/centauro_ws/src/iit-centauro-ros-pkg/centauro_urdf/meshes/simple/ShoulderRoll.STL</uri>
            </mesh>
          </geometry>
          <surface>
            <contact>
              <ode/>
            </contact>
            <friction>
              <ode/>
              <torsional>
                <ode/>
              </torsional>
            </friction>
            <bounce/>
          </surface>
          <max_contacts>10</max_contacts>
        </collision>
        <visual name='arm1_2_visual'>
          <pose frame=''>0 0 0 0 -0 0</pose>
          <geometry>
            <mesh>
              <scale>0.001 -0.001 0.001</scale>
              <uri>/home/ioannis/centauro_ws/src/iit-centauro-ros-pkg/centauro_urdf/meshes/ShoulderRoll.STL</uri>
            </mesh>
          </geometry>
          <material>
            <script>
              <name>Gazebo/LightBlueLaser</name>
              <uri>file://media/materials/scripts/gazebo.material</uri>
            </script>
          </material>
        </visual>
        <gravity>1</gravity>
        <velocity_decay/>
        <self_collide>0</self_collide>
        <enable_wind>0</enable_wind>
        <kinematic>0</kinematic>
      </link>
      <joint name='j_arm1_2' type='revolute'>
        <child>arm1_2</child>
        <parent>arm1_1</parent>
        <axis>
          <xyz>0.866025 -0.5 -0</xyz>
          <limit>
            <lower>0.02</lower>
            <upper>3.431</upper>
            <effort>147</effort>
            <velocity>3.86</velocity>
          </limit>
          <dynamics>
            <spring_reference>0</spring_reference>
            <spring_stiffness>0</spring_stiffness>
          </dynamics>
          <use_parent_model_frame>1</use_parent_model_frame>
        </axis>
        <physics>
          <provide_feedback>1</provide_feedback>
          <ode>
            <provide_feedback>1</provide_feedback>
            <implicit_spring_damper>1</implicit_spring_damper>
            <cfm_damping>1</cfm_damping>
            <limit>
              <cfm>0</cfm>
              <erp>0.2</erp>
            </limit>
          </ode>
        </physics>
      </joint>
      <link name='arm1_3'>
        <pose frame=''>0.276277 0.222015 0.165242 0 0 -0.523599</pose>
        <inertial>
          <pose frame=''>0.014625 0.000817 -0.028334 0 -0 0</pose>
          <mass>1.66781</mass>
          <inertia>
            <ixx>0.00644804</ixx>
            <ixy>-0.000156391</ixy>
            <ixz>0.00122054</ixz>
            <iyy>0.00733721</iyy>
            <iyz>8.99415e-05</iyz>
            <izz>0.00367384</izz>
          </inertia>
        </inertial>
        <collision name='arm1_3_collision'>
          <pose frame=''>0 0 0 0 -0 0</pose>
          <geometry>
            <mesh>
              <scale>0.001 -0.001 0.001</scale>
              <uri>/home/ioannis/centauro_ws/src/iit-centauro-ros-pkg/centauro_urdf/meshes/simple/ShoulderYaw.STL</uri>
            </mesh>
          </geometry>
          <surface>
            <contact>
              <ode/>
            </contact>
            <friction>
              <ode/>
              <torsional>
                <ode/>
              </torsional>
            </friction>
            <bounce/>
          </surface>
          <max_contacts>10</max_contacts>
        </collision>
        <visual name='arm1_3_visual'>
          <pose frame=''>0 0 0 0 -0 0</pose>
          <geometry>
            <mesh>
              <scale>0.001 -0.001 0.001</scale>
              <uri>/home/ioannis/centauro_ws/src/iit-centauro-ros-pkg/centauro_urdf/meshes/ShoulderYaw.STL</uri>
            </mesh>
          </geometry>
          <material>
            <script>
              <name>Gazebo/LightBlueLaser</name>
              <uri>file://media/materials/scripts/gazebo.material</uri>
            </script>
          </material>
        </visual>
        <gravity>1</gravity>
        <velocity_decay/>
        <self_collide>0</self_collide>
        <enable_wind>0</enable_wind>
        <kinematic>0</kinematic>
      </link>
      <joint name='j_arm1_3' type='revolute'>
        <child>arm1_3</child>
        <parent>arm1_2</parent>
        <axis>
          <xyz>-0 -0 1</xyz>
          <limit>
            <lower>-2.552</lower>
            <upper>2.566</upper>
            <effort>147</effort>
            <velocity>6.06</velocity>
          </limit>
          <dynamics>
            <spring_reference>0</spring_reference>
            <spring_stiffness>0</spring_stiffness>
          </dynamics>
          <use_parent_model_frame>1</use_parent_model_frame>
        </axis>
        <physics>
          <provide_feedback>1</provide_feedback>
          <ode>
            <provide_feedback>1</provide_feedback>
            <implicit_spring_damper>1</implicit_spring_damper>
            <cfm_damping>1</cfm_damping>
            <limit>
              <cfm>0</cfm>
              <erp>0.2</erp>
            </limit>
          </ode>
        </physics>
      </joint>
      <link name='arm1_4'>
        <pose frame=''>0.342823 0.247276 0.091242 0 0 -0.523599</pose>
        <inertial>
          <pose frame=''>-0.007683 -0.040302 -0.043493 0 -0 0</pose>
          <mass>1.31573</mass>
          <inertia>
            <ixx>0.00433039</ixx>
            <ixy>-0.000117374</ixy>
            <ixz>-0.000419232</ixz>
            <iyy>0.00385399</iyy>
            <iyz>-0.00079573</iyz>
            <izz>0.00175947</izz>
          </inertia>
        </inertial>
        <collision name='arm1_4_collision'>
          <pose frame=''>0 0 0 0 -0 0</pose>
          <geometry>
            <mesh>
              <scale>0.001 -0.001 0.001</scale>
              <uri>/home/ioannis/centauro_ws/src/iit-centauro-ros-pkg/centauro_urdf/meshes/simple/Elbow.STL</uri>
            </mesh>
          </geometry>
          <surface>
            <contact>
              <ode/>
            </contact>
            <friction>
              <ode/>
              <torsional>
                <ode/>
              </torsional>
            </friction>
            <bounce/>
          </surface>
          <max_contacts>10</max_contacts>
        </collision>
        <visual name='arm1_4_visual'>
          <pose frame=''>0 0 0 0 -0 0</pose>
          <geometry>
            <mesh>
              <scale>0.001 -0.001 0.001</scale>
              <uri>/home/ioannis/centauro_ws/src/iit-centauro-ros-pkg/centauro_urdf/meshes/Elbow.STL</uri>
            </mesh>
          </geometry>
          <material>
            <script>
              <name>Gazebo/LightBlueLaser</name>
              <uri>file://media/materials/scripts/gazebo.material</uri>
            </script>
          </material>
        </visual>
        <gravity>1</gravity>
        <velocity_decay/>
        <self_collide>0</self_collide>
        <enable_wind>0</enable_wind>
        <kinematic>0</kinematic>
      </link>
      <joint name='j_arm1_4' type='revolute'>
        <child>arm1_4</child>
        <parent>arm1_3</parent>
        <axis>
          <xyz>0.5 0.866025 0</xyz>
          <limit>
            <lower>-2.465</lower>
            <upper>0.28</upper>
            <effort>147</effort>
            <velocity>6.06</velocity>
          </limit>
          <dynamics>
            <spring_reference>0</spring_reference>
            <spring_stiffness>0</spring_stiffness>
          </dynamics>
          <use_parent_model_frame>1</use_parent_model_frame>
        </axis>
        <physics>
          <provide_feedback>1</provide_feedback>
          <ode>
            <provide_feedback>1</provide_feedback>
            <implicit_spring_damper>1</implicit_spring_damper>
            <cfm_damping>1</cfm_damping>
            <limit>
              <cfm>0</cfm>
              <erp>0.2</erp>
            </limit>
          </ode>
        </physics>
      </joint>
      <link name='arm1_5'>
        <pose frame=''>0.302257 0.207015 -0.003758 0 0 -0.523599</pose>
        <inertial>
          <pose frame=''>-0.000111 0.011591 -0.07816 0 -0 0</pose>
          <mass>1.49085</mass>
          <inertia>
            <ixx>0.00856921</ixx>
            <ixy>1.78563e-05</ixy>
            <ixz>1.93794e-05</ixz>
            <iyy>0.00774542</iyy>
            <iyz>-0.000328601</iyz>
            <izz>0.00274419</izz>
          </inertia>
        </inertial>
        <collision name='arm1_5_collision'>
          <pose frame=''>0 0 0 0 -0 0</pose>
          <geometry>
            <mesh>
              <scale>0.001 -0.001 0.001</scale>
              <uri>/home/ioannis/centauro_ws/src/iit-centauro-ros-pkg/centauro_urdf/meshes/simple/Forearm.STL</uri>
            </mesh>
          </geometry>
          <surface>
            <contact>
              <ode/>
            </contact>
            <friction>
              <ode/>
              <torsional>
                <ode/>
              </torsional>
            </friction>
            <bounce/>
          </surface>
          <max_contacts>10</max_contacts>
        </collision>
        <visual name='arm1_5_visual'>
          <pose frame=''>0 0 0 0 -0 0</pose>
          <geometry>
            <mesh>
              <scale>0.001 -0.001 0.001</scale>
              <uri>/home/ioannis/centauro_ws/src/iit-centauro-ros-pkg/centauro_urdf/meshes/Forearm.STL</uri>
            </mesh>
          </geometry>
          <material>
            <script>
              <name>Gazebo/BlackTransparent</name>
              <uri>file://media/materials/scripts/gazebo.material</uri>
            </script>
          </material>
        </visual>
        <gravity>1</gravity>
        <velocity_decay/>
        <self_collide>0</self_collide>
        <enable_wind>0</enable_wind>
        <kinematic>0</kinematic>
      </link>
      <joint name='j_arm1_5' type='revolute'>
        <child>arm1_5</child>
        <parent>arm1_4</parent>
        <axis>
          <xyz>-0 -0 1</xyz>
          <limit>
            <lower>-2.569</lower>
            <upper>2.562</upper>
            <effort>55</effort>
            <velocity>11.72</velocity>
          </limit>
          <dynamics>
            <spring_reference>0</spring_reference>
            <spring_stiffness>0</spring_stiffness>
          </dynamics>
          <use_parent_model_frame>1</use_parent_model_frame>
        </axis>
        <physics>
          <provide_feedback>1</provide_feedback>
          <ode>
            <provide_feedback>1</provide_feedback>
            <implicit_spring_damper>1</implicit_spring_damper>
            <cfm_damping>1</cfm_damping>
            <limit>
              <cfm>0</cfm>
              <erp>0.2</erp>
            </limit>
          </ode>
        </physics>
      </joint>
      <link name='arm1_6'>
        <pose frame=''>0.326757 0.24945 -0.159758 0 0 -0.523599</pose>
        <inertial>
          <pose frame=''>-5e-06 -0.038014 -0.069927 0 -0 0</pose>
          <mass>1.12636</mass>
          <inertia>
            <ixx>0.00518718</ixx>
            <ixy>2.72444e-05</ixy>
            <ixz>2.28335e-06</ixz>
            <iyy>0.00480378</iyy>
            <iyz>-0.000721657</iyz>
            <izz>0.00127714</izz>
          </inertia>
        </inertial>
        <collision name='arm1_6_collision'>
          <pose frame=''>0 0 0 0 -0 0</pose>
          <geometry>
            <mesh>
              <scale>0.001 -0.001 0.001</scale>
              <uri>/home/ioannis/centauro_ws/src/iit-centauro-ros-pkg/centauro_urdf/meshes/simple/ForearmPitch.STL</uri>
            </mesh>
          </geometry>
          <surface>
            <contact>
              <ode/>
            </contact>
            <friction>
              <ode/>
              <torsional>
                <ode/>
              </torsional>
            </friction>
            <bounce/>
          </surface>
          <max_contacts>10</max_contacts>
        </collision>
        <visual name='arm1_6_visual'>
          <pose frame=''>0 0 0 0 -0 0</pose>
          <geometry>
            <mesh>
              <scale>0.001 -0.001 0.001</scale>
              <uri>/home/ioannis/centauro_ws/src/iit-centauro-ros-pkg/centauro_urdf/meshes/ForearmPitch.STL</uri>
            </mesh>
          </geometry>
          <material>
            <script>
              <name>Gazebo/LightBlueLaser</name>
              <uri>file://media/materials/scripts/gazebo.material</uri>
            </script>
          </material>
        </visual>
        <gravity>1</gravity>
        <velocity_decay/>
        <self_collide>0</self_collide>
        <enable_wind>0</enable_wind>
        <kinematic>0</kinematic>
      </link>
      <joint name='j_arm1_6' type='revolute'>
        <child>arm1_6</child>
        <parent>arm1_5</parent>
        <axis>
          <xyz>0.5 0.866025 0</xyz>
          <limit>
            <lower>-1.529</lower>
            <upper>1.509</upper>
            <effort>55</effort>
            <velocity>11.72</velocity>
          </limit>
          <dynamics>
            <spring_reference>0</spring_reference>
            <spring_stiffness>0</spring_stiffness>
          </dynamics>
          <use_parent_model_frame>1</use_parent_model_frame>
        </axis>
        <physics>
          <provide_feedback>1</provide_feedback>
          <ode>
            <provide_feedback>1</provide_feedback>
            <implicit_spring_damper>1</implicit_spring_damper>
            <cfm_damping>1</cfm_damping>
            <limit>
              <cfm>0</cfm>
              <erp>0.2</erp>
            </limit>
          </ode>
        </physics>
      </joint>
      <link name='arm1_7'>
        <pose frame=''>0.302257 0.207015 -0.333758 0 0 -0.523599</pose>
        <inertial>
          <pose frame=''>9e-06 0.000541 0.01433 0 -0 0</pose>
          <mass>1.92794</mass>
          <inertia>
            <ixx>0.00316217</ixx>
            <ixy>2.68715e-06</ixy>
            <ixz>-9.8962e-07</ixz>
            <iyy>0.00313238</iyy>
            <iyz>6.27992e-05</iyz>
            <izz>0.00340412</izz>
          </inertia>
        </inertial>
        <collision name='arm1_7_collision'>
          <pose frame=''>0 0 0 0 -0 0</pose>
          <geometry>
            <mesh>
              <scale>0.001 -0.001 0.001</scale>
              <uri>/home/ioannis/centauro_ws/src/iit-centauro-ros-pkg/centauro_urdf/meshes/simple/ForearmYaw.STL</uri>
            </mesh>
          </geometry>
          <surface>
            <contact>
              <ode/>
            </contact>
            <friction>
              <ode/>
              <torsional>
                <ode/>
              </torsional>
            </friction>
            <bounce/>
          </surface>
          <max_contacts>10</max_contacts>
        </collision>
        <collision name='arm1_7_fixed_joint_lump__ball1_collision_1'>
          <pose frame=''>0 0 0 0 -0 0</pose>
          <geometry>
            <mesh>
              <scale>0.001 0.001 0.001</scale>
              <uri>/home/ioannis/centauro_ws/src/iit-centauro-ros-pkg/centauro_urdf/meshes/simple/BallHand.stl</uri>
            </mesh>
          </geometry>
          <surface>
            <contact>
              <ode/>
            </contact>
            <friction>
              <ode/>
              <torsional>
                <ode/>
              </torsional>
            </friction>
            <bounce/>
          </surface>
          <max_contacts>10</max_contacts>
        </collision>
        <visual name='arm1_7_visual'>
          <pose frame=''>0 0 0 0 -0 0</pose>
          <geometry>
            <mesh>
              <scale>0.001 -0.001 0.001</scale>
              <uri>/home/ioannis/centauro_ws/src/iit-centauro-ros-pkg/centauro_urdf/meshes/ForearmYaw.STL</uri>
            </mesh>
          </geometry>
          <material>
            <script>
              <name>Gazebo/LightBlueLaser</name>
              <uri>file://media/materials/scripts/gazebo.material</uri>
            </script>
          </material>
        </visual>
        <visual name='arm1_7_fixed_joint_lump__ball1_visual_1'>
          <pose frame=''>0 0 0 0 -0 0</pose>
          <geometry>
            <mesh>
              <scale>0.001 0.001 0.001</scale>
              <uri>/home/ioannis/centauro_ws/src/iit-centauro-ros-pkg/centauro_urdf/meshes/BallHand.stl</uri>
            </mesh>
          </geometry>
          <material>
            <script>
              <name>Gazebo/BlackTransparent</name>
              <uri>file://media/materials/scripts/gazebo.material</uri>
            </script>
          </material>
        </visual>
        <velocity_decay/>
        <gravity>1</gravity>
        <velocity_decay/>
        <self_collide>0</self_collide>
        <enable_wind>0</enable_wind>
        <kinematic>0</kinematic>
      </link>
      <joint name='j_arm1_7' type='revolute'>
        <child>arm1_7</child>
        <parent>arm1_6</parent>
        <axis>
          <xyz>-0 -0 1</xyz>
          <limit>
            <lower>-2.565</lower>
            <upper>2.569</upper>
            <effort>28.32</effort>
            <velocity>20.35</velocity>
          </limit>
          <dynamics>
            <spring_reference>0</spring_reference>
            <spring_stiffness>0</spring_stiffness>
          </dynamics>
          <use_parent_model_frame>1</use_parent_model_frame>
        </axis>
        <physics>
          <provide_feedback>1</provide_feedback>
          <ode>
            <provide_feedback>1</provide_feedback>
            <implicit_spring_damper>1</implicit_spring_damper>
            <cfm_damping>1</cfm_damping>
            <limit>
              <cfm>0</cfm>
              <erp>0.2</erp>
            </limit>
          </ode>
        </physics>
      </joint>
      <link name='arm2_1'>
        <pose frame=''>0.245748 -0.169137 0.372626 -0.174533 -0 0.523599</pose>
        <inertial>
          <pose frame=''>-0.007446 -0.034108 0.00011 0 -0 0</pose>
          <mass>1.96287</mass>
          <inertia>
            <ixx>0.00535477</ixx>
            <ixy>-0.000364289</ixy>
            <ixz>1.50896e-05</ixz>
            <iyy>0.00339233</iyy>
            <iyz>-5.56923e-05</iyz>
            <izz>0.00689214</izz>
          </inertia>
        </inertial>
        <collision name='arm2_1_collision'>
          <pose frame=''>0 0 0 0 -0 0</pose>
          <geometry>
            <mesh>
              <scale>0.001 0.001 0.001</scale>
              <uri>/home/ioannis/centauro_ws/src/iit-centauro-ros-pkg/centauro_urdf/meshes/simple/ShoulderPitch.STL</uri>
            </mesh>
          </geometry>
          <surface>
            <contact>
              <ode/>
            </contact>
            <friction>
              <ode/>
              <torsional>
                <ode/>
              </torsional>
            </friction>
            <bounce/>
          </surface>
          <max_contacts>10</max_contacts>
        </collision>
        <visual name='arm2_1_visual'>
          <pose frame=''>0 0 0 0 -0 0</pose>
          <geometry>
            <mesh>
              <scale>0.001 0.001 0.001</scale>
              <uri>/home/ioannis/centauro_ws/src/iit-centauro-ros-pkg/centauro_urdf/meshes/ShoulderPitch.STL</uri>
            </mesh>
          </geometry>
          <material>
            <script>
              <name>Gazebo/BlackTransparent</name>
              <uri>file://media/materials/scripts/gazebo.material</uri>
            </script>
          </material>
        </visual>
        <gravity>1</gravity>
        <velocity_decay/>
        <self_collide>0</self_collide>
        <enable_wind>0</enable_wind>
        <kinematic>0</kinematic>
      </link>
      <joint name='j_arm2_1' type='revolute'>
        <child>arm2_1</child>
        <parent>torso_2</parent>
        <axis>
          <xyz>-0.492404 0.852869 -0.173648</xyz>
          <limit>
            <lower>-3.3458</lower>
            <upper>1.6012</upper>
            <effort>147</effort>
            <velocity>3.86</velocity>
          </limit>
          <dynamics>
            <spring_reference>0</spring_reference>
            <spring_stiffness>0</spring_stiffness>
          </dynamics>
          <use_parent_model_frame>1</use_parent_model_frame>
        </axis>
        <physics>
          <provide_feedback>1</provide_feedback>
          <ode>
            <provide_feedback>1</provide_feedback>
            <implicit_spring_damper>1</implicit_spring_damper>
            <cfm_damping>1</cfm_damping>
            <limit>
              <cfm>0</cfm>
              <erp>0.2</erp>
            </limit>
          </ode>
        </physics>
      </joint>
      <link name='arm2_2'>
        <pose frame=''>0.198204 -0.26709 0.383392 0 -0 0.523599</pose>
        <inertial>
          <pose frame=''>0.058142 -5.7e-05 -0.077478 0 -0 0</pose>
          <mass>1.85958</mass>
          <inertia>
            <ixx>0.0137766</ixx>
            <ixy>-3.77887e-05</ixy>
            <ixz>0.00376902</ixz>
            <iyy>0.0156775</iyy>
            <iyz>9.48935e-06</iyz>
            <izz>0.00463177</izz>
          </inertia>
        </inertial>
        <collision name='arm2_2_collision'>
          <pose frame=''>0 0 0 0 -0 0</pose>
          <geometry>
            <mesh>
              <scale>0.001 0.001 0.001</scale>
              <uri>/home/ioannis/centauro_ws/src/iit-centauro-ros-pkg/centauro_urdf/meshes/simple/ShoulderRoll.STL</uri>
            </mesh>
          </geometry>
          <surface>
            <contact>
              <ode/>
            </contact>
            <friction>
              <ode/>
              <torsional>
                <ode/>
              </torsional>
            </friction>
            <bounce/>
          </surface>
          <max_contacts>10</max_contacts>
        </collision>
        <visual name='arm2_2_visual'>
          <pose frame=''>0 0 0 0 -0 0</pose>
          <geometry>
            <mesh>
              <scale>0.001 0.001 0.001</scale>
              <uri>/home/ioannis/centauro_ws/src/iit-centauro-ros-pkg/centauro_urdf/meshes/ShoulderRoll.STL</uri>
            </mesh>
          </geometry>
          <material>
            <script>
              <name>Gazebo/LightBlueLaser</name>
              <uri>file://media/materials/scripts/gazebo.material</uri>
            </script>
          </material>
        </visual>
        <gravity>1</gravity>
        <velocity_decay/>
        <self_collide>0</self_collide>
        <enable_wind>0</enable_wind>
        <kinematic>0</kinematic>
      </link>
      <joint name='j_arm2_2' type='revolute'>
        <child>arm2_2</child>
        <parent>arm2_1</parent>
        <axis>
          <xyz>0.866025 0.5 -0</xyz>
          <limit>
            <lower>-3.4258</lower>
            <upper>-0.0138</upper>
            <effort>147</effort>
            <velocity>3.86</velocity>
          </limit>
          <dynamics>
            <spring_reference>0</spring_reference>
            <spring_stiffness>0</spring_stiffness>
          </dynamics>
          <use_parent_model_frame>1</use_parent_model_frame>
        </axis>
        <physics>
          <provide_feedback>1</provide_feedback>
          <ode>
            <provide_feedback>1</provide_feedback>
            <implicit_spring_damper>1</implicit_spring_damper>
            <cfm_damping>1</cfm_damping>
            <limit>
              <cfm>0</cfm>
              <erp>0.2</erp>
            </limit>
          </ode>
        </physics>
      </joint>
      <link name='arm2_3'>
        <pose frame=''>0.276277 -0.222015 0.165242 0 -0 0.523599</pose>
        <inertial>
          <pose frame=''>0.014625 -0.000817 -0.028334 0 -0 0</pose>
          <mass>1.66781</mass>
          <inertia>
            <ixx>0.00644804</ixx>
            <ixy>0.000156391</ixy>
            <ixz>0.00122054</ixz>
            <iyy>0.00733721</iyy>
            <iyz>-8.99415e-05</iyz>
            <izz>0.00367384</izz>
          </inertia>
        </inertial>
        <collision name='arm2_3_collision'>
          <pose frame=''>0 0 0 0 -0 0</pose>
          <geometry>
            <mesh>
              <scale>0.001 0.001 0.001</scale>
              <uri>/home/ioannis/centauro_ws/src/iit-centauro-ros-pkg/centauro_urdf/meshes/simple/ShoulderYaw.STL</uri>
            </mesh>
          </geometry>
          <surface>
            <contact>
              <ode/>
            </contact>
            <friction>
              <ode/>
              <torsional>
                <ode/>
              </torsional>
            </friction>
            <bounce/>
          </surface>
          <max_contacts>10</max_contacts>
        </collision>
        <visual name='arm2_3_visual'>
          <pose frame=''>0 0 0 0 -0 0</pose>
          <geometry>
            <mesh>
              <scale>0.001 0.001 0.001</scale>
              <uri>/home/ioannis/centauro_ws/src/iit-centauro-ros-pkg/centauro_urdf/meshes/ShoulderYaw.STL</uri>
            </mesh>
          </geometry>
          <material>
            <script>
              <name>Gazebo/LightBlueLaser</name>
              <uri>file://media/materials/scripts/gazebo.material</uri>
            </script>
          </material>
        </visual>
        <gravity>1</gravity>
        <velocity_decay/>
        <self_collide>0</self_collide>
        <enable_wind>0</enable_wind>
        <kinematic>0</kinematic>
      </link>
      <joint name='j_arm2_3' type='revolute'>
        <child>arm2_3</child>
        <parent>arm2_2</parent>
        <axis>
          <xyz>-0 0 1</xyz>
          <limit>
            <lower>-2.5614</lower>
            <upper>2.5606</upper>
            <effort>147</effort>
            <velocity>6.06</velocity>
          </limit>
          <dynamics>
            <spring_reference>0</spring_reference>
            <spring_stiffness>0</spring_stiffness>
          </dynamics>
          <use_parent_model_frame>1</use_parent_model_frame>
        </axis>
        <physics>
          <provide_feedback>1</provide_feedback>
          <ode>
            <provide_feedback>1</provide_feedback>
            <implicit_spring_damper>1</implicit_spring_damper>
            <cfm_damping>1</cfm_damping>
            <limit>
              <cfm>0</cfm>
              <erp>0.2</erp>
            </limit>
          </ode>
        </physics>
      </joint>
      <link name='arm2_4'>
        <pose frame=''>0.342823 -0.247276 0.091242 0 -0 0.523599</pose>
        <inertial>
          <pose frame=''>-0.007683 0.040302 -0.043493 0 -0 0</pose>
          <mass>1.31573</mass>
          <inertia>
            <ixx>0.00433039</ixx>
            <ixy>0.000117374</ixy>
            <ixz>-0.000419232</ixz>
            <iyy>0.00385399</iyy>
            <iyz>0.00079573</iyz>
            <izz>0.00175947</izz>
          </inertia>
        </inertial>
        <collision name='arm2_4_collision'>
          <pose frame=''>0 0 0 0 -0 0</pose>
          <geometry>
            <mesh>
              <scale>0.001 0.001 0.001</scale>
              <uri>/home/ioannis/centauro_ws/src/iit-centauro-ros-pkg/centauro_urdf/meshes/simple/Elbow.STL</uri>
            </mesh>
          </geometry>
          <surface>
            <contact>
              <ode/>
            </contact>
            <friction>
              <ode/>
              <torsional>
                <ode/>
              </torsional>
            </friction>
            <bounce/>
          </surface>
          <max_contacts>10</max_contacts>
        </collision>
        <visual name='arm2_4_visual'>
          <pose frame=''>0 0 0 0 -0 0</pose>
          <geometry>
            <mesh>
              <scale>0.001 0.001 0.001</scale>
              <uri>/home/ioannis/centauro_ws/src/iit-centauro-ros-pkg/centauro_urdf/meshes/Elbow.STL</uri>
            </mesh>
          </geometry>
          <material>
            <script>
              <name>Gazebo/LightBlueLaser</name>
              <uri>file://media/materials/scripts/gazebo.material</uri>
            </script>
          </material>
        </visual>
        <gravity>1</gravity>
        <velocity_decay/>
        <self_collide>0</self_collide>
        <enable_wind>0</enable_wind>
        <kinematic>0</kinematic>
      </link>
      <joint name='j_arm2_4' type='revolute'>
        <child>arm2_4</child>
        <parent>arm2_3</parent>
        <axis>
          <xyz>-0.5 0.866025 -0</xyz>
          <limit>
            <lower>-2.4794</lower>
            <upper>0.2886</upper>
            <effort>147</effort>
            <velocity>6.06</velocity>
          </limit>
          <dynamics>
            <spring_reference>0</spring_reference>
            <spring_stiffness>0</spring_stiffness>
          </dynamics>
          <use_parent_model_frame>1</use_parent_model_frame>
        </axis>
        <physics>
          <provide_feedback>1</provide_feedback>
          <ode>
            <provide_feedback>1</provide_feedback>
            <implicit_spring_damper>1</implicit_spring_damper>
            <cfm_damping>1</cfm_damping>
            <limit>
              <cfm>0</cfm>
              <erp>0.2</erp>
            </limit>
          </ode>
        </physics>
      </joint>
      <link name='arm2_5'>
        <pose frame=''>0.302257 -0.207015 -0.003758 0 -0 0.523599</pose>
        <inertial>
          <pose frame=''>-0.000111 -0.011591 -0.07816 0 -0 0</pose>
          <mass>1.49085</mass>
          <inertia>
            <ixx>0.00856921</ixx>
            <ixy>-1.78563e-05</ixy>
            <ixz>1.93794e-05</ixz>
            <iyy>0.00774542</iyy>
            <iyz>0.000328601</iyz>
            <izz>0.00274419</izz>
          </inertia>
        </inertial>
        <collision name='arm2_5_collision'>
          <pose frame=''>0 0 0 0 -0 0</pose>
          <geometry>
            <mesh>
              <scale>0.001 0.001 0.001</scale>
              <uri>/home/ioannis/centauro_ws/src/iit-centauro-ros-pkg/centauro_urdf/meshes/simple/Forearm.STL</uri>
            </mesh>
          </geometry>
          <surface>
            <contact>
              <ode/>
            </contact>
            <friction>
              <ode/>
              <torsional>
                <ode/>
              </torsional>
            </friction>
            <bounce/>
          </surface>
          <max_contacts>10</max_contacts>
        </collision>
        <visual name='arm2_5_visual'>
          <pose frame=''>0 0 0 0 -0 0</pose>
          <geometry>
            <mesh>
              <scale>0.001 0.001 0.001</scale>
              <uri>/home/ioannis/centauro_ws/src/iit-centauro-ros-pkg/centauro_urdf/meshes/Forearm.STL</uri>
            </mesh>
          </geometry>
          <material>
            <script>
              <name>Gazebo/BlackTransparent</name>
              <uri>file://media/materials/scripts/gazebo.material</uri>
            </script>
          </material>
        </visual>
        <gravity>1</gravity>
        <velocity_decay/>
        <self_collide>0</self_collide>
        <enable_wind>0</enable_wind>
        <kinematic>0</kinematic>
      </link>
      <joint name='j_arm2_5' type='revolute'>
        <child>arm2_5</child>
        <parent>arm2_4</parent>
        <axis>
          <xyz>-0 0 1</xyz>
          <limit>
            <lower>-2.5394</lower>
            <upper>2.5546</upper>
            <effort>55</effort>
            <velocity>11.72</velocity>
          </limit>
          <dynamics>
            <spring_reference>0</spring_reference>
            <spring_stiffness>0</spring_stiffness>
          </dynamics>
          <use_parent_model_frame>1</use_parent_model_frame>
        </axis>
        <physics>
          <provide_feedback>1</provide_feedback>
          <ode>
            <provide_feedback>1</provide_feedback>
            <implicit_spring_damper>1</implicit_spring_damper>
            <cfm_damping>1</cfm_damping>
            <limit>
              <cfm>0</cfm>
              <erp>0.2</erp>
            </limit>
          </ode>
        </physics>
      </joint>
      <link name='arm2_6'>
        <pose frame=''>0.326757 -0.24945 -0.159758 0 -0 0.523599</pose>
        <inertial>
          <pose frame=''>-5e-06 0.038014 -0.069927 0 -0 0</pose>
          <mass>1.12636</mass>
          <inertia>
            <ixx>0.00518718</ixx>
            <ixy>-2.72444e-05</ixy>
            <ixz>2.28335e-06</ixz>
            <iyy>0.00480378</iyy>
            <iyz>0.000721657</iyz>
            <izz>0.00127714</izz>
          </inertia>
        </inertial>
        <collision name='arm2_6_collision'>
          <pose frame=''>0 0 0 0 -0 0</pose>
          <geometry>
            <mesh>
              <scale>0.001 0.001 0.001</scale>
              <uri>/home/ioannis/centauro_ws/src/iit-centauro-ros-pkg/centauro_urdf/meshes/simple/ForearmPitch.STL</uri>
            </mesh>
          </geometry>
          <surface>
            <contact>
              <ode/>
            </contact>
            <friction>
              <ode/>
              <torsional>
                <ode/>
              </torsional>
            </friction>
            <bounce/>
          </surface>
          <max_contacts>10</max_contacts>
        </collision>
        <visual name='arm2_6_visual'>
          <pose frame=''>0 0 0 0 -0 0</pose>
          <geometry>
            <mesh>
              <scale>0.001 0.001 0.001</scale>
              <uri>/home/ioannis/centauro_ws/src/iit-centauro-ros-pkg/centauro_urdf/meshes/ForearmPitch.STL</uri>
            </mesh>
          </geometry>
          <material>
            <script>
              <name>Gazebo/LightBlueLaser</name>
              <uri>file://media/materials/scripts/gazebo.material</uri>
            </script>
          </material>
        </visual>
        <gravity>1</gravity>
        <velocity_decay/>
        <self_collide>0</self_collide>
        <enable_wind>0</enable_wind>
        <kinematic>0</kinematic>
      </link>
      <joint name='j_arm2_6' type='revolute'>
        <child>arm2_6</child>
        <parent>arm2_5</parent>
        <axis>
          <xyz>-0.5 0.866025 -0</xyz>
          <limit>
            <lower>-1.5154</lower>
            <upper>1.5156</upper>
            <effort>55</effort>
            <velocity>11.72</velocity>
          </limit>
          <dynamics>
            <spring_reference>0</spring_reference>
            <spring_stiffness>0</spring_stiffness>
          </dynamics>
          <use_parent_model_frame>1</use_parent_model_frame>
        </axis>
        <physics>
          <provide_feedback>1</provide_feedback>
          <ode>
            <provide_feedback>1</provide_feedback>
            <implicit_spring_damper>1</implicit_spring_damper>
            <cfm_damping>1</cfm_damping>
            <limit>
              <cfm>0</cfm>
              <erp>0.2</erp>
            </limit>
          </ode>
        </physics>
      </joint>
      <link name='arm2_7'>
        <pose frame=''>0.302257 -0.207015 -0.333758 0 -0 0.523599</pose>
        <inertial>
          <pose frame=''>9e-06 -0.000492 0.01433 0 -0 0</pose>
          <mass>1.92794</mass>
          <inertia>
            <ixx>0.00316227</ixx>
            <ixy>-2.10165e-06</ixy>
            <ixz>-9.8962e-07</ixz>
            <iyy>0.00313238</iyy>
            <iyz>-6.1733e-05</iyz>
            <izz>0.00340422</izz>
          </inertia>
        </inertial>
        <collision name='arm2_7_collision'>
          <pose frame=''>0 0 0 0 -0 0</pose>
          <geometry>
            <mesh>
              <scale>0.001 0.001 0.001</scale>
              <uri>/home/ioannis/centauro_ws/src/iit-centauro-ros-pkg/centauro_urdf/meshes/simple/ForearmYaw.STL</uri>
            </mesh>
          </geometry>
          <surface>
            <contact>
              <ode/>
            </contact>
            <friction>
              <ode/>
              <torsional>
                <ode/>
              </torsional>
            </friction>
            <bounce/>
          </surface>
          <max_contacts>10</max_contacts>
        </collision>
        <collision name='arm2_7_fixed_joint_lump__ball2_collision_1'>
          <pose frame=''>0 0 0 0 -0 0</pose>
          <geometry>
            <mesh>
              <scale>0.001 0.001 0.001</scale>
              <uri>/home/ioannis/centauro_ws/src/iit-centauro-ros-pkg/centauro_urdf/meshes/simple/BallHand.stl</uri>
            </mesh>
          </geometry>
          <surface>
            <contact>
              <ode/>
            </contact>
            <friction>
              <ode/>
              <torsional>
                <ode/>
              </torsional>
            </friction>
            <bounce/>
          </surface>
          <max_contacts>10</max_contacts>
        </collision>
        <visual name='arm2_7_visual'>
          <pose frame=''>0 0 0 0 -0 0</pose>
          <geometry>
            <mesh>
              <scale>0.001 0.001 0.001</scale>
              <uri>/home/ioannis/centauro_ws/src/iit-centauro-ros-pkg/centauro_urdf/meshes/ForearmYaw.STL</uri>
            </mesh>
          </geometry>
          <material>
            <script>
              <name>Gazebo/LightBlueLaser</name>
              <uri>file://media/materials/scripts/gazebo.material</uri>
            </script>
          </material>
        </visual>
        <visual name='arm2_7_fixed_joint_lump__ball2_visual_1'>
          <pose frame=''>0 0 0 0 -0 0</pose>
          <geometry>
            <mesh>
              <scale>0.001 0.001 0.001</scale>
              <uri>/home/ioannis/centauro_ws/src/iit-centauro-ros-pkg/centauro_urdf/meshes/BallHand.stl</uri>
            </mesh>
          </geometry>
          <material>
            <script>
              <name>Gazebo/BlackTransparent</name>
              <uri>file://media/materials/scripts/gazebo.material</uri>
            </script>
          </material>
        </visual>
        <velocity_decay/>
        <gravity>1</gravity>
        <velocity_decay/>
        <self_collide>0</self_collide>
        <enable_wind>0</enable_wind>
        <kinematic>0</kinematic>
      </link>
      <joint name='j_arm2_7' type='revolute'>
        <child>arm2_7</child>
        <parent>arm2_6</parent>
        <axis>
          <xyz>-0 0 1</xyz>
          <limit>
            <lower>-2.5554</lower>
            <upper>2.5686</upper>
            <effort>28.32</effort>
            <velocity>20.35</velocity>
          </limit>
          <dynamics>
            <spring_reference>0</spring_reference>
            <spring_stiffness>0</spring_stiffness>
          </dynamics>
          <use_parent_model_frame>1</use_parent_model_frame>
        </axis>
        <physics>
          <provide_feedback>1</provide_feedback>
          <ode>
            <provide_feedback>1</provide_feedback>
            <implicit_spring_damper>1</implicit_spring_damper>
            <cfm_damping>1</cfm_damping>
            <limit>
              <cfm>0</cfm>
              <erp>0.2</erp>
            </limit>
          </ode>
        </physics>
      </joint>
      <link name='neck_3'>
        <pose frame=''>0.255 0 0.729262 0 0 -1.828</pose>
        <inertial>
          <pose frame=''>0.048467 -0.059852 -0.008531 0 -0 0</pose>
          <mass>0.785269</mass>
          <inertia>
            <ixx>0.000468234</ixx>
            <ixy>-1.05438e-05</ixy>
            <ixz>7.24398e-05</ixz>
            <iyy>0.000263525</iyy>
            <iyz>1.6904e-06</iyz>
            <izz>0.000376335</izz>
          </inertia>
        </inertial>
        <collision name='neck_3_collision'>
          <pose frame=''>0 0 0 0 -0 0</pose>
          <geometry>
            <mesh>
              <scale>0.001 0.001 0.001</scale>
              <uri>/home/ioannis/centauro_ws/src/iit-centauro-ros-pkg/centauro_urdf/meshes/simple/lidar.stl</uri>
            </mesh>
          </geometry>
          <max_contacts>10</max_contacts>
          <surface>
            <contact>
              <ode/>
            </contact>
            <bounce/>
            <friction>
              <torsional>
                <ode/>
              </torsional>
              <ode/>
            </friction>
          </surface>
        </collision>
        <visual name='neck_3_visual'>
          <pose frame=''>0 0 0 0 -0 0</pose>
          <geometry>
            <mesh>
              <scale>0.001 0.001 0.001</scale>
              <uri>/home/ioannis/centauro_ws/src/iit-centauro-ros-pkg/centauro_urdf/meshes/lidar.stl</uri>
            </mesh>
          </geometry>
        </visual>
        <self_collide>0</self_collide>
        <enable_wind>0</enable_wind>
        <kinematic>0</kinematic>
      </link>
      <joint name='neck_velodyne' type='revolute'>
        <child>neck_3</child>
        <parent>torso_2</parent>
        <axis>
          <xyz>0 0 1</xyz>
          <limit>
            <lower>-1e+16</lower>
            <upper>1e+16</upper>
          </limit>
          <dynamics>
            <damping>0.2</damping>
            <friction>10</friction>
            <spring_reference>0</spring_reference>
            <spring_stiffness>0</spring_stiffness>
          </dynamics>
          <use_parent_model_frame>1</use_parent_model_frame>
        </axis>
      </joint>
      <link name='neck_1'>
        <pose frame=''>0.2 0 0.5355 0 -0 0</pose>
        <inertial>
          <pose frame=''>0.04048 0.021378 -0.014595 0 -0 0</pose>
          <mass>0.338787</mass>
          <inertia>
            <ixx>0.000371857</ixx>
            <ixy>-9.42983e-05</ixy>
            <ixz>-2.80644e-05</ixz>
            <iyy>0.000188688</iyy>
            <iyz>-1.54534e-05</iyz>
            <izz>0.000502344</izz>
          </inertia>
        </inertial>
        <collision name='neck_1_collision'>
          <pose frame=''>0 0 0 0 -0 0</pose>
          <geometry>
            <mesh>
              <scale>0.001 0.001 0.001</scale>
              <uri>/home/ioannis/centauro_ws/src/iit-centauro-ros-pkg/centauro_urdf/meshes/simple/neck_yaw.stl</uri>
            </mesh>
          </geometry>
          <max_contacts>10</max_contacts>
          <surface>
            <contact>
              <ode/>
            </contact>
            <bounce/>
            <friction>
              <torsional>
                <ode/>
              </torsional>
              <ode/>
            </friction>
          </surface>
        </collision>
        <visual name='neck_1_visual'>
          <pose frame=''>0 0 0 0 -0 0</pose>
          <geometry>
            <mesh>
              <scale>0.001 0.001 0.001</scale>
              <uri>/home/ioannis/centauro_ws/src/iit-centauro-ros-pkg/centauro_urdf/meshes/neck_yaw.stl</uri>
            </mesh>
          </geometry>
        </visual>
        <self_collide>0</self_collide>
        <enable_wind>0</enable_wind>
        <kinematic>0</kinematic>
      </link>
      <joint name='neck_yaw' type='revolute'>
        <child>neck_1</child>
        <parent>torso_2</parent>
        <axis>
          <xyz>0 0 1</xyz>
          <limit>
            <lower>-0.785398</lower>
            <upper>0.785398</upper>
            <effort>35</effort>
            <velocity>5.7</velocity>
          </limit>
          <dynamics>
            <damping>0</damping>
            <friction>10</friction>
            <spring_reference>0</spring_reference>
            <spring_stiffness>0</spring_stiffness>
          </dynamics>
          <use_parent_model_frame>1</use_parent_model_frame>
        </axis>
      </joint>
      <link name='neck_2'>
        <pose frame=''>0.254 0.0596 0.523003 0 -0 0</pose>
        <inertial>
          <pose frame=''>0.048467 -0.059852 -0.008531 0 -0 0</pose>
          <mass>0.785269</mass>
          <inertia>
            <ixx>0.000468234</ixx>
            <ixy>-1.05438e-05</ixy>
            <ixz>7.24398e-05</ixz>
            <iyy>0.000263525</iyy>
            <iyz>1.6904e-06</iyz>
            <izz>0.000376335</izz>
          </inertia>
        </inertial>
        <collision name='neck_2_collision'>
          <pose frame=''>0 0 0 0 -0 0</pose>
          <geometry>
            <mesh>
              <scale>0.001 0.001 0.001</scale>
              <uri>/home/ioannis/centauro_ws/src/iit-centauro-ros-pkg/centauro_urdf/meshes/simple/neck_pitch.stl</uri>
            </mesh>
          </geometry>
          <max_contacts>10</max_contacts>
          <surface>
            <contact>
              <ode/>
            </contact>
            <bounce/>
            <friction>
              <torsional>
                <ode/>
              </torsional>
              <ode/>
            </friction>
          </surface>
        </collision>
        <visual name='neck_2_visual'>
          <pose frame=''>0 0 0 0 -0 0</pose>
          <geometry>
            <mesh>
              <scale>0.001 0.001 0.001</scale>
              <uri>/home/ioannis/centauro_ws/src/iit-centauro-ros-pkg/centauro_urdf/meshes/neck_pitch.stl</uri>
            </mesh>
          </geometry>
        </visual>
        <self_collide>0</self_collide>
        <enable_wind>0</enable_wind>
        <kinematic>0</kinematic>
      </link>
      <joint name='neck_pitch' type='revolute'>
        <child>neck_2</child>
        <parent>neck_1</parent>
        <axis>
          <xyz>0 1 0</xyz>
          <limit>
            <lower>-0.349066</lower>
            <upper>0.785398</upper>
            <effort>35</effort>
            <velocity>5.7</velocity>
          </limit>
          <dynamics>
            <damping>0</damping>
            <friction>10</friction>
            <spring_reference>0</spring_reference>
            <spring_stiffness>0</spring_stiffness>
          </dynamics>
          <use_parent_model_frame>1</use_parent_model_frame>
        </axis>
      </joint>
      <static>0</static>
      <plugin name='xbot2_link_state_sensor' filename='libxbot2_gz_link_state_sensor.so'>
        <links>
          <link name='pelvis'/>
          <link name='wheel_1'/>
        </links>
        <robotNamespace>/</robotNamespace>
      </plugin>
      <plugin name='xbot2_ft_driver' filename='libxbot2_gz_ft_server.so'>
        <robotNamespace>/</robotNamespace>
      </plugin>
      <plugin name='xbot2_imu_driver' filename='libxbot2_gz_imu_server.so'>
        <robotNamespace>/</robotNamespace>
      </plugin>
      <plugin name='xbot2_joint_driver' filename='libxbot2_gz_joint_server.so'>
        <pid>
          <gain d='5' name='lowpwr_mot' p='50'/>
          <gain d='5' name='small_mot' p='250'/>
          <gain d='10' name='medium_mot' p='1000'/>
          <gain d='10' name='big_mot' p='3000'/>
          <gain d='10' name='wheel_mot' p='0'/>
          <pid name='neck_yaw' profile='lowpwr_mot'/>
          <pid name='neck_pitch' profile='lowpwr_mot'/>
          <pid d='20' name='neck_velodyne' p='0'/>
          <pid name='j_arm1_1' profile='medium_mot'/>
          <pid name='j_arm1_2' profile='medium_mot'/>
          <pid name='j_arm1_3' profile='medium_mot'/>
          <pid name='j_arm1_4' profile='medium_mot'/>
          <pid name='j_arm1_5' profile='small_mot'/>
          <pid name='j_arm1_6' profile='small_mot'/>
          <pid name='j_arm1_7' profile='small_mot'/>
          <pid name='j_arm2_1' profile='medium_mot'/>
          <pid name='j_arm2_2' profile='medium_mot'/>
          <pid name='j_arm2_3' profile='medium_mot'/>
          <pid name='j_arm2_4' profile='medium_mot'/>
          <pid name='j_arm2_5' profile='small_mot'/>
          <pid name='j_arm2_6' profile='small_mot'/>
          <pid name='j_arm2_7' profile='small_mot'/>
          <pid name='torso_yaw' profile='big_mot'/>
          <pid name='hip_yaw_1' profile='big_mot'/>
          <pid name='hip_pitch_1' profile='big_mot'/>
          <pid name='knee_pitch_1' profile='big_mot'/>
          <pid name='ankle_pitch_1' profile='medium_mot'/>
          <pid name='ankle_yaw_1' profile='small_mot'/>
          <pid name='j_wheel_1' profile='wheel_mot'/>
          <pid name='hip_yaw_2' profile='big_mot'/>
          <pid name='hip_pitch_2' profile='big_mot'/>
          <pid name='knee_pitch_2' profile='big_mot'/>
          <pid name='ankle_pitch_2' profile='medium_mot'/>
          <pid name='ankle_yaw_2' profile='small_mot'/>
          <pid name='j_wheel_2' profile='wheel_mot'/>
          <pid name='hip_yaw_3' profile='big_mot'/>
          <pid name='hip_pitch_3' profile='big_mot'/>
          <pid name='knee_pitch_3' profile='big_mot'/>
          <pid name='ankle_pitch_3' profile='medium_mot'/>
          <pid name='ankle_yaw_3' profile='small_mot'/>
          <pid name='j_wheel_3' profile='wheel_mot'/>
          <pid name='hip_yaw_4' profile='big_mot'/>
          <pid name='hip_pitch_4' profile='big_mot'/>
          <pid name='knee_pitch_4' profile='big_mot'/>
          <pid name='ankle_pitch_4' profile='medium_mot'/>
          <pid name='ankle_yaw_4' profile='small_mot'/>
          <pid name='j_wheel_4' profile='wheel_mot'/>
        </pid>
        <robotNamespace>/</robotNamespace>
      </plugin>
      <pose frame=''>0 0 1.2 0 -0 0</pose>
    </model>
    <state world_name='default'>
      <sim_time>66 758250000</sim_time>
      <real_time>465 634741747</real_time>
      <wall_time>1615487789 109103925</wall_time>
      <iterations>267033</iterations>
      <model name='centauro'>
        <pose frame=''>0.405844 -0.01798 0.754282 0.036525 -0.155507 0.049027</pose>
        <scale>1 1 1</scale>
        <link name='ankle1_1'>
          <pose frame=''>0.710985 0.350163 0.313396 -2.60932 1.43042 0.100814</pose>
          <velocity>0.014196 0.002069 -0.001312 -0.000213 0.00447 -0.042266</velocity>
          <acceleration>-0.007689 -0.022052 -0.000137 0.428008 -1.27814 2.6391</acceleration>
          <wrench>-0.009519 -0.027302 -0.00017 0 -0 0</wrench>
        </link>
        <link name='ankle1_2'>
          <pose frame=''>0.769255 -0.354716 0.508518 2.38383 1.36736 -0.08561</pose>
          <velocity>0.081166 -0.080869 -0.24843 0.288929 0.351562 -0.083734</velocity>
          <acceleration>0.003392 -0.013675 0.01506 -0.674436 1.53607 -2.65148</acceleration>
          <wrench>0.0042 -0.01693 0.018645 0 -0 0</wrench>
        </link>
        <link name='ankle1_3'>
          <pose frame=''>0.207405 0.340867 0.312483 -0.36675 1.40286 0.106311</pose>
          <velocity>0.017145 0.000878 -0.000184 -0.00356 0.001507 -0.002018</velocity>
          <acceleration>0.010786 -0.028118 0.003189 1.33017 0.713575 0.650423</acceleration>
          <wrench>0.013354 -0.034812 0.003949 0 -0 0</wrench>
        </link>
        <link name='ankle1_4'>
          <pose frame=''>0.254355 -0.361735 0.511841 0.401926 1.41582 0.21486</pose>
          <velocity>0.011959 -0.07156 -0.124408 0.216638 0.027102 0.05968</velocity>
          <acceleration>-0.007886 -0.033173 -0.002051 1.65208 -1.11582 -0.93977</acceleration>
          <wrench>-0.009764 -0.041071 -0.00254 0 -0 0</wrench>
        </link>
        <link name='ankle2_1'>
          <pose frame=''>0.710984 0.350163 0.313396 3.1252 0.139431 3.12502</pose>
          <velocity>0.01519 0.001722 -0.001122 -0.005537 0.005042 -0.002649</velocity>
          <acceleration>-0.004207 -0.009626 0.000564 -1.84041 -1.56781 0.503857</acceleration>
          <wrench>-0.004865 -0.011133 0.000652 0 -0 0</wrench>
        </link>
        <link name='ankle2_2'>
          <pose frame=''>0.76926 -0.354713 0.508523 3.1195 -0.202244 0.023957</pose>
          <velocity>0.076403 -0.083852 -0.25426 0.272733 0.346684 -0.007594</velocity>
          <acceleration>0.000338 -0.006029 0.014364 -3.08107 -0.628026 -2.71103</acceleration>
          <wrench>0.00039 -0.006974 0.016613 0 -0 0</wrench>
        </link>
        <link name='ankle2_3'>
          <pose frame=''>0.207405 0.340867 0.312484 3.11945 0.166483 3.11501</pose>
          <velocity>0.016927 0.000797 -0.000217 -0.003093 0.001301 -0.004558</velocity>
          <acceleration>0.003169 -0.012324 0.002218 2.42025 -0.629389 -0.528657</acceleration>
          <wrench>0.003666 -0.014254 0.002565 0 -0 0</wrench>
        </link>
        <link name='ankle2_4'>
          <pose frame=''>0.254359 -0.361735 0.511844 -3.10355 -0.150284 -0.034084</pose>
          <velocity>0.00838 -0.071049 -0.127209 0.2281 0.041917 0.001301</velocity>
          <acceleration>-0.005794 -0.01432 -0.001308 -1.55645 -1.39933 0.594138</acceleration>
          <wrench>-0.006701 -0.016562 -0.001512 0 -0 0</wrench>
        </link>
        <link name='arm1_1'>
          <pose frame=''>0.582842 0.146122 1.16643 0.30594 0.386869 -0.329723</pose>
          <velocity>0.014876 0.000383 0.002553 0.013972 -0.011435 0.000682</velocity>
          <acceleration>-0.000845 -0.026117 0.002697 2.42317 -1.54466 0.569466</acceleration>
          <wrench>-0.001659 -0.051265 0.005294 0 -0 0</wrench>
        </link>
        <link name='arm1_2'>
          <pose frame=''>0.529659 0.226809 1.21774 0.423122 0.386869 -0.329723</pose>
          <velocity>0.014242 -0.000395 0.003108 -0.002474 -0.005777 0.007804</velocity>
          <acceleration>-0.002407 -0.027342 0.002744 0.90886 -0.835521 1.12468</acceleration>
          <wrench>-0.004477 -0.050845 0.005102 0 -0 0</wrench>
        </link>
        <link name='arm1_3'>
          <pose frame=''>0.566648 0.308826 0.999511 0.508425 0.258794 -0.062827</pose>
          <velocity>0.014849 -0.000649 0.003099 -0.004653 -0.000112 -0.00185</velocity>
          <acceleration>-0.004475 -0.028818 0.00195 0.055121 -0.108005 2.21428</acceleration>
          <wrench>-0.007464 -0.048063 0.003253 0 -0 0</wrench>
        </link>
        <link name='arm1_4'>
          <pose frame=''>0.605697 0.390733 0.95146 2.15867 -0.969718 -2.45496</pose>
          <velocity>0.015009 -0.00094 0.002726 -0.002234 0.011632 0.004499</velocity>
          <acceleration>-0.005181 -0.029486 0.001564 -1.36898 1.26187 0.608209</acceleration>
          <wrench>-0.006817 -0.038795 0.002057 0 -0 0</wrench>
        </link>
        <link name='arm1_5'>
          <pose frame=''>0.686095 0.314871 0.942931 2.1729 -0.98392 -2.47214</pose>
          <velocity>0.015248 -0.000595 0.001959 0.00796 0.007521 0.008126</velocity>
          <acceleration>-0.005643 -0.029822 0.002749 0.804578 -0.395819 -2.33441</acceleration>
          <wrench>-0.008412 -0.04446 0.004099 0 -0 0</wrench>
        </link>
        <link name='arm1_6'>
          <pose frame=''>0.832715 0.302339 1.01422 2.62684 -0.384462 3.13929</pose>
          <velocity>0.015885 2.8e-05 0.000755 0.005157 -0.005411 0.001333</velocity>
          <acceleration>-0.009938 -0.029558 0.005247 0.636614 -1.08813 -2.15615</acceleration>
          <wrench>-0.011194 -0.033293 0.00591 0 -0 0</wrench>
        </link>
        <link name='arm1_7'>
          <pose frame=''>0.880176 0.173916 1.13226 2.61756 -0.371095 -3.11874</pose>
          <velocity>0.01542 -0.000517 0.000348 0.003774 -0.003308 -0.002094</velocity>
          <acceleration>-0.015119 -0.029132 0.007666 0.003462 -0.132932 -0.037695</acceleration>
          <wrench>-0.029148 -0.056166 0.01478 0 -0 0</wrench>
        </link>
        <link name='arm2_1'>
          <pose frame=''>0.599972 -0.191489 1.15401 -0.233077 0.358007 0.457814</pose>
          <velocity>0.017196 0.00083 -0.005469 0.013765 0.02566 0.003145</velocity>
          <acceleration>0.006731 -0.025509 -0.000345 -0.765557 -1.24996 -2.81016</acceleration>
          <wrench>0.013212 -0.050071 -0.000678 0 -0 0</wrench>
        </link>
        <link name='arm2_2'>
          <pose frame=''>0.555395 -0.280702 1.19901 -0.381685 0.358007 0.457814</pose>
          <velocity>0.018618 0.000132 -0.005358 -0.007471 0.015254 0.01196</velocity>
          <acceleration>0.005781 -0.026578 0.000894 -0.543165 0.234639 -0.481176</acceleration>
          <wrench>0.010749 -0.049424 0.001662 0 -0 0</wrench>
        </link>
        <link name='arm2_3'>
          <pose frame=''>0.603415 -0.347628 0.977809 -0.457133 0.251025 0.20773</pose>
          <velocity>0.016033 -0.000902 -0.005543 -0.009982 0.005701 -0.005196</velocity>
          <acceleration>0.001135 -0.028802 0.00116 -1.20156 0.480736 0.242618</acceleration>
          <wrench>0.001893 -0.048036 0.001934 0 -0 0</wrench>
        </link>
        <link name='arm2_4'>
          <pose frame=''>0.652787 -0.421176 0.92589 -2.22961 -0.999523 2.64405</pose>
          <velocity>0.015381 -0.001652 -0.005046 -0.00148 -0.018979 0.007194</velocity>
          <acceleration>-0.000121 -0.028792 8.4e-05 -1.5932 -0.271301 0.737555</acceleration>
          <wrench>-0.000159 -0.037882 0.000111 0 -0 0</wrench>
        </link>
        <link name='arm2_5'>
          <pose frame=''>0.722634 -0.335209 0.921138 -2.29064 -1.04479 2.71555</pose>
          <velocity>0.014868 -0.001149 -0.003841 0.013415 -0.010974 0.013128</velocity>
          <acceleration>-0.000473 -0.027089 -0.001758 2.60125 -1.13931 -2.12574</acceleration>
          <wrench>-0.000706 -0.040385 -0.002621 0 -0 0</wrench>
        </link>
        <link name='arm2_6'>
          <pose frame=''>0.867766 -0.307738 0.991273 -2.72014 -0.395406 -2.96011</pose>
          <velocity>0.013749 -0.000181 -0.001878 0.003481 0.016269 0.001326</velocity>
          <acceleration>0.002417 -0.024508 -0.004717 -0.894137 1.47672 3.00213</acceleration>
          <wrench>0.002722 -0.027604 -0.005313 0 -0 0</wrench>
        </link>
        <link name='arm2_7'>
          <pose frame=''>0.899407 -0.184104 1.1193 -2.69519 -0.366538 -3.02719</pose>
          <velocity>0.015673 -0.000583 -0.001964 0.001285 0.012528 -0.00547</velocity>
          <acceleration>0.006161 -0.022617 -0.007167 -0.043125 -0.021131 -0.006661</acceleration>
          <wrench>0.011878 -0.043604 -0.013818 0 -0 0</wrench>
        </link>
        <link name='hip1_1'>
          <pose frame=''>0.654351 0.12135 0.741632 2.98673 -0.039167 1.6058</pose>
          <velocity>0.011738 0.010622 0.001204 0.02774 0.003164 -0.043257</velocity>
          <acceleration>-0.001976 -0.021084 0.002007 0.594588 0.643703 2.37161</acceleration>
          <wrench>-0.003793 -0.04047 0.003853 0 -0 0</wrench>
        </link>
        <link name='hip1_2'>
          <pose frame=''>0.668007 -0.128115 0.732613 -2.98217 0.010213 -1.35344</pose>
          <velocity>0.011979 0.011677 -0.00502 0.02152 0.049407 -0.114464</velocity>
          <acceleration>0.003293 -0.020965 0.000235 -2.89294 -1.40675 1.12717</acceleration>
          <wrench>0.006321 -0.04024 0.000452 0 -0 0</wrench>
        </link>
        <link name='hip1_3'>
          <pose frame=''>0.160978 0.097141 0.664192 2.98745 -0.041933 1.588</pose>
          <velocity>0.010952 0.011196 0.005862 0.023764 0.012785 0.003001</velocity>
          <acceleration>-0.001413 -0.03164 0.003821 2.11593 -0.01814 -0.004265</acceleration>
          <wrench>-0.002712 -0.060731 0.007333 0 -0 0</wrench>
        </link>
        <link name='hip1_4'>
          <pose frame=''>0.174634 -0.152323 0.655173 -2.98186 0.000875 -1.29558</pose>
          <velocity>0.011626 0.012253 -0.000642 0.02193 0.03434 0.052702</velocity>
          <acceleration>0.002926 -0.031247 0.001992 -0.665573 1.52671 -3.00969</acceleration>
          <wrench>0.005616 -0.059976 0.003823 0 -0 0</wrench>
        </link>
        <link name='hip2_1'>
          <pose frame=''>0.663901 0.124104 0.679928 -1.79519 -0.998171 1.32452</pose>
          <velocity>0.011498 0.011876 0.000997 -0.008113 0.012464 -0.042</velocity>
          <acceleration>-0.004148 -0.021451 0.000556 -1.35556 -1.19427 0.943103</acceleration>
          <wrench>-0.011308 -0.058485 0.001515 0 -0 0</wrench>
        </link>
        <link name='hip2_2'>
          <pose frame=''>0.677559 -0.125361 0.670908 2.40343 1.37113 -0.065604</pose>
          <velocity>0.009558 0.013069 -0.004346 0.524079 0.505567 -0.020431</velocity>
          <acceleration>0.006733 -0.019364 0.007839 -0.307164 0.929528 -2.60919</acceleration>
          <wrench>0.018358 -0.052794 0.021373 0 -0 0</wrench>
        </link>
        <link name='hip2_3'>
          <pose frame=''>0.170528 0.099895 0.602488 -1.20557 1.1187 -0.761677</pose>
          <velocity>0.010222 0.012587 0.005728 -0.030591 -0.013724 -0.00752</velocity>
          <acceleration>0.009317 -0.030923 0.00377 -1.9912 1.33323 -0.774484</acceleration>
          <wrench>0.025404 -0.08431 0.010279 0 -0 0</wrench>
        </link>
        <link name='hip2_4'>
          <pose frame=''>0.184184 -0.149569 0.593472 1.07783 -1.26601 1.85291</pose>
          <velocity>0.010757 0.01359 -0.004922 0.255458 -0.021628 0.086532</velocity>
          <acceleration>-0.005582 -0.033297 -0.000619 2.96244 1.01691 -2.62178</acceleration>
          <wrench>-0.015219 -0.090783 -0.001688 0 -0 0</wrench>
        </link>
        <link name='knee_1'>
          <pose frame=''>0.79181 0.344727 0.521886 -0.87679 1.38116 -1.32147</pose>
          <velocity>0.018774 0.00472 -0.003136 -0.030397 0.023037 -0.046465</velocity>
          <acceleration>-0.006794 -0.022745 -0.00096 2.68938 1.51095 0.870015</acceleration>
          <wrench>-0.013152 -0.044027 -0.001859 0 -0 0</wrench>
        </link>
        <link name='knee_2'>
          <pose frame=''>0.863217 -0.357522 0.711475 1.12101 1.22656 1.82681</pose>
          <velocity>0.023776 -0.011588 -0.21706 -0.442808 -0.275734 -0.224008</velocity>
          <acceleration>0.004897 -0.014999 0.014312 -2.73743 0.263254 0.558735</acceleration>
          <wrench>0.009479 -0.029034 0.027704 0 -0 0</wrench>
        </link>
        <link name='knee_3'>
          <pose frame=''>0.058908 0.349758 0.479515 1.96393 1.15129 -0.730915</pose>
          <velocity>0.013827 0.009563 -0.003633 -0.043608 -0.020326 -0.009227</velocity>
          <acceleration>0.011843 -0.026284 0.003399 -0.072169 -1.501 -0.338094</acceleration>
          <wrench>0.022924 -0.050878 0.00658 0 -0 0</wrench>
        </link>
        <link name='knee_4'>
          <pose frame=''>0.114509 -0.430549 0.67227 -1.86665 1.0619 1.11923</pose>
          <velocity>0.03274 -0.011803 -0.079336 -0.362076 0.132016 -0.015553</velocity>
          <acceleration>-0.00889 -0.031562 -0.001395 2.55501 -0.269199 3.05756</acceleration>
          <wrench>-0.017209 -0.061094 -0.0027 0 -0 0</wrench>
        </link>
        <link name='neck_1'>
          <pose frame=''>0.521368 -0.03189 1.31394 0.03728 -0.155332 0.044145</pose>
          <velocity>0.017806 -0.003671 -0.00083 0.024102 0.01213 0.007389</velocity>
          <acceleration>0.003204 -0.027417 0.001259 0.100862 -1.31716 0.971031</acceleration>
          <wrench>0.001085 -0.009289 0.000427 0 -0 0</wrench>
        </link>
        <link name='neck_2'>
          <pose frame=''>0.573604 0.030501 1.31215 0.036982 0.089956 0.053241</pose>
          <velocity>0.017084 -0.00346 0.000251 0.023074 0.015471 0.006436</velocity>
          <acceleration>0.003489 -0.026133 0.000785 2.0655 -0.828317 -1.5964</acceleration>
          <wrench>0.002739 -0.020521 0.000616 0 -0 0</wrench>
        </link>
        <link name='neck_3'>
          <pose frame=''>0.546044 -0.037985 1.51375 0.141476 0.074344 -1.77077</pose>
          <velocity>0.019639 -0.008217 -0.001324 0.024006 0.009502 0.007649</velocity>
          <acceleration>0.005282 -0.030182 0.001246 1.91647 0.730794 0.396542</acceleration>
          <wrench>0.004148 -0.023701 0.000979 0 -0 0</wrench>
        </link>
        <link name='pelvis'>
          <pose frame=''>0.405844 -0.01798 0.754282 0.036525 -0.155507 0.049027</pose>
          <velocity>0.012175 0.009852 0.000452 0.024236 0.01066 0.002746</velocity>
          <acceleration>0.001344 -0.027122 0.002035 2.09154 0.150268 0.398757</acceleration>
          <wrench>0.021632 -0.436594 0.032752 0 -0 0</wrench>
        </link>
        <link name='torso_2'>
          <pose frame=''>0.564076 -0.019576 1.038 0.037157 -0.155359 0.044943</pose>
          <velocity>0.014769 0.003309 -0.001237 0.023657 0.010574 0.007479</velocity>
          <acceleration>0.002898 -0.02725 0.001412 2.21471 -1.00285 2.84335</acceleration>
          <wrench>0.033304 -0.31317 0.016226 0 -0 0</wrench>
        </link>
        <link name='wheel_1'>
          <pose frame=''>0.744039 0.354357 0.078395 1.50419 -1.32441 -3.09128</pose>
          <velocity>0.014055 0.000312 -0.001298 -0.003963 0.179092 7e-06</velocity>
          <acceleration>-0.003233 -0.006237 0.000976 2.66395 -0.70112 -3.05427</acceleration>
          <wrench>-0.00559 -0.010783 0.001687 0 -0 0</wrench>
        </link>
        <link name='wheel_2'>
          <pose frame=''>0.817053 -0.359664 0.276091 1.54913 -0.041504 0.020415</pose>
          <velocity>-0.004023 -0.021143 -0.277892 0.271543 -0.051651 9.2e-05</velocity>
          <acceleration>-0.000602 -0.003944 0.014268 1.46332 0.120831 -2.86998</acceleration>
          <wrench>-0.001041 -0.006819 0.024667 0 -0 0</wrench>
        </link>
        <link name='wheel_3'>
          <pose frame=''>0.246874 0.345925 0.078492 -1.42925 1.41541 0.116961</pose>
          <velocity>0.016639 -0.000111 -0.000278 0.001438 0.21162 2.1e-05</velocity>
          <acceleration>0.001045 -0.007981 0.00218 2.18561 0.323115 -3.0029</acceleration>
          <wrench>0.001807 -0.013798 0.003769 0 -0 0</wrench>
        </link>
        <link name='wheel_4'>
          <pose frame=''>0.290132 -0.354772 0.277309 -1.61303 -0.472081 3.13242</pose>
          <velocity>-0.001868 -0.017722 -0.129895 0.226222 -0.023849 -2.8e-05</velocity>
          <acceleration>-0.005017 -0.009117 -0.001376 -2.6198 1.08772 3.06706</acceleration>
          <wrench>-0.008674 -0.015763 -0.002378 0 -0 0</wrench>
        </link>
      </model>
      <model name='ground_plane'>
        <pose frame=''>0 0 0 0 -0 0</pose>
        <scale>1 1 1</scale>
        <link name='link'>
          <pose frame=''>0 0 0 0 -0 0</pose>
          <velocity>0 0 0 0 -0 0</velocity>
          <acceleration>0 0 0 0 -0 0</acceleration>
          <wrench>0 0 0 0 -0 0</wrench>
        </link>
      </model>
      <model name='unit_box'>
        <pose frame=''>1.1736 -0.5 0.1 0 -0 0</pose>
        <scale>1 1 1</scale>
        <link name='link'>
          <pose frame=''>1.1736 -0.5 0.1 0 -0 0</pose>
          <velocity>0 0 0 0 -0 0</velocity>
          <acceleration>0 0 -0.00981 0 -0 0</acceleration>
          <wrench>0 0 -9.81 0 -0 0</wrench>
        </link>
      </model>
      <light name='sun'>
        <pose frame=''>0 0 10 0 -0 0</pose>
      </light>
    </state>
  </world>
</sdf>
