<sdf version='1.6'>
  <world name='default'>
    <plugin name='xbot2_clock' filename='libxbot2_gz_clock.so'/>
    <gravity>0 0 -9.81</gravity>
    <model name='ground_plane'>
      <static>1</static>
      <link name='link'>
        <collision name='collision'>
          <geometry>
            <plane>
              <normal>0 0 1</normal>
              <size>100 100</size>
            </plane>
          </geometry>
          <surface>
            <friction>
              <ode>
                <mu>1</mu>
                <mu2>1</mu2>
              </ode>
              <torsional>
                <ode/>
              </torsional>
            </friction>
            <contact>
              <ode/>
            </contact>
            <bounce/>
          </surface>
          <max_contacts>10</max_contacts>
        </collision>
        <visual name='visual'>
          <cast_shadows>0</cast_shadows>
          <geometry>
            <plane>
              <normal>0 0 1</normal>
              <size>100 100</size>
            </plane>
          </geometry>
          <material>
            <script>
              <uri>file://media/materials/scripts/gazebo.material</uri>
              <name>Gazebo/Grey</name>
            </script>
          </material>
        </visual>
        <self_collide>0</self_collide>
        <enable_wind>0</enable_wind>
        <kinematic>0</kinematic>
      </link>
    </model>
    <model name='unit_box'>
      <pose frame=''>2 -0.5 0.1 0 -0 0</pose>
      <link name='link'>
        <inertial>
          <mass>1000</mass>
          <inertia>
            <ixx>100</ixx>
            <ixy>0</ixy>
            <ixz>0</ixz>
            <iyy>100</iyy>
            <iyz>0</iyz>
            <izz>166</izz>
          </inertia>
        </inertial>
        <collision name='collision'>
          <geometry>
            <box>
              <size>2 1 0.2</size>
            </box>
          </geometry>
          <max_contacts>10</max_contacts>
          <surface>
            <contact>
              <ode/>
            </contact>
            <bounce/>
            <friction>
              <torsional>
                <ode/>
              </torsional>
              <ode/>
            </friction>
          </surface>
        </collision>
        <visual name='visual'>
          <geometry>
            <box>
              <size>2 1 0.2</size>
            </box>
          </geometry>
          <material>
            <script>
              <name>Gazebo/Grey</name>
              <uri>file://media/materials/scripts/gazebo.material</uri>
            </script>
          </material>
        </visual>
        <self_collide>0</self_collide>
        <enable_wind>0</enable_wind>
        <kinematic>1</kinematic>
      </link>
    </model>
    <light name='sun' type='directional'>
      <cast_shadows>1</cast_shadows>
      <pose frame=''>0 0 10 0 -0 0</pose>
      <diffuse>0.8 0.8 0.8 1</diffuse>
      <specular>0.2 0.2 0.2 1</specular>
      <attenuation>
        <range>1000</range>
        <constant>0.9</constant>
        <linear>0.01</linear>
        <quadratic>0.001</quadratic>
      </attenuation>
      <direction>-0.5 0.1 -0.9</direction>
    </light>
    <gui fullscreen='0'>
      <camera name='user_camera'>
        <pose frame=''>0.420121 -3.38508 1.11799 0 0.263643 1.3002</pose>
        <view_controller>orbit</view_controller>
        <projection_type>perspective</projection_type>
      </camera>
    </gui>
    <physics name='update_rate' default='0' type='ode'>
      <real_time_update_rate>4000</real_time_update_rate>
      <max_step_size>0.00025</max_step_size>
      <max_contacts>5</max_contacts>
      <bullet>
        <solver>
          <iters>100</iters>
          <sor>1.55</sor>
          <type>sequential_impulse</type>
        </solver>
        <constraints>
          <contact_surface_layer>0.2</contact_surface_layer>
          <cfm>0.005</cfm>
          <erp>0.2</erp>
          <split_impulse>1</split_impulse>
          <split_impulse_penetration_threshold>-0.01</split_impulse_penetration_threshold>
        </constraints>
      </bullet>
      <ode>
        <solver>
          <iters>50</iters>
          <sor>1.2</sor>
          <type>quick</type>
          <use_dynamic_moi_rescaling>0</use_dynamic_moi_rescaling>
        </solver>
        <constraints>
          <contact_surface_layer>0.0002</contact_surface_layer>
          <contact_max_correcting_vel>500</contact_max_correcting_vel>
          <cfm>1e-06</cfm>
          <erp>0.3</erp>
        </constraints>
      </ode>
      <real_time_factor>1</real_time_factor>
    </physics>
    <magnetic_field>6e-06 2.3e-05 -4.2e-05</magnetic_field>
    <atmosphere type='adiabatic'/>
    <scene>
      <ambient>0.4 0.4 0.4 1</ambient>
      <background>0.7 0.7 0.7 1</background>
      <shadows>1</shadows>
    </scene>
    <audio>
      <device>default</device>
    </audio>
    <wind/>
    <spherical_coordinates>
      <surface_model>EARTH_WGS84</surface_model>
      <latitude_deg>0</latitude_deg>
      <longitude_deg>0</longitude_deg>
      <elevation>0</elevation>
      <heading_deg>0</heading_deg>
    </spherical_coordinates>
    <model name='centauro'>
      <link name='pelvis'>
        <pose frame=''>0 0 0 0 -0 0</pose>
        <inertial>
          <pose frame=''>0.001389 -0.001599 0.063101 0 -0 0</pose>
          <mass>16.0976</mass>
          <inertia>
            <ixx>0.239126</ixx>
            <ixy>-0.00505413</ixy>
            <ixz>-0.0197461</ixz>
            <iyy>0.714301</iyy>
            <iyz>0.00021312</iyz>
            <izz>0.818704</izz>
          </inertia>
        </inertial>
        <collision name='pelvis_collision'>
          <pose frame=''>0 0 0 0 -0 0</pose>
          <geometry>
            <mesh>
              <scale>0.001 0.001 0.001</scale>
              <uri>/home/ioannis/centauro_ws/src/iit-centauro-ros-pkg/centauro_urdf/meshes/simple/pelvis.stl</uri>
            </mesh>
          </geometry>
          <surface>
            <contact>
              <ode/>
            </contact>
            <friction>
              <ode/>
              <torsional>
                <ode/>
              </torsional>
            </friction>
            <bounce/>
          </surface>
          <max_contacts>10</max_contacts>
        </collision>
        <visual name='pelvis_visual'>
          <pose frame=''>0 0 0 0 -0 0</pose>
          <geometry>
            <mesh>
              <scale>0.001 0.001 0.001</scale>
              <uri>/home/ioannis/centauro_ws/src/iit-centauro-ros-pkg/centauro_urdf/meshes/pelvis.stl</uri>
            </mesh>
          </geometry>
          <material>
            <script>
              <name>Gazebo/LightBlueLaser</name>
              <uri>file://media/materials/scripts/gazebo.material</uri>
            </script>
          </material>
        </visual>
        <velocity_decay/>
        <gravity>1</gravity>
        <velocity_decay/>
        <sensor name='imu_link' type='imu'>
          <always_on>1</always_on>
          <update_rate>500</update_rate>
          <visualize>1</visualize>
          <topic>__default_topic__</topic>
          <imu>
            <angular_velocity/>
            <linear_acceleration/>
          </imu>
          <pose frame=''>0.248316 0 0.015 0 -0 0</pose>
        </sensor>
        <self_collide>0</self_collide>
        <enable_wind>0</enable_wind>
        <kinematic>0</kinematic>
      </link>
      <link name='hip1_1'>
        <pose frame=''>0.25 0.125 -0.0566 -3.14159 -0 0.461416</pose>
        <inertial>
          <pose frame=''>0.010214 -0.018348 0.038091 0 -0 0</pose>
          <mass>1.91944</mass>
          <inertia>
            <ixx>0.00474396</ixx>
            <ixy>0.000574705</ixy>
            <ixz>-0.000378414</ixz>
            <iyy>0.00405519</iyy>
            <iyz>0.000740751</iyz>
            <izz>0.00341462</izz>
          </inertia>
        </inertial>
        <collision name='hip1_1_collision'>
          <pose frame=''>0 0 0 0 -0 -2.21876</pose>
          <geometry>
            <mesh>
              <scale>0.001 0.001 0.001</scale>
              <uri>/home/ioannis/centauro_ws/src/iit-centauro-ros-pkg/centauro_urdf/meshes/simple/hip-yaw.stl</uri>
            </mesh>
          </geometry>
          <surface>
            <contact>
              <ode/>
            </contact>
            <friction>
              <ode/>
              <torsional>
                <ode/>
              </torsional>
            </friction>
            <bounce/>
          </surface>
          <max_contacts>10</max_contacts>
        </collision>
        <visual name='hip1_1_visual'>
          <pose frame=''>0 0 0 0 -0 -2.21876</pose>
          <geometry>
            <mesh>
              <scale>0.001 0.001 0.001</scale>
              <uri>/home/ioannis/centauro_ws/src/iit-centauro-ros-pkg/centauro_urdf/meshes/hip-yaw.stl</uri>
            </mesh>
          </geometry>
          <material>
            <script>
              <name>Gazebo/LightBlueLaser</name>
              <uri>file://media/materials/scripts/gazebo.material</uri>
            </script>
          </material>
        </visual>
        <gravity>1</gravity>
        <velocity_decay/>
        <self_collide>0</self_collide>
        <enable_wind>0</enable_wind>
        <kinematic>0</kinematic>
      </link>
      <joint name='hip_yaw_1' type='revolute'>
        <child>hip1_1</child>
        <parent>pelvis</parent>
        <axis>
          <xyz>-0 0 -1</xyz>
          <limit>
            <lower>-2.03</lower>
            <upper>2.51</upper>
            <effort>304</effort>
            <velocity>8.8</velocity>
          </limit>
          <dynamics>
            <spring_reference>0</spring_reference>
            <spring_stiffness>0</spring_stiffness>
          </dynamics>
          <use_parent_model_frame>1</use_parent_model_frame>
        </axis>
        <physics>
          <provide_feedback>1</provide_feedback>
          <ode>
            <provide_feedback>1</provide_feedback>
            <implicit_spring_damper>1</implicit_spring_damper>
            <cfm_damping>1</cfm_damping>
            <limit>
              <cfm>0</cfm>
              <erp>0.2</erp>
            </limit>
          </ode>
        </physics>
      </joint>
      <link name='hip2_1'>
        <pose frame=''>0.25 0.125 -0.1191 -1.5708 0 0</pose>
        <inertial>
          <pose frame=''>2.6e-05 0.181027 0.08567 0 -0 0</pose>
          <mass>2.72645</mass>
          <inertia>
            <ixx>0.0485187</ixx>
            <ixy>-4.11894e-05</ixy>
            <ixz>-1.68778e-05</ixz>
            <iyy>0.00424205</iyy>
            <iyz>0.00322432</iyz>
            <izz>0.0482558</izz>
          </inertia>
        </inertial>
        <collision name='hip2_1_collision'>
          <pose frame=''>0 0 0 0 -0 0</pose>
          <geometry>
            <mesh>
              <scale>0.001 0.001 0.001</scale>
              <uri>/home/ioannis/centauro_ws/src/iit-centauro-ros-pkg/centauro_urdf/meshes/simple/hip-pitch.stl</uri>
            </mesh>
          </geometry>
          <surface>
            <contact>
              <ode/>
            </contact>
            <friction>
              <ode/>
              <torsional>
                <ode/>
              </torsional>
            </friction>
            <bounce/>
          </surface>
          <max_contacts>10</max_contacts>
        </collision>
        <visual name='hip2_1_visual'>
          <pose frame=''>0 0 0 0 -0 0</pose>
          <geometry>
            <mesh>
              <scale>0.001 0.001 0.001</scale>
              <uri>/home/ioannis/centauro_ws/src/iit-centauro-ros-pkg/centauro_urdf/meshes/hip-pitch.stl</uri>
            </mesh>
          </geometry>
          <material>
            <script>
              <name>Gazebo/BlackTransparent</name>
              <uri>file://media/materials/scripts/gazebo.material</uri>
            </script>
          </material>
        </visual>
        <gravity>1</gravity>
        <velocity_decay/>
        <self_collide>0</self_collide>
        <enable_wind>0</enable_wind>
        <kinematic>0</kinematic>
      </link>
      <joint name='hip_pitch_1' type='revolute'>
        <child>hip2_1</child>
        <parent>hip1_1</parent>
        <axis>
          <xyz>0 1 -0</xyz>
          <limit>
            <lower>-2.0226</lower>
            <upper>2.02748</upper>
            <effort>304</effort>
            <velocity>8.8</velocity>
          </limit>
          <dynamics>
            <spring_reference>0</spring_reference>
            <spring_stiffness>0</spring_stiffness>
          </dynamics>
          <use_parent_model_frame>1</use_parent_model_frame>
        </axis>
        <physics>
          <provide_feedback>1</provide_feedback>
          <ode>
            <provide_feedback>1</provide_feedback>
            <implicit_spring_damper>1</implicit_spring_damper>
            <cfm_damping>1</cfm_damping>
            <limit>
              <cfm>0</cfm>
              <erp>0.2</erp>
            </limit>
          </ode>
        </physics>
      </joint>
      <link name='knee_1'>
        <pose frame=''>0.25 0.1214 -0.4191 -1.57079 1.57079 3.14159</pose>
        <inertial>
          <pose frame=''>0.108817 0.000109 -0.022639 0 -0 0</pose>
          <mass>1.93568</mass>
          <inertia>
            <ixx>0.00305342</ixx>
            <ixy>-4.22079e-05</ixy>
            <ixz>0.00136793</ixz>
            <iyy>0.0196033</iyy>
            <iyz>6.9941e-06</iyz>
            <izz>0.0198498</izz>
          </inertia>
        </inertial>
        <collision name='knee_1_collision'>
          <pose frame=''>0 0 0 0 -0 0</pose>
          <geometry>
            <mesh>
              <scale>0.001 0.001 0.001</scale>
              <uri>/home/ioannis/centauro_ws/src/iit-centauro-ros-pkg/centauro_urdf/meshes/simple/knee.stl</uri>
            </mesh>
          </geometry>
          <surface>
            <contact>
              <ode/>
            </contact>
            <friction>
              <ode/>
              <torsional>
                <ode/>
              </torsional>
            </friction>
            <bounce/>
          </surface>
          <max_contacts>10</max_contacts>
        </collision>
        <visual name='knee_1_visual'>
          <pose frame=''>0 0 0 0 -0 0</pose>
          <geometry>
            <mesh>
              <scale>0.001 0.001 0.001</scale>
              <uri>/home/ioannis/centauro_ws/src/iit-centauro-ros-pkg/centauro_urdf/meshes/knee.stl</uri>
            </mesh>
          </geometry>
          <material>
            <script>
              <name>Gazebo/LightBlueLaser</name>
              <uri>file://media/materials/scripts/gazebo.material</uri>
            </script>
          </material>
        </visual>
        <gravity>1</gravity>
        <velocity_decay/>
        <self_collide>0</self_collide>
        <enable_wind>0</enable_wind>
        <kinematic>0</kinematic>
      </link>
      <joint name='knee_pitch_1' type='revolute'>
        <child>knee_1</child>
        <parent>hip2_1</parent>
        <axis>
          <xyz>-0 -1 0</xyz>
          <limit>
            <lower>-2.4056</lower>
            <upper>2.3994</upper>
            <effort>304</effort>
            <velocity>8.8</velocity>
          </limit>
          <dynamics>
            <spring_reference>0</spring_reference>
            <spring_stiffness>0</spring_stiffness>
          </dynamics>
          <use_parent_model_frame>1</use_parent_model_frame>
        </axis>
        <physics>
          <provide_feedback>1</provide_feedback>
          <ode>
            <provide_feedback>1</provide_feedback>
            <implicit_spring_damper>1</implicit_spring_damper>
            <cfm_damping>1</cfm_damping>
            <limit>
              <cfm>0</cfm>
              <erp>0.2</erp>
            </limit>
          </ode>
        </physics>
      </joint>
      <link name='ankle1_1'>
        <pose frame=''>0.25 0.22155 -0.6191 1.57079 1.57079 3.14159</pose>
        <inertial>
          <pose frame=''>0.032137 9.7e-05 -0.004422 0 -0 0</pose>
          <mass>1.23807</mass>
          <inertia>
            <ixx>0.00156105</ixx>
            <ixy>3.30597e-05</ixy>
            <ixz>-0.000131417</ixz>
            <iyy>0.00374232</iyy>
            <iyz>-2.12589e-05</iyz>
            <izz>0.00383124</izz>
          </inertia>
        </inertial>
        <collision name='ankle1_1_collision'>
          <pose frame=''>0 0 0 0 -0 0</pose>
          <geometry>
            <mesh>
              <scale>0.001 0.001 0.001</scale>
              <uri>/home/ioannis/centauro_ws/src/iit-centauro-ros-pkg/centauro_urdf/meshes/simple/ankle-pitch.stl</uri>
            </mesh>
          </geometry>
          <surface>
            <contact>
              <ode/>
            </contact>
            <friction>
              <ode/>
              <torsional>
                <ode/>
              </torsional>
            </friction>
            <bounce/>
          </surface>
          <max_contacts>10</max_contacts>
        </collision>
        <visual name='ankle1_1_visual'>
          <pose frame=''>0 0 0 0 -0 0</pose>
          <geometry>
            <mesh>
              <scale>0.001 0.001 0.001</scale>
              <uri>/home/ioannis/centauro_ws/src/iit-centauro-ros-pkg/centauro_urdf/meshes/ankle-pitch.stl</uri>
            </mesh>
          </geometry>
          <material>
            <script>
              <name>Gazebo/LightBlueLaser</name>
              <uri>file://media/materials/scripts/gazebo.material</uri>
            </script>
          </material>
        </visual>
        <gravity>1</gravity>
        <velocity_decay/>
        <self_collide>0</self_collide>
        <enable_wind>0</enable_wind>
        <kinematic>0</kinematic>
      </link>
      <joint name='ankle_pitch_1' type='revolute'>
        <child>ankle1_1</child>
        <parent>knee_1</parent>
        <axis>
          <xyz>0 1 -0</xyz>
          <limit>
            <lower>-2.4056</lower>
            <upper>2.3184</upper>
            <effort>147</effort>
            <velocity>8.1</velocity>
          </limit>
          <dynamics>
            <spring_reference>0</spring_reference>
            <spring_stiffness>0</spring_stiffness>
          </dynamics>
          <use_parent_model_frame>1</use_parent_model_frame>
        </axis>
        <physics>
          <provide_feedback>1</provide_feedback>
          <ode>
            <provide_feedback>1</provide_feedback>
            <implicit_spring_damper>1</implicit_spring_damper>
            <cfm_damping>1</cfm_damping>
            <limit>
              <cfm>0</cfm>
              <erp>0.2</erp>
            </limit>
          </ode>
        </physics>
      </joint>
      <link name='ankle2_1'>
        <pose frame=''>0.25 0.22155 -0.6191 3.14159 -0 3.14159</pose>
        <inertial>
          <pose frame=''>0.000444 0.000439 0.193921 0 -0 0</pose>
          <mass>1.15659</mass>
          <inertia>
            <ixx>0.00490195</ixx>
            <ixy>4.3032e-06</ixy>
            <ixz>3.46491e-05</ixz>
            <iyy>0.00387242</iyy>
            <iyz>1.7099e-05</iyz>
            <izz>0.00217832</izz>
          </inertia>
        </inertial>
        <collision name='ankle2_1_collision'>
          <pose frame=''>0 0 0 0 -0 0</pose>
          <geometry>
            <mesh>
              <scale>0.001 0.001 0.001</scale>
              <uri>/home/ioannis/centauro_ws/src/iit-centauro-ros-pkg/centauro_urdf/meshes/simple/ankle-yaw.stl</uri>
            </mesh>
          </geometry>
          <surface>
            <contact>
              <ode/>
            </contact>
            <friction>
              <ode/>
              <torsional>
                <ode/>
              </torsional>
            </friction>
            <bounce/>
          </surface>
          <max_contacts>10</max_contacts>
        </collision>
        <visual name='ankle2_1_visual'>
          <pose frame=''>0 0 0 0 -0 0</pose>
          <geometry>
            <mesh>
              <scale>0.001 0.001 0.001</scale>
              <uri>/home/ioannis/centauro_ws/src/iit-centauro-ros-pkg/centauro_urdf/meshes/ankle-yaw.stl</uri>
            </mesh>
          </geometry>
          <material>
            <script>
              <name>Gazebo/LightBlueLaser</name>
              <uri>file://media/materials/scripts/gazebo.material</uri>
            </script>
          </material>
        </visual>
        <gravity>1</gravity>
        <velocity_decay/>
        <self_collide>0</self_collide>
        <enable_wind>0</enable_wind>
        <kinematic>0</kinematic>
      </link>
      <joint name='ankle_yaw_1' type='revolute'>
        <child>ankle2_1</child>
        <parent>ankle1_1</parent>
        <axis>
          <xyz>0 0 -1</xyz>
          <limit>
            <lower>-2.5626</lower>
            <upper>2.5384</upper>
            <effort>35</effort>
            <velocity>20</velocity>
          </limit>
          <dynamics>
            <spring_reference>0</spring_reference>
            <spring_stiffness>0</spring_stiffness>
          </dynamics>
          <use_parent_model_frame>1</use_parent_model_frame>
        </axis>
        <physics>
          <provide_feedback>1</provide_feedback>
          <ode>
            <provide_feedback>1</provide_feedback>
            <implicit_spring_damper>1</implicit_spring_damper>
            <cfm_damping>1</cfm_damping>
            <limit>
              <cfm>0</cfm>
              <erp>0.2</erp>
            </limit>
          </ode>
        </physics>
      </joint>
      <link name='wheel_1'>
        <pose frame=''>0.25 0.2224 -0.85645 -1.5708 -0 -0</pose>
        <inertial>
          <pose frame=''>0 0 0.002427 0 -0 0</pose>
          <mass>1.7289</mass>
          <inertia>
            <ixx>0.00468643</ixx>
            <ixy>0</ixy>
            <ixz>0</ixz>
            <iyy>0.00467135</iyy>
            <iyz>0</iyz>
            <izz>0.0053126</izz>
          </inertia>
        </inertial>
        <collision name='wheel_1_collision'>
          <pose frame=''>0 0 0 0 -0 0</pose>
          <geometry>
            <cylinder>
              <length>0.06</length>
              <radius>0.078</radius>
            </cylinder>
          </geometry>
          <surface>
            <friction>
              <ode>
                <mu>0.5</mu>
                <mu2>0.5</mu2>
              </ode>
              <bullet>
                <friction>0.5</friction>
                <friction2>0.5</friction2>
              </bullet>
              <torsional>
                <ode/>
              </torsional>
            </friction>
            <contact>
              <ode>
                <kp>2.1e+06</kp>
                <kd>1</kd>
                <max_vel>100</max_vel>
              </ode>
              <bullet>
                <soft_cfm>0.007</soft_cfm>
                <soft_erp>0.25</soft_erp>
                <kp>1e+06</kp>
                <kd>5</kd>
                <split_impulse>1</split_impulse>
                <split_impulse_penetration_threshold>-0.01</split_impulse_penetration_threshold>
              </bullet>
            </contact>
            <bounce/>
          </surface>
          <max_contacts>10</max_contacts>
        </collision>
        <visual name='wheel_1_visual'>
          <pose frame=''>0 0 0 0 -0 0</pose>
          <geometry>
            <mesh>
              <scale>0.001 0.001 0.001</scale>
              <uri>/home/ioannis/centauro_ws/src/iit-centauro-ros-pkg/centauro_urdf/meshes/wheel.stl</uri>
            </mesh>
          </geometry>
          <material>
            <script>
              <name>Gazebo/BlackTransparent</name>
              <uri>file://media/materials/scripts/gazebo.material</uri>
            </script>
          </material>
        </visual>
        <velocity_decay/>
        <gravity>1</gravity>
        <velocity_decay/>
        <self_collide>0</self_collide>
        <enable_wind>0</enable_wind>
        <kinematic>0</kinematic>
      </link>
      <joint name='j_wheel_1' type='revolute'>
        <child>wheel_1</child>
        <parent>ankle2_1</parent>
        <axis>
          <xyz>0 1 -0</xyz>
          <limit>
            <lower>-1e+16</lower>
            <upper>1e+16</upper>
          </limit>
          <dynamics>
            <spring_reference>0</spring_reference>
            <spring_stiffness>0</spring_stiffness>
          </dynamics>
          <use_parent_model_frame>1</use_parent_model_frame>
        </axis>
        <physics>
          <provide_feedback>1</provide_feedback>
          <ode>
            <provide_feedback>1</provide_feedback>
            <implicit_spring_damper>1</implicit_spring_damper>
            <cfm_damping>1</cfm_damping>
            <limit>
              <cfm>0</cfm>
              <erp>0.2</erp>
            </limit>
          </ode>
        </physics>
      </joint>
      <link name='hip1_2'>
        <pose frame=''>0.25 -0.125 -0.0566 -3.14159 -0 -0.461416</pose>
        <inertial>
          <pose frame=''>0.010214 0.018348 0.038091 0 -0 0</pose>
          <mass>1.91944</mass>
          <inertia>
            <ixx>0.00474396</ixx>
            <ixy>-0.000574705</ixy>
            <ixz>-0.000378414</ixz>
            <iyy>0.00405519</iyy>
            <iyz>-0.000740751</iyz>
            <izz>0.00341462</izz>
          </inertia>
        </inertial>
        <collision name='hip1_2_collision'>
          <pose frame=''>0 0 0 0 -0 0</pose>
          <geometry>
            <mesh>
              <scale>0.001 0.001 0.001</scale>
              <uri>/home/ioannis/centauro_ws/src/iit-centauro-ros-pkg/centauro_urdf/meshes/simple/hip-yaw.stl</uri>
            </mesh>
          </geometry>
          <surface>
            <contact>
              <ode/>
            </contact>
            <friction>
              <ode/>
              <torsional>
                <ode/>
              </torsional>
            </friction>
            <bounce/>
          </surface>
          <max_contacts>10</max_contacts>
        </collision>
        <visual name='hip1_2_visual'>
          <pose frame=''>0 0 0 0 -0 0</pose>
          <geometry>
            <mesh>
              <scale>0.001 0.001 0.001</scale>
              <uri>/home/ioannis/centauro_ws/src/iit-centauro-ros-pkg/centauro_urdf/meshes/hip-yaw.stl</uri>
            </mesh>
          </geometry>
          <material>
            <script>
              <name>Gazebo/LightBlueLaser</name>
              <uri>file://media/materials/scripts/gazebo.material</uri>
            </script>
          </material>
        </visual>
        <gravity>1</gravity>
        <velocity_decay/>
        <self_collide>0</self_collide>
        <enable_wind>0</enable_wind>
        <kinematic>0</kinematic>
      </link>
      <joint name='hip_yaw_2' type='revolute'>
        <child>hip1_2</child>
        <parent>pelvis</parent>
        <axis>
          <xyz>0 0 -1</xyz>
          <limit>
            <lower>-2.51</lower>
            <upper>2.03</upper>
            <effort>304</effort>
            <velocity>8.8</velocity>
          </limit>
          <dynamics>
            <spring_reference>0</spring_reference>
            <spring_stiffness>0</spring_stiffness>
          </dynamics>
          <use_parent_model_frame>1</use_parent_model_frame>
        </axis>
        <physics>
          <provide_feedback>1</provide_feedback>
          <ode>
            <provide_feedback>1</provide_feedback>
            <implicit_spring_damper>1</implicit_spring_damper>
            <cfm_damping>1</cfm_damping>
            <limit>
              <cfm>0</cfm>
              <erp>0.2</erp>
            </limit>
          </ode>
        </physics>
      </joint>
      <link name='hip2_2'>
        <pose frame=''>0.25 -0.125 -0.1191 -1.5708 -0 -3.14159</pose>
        <inertial>
          <pose frame=''>2.6e-05 0.181027 0.08567 0 -0 0</pose>
          <mass>2.72645</mass>
          <inertia>
            <ixx>0.0485187</ixx>
            <ixy>-4.11894e-05</ixy>
            <ixz>-1.68778e-05</ixz>
            <iyy>0.00424205</iyy>
            <iyz>0.00322432</iyz>
            <izz>0.0482558</izz>
          </inertia>
        </inertial>
        <collision name='hip2_2_collision'>
          <pose frame=''>0 0 0 0 -0 0</pose>
          <geometry>
            <mesh>
              <scale>0.001 0.001 0.001</scale>
              <uri>/home/ioannis/centauro_ws/src/iit-centauro-ros-pkg/centauro_urdf/meshes/simple/hip-pitch.stl</uri>
            </mesh>
          </geometry>
          <surface>
            <contact>
              <ode/>
            </contact>
            <friction>
              <ode/>
              <torsional>
                <ode/>
              </torsional>
            </friction>
            <bounce/>
          </surface>
          <max_contacts>10</max_contacts>
        </collision>
        <visual name='hip2_2_visual'>
          <pose frame=''>0 0 0 0 -0 0</pose>
          <geometry>
            <mesh>
              <scale>0.001 0.001 0.001</scale>
              <uri>/home/ioannis/centauro_ws/src/iit-centauro-ros-pkg/centauro_urdf/meshes/hip-pitch.stl</uri>
            </mesh>
          </geometry>
          <material>
            <script>
              <name>Gazebo/BlackTransparent</name>
              <uri>file://media/materials/scripts/gazebo.material</uri>
            </script>
          </material>
        </visual>
        <gravity>1</gravity>
        <velocity_decay/>
        <self_collide>0</self_collide>
        <enable_wind>0</enable_wind>
        <kinematic>0</kinematic>
      </link>
      <joint name='hip_pitch_2' type='revolute'>
        <child>hip2_2</child>
        <parent>hip1_2</parent>
        <axis>
          <xyz>0 -1 -0</xyz>
          <limit>
            <lower>-2.0156</lower>
            <upper>2.0354</upper>
            <effort>304</effort>
            <velocity>8.8</velocity>
          </limit>
          <dynamics>
            <spring_reference>0</spring_reference>
            <spring_stiffness>0</spring_stiffness>
          </dynamics>
          <use_parent_model_frame>1</use_parent_model_frame>
        </axis>
        <physics>
          <provide_feedback>1</provide_feedback>
          <ode>
            <provide_feedback>1</provide_feedback>
            <implicit_spring_damper>1</implicit_spring_damper>
            <cfm_damping>1</cfm_damping>
            <limit>
              <cfm>0</cfm>
              <erp>0.2</erp>
            </limit>
          </ode>
        </physics>
      </joint>
      <link name='knee_2'>
        <pose frame=''>0.25 -0.1214 -0.4191 1.57079 1.57079 3.14159</pose>
        <inertial>
          <pose frame=''>0.108817 0.000109 -0.022639 0 -0 0</pose>
          <mass>1.93568</mass>
          <inertia>
            <ixx>0.00305342</ixx>
            <ixy>-4.22079e-05</ixy>
            <ixz>0.00136793</ixz>
            <iyy>0.0196033</iyy>
            <iyz>6.9941e-06</iyz>
            <izz>0.0198498</izz>
          </inertia>
        </inertial>
        <collision name='knee_2_collision'>
          <pose frame=''>0 0 0 0 -0 0</pose>
          <geometry>
            <mesh>
              <scale>0.001 0.001 0.001</scale>
              <uri>/home/ioannis/centauro_ws/src/iit-centauro-ros-pkg/centauro_urdf/meshes/simple/knee.stl</uri>
            </mesh>
          </geometry>
          <surface>
            <contact>
              <ode/>
            </contact>
            <friction>
              <ode/>
              <torsional>
                <ode/>
              </torsional>
            </friction>
            <bounce/>
          </surface>
          <max_contacts>10</max_contacts>
        </collision>
        <visual name='knee_2_visual'>
          <pose frame=''>0 0 0 0 -0 0</pose>
          <geometry>
            <mesh>
              <scale>0.001 0.001 0.001</scale>
              <uri>/home/ioannis/centauro_ws/src/iit-centauro-ros-pkg/centauro_urdf/meshes/knee.stl</uri>
            </mesh>
          </geometry>
          <material>
            <script>
              <name>Gazebo/LightBlueLaser</name>
              <uri>file://media/materials/scripts/gazebo.material</uri>
            </script>
          </material>
        </visual>
        <gravity>1</gravity>
        <velocity_decay/>
        <self_collide>0</self_collide>
        <enable_wind>0</enable_wind>
        <kinematic>0</kinematic>
      </link>
      <joint name='knee_pitch_2' type='revolute'>
        <child>knee_2</child>
        <parent>hip2_2</parent>
        <axis>
          <xyz>-0 1 0</xyz>
          <limit>
            <lower>-2.4006</lower>
            <upper>2.4034</upper>
            <effort>304</effort>
            <velocity>8.8</velocity>
          </limit>
          <dynamics>
            <spring_reference>0</spring_reference>
            <spring_stiffness>0</spring_stiffness>
          </dynamics>
          <use_parent_model_frame>1</use_parent_model_frame>
        </axis>
        <physics>
          <provide_feedback>1</provide_feedback>
          <ode>
            <provide_feedback>1</provide_feedback>
            <implicit_spring_damper>1</implicit_spring_damper>
            <cfm_damping>1</cfm_damping>
            <limit>
              <cfm>0</cfm>
              <erp>0.2</erp>
            </limit>
          </ode>
        </physics>
      </joint>
      <link name='ankle1_2'>
        <pose frame=''>0.25 -0.22155 -0.6191 -1.57079 1.57079 3.14159</pose>
        <inertial>
          <pose frame=''>0.032137 9.7e-05 -0.004422 0 -0 0</pose>
          <mass>1.23807</mass>
          <inertia>
            <ixx>0.00156105</ixx>
            <ixy>3.30597e-05</ixy>
            <ixz>-0.000131417</ixz>
            <iyy>0.00374232</iyy>
            <iyz>-2.12589e-05</iyz>
            <izz>0.00383124</izz>
          </inertia>
        </inertial>
        <collision name='ankle1_2_collision'>
          <pose frame=''>0 0 0 0 -0 0</pose>
          <geometry>
            <mesh>
              <scale>0.001 0.001 0.001</scale>
              <uri>/home/ioannis/centauro_ws/src/iit-centauro-ros-pkg/centauro_urdf/meshes/simple/ankle-pitch.stl</uri>
            </mesh>
          </geometry>
          <surface>
            <contact>
              <ode/>
            </contact>
            <friction>
              <ode/>
              <torsional>
                <ode/>
              </torsional>
            </friction>
            <bounce/>
          </surface>
          <max_contacts>10</max_contacts>
        </collision>
        <visual name='ankle1_2_visual'>
          <pose frame=''>0 0 0 0 -0 0</pose>
          <geometry>
            <mesh>
              <scale>0.001 0.001 0.001</scale>
              <uri>/home/ioannis/centauro_ws/src/iit-centauro-ros-pkg/centauro_urdf/meshes/ankle-pitch.stl</uri>
            </mesh>
          </geometry>
          <material>
            <script>
              <name>Gazebo/LightBlueLaser</name>
              <uri>file://media/materials/scripts/gazebo.material</uri>
            </script>
          </material>
        </visual>
        <gravity>1</gravity>
        <velocity_decay/>
        <self_collide>0</self_collide>
        <enable_wind>0</enable_wind>
        <kinematic>0</kinematic>
      </link>
      <joint name='ankle_pitch_2' type='revolute'>
        <child>ankle1_2</child>
        <parent>knee_2</parent>
        <axis>
          <xyz>0 -1 -0</xyz>
          <limit>
            <lower>-2.3266</lower>
            <upper>2.3914</upper>
            <effort>147</effort>
            <velocity>8.1</velocity>
          </limit>
          <dynamics>
            <spring_reference>0</spring_reference>
            <spring_stiffness>0</spring_stiffness>
          </dynamics>
          <use_parent_model_frame>1</use_parent_model_frame>
        </axis>
        <physics>
          <provide_feedback>1</provide_feedback>
          <ode>
            <provide_feedback>1</provide_feedback>
            <implicit_spring_damper>1</implicit_spring_damper>
            <cfm_damping>1</cfm_damping>
            <limit>
              <cfm>0</cfm>
              <erp>0.2</erp>
            </limit>
          </ode>
        </physics>
      </joint>
      <link name='ankle2_2'>
        <pose frame=''>0.25 -0.22155 -0.6191 -3.14159 0 0</pose>
        <inertial>
          <pose frame=''>0.000444 0.000439 0.193921 0 -0 0</pose>
          <mass>1.15659</mass>
          <inertia>
            <ixx>0.00490195</ixx>
            <ixy>4.3032e-06</ixy>
            <ixz>3.46491e-05</ixz>
            <iyy>0.00387242</iyy>
            <iyz>1.7099e-05</iyz>
            <izz>0.00217832</izz>
          </inertia>
        </inertial>
        <collision name='ankle2_2_collision'>
          <pose frame=''>0 0 0 0 -0 0</pose>
          <geometry>
            <mesh>
              <scale>0.001 0.001 0.001</scale>
              <uri>/home/ioannis/centauro_ws/src/iit-centauro-ros-pkg/centauro_urdf/meshes/simple/ankle-yaw.stl</uri>
            </mesh>
          </geometry>
          <surface>
            <contact>
              <ode/>
            </contact>
            <friction>
              <ode/>
              <torsional>
                <ode/>
              </torsional>
            </friction>
            <bounce/>
          </surface>
          <max_contacts>10</max_contacts>
        </collision>
        <visual name='ankle2_2_visual'>
          <pose frame=''>0 0 0 0 -0 0</pose>
          <geometry>
            <mesh>
              <scale>0.001 0.001 0.001</scale>
              <uri>/home/ioannis/centauro_ws/src/iit-centauro-ros-pkg/centauro_urdf/meshes/ankle-yaw.stl</uri>
            </mesh>
          </geometry>
          <material>
            <script>
              <name>Gazebo/LightBlueLaser</name>
              <uri>file://media/materials/scripts/gazebo.material</uri>
            </script>
          </material>
        </visual>
        <gravity>1</gravity>
        <velocity_decay/>
        <self_collide>0</self_collide>
        <enable_wind>0</enable_wind>
        <kinematic>0</kinematic>
      </link>
      <joint name='ankle_yaw_2' type='revolute'>
        <child>ankle2_2</child>
        <parent>ankle1_2</parent>
        <axis>
          <xyz>-0 0 -1</xyz>
          <limit>
            <lower>-2.5546</lower>
            <upper>2.5484</upper>
            <effort>35</effort>
            <velocity>20</velocity>
          </limit>
          <dynamics>
            <spring_reference>0</spring_reference>
            <spring_stiffness>0</spring_stiffness>
          </dynamics>
          <use_parent_model_frame>1</use_parent_model_frame>
        </axis>
        <physics>
          <provide_feedback>1</provide_feedback>
          <ode>
            <provide_feedback>1</provide_feedback>
            <implicit_spring_damper>1</implicit_spring_damper>
            <cfm_damping>1</cfm_damping>
            <limit>
              <cfm>0</cfm>
              <erp>0.2</erp>
            </limit>
          </ode>
        </physics>
      </joint>
      <link name='wheel_2'>
        <pose frame=''>0.25 -0.2224 -0.85645 -1.5708 -0 -3.14159</pose>
        <inertial>
          <pose frame=''>0 0 0.002427 0 -0 0</pose>
          <mass>1.7289</mass>
          <inertia>
            <ixx>0.00468643</ixx>
            <ixy>0</ixy>
            <ixz>0</ixz>
            <iyy>0.00467135</iyy>
            <iyz>0</iyz>
            <izz>0.0053126</izz>
          </inertia>
        </inertial>
        <collision name='wheel_2_collision'>
          <pose frame=''>0 0 0 0 -0 0</pose>
          <geometry>
            <cylinder>
              <length>0.06</length>
              <radius>0.078</radius>
            </cylinder>
          </geometry>
          <surface>
            <friction>
              <ode>
                <mu>0.5</mu>
                <mu2>0.5</mu2>
              </ode>
              <bullet>
                <friction>0.5</friction>
                <friction2>0.5</friction2>
              </bullet>
              <torsional>
                <ode/>
              </torsional>
            </friction>
            <contact>
              <ode>
                <kp>2.1e+06</kp>
                <kd>1</kd>
                <max_vel>100</max_vel>
              </ode>
              <bullet>
                <soft_cfm>0.007</soft_cfm>
                <soft_erp>0.25</soft_erp>
                <kp>1e+06</kp>
                <kd>5</kd>
                <split_impulse>1</split_impulse>
                <split_impulse_penetration_threshold>-0.01</split_impulse_penetration_threshold>
              </bullet>
            </contact>
            <bounce/>
          </surface>
          <max_contacts>10</max_contacts>
        </collision>
        <visual name='wheel_2_visual'>
          <pose frame=''>0 0 0 0 -0 0</pose>
          <geometry>
            <mesh>
              <scale>0.001 0.001 0.001</scale>
              <uri>/home/ioannis/centauro_ws/src/iit-centauro-ros-pkg/centauro_urdf/meshes/wheel.stl</uri>
            </mesh>
          </geometry>
          <material>
            <script>
              <name>Gazebo/BlackTransparent</name>
              <uri>file://media/materials/scripts/gazebo.material</uri>
            </script>
          </material>
        </visual>
        <velocity_decay/>
        <gravity>1</gravity>
        <velocity_decay/>
        <self_collide>0</self_collide>
        <enable_wind>0</enable_wind>
        <kinematic>0</kinematic>
      </link>
      <joint name='j_wheel_2' type='revolute'>
        <child>wheel_2</child>
        <parent>ankle2_2</parent>
        <axis>
          <xyz>0 -1 -0</xyz>
          <limit>
            <lower>-1e+16</lower>
            <upper>1e+16</upper>
          </limit>
          <dynamics>
            <spring_reference>0</spring_reference>
            <spring_stiffness>0</spring_stiffness>
          </dynamics>
          <use_parent_model_frame>1</use_parent_model_frame>
        </axis>
        <physics>
          <provide_feedback>1</provide_feedback>
          <ode>
            <provide_feedback>1</provide_feedback>
            <implicit_spring_damper>1</implicit_spring_damper>
            <cfm_damping>1</cfm_damping>
            <limit>
              <cfm>0</cfm>
              <erp>0.2</erp>
            </limit>
          </ode>
        </physics>
      </joint>
      <link name='hip1_3'>
        <pose frame=''>-0.25 0.125 -0.0566 -3.14159 -0 2.68018</pose>
        <inertial>
          <pose frame=''>0.010214 0.018348 0.038091 0 -0 0</pose>
          <mass>1.91944</mass>
          <inertia>
            <ixx>0.00474396</ixx>
            <ixy>-0.000574705</ixy>
            <ixz>-0.000378414</ixz>
            <iyy>0.00405519</iyy>
            <iyz>-0.000740751</iyz>
            <izz>0.00341462</izz>
          </inertia>
        </inertial>
        <collision name='hip1_3_collision'>
          <pose frame=''>0 0 0 0 -0 0</pose>
          <geometry>
            <mesh>
              <scale>0.001 0.001 0.001</scale>
              <uri>/home/ioannis/centauro_ws/src/iit-centauro-ros-pkg/centauro_urdf/meshes/simple/hip-yaw.stl</uri>
            </mesh>
          </geometry>
          <surface>
            <contact>
              <ode/>
            </contact>
            <friction>
              <ode/>
              <torsional>
                <ode/>
              </torsional>
            </friction>
            <bounce/>
          </surface>
          <max_contacts>10</max_contacts>
        </collision>
        <visual name='hip1_3_visual'>
          <pose frame=''>0 0 0 0 -0 0</pose>
          <geometry>
            <mesh>
              <scale>0.001 0.001 0.001</scale>
              <uri>/home/ioannis/centauro_ws/src/iit-centauro-ros-pkg/centauro_urdf/meshes/hip-yaw.stl</uri>
            </mesh>
          </geometry>
          <material>
            <script>
              <name>Gazebo/LightBlueLaser</name>
              <uri>file://media/materials/scripts/gazebo.material</uri>
            </script>
          </material>
        </visual>
        <gravity>1</gravity>
        <velocity_decay/>
        <self_collide>0</self_collide>
        <enable_wind>0</enable_wind>
        <kinematic>0</kinematic>
      </link>
      <joint name='hip_yaw_3' type='revolute'>
        <child>hip1_3</child>
        <parent>pelvis</parent>
        <axis>
          <xyz>-0 -0 -1</xyz>
          <limit>
            <lower>-2.51</lower>
            <upper>2.03</upper>
            <effort>304</effort>
            <velocity>8.8</velocity>
          </limit>
          <dynamics>
            <spring_reference>0</spring_reference>
            <spring_stiffness>0</spring_stiffness>
          </dynamics>
          <use_parent_model_frame>1</use_parent_model_frame>
        </axis>
        <physics>
          <provide_feedback>1</provide_feedback>
          <ode>
            <provide_feedback>1</provide_feedback>
            <implicit_spring_damper>1</implicit_spring_damper>
            <cfm_damping>1</cfm_damping>
            <limit>
              <cfm>0</cfm>
              <erp>0.2</erp>
            </limit>
          </ode>
        </physics>
      </joint>
      <link name='hip2_3'>
        <pose frame=''>-0.25 0.125 -0.1191 -1.5708 0 0</pose>
        <inertial>
          <pose frame=''>2.6e-05 0.181027 0.08567 0 -0 0</pose>
          <mass>2.72645</mass>
          <inertia>
            <ixx>0.0485187</ixx>
            <ixy>-4.11894e-05</ixy>
            <ixz>-1.68778e-05</ixz>
            <iyy>0.00424205</iyy>
            <iyz>0.00322432</iyz>
            <izz>0.0482558</izz>
          </inertia>
        </inertial>
        <collision name='hip2_3_collision'>
          <pose frame=''>0 0 0 0 -0 0</pose>
          <geometry>
            <mesh>
              <scale>0.001 0.001 0.001</scale>
              <uri>/home/ioannis/centauro_ws/src/iit-centauro-ros-pkg/centauro_urdf/meshes/simple/hip-pitch.stl</uri>
            </mesh>
          </geometry>
          <surface>
            <contact>
              <ode/>
            </contact>
            <friction>
              <ode/>
              <torsional>
                <ode/>
              </torsional>
            </friction>
            <bounce/>
          </surface>
          <max_contacts>10</max_contacts>
        </collision>
        <visual name='hip2_3_visual'>
          <pose frame=''>0 0 0 0 -0 0</pose>
          <geometry>
            <mesh>
              <scale>0.001 0.001 0.001</scale>
              <uri>/home/ioannis/centauro_ws/src/iit-centauro-ros-pkg/centauro_urdf/meshes/hip-pitch.stl</uri>
            </mesh>
          </geometry>
          <material>
            <script>
              <name>Gazebo/BlackTransparent</name>
              <uri>file://media/materials/scripts/gazebo.material</uri>
            </script>
          </material>
        </visual>
        <gravity>1</gravity>
        <velocity_decay/>
        <self_collide>0</self_collide>
        <enable_wind>0</enable_wind>
        <kinematic>0</kinematic>
      </link>
      <joint name='hip_pitch_3' type='revolute'>
        <child>hip2_3</child>
        <parent>hip1_3</parent>
        <axis>
          <xyz>-0 1 -0</xyz>
          <limit>
            <lower>-2.0126</lower>
            <upper>2.0384</upper>
            <effort>304</effort>
            <velocity>8.8</velocity>
          </limit>
          <dynamics>
            <spring_reference>0</spring_reference>
            <spring_stiffness>0</spring_stiffness>
          </dynamics>
          <use_parent_model_frame>1</use_parent_model_frame>
        </axis>
        <physics>
          <provide_feedback>1</provide_feedback>
          <ode>
            <provide_feedback>1</provide_feedback>
            <implicit_spring_damper>1</implicit_spring_damper>
            <cfm_damping>1</cfm_damping>
            <limit>
              <cfm>0</cfm>
              <erp>0.2</erp>
            </limit>
          </ode>
        </physics>
      </joint>
      <link name='knee_3'>
        <pose frame=''>-0.25 0.1214 -0.4191 -1.57079 1.57079 3.14159</pose>
        <inertial>
          <pose frame=''>0.108817 0.000109 -0.022639 0 -0 0</pose>
          <mass>1.93568</mass>
          <inertia>
            <ixx>0.00305342</ixx>
            <ixy>-4.22079e-05</ixy>
            <ixz>0.00136793</ixz>
            <iyy>0.0196033</iyy>
            <iyz>6.9941e-06</iyz>
            <izz>0.0198498</izz>
          </inertia>
        </inertial>
        <collision name='knee_3_collision'>
          <pose frame=''>0 0 0 0 -0 0</pose>
          <geometry>
            <mesh>
              <scale>0.001 0.001 0.001</scale>
              <uri>/home/ioannis/centauro_ws/src/iit-centauro-ros-pkg/centauro_urdf/meshes/simple/knee.stl</uri>
            </mesh>
          </geometry>
          <surface>
            <contact>
              <ode/>
            </contact>
            <friction>
              <ode/>
              <torsional>
                <ode/>
              </torsional>
            </friction>
            <bounce/>
          </surface>
          <max_contacts>10</max_contacts>
        </collision>
        <visual name='knee_3_visual'>
          <pose frame=''>0 0 0 0 -0 0</pose>
          <geometry>
            <mesh>
              <scale>0.001 0.001 0.001</scale>
              <uri>/home/ioannis/centauro_ws/src/iit-centauro-ros-pkg/centauro_urdf/meshes/knee.stl</uri>
            </mesh>
          </geometry>
          <material>
            <script>
              <name>Gazebo/LightBlueLaser</name>
              <uri>file://media/materials/scripts/gazebo.material</uri>
            </script>
          </material>
        </visual>
        <gravity>1</gravity>
        <velocity_decay/>
        <self_collide>0</self_collide>
        <enable_wind>0</enable_wind>
        <kinematic>0</kinematic>
      </link>
      <joint name='knee_pitch_3' type='revolute'>
        <child>knee_3</child>
        <parent>hip2_3</parent>
        <axis>
          <xyz>-0 -1 0</xyz>
          <limit>
            <lower>-2.4056</lower>
            <upper>2.4064</upper>
            <effort>304</effort>
            <velocity>8.8</velocity>
          </limit>
          <dynamics>
            <spring_reference>0</spring_reference>
            <spring_stiffness>0</spring_stiffness>
          </dynamics>
          <use_parent_model_frame>1</use_parent_model_frame>
        </axis>
        <physics>
          <provide_feedback>1</provide_feedback>
          <ode>
            <provide_feedback>1</provide_feedback>
            <implicit_spring_damper>1</implicit_spring_damper>
            <cfm_damping>1</cfm_damping>
            <limit>
              <cfm>0</cfm>
              <erp>0.2</erp>
            </limit>
          </ode>
        </physics>
      </joint>
      <link name='ankle1_3'>
        <pose frame=''>-0.25 0.22155 -0.6191 1.57079 1.57079 3.14159</pose>
        <inertial>
          <pose frame=''>0.032137 9.7e-05 -0.004422 0 -0 0</pose>
          <mass>1.23807</mass>
          <inertia>
            <ixx>0.00156105</ixx>
            <ixy>3.30597e-05</ixy>
            <ixz>-0.000131417</ixz>
            <iyy>0.00374232</iyy>
            <iyz>-2.12589e-05</iyz>
            <izz>0.00383124</izz>
          </inertia>
        </inertial>
        <collision name='ankle1_3_collision'>
          <pose frame=''>0 0 0 0 -0 0</pose>
          <geometry>
            <mesh>
              <scale>0.001 0.001 0.001</scale>
              <uri>/home/ioannis/centauro_ws/src/iit-centauro-ros-pkg/centauro_urdf/meshes/simple/ankle-pitch.stl</uri>
            </mesh>
          </geometry>
          <surface>
            <contact>
              <ode/>
            </contact>
            <friction>
              <ode/>
              <torsional>
                <ode/>
              </torsional>
            </friction>
            <bounce/>
          </surface>
          <max_contacts>10</max_contacts>
        </collision>
        <visual name='ankle1_3_visual'>
          <pose frame=''>0 0 0 0 -0 0</pose>
          <geometry>
            <mesh>
              <scale>0.001 0.001 0.001</scale>
              <uri>/home/ioannis/centauro_ws/src/iit-centauro-ros-pkg/centauro_urdf/meshes/ankle-pitch.stl</uri>
            </mesh>
          </geometry>
          <material>
            <script>
              <name>Gazebo/LightBlueLaser</name>
              <uri>file://media/materials/scripts/gazebo.material</uri>
            </script>
          </material>
        </visual>
        <gravity>1</gravity>
        <velocity_decay/>
        <self_collide>0</self_collide>
        <enable_wind>0</enable_wind>
        <kinematic>0</kinematic>
      </link>
      <joint name='ankle_pitch_3' type='revolute'>
        <child>ankle1_3</child>
        <parent>knee_3</parent>
        <axis>
          <xyz>0 1 -0</xyz>
          <limit>
            <lower>-2.4696</lower>
            <upper>2.4464</upper>
            <effort>147</effort>
            <velocity>8.1</velocity>
          </limit>
          <dynamics>
            <spring_reference>0</spring_reference>
            <spring_stiffness>0</spring_stiffness>
          </dynamics>
          <use_parent_model_frame>1</use_parent_model_frame>
        </axis>
        <physics>
          <provide_feedback>1</provide_feedback>
          <ode>
            <provide_feedback>1</provide_feedback>
            <implicit_spring_damper>1</implicit_spring_damper>
            <cfm_damping>1</cfm_damping>
            <limit>
              <cfm>0</cfm>
              <erp>0.2</erp>
            </limit>
          </ode>
        </physics>
      </joint>
      <link name='ankle2_3'>
        <pose frame=''>-0.25 0.22155 -0.6191 -3.14159 -0 3.14159</pose>
        <inertial>
          <pose frame=''>0.000444 0.000439 0.193921 0 -0 0</pose>
          <mass>1.15659</mass>
          <inertia>
            <ixx>0.00490195</ixx>
            <ixy>4.3032e-06</ixy>
            <ixz>3.46491e-05</ixz>
            <iyy>0.00387242</iyy>
            <iyz>1.7099e-05</iyz>
            <izz>0.00217832</izz>
          </inertia>
        </inertial>
        <collision name='ankle2_3_collision'>
          <pose frame=''>0 0 0 0 -0 0</pose>
          <geometry>
            <mesh>
              <scale>0.001 0.001 0.001</scale>
              <uri>/home/ioannis/centauro_ws/src/iit-centauro-ros-pkg/centauro_urdf/meshes/simple/ankle-yaw.stl</uri>
            </mesh>
          </geometry>
          <surface>
            <contact>
              <ode/>
            </contact>
            <friction>
              <ode/>
              <torsional>
                <ode/>
              </torsional>
            </friction>
            <bounce/>
          </surface>
          <max_contacts>10</max_contacts>
        </collision>
        <visual name='ankle2_3_visual'>
          <pose frame=''>0 0 0 0 -0 0</pose>
          <geometry>
            <mesh>
              <scale>0.001 0.001 0.001</scale>
              <uri>/home/ioannis/centauro_ws/src/iit-centauro-ros-pkg/centauro_urdf/meshes/ankle-yaw.stl</uri>
            </mesh>
          </geometry>
          <material>
            <script>
              <name>Gazebo/LightBlueLaser</name>
              <uri>file://media/materials/scripts/gazebo.material</uri>
            </script>
          </material>
        </visual>
        <gravity>1</gravity>
        <velocity_decay/>
        <self_collide>0</self_collide>
        <enable_wind>0</enable_wind>
        <kinematic>0</kinematic>
      </link>
      <joint name='ankle_yaw_3' type='revolute'>
        <child>ankle2_3</child>
        <parent>ankle1_3</parent>
        <axis>
          <xyz>0 -0 -1</xyz>
          <limit>
            <lower>-2.5606</lower>
            <upper>2.5454</upper>
            <effort>35</effort>
            <velocity>20</velocity>
          </limit>
          <dynamics>
            <spring_reference>0</spring_reference>
            <spring_stiffness>0</spring_stiffness>
          </dynamics>
          <use_parent_model_frame>1</use_parent_model_frame>
        </axis>
        <physics>
          <provide_feedback>1</provide_feedback>
          <ode>
            <provide_feedback>1</provide_feedback>
            <implicit_spring_damper>1</implicit_spring_damper>
            <cfm_damping>1</cfm_damping>
            <limit>
              <cfm>0</cfm>
              <erp>0.2</erp>
            </limit>
          </ode>
        </physics>
      </joint>
      <link name='wheel_3'>
        <pose frame=''>-0.25 0.2224 -0.85645 -1.5708 -0 -0</pose>
        <inertial>
          <pose frame=''>0 0 0.002427 0 -0 0</pose>
          <mass>1.7289</mass>
          <inertia>
            <ixx>0.00468643</ixx>
            <ixy>0</ixy>
            <ixz>0</ixz>
            <iyy>0.00467135</iyy>
            <iyz>0</iyz>
            <izz>0.0053126</izz>
          </inertia>
        </inertial>
        <collision name='wheel_3_collision'>
          <pose frame=''>0 0 0 0 -0 0</pose>
          <geometry>
            <cylinder>
              <length>0.06</length>
              <radius>0.078</radius>
            </cylinder>
          </geometry>
          <surface>
            <friction>
              <ode>
                <mu>0.5</mu>
                <mu2>0.5</mu2>
              </ode>
              <bullet>
                <friction>0.5</friction>
                <friction2>0.5</friction2>
              </bullet>
              <torsional>
                <ode/>
              </torsional>
            </friction>
            <contact>
              <ode>
                <kp>2.1e+06</kp>
                <kd>1</kd>
                <max_vel>100</max_vel>
              </ode>
              <bullet>
                <soft_cfm>0.007</soft_cfm>
                <soft_erp>0.25</soft_erp>
                <kp>1e+06</kp>
                <kd>5</kd>
                <split_impulse>1</split_impulse>
                <split_impulse_penetration_threshold>-0.01</split_impulse_penetration_threshold>
              </bullet>
            </contact>
            <bounce/>
          </surface>
          <max_contacts>10</max_contacts>
        </collision>
        <visual name='wheel_3_visual'>
          <pose frame=''>0 0 0 0 -0 0</pose>
          <geometry>
            <mesh>
              <scale>0.001 0.001 0.001</scale>
              <uri>/home/ioannis/centauro_ws/src/iit-centauro-ros-pkg/centauro_urdf/meshes/wheel.stl</uri>
            </mesh>
          </geometry>
          <material>
            <script>
              <name>Gazebo/BlackTransparent</name>
              <uri>file://media/materials/scripts/gazebo.material</uri>
            </script>
          </material>
        </visual>
        <velocity_decay/>
        <gravity>1</gravity>
        <velocity_decay/>
        <self_collide>0</self_collide>
        <enable_wind>0</enable_wind>
        <kinematic>0</kinematic>
      </link>
      <joint name='j_wheel_3' type='revolute'>
        <child>wheel_3</child>
        <parent>ankle2_3</parent>
        <axis>
          <xyz>0 1 -0</xyz>
          <limit>
            <lower>-1e+16</lower>
            <upper>1e+16</upper>
          </limit>
          <dynamics>
            <spring_reference>0</spring_reference>
            <spring_stiffness>0</spring_stiffness>
          </dynamics>
          <use_parent_model_frame>1</use_parent_model_frame>
        </axis>
        <physics>
          <provide_feedback>1</provide_feedback>
          <ode>
            <provide_feedback>1</provide_feedback>
            <implicit_spring_damper>1</implicit_spring_damper>
            <cfm_damping>1</cfm_damping>
            <limit>
              <cfm>0</cfm>
              <erp>0.2</erp>
            </limit>
          </ode>
        </physics>
      </joint>
      <link name='hip1_4'>
        <pose frame=''>-0.25 -0.125 -0.0566 -3.14159 -0 -2.68018</pose>
        <inertial>
          <pose frame=''>0.010214 -0.018348 0.038091 0 -0 0</pose>
          <mass>1.91944</mass>
          <inertia>
            <ixx>0.00474396</ixx>
            <ixy>0.000574705</ixy>
            <ixz>-0.000378414</ixz>
            <iyy>0.00405519</iyy>
            <iyz>0.000740751</iyz>
            <izz>0.00341462</izz>
          </inertia>
        </inertial>
        <collision name='hip1_4_collision'>
          <pose frame=''>0 0 0 0 -0 -2.21876</pose>
          <geometry>
            <mesh>
              <scale>0.001 0.001 0.001</scale>
              <uri>/home/ioannis/centauro_ws/src/iit-centauro-ros-pkg/centauro_urdf/meshes/simple/hip-yaw.stl</uri>
            </mesh>
          </geometry>
          <surface>
            <contact>
              <ode/>
            </contact>
            <friction>
              <ode/>
              <torsional>
                <ode/>
              </torsional>
            </friction>
            <bounce/>
          </surface>
          <max_contacts>10</max_contacts>
        </collision>
        <visual name='hip1_4_visual'>
          <pose frame=''>0 0 0 0 -0 -2.21876</pose>
          <geometry>
            <mesh>
              <scale>0.001 0.001 0.001</scale>
              <uri>/home/ioannis/centauro_ws/src/iit-centauro-ros-pkg/centauro_urdf/meshes/hip-yaw.stl</uri>
            </mesh>
          </geometry>
          <material>
            <script>
              <name>Gazebo/LightBlueLaser</name>
              <uri>file://media/materials/scripts/gazebo.material</uri>
            </script>
          </material>
        </visual>
        <gravity>1</gravity>
        <velocity_decay/>
        <self_collide>0</self_collide>
        <enable_wind>0</enable_wind>
        <kinematic>0</kinematic>
      </link>
      <joint name='hip_yaw_4' type='revolute'>
        <child>hip1_4</child>
        <parent>pelvis</parent>
        <axis>
          <xyz>0 -0 -1</xyz>
          <limit>
            <lower>-2.03</lower>
            <upper>2.51</upper>
            <effort>304</effort>
            <velocity>8.8</velocity>
          </limit>
          <dynamics>
            <spring_reference>0</spring_reference>
            <spring_stiffness>0</spring_stiffness>
          </dynamics>
          <use_parent_model_frame>1</use_parent_model_frame>
        </axis>
        <physics>
          <provide_feedback>1</provide_feedback>
          <ode>
            <provide_feedback>1</provide_feedback>
            <implicit_spring_damper>1</implicit_spring_damper>
            <cfm_damping>1</cfm_damping>
            <limit>
              <cfm>0</cfm>
              <erp>0.2</erp>
            </limit>
          </ode>
        </physics>
      </joint>
      <link name='hip2_4'>
        <pose frame=''>-0.25 -0.125 -0.1191 -1.5708 -0 -3.14159</pose>
        <inertial>
          <pose frame=''>2.6e-05 0.181027 0.08567 0 -0 0</pose>
          <mass>2.72645</mass>
          <inertia>
            <ixx>0.0485187</ixx>
            <ixy>-4.11894e-05</ixy>
            <ixz>-1.68778e-05</ixz>
            <iyy>0.00424205</iyy>
            <iyz>0.00322432</iyz>
            <izz>0.0482558</izz>
          </inertia>
        </inertial>
        <collision name='hip2_4_collision'>
          <pose frame=''>0 0 0 0 -0 0</pose>
          <geometry>
            <mesh>
              <scale>0.001 0.001 0.001</scale>
              <uri>/home/ioannis/centauro_ws/src/iit-centauro-ros-pkg/centauro_urdf/meshes/simple/hip-pitch.stl</uri>
            </mesh>
          </geometry>
          <surface>
            <contact>
              <ode/>
            </contact>
            <friction>
              <ode/>
              <torsional>
                <ode/>
              </torsional>
            </friction>
            <bounce/>
          </surface>
          <max_contacts>10</max_contacts>
        </collision>
        <visual name='hip2_4_visual'>
          <pose frame=''>0 0 0 0 -0 0</pose>
          <geometry>
            <mesh>
              <scale>0.001 0.001 0.001</scale>
              <uri>/home/ioannis/centauro_ws/src/iit-centauro-ros-pkg/centauro_urdf/meshes/hip-pitch.stl</uri>
            </mesh>
          </geometry>
          <material>
            <script>
              <name>Gazebo/BlackTransparent</name>
              <uri>file://media/materials/scripts/gazebo.material</uri>
            </script>
          </material>
        </visual>
        <gravity>1</gravity>
        <velocity_decay/>
        <self_collide>0</self_collide>
        <enable_wind>0</enable_wind>
        <kinematic>0</kinematic>
      </link>
      <joint name='hip_pitch_4' type='revolute'>
        <child>hip2_4</child>
        <parent>hip1_4</parent>
        <axis>
          <xyz>0 -1 -0</xyz>
          <limit>
            <lower>-2.0326</lower>
            <upper>2.0524</upper>
            <effort>304</effort>
            <velocity>8.8</velocity>
          </limit>
          <dynamics>
            <spring_reference>0</spring_reference>
            <spring_stiffness>0</spring_stiffness>
          </dynamics>
          <use_parent_model_frame>1</use_parent_model_frame>
        </axis>
        <physics>
          <provide_feedback>1</provide_feedback>
          <ode>
            <provide_feedback>1</provide_feedback>
            <implicit_spring_damper>1</implicit_spring_damper>
            <cfm_damping>1</cfm_damping>
            <limit>
              <cfm>0</cfm>
              <erp>0.2</erp>
            </limit>
          </ode>
        </physics>
      </joint>
      <link name='knee_4'>
        <pose frame=''>-0.25 -0.1214 -0.4191 1.57079 1.57079 3.14159</pose>
        <inertial>
          <pose frame=''>0.108817 0.000109 -0.022639 0 -0 0</pose>
          <mass>1.93568</mass>
          <inertia>
            <ixx>0.00305342</ixx>
            <ixy>-4.22079e-05</ixy>
            <ixz>0.00136793</ixz>
            <iyy>0.0196033</iyy>
            <iyz>6.9941e-06</iyz>
            <izz>0.0198498</izz>
          </inertia>
        </inertial>
        <collision name='knee_4_collision'>
          <pose frame=''>0 0 0 0 -0 0</pose>
          <geometry>
            <mesh>
              <scale>0.001 0.001 0.001</scale>
              <uri>/home/ioannis/centauro_ws/src/iit-centauro-ros-pkg/centauro_urdf/meshes/simple/knee.stl</uri>
            </mesh>
          </geometry>
          <surface>
            <contact>
              <ode/>
            </contact>
            <friction>
              <ode/>
              <torsional>
                <ode/>
              </torsional>
            </friction>
            <bounce/>
          </surface>
          <max_contacts>10</max_contacts>
        </collision>
        <visual name='knee_4_visual'>
          <pose frame=''>0 0 0 0 -0 0</pose>
          <geometry>
            <mesh>
              <scale>0.001 0.001 0.001</scale>
              <uri>/home/ioannis/centauro_ws/src/iit-centauro-ros-pkg/centauro_urdf/meshes/knee.stl</uri>
            </mesh>
          </geometry>
          <material>
            <script>
              <name>Gazebo/LightBlueLaser</name>
              <uri>file://media/materials/scripts/gazebo.material</uri>
            </script>
          </material>
        </visual>
        <gravity>1</gravity>
        <velocity_decay/>
        <self_collide>0</self_collide>
        <enable_wind>0</enable_wind>
        <kinematic>0</kinematic>
      </link>
      <joint name='knee_pitch_4' type='revolute'>
        <child>knee_4</child>
        <parent>hip2_4</parent>
        <axis>
          <xyz>0 1 0</xyz>
          <limit>
            <lower>-2.4176</lower>
            <upper>2.3884</upper>
            <effort>304</effort>
            <velocity>8.8</velocity>
          </limit>
          <dynamics>
            <spring_reference>0</spring_reference>
            <spring_stiffness>0</spring_stiffness>
          </dynamics>
          <use_parent_model_frame>1</use_parent_model_frame>
        </axis>
        <physics>
          <provide_feedback>1</provide_feedback>
          <ode>
            <provide_feedback>1</provide_feedback>
            <implicit_spring_damper>1</implicit_spring_damper>
            <cfm_damping>1</cfm_damping>
            <limit>
              <cfm>0</cfm>
              <erp>0.2</erp>
            </limit>
          </ode>
        </physics>
      </joint>
      <link name='ankle1_4'>
        <pose frame=''>-0.25 -0.22155 -0.6191 -1.57079 1.57079 3.14159</pose>
        <inertial>
          <pose frame=''>0.032137 9.7e-05 -0.004422 0 -0 0</pose>
          <mass>1.23807</mass>
          <inertia>
            <ixx>0.00156105</ixx>
            <ixy>3.30597e-05</ixy>
            <ixz>-0.000131417</ixz>
            <iyy>0.00374232</iyy>
            <iyz>-2.12589e-05</iyz>
            <izz>0.00383124</izz>
          </inertia>
        </inertial>
        <collision name='ankle1_4_collision'>
          <pose frame=''>0 0 0 0 -0 0</pose>
          <geometry>
            <mesh>
              <scale>0.001 0.001 0.001</scale>
              <uri>/home/ioannis/centauro_ws/src/iit-centauro-ros-pkg/centauro_urdf/meshes/simple/ankle-pitch.stl</uri>
            </mesh>
          </geometry>
          <surface>
            <contact>
              <ode/>
            </contact>
            <friction>
              <ode/>
              <torsional>
                <ode/>
              </torsional>
            </friction>
            <bounce/>
          </surface>
          <max_contacts>10</max_contacts>
        </collision>
        <visual name='ankle1_4_visual'>
          <pose frame=''>0 0 0 0 -0 0</pose>
          <geometry>
            <mesh>
              <scale>0.001 0.001 0.001</scale>
              <uri>/home/ioannis/centauro_ws/src/iit-centauro-ros-pkg/centauro_urdf/meshes/ankle-pitch.stl</uri>
            </mesh>
          </geometry>
          <material>
            <script>
              <name>Gazebo/LightBlueLaser</name>
              <uri>file://media/materials/scripts/gazebo.material</uri>
            </script>
          </material>
        </visual>
        <gravity>1</gravity>
        <velocity_decay/>
        <self_collide>0</self_collide>
        <enable_wind>0</enable_wind>
        <kinematic>0</kinematic>
      </link>
      <joint name='ankle_pitch_4' type='revolute'>
        <child>ankle1_4</child>
        <parent>knee_4</parent>
        <axis>
          <xyz>-0 -1 -0</xyz>
          <limit>
            <lower>-2.3426</lower>
            <upper>2.3934</upper>
            <effort>147</effort>
            <velocity>8.1</velocity>
          </limit>
          <dynamics>
            <spring_reference>0</spring_reference>
            <spring_stiffness>0</spring_stiffness>
          </dynamics>
          <use_parent_model_frame>1</use_parent_model_frame>
        </axis>
        <physics>
          <provide_feedback>1</provide_feedback>
          <ode>
            <provide_feedback>1</provide_feedback>
            <implicit_spring_damper>1</implicit_spring_damper>
            <cfm_damping>1</cfm_damping>
            <limit>
              <cfm>0</cfm>
              <erp>0.2</erp>
            </limit>
          </ode>
        </physics>
      </joint>
      <link name='ankle2_4'>
        <pose frame=''>-0.25 -0.22155 -0.6191 3.14159 -0 0</pose>
        <inertial>
          <pose frame=''>0.000444 0.000439 0.193921 0 -0 0</pose>
          <mass>1.15659</mass>
          <inertia>
            <ixx>0.00490195</ixx>
            <ixy>4.3032e-06</ixy>
            <ixz>3.46491e-05</ixz>
            <iyy>0.00387242</iyy>
            <iyz>1.7099e-05</iyz>
            <izz>0.00217832</izz>
          </inertia>
        </inertial>
        <collision name='ankle2_4_collision'>
          <pose frame=''>0 0 0 0 -0 0</pose>
          <geometry>
            <mesh>
              <scale>0.001 0.001 0.001</scale>
              <uri>/home/ioannis/centauro_ws/src/iit-centauro-ros-pkg/centauro_urdf/meshes/simple/ankle-yaw.stl</uri>
            </mesh>
          </geometry>
          <surface>
            <contact>
              <ode/>
            </contact>
            <friction>
              <ode/>
              <torsional>
                <ode/>
              </torsional>
            </friction>
            <bounce/>
          </surface>
          <max_contacts>10</max_contacts>
        </collision>
        <visual name='ankle2_4_visual'>
          <pose frame=''>0 0 0 0 -0 0</pose>
          <geometry>
            <mesh>
              <scale>0.001 0.001 0.001</scale>
              <uri>/home/ioannis/centauro_ws/src/iit-centauro-ros-pkg/centauro_urdf/meshes/ankle-yaw.stl</uri>
            </mesh>
          </geometry>
          <material>
            <script>
              <name>Gazebo/LightBlueLaser</name>
              <uri>file://media/materials/scripts/gazebo.material</uri>
            </script>
          </material>
        </visual>
        <gravity>1</gravity>
        <velocity_decay/>
        <self_collide>0</self_collide>
        <enable_wind>0</enable_wind>
        <kinematic>0</kinematic>
      </link>
      <joint name='ankle_yaw_4' type='revolute'>
        <child>ankle2_4</child>
        <parent>ankle1_4</parent>
        <axis>
          <xyz>-0 -0 -1</xyz>
          <limit>
            <lower>-2.6046</lower>
            <upper>2.5514</upper>
            <effort>35</effort>
            <velocity>20</velocity>
          </limit>
          <dynamics>
            <spring_reference>0</spring_reference>
            <spring_stiffness>0</spring_stiffness>
          </dynamics>
          <use_parent_model_frame>1</use_parent_model_frame>
        </axis>
        <physics>
          <provide_feedback>1</provide_feedback>
          <ode>
            <provide_feedback>1</provide_feedback>
            <implicit_spring_damper>1</implicit_spring_damper>
            <cfm_damping>1</cfm_damping>
            <limit>
              <cfm>0</cfm>
              <erp>0.2</erp>
            </limit>
          </ode>
        </physics>
      </joint>
      <link name='wheel_4'>
        <pose frame=''>-0.25 -0.2224 -0.85645 -1.5708 -0 3.14159</pose>
        <inertial>
          <pose frame=''>0 0 0.002427 0 -0 0</pose>
          <mass>1.7289</mass>
          <inertia>
            <ixx>0.00468643</ixx>
            <ixy>0</ixy>
            <ixz>0</ixz>
            <iyy>0.00467135</iyy>
            <iyz>0</iyz>
            <izz>0.0053126</izz>
          </inertia>
        </inertial>
        <collision name='wheel_4_collision'>
          <pose frame=''>0 0 0 0 -0 0</pose>
          <geometry>
            <cylinder>
              <length>0.06</length>
              <radius>0.078</radius>
            </cylinder>
          </geometry>
          <surface>
            <friction>
              <ode>
                <mu>0.5</mu>
                <mu2>0.5</mu2>
              </ode>
              <bullet>
                <friction>0.5</friction>
                <friction2>0.5</friction2>
              </bullet>
              <torsional>
                <ode/>
              </torsional>
            </friction>
            <contact>
              <ode>
                <kp>2.1e+06</kp>
                <kd>1</kd>
                <max_vel>100</max_vel>
              </ode>
              <bullet>
                <soft_cfm>0.007</soft_cfm>
                <soft_erp>0.25</soft_erp>
                <kp>1e+06</kp>
                <kd>5</kd>
                <split_impulse>1</split_impulse>
                <split_impulse_penetration_threshold>-0.01</split_impulse_penetration_threshold>
              </bullet>
            </contact>
            <bounce/>
          </surface>
          <max_contacts>10</max_contacts>
        </collision>
        <visual name='wheel_4_visual'>
          <pose frame=''>0 0 0 0 -0 0</pose>
          <geometry>
            <mesh>
              <scale>0.001 0.001 0.001</scale>
              <uri>/home/ioannis/centauro_ws/src/iit-centauro-ros-pkg/centauro_urdf/meshes/wheel.stl</uri>
            </mesh>
          </geometry>
          <material>
            <script>
              <name>Gazebo/BlackTransparent</name>
              <uri>file://media/materials/scripts/gazebo.material</uri>
            </script>
          </material>
        </visual>
        <velocity_decay/>
        <gravity>1</gravity>
        <velocity_decay/>
        <self_collide>0</self_collide>
        <enable_wind>0</enable_wind>
        <kinematic>0</kinematic>
      </link>
      <joint name='j_wheel_4' type='revolute'>
        <child>wheel_4</child>
        <parent>ankle2_4</parent>
        <axis>
          <xyz>-0 -1 -0</xyz>
          <limit>
            <lower>-1e+16</lower>
            <upper>1e+16</upper>
          </limit>
          <dynamics>
            <spring_reference>0</spring_reference>
            <spring_stiffness>0</spring_stiffness>
          </dynamics>
          <use_parent_model_frame>1</use_parent_model_frame>
        </axis>
        <physics>
          <provide_feedback>1</provide_feedback>
          <ode>
            <provide_feedback>1</provide_feedback>
            <implicit_spring_damper>1</implicit_spring_damper>
            <cfm_damping>1</cfm_damping>
            <limit>
              <cfm>0</cfm>
              <erp>0.2</erp>
            </limit>
          </ode>
        </physics>
      </joint>
      <link name='torso_2'>
        <pose frame=''>0.2 0 0.256 0 -0 0</pose>
        <inertial>
          <pose frame=''>-0.019498 0.004532 0.137683 0 -0 0</pose>
          <mass>11.4927</mass>
          <inertia>
            <ixx>0.0636434</ixx>
            <ixy>8.939e-05</ixy>
            <ixz>-0.00086873</ixz>
            <iyy>0.0268023</iyy>
            <iyz>-4.657e-05</iyz>
            <izz>0.0474301</izz>
          </inertia>
        </inertial>
        <collision name='torso_2_collision'>
          <pose frame=''>0 0 0 0 -0 0</pose>
          <geometry>
            <mesh>
              <scale>0.001 0.001 0.001</scale>
              <uri>/home/ioannis/centauro_ws/src/iit-centauro-ros-pkg/centauro_urdf/meshes/simple/link1.stl</uri>
            </mesh>
          </geometry>
          <surface>
            <contact>
              <ode/>
            </contact>
            <friction>
              <ode/>
              <torsional>
                <ode/>
              </torsional>
            </friction>
            <bounce/>
          </surface>
          <max_contacts>10</max_contacts>
        </collision>
        <visual name='torso_2_visual'>
          <pose frame=''>0 0 0 0 -0 0</pose>
          <geometry>
            <mesh>
              <scale>0.001 0.001 0.001</scale>
              <uri>/home/ioannis/centauro_ws/src/iit-centauro-ros-pkg/centauro_urdf/meshes/link1.stl</uri>
            </mesh>
          </geometry>
          <material>
            <script>
              <name>Gazebo/BlackTransparent</name>
              <uri>file://media/materials/scripts/gazebo.material</uri>
            </script>
          </material>
        </visual>
        <gravity>1</gravity>
        <velocity_decay/>
        <self_collide>0</self_collide>
        <enable_wind>0</enable_wind>
        <kinematic>0</kinematic>
      </link>
      <joint name='torso_yaw' type='revolute'>
        <child>torso_2</child>
        <parent>pelvis</parent>
        <axis>
          <xyz>0 0 1</xyz>
          <limit>
            <lower>-2.618</lower>
            <upper>2.618</upper>
            <effort>147</effort>
            <velocity>5.7</velocity>
          </limit>
          <dynamics>
            <spring_reference>0</spring_reference>
            <spring_stiffness>0</spring_stiffness>
          </dynamics>
          <use_parent_model_frame>1</use_parent_model_frame>
        </axis>
        <physics>
          <provide_feedback>1</provide_feedback>
          <ode>
            <provide_feedback>1</provide_feedback>
            <implicit_spring_damper>1</implicit_spring_damper>
            <cfm_damping>1</cfm_damping>
            <limit>
              <cfm>0</cfm>
              <erp>0.2</erp>
            </limit>
          </ode>
        </physics>
      </joint>
      <link name='arm1_1'>
        <pose frame=''>0.245748 0.169137 0.372626 0.174533 -0 -0.523599</pose>
        <inertial>
          <pose frame=''>-0.007446 0.034108 0.00011 0 -0 0</pose>
          <mass>1.96287</mass>
          <inertia>
            <ixx>0.00535477</ixx>
            <ixy>0.000364289</ixy>
            <ixz>1.50896e-05</ixz>
            <iyy>0.00339233</iyy>
            <iyz>5.56923e-05</iyz>
            <izz>0.00689214</izz>
          </inertia>
        </inertial>
        <collision name='arm1_1_collision'>
          <pose frame=''>0 0 0 0 -0 0</pose>
          <geometry>
            <mesh>
              <scale>0.001 -0.001 0.001</scale>
              <uri>/home/ioannis/centauro_ws/src/iit-centauro-ros-pkg/centauro_urdf/meshes/simple/ShoulderPitch.STL</uri>
            </mesh>
          </geometry>
          <surface>
            <contact>
              <ode/>
            </contact>
            <friction>
              <ode/>
              <torsional>
                <ode/>
              </torsional>
            </friction>
            <bounce/>
          </surface>
          <max_contacts>10</max_contacts>
        </collision>
        <visual name='arm1_1_visual'>
          <pose frame=''>0 0 0 0 -0 0</pose>
          <geometry>
            <mesh>
              <scale>0.001 -0.001 0.001</scale>
              <uri>/home/ioannis/centauro_ws/src/iit-centauro-ros-pkg/centauro_urdf/meshes/ShoulderPitch.STL</uri>
            </mesh>
          </geometry>
          <material>
            <script>
              <name>Gazebo/BlackTransparent</name>
              <uri>file://media/materials/scripts/gazebo.material</uri>
            </script>
          </material>
        </visual>
        <gravity>1</gravity>
        <velocity_decay/>
        <self_collide>0</self_collide>
        <enable_wind>0</enable_wind>
        <kinematic>0</kinematic>
      </link>
      <joint name='j_arm1_1' type='revolute'>
        <child>arm1_1</child>
        <parent>torso_2</parent>
        <axis>
          <xyz>0.492404 0.852869 0.173648</xyz>
          <limit>
            <lower>-3.312</lower>
            <upper>1.615</upper>
            <effort>147</effort>
            <velocity>3.86</velocity>
          </limit>
          <dynamics>
            <spring_reference>0</spring_reference>
            <spring_stiffness>0</spring_stiffness>
          </dynamics>
          <use_parent_model_frame>1</use_parent_model_frame>
        </axis>
        <physics>
          <provide_feedback>1</provide_feedback>
          <ode>
            <provide_feedback>1</provide_feedback>
            <implicit_spring_damper>1</implicit_spring_damper>
            <cfm_damping>1</cfm_damping>
            <limit>
              <cfm>0</cfm>
              <erp>0.2</erp>
            </limit>
          </ode>
        </physics>
      </joint>
      <link name='arm1_2'>
        <pose frame=''>0.198204 0.26709 0.383392 0 0 -0.523599</pose>
        <inertial>
          <pose frame=''>0.058142 5.7e-05 -0.077478 0 -0 0</pose>
          <mass>1.85958</mass>
          <inertia>
            <ixx>0.0137766</ixx>
            <ixy>3.77887e-05</ixy>
            <ixz>0.00376902</ixz>
            <iyy>0.0156775</iyy>
            <iyz>-9.48935e-06</iyz>
            <izz>0.00463177</izz>
          </inertia>
        </inertial>
        <collision name='arm1_2_collision'>
          <pose frame=''>0 0 0 0 -0 0</pose>
          <geometry>
            <mesh>
              <scale>0.001 -0.001 0.001</scale>
              <uri>/home/ioannis/centauro_ws/src/iit-centauro-ros-pkg/centauro_urdf/meshes/simple/ShoulderRoll.STL</uri>
            </mesh>
          </geometry>
          <surface>
            <contact>
              <ode/>
            </contact>
            <friction>
              <ode/>
              <torsional>
                <ode/>
              </torsional>
            </friction>
            <bounce/>
          </surface>
          <max_contacts>10</max_contacts>
        </collision>
        <visual name='arm1_2_visual'>
          <pose frame=''>0 0 0 0 -0 0</pose>
          <geometry>
            <mesh>
              <scale>0.001 -0.001 0.001</scale>
              <uri>/home/ioannis/centauro_ws/src/iit-centauro-ros-pkg/centauro_urdf/meshes/ShoulderRoll.STL</uri>
            </mesh>
          </geometry>
          <material>
            <script>
              <name>Gazebo/LightBlueLaser</name>
              <uri>file://media/materials/scripts/gazebo.material</uri>
            </script>
          </material>
        </visual>
        <gravity>1</gravity>
        <velocity_decay/>
        <self_collide>0</self_collide>
        <enable_wind>0</enable_wind>
        <kinematic>0</kinematic>
      </link>
      <joint name='j_arm1_2' type='revolute'>
        <child>arm1_2</child>
        <parent>arm1_1</parent>
        <axis>
          <xyz>0.866025 -0.5 -0</xyz>
          <limit>
            <lower>0.02</lower>
            <upper>3.431</upper>
            <effort>147</effort>
            <velocity>3.86</velocity>
          </limit>
          <dynamics>
            <spring_reference>0</spring_reference>
            <spring_stiffness>0</spring_stiffness>
          </dynamics>
          <use_parent_model_frame>1</use_parent_model_frame>
        </axis>
        <physics>
          <provide_feedback>1</provide_feedback>
          <ode>
            <provide_feedback>1</provide_feedback>
            <implicit_spring_damper>1</implicit_spring_damper>
            <cfm_damping>1</cfm_damping>
            <limit>
              <cfm>0</cfm>
              <erp>0.2</erp>
            </limit>
          </ode>
        </physics>
      </joint>
      <link name='arm1_3'>
        <pose frame=''>0.276277 0.222015 0.165242 0 0 -0.523599</pose>
        <inertial>
          <pose frame=''>0.014625 0.000817 -0.028334 0 -0 0</pose>
          <mass>1.66781</mass>
          <inertia>
            <ixx>0.00644804</ixx>
            <ixy>-0.000156391</ixy>
            <ixz>0.00122054</ixz>
            <iyy>0.00733721</iyy>
            <iyz>8.99415e-05</iyz>
            <izz>0.00367384</izz>
          </inertia>
        </inertial>
        <collision name='arm1_3_collision'>
          <pose frame=''>0 0 0 0 -0 0</pose>
          <geometry>
            <mesh>
              <scale>0.001 -0.001 0.001</scale>
              <uri>/home/ioannis/centauro_ws/src/iit-centauro-ros-pkg/centauro_urdf/meshes/simple/ShoulderYaw.STL</uri>
            </mesh>
          </geometry>
          <surface>
            <contact>
              <ode/>
            </contact>
            <friction>
              <ode/>
              <torsional>
                <ode/>
              </torsional>
            </friction>
            <bounce/>
          </surface>
          <max_contacts>10</max_contacts>
        </collision>
        <visual name='arm1_3_visual'>
          <pose frame=''>0 0 0 0 -0 0</pose>
          <geometry>
            <mesh>
              <scale>0.001 -0.001 0.001</scale>
              <uri>/home/ioannis/centauro_ws/src/iit-centauro-ros-pkg/centauro_urdf/meshes/ShoulderYaw.STL</uri>
            </mesh>
          </geometry>
          <material>
            <script>
              <name>Gazebo/LightBlueLaser</name>
              <uri>file://media/materials/scripts/gazebo.material</uri>
            </script>
          </material>
        </visual>
        <gravity>1</gravity>
        <velocity_decay/>
        <self_collide>0</self_collide>
        <enable_wind>0</enable_wind>
        <kinematic>0</kinematic>
      </link>
      <joint name='j_arm1_3' type='revolute'>
        <child>arm1_3</child>
        <parent>arm1_2</parent>
        <axis>
          <xyz>-0 -0 1</xyz>
          <limit>
            <lower>-2.552</lower>
            <upper>2.566</upper>
            <effort>147</effort>
            <velocity>6.06</velocity>
          </limit>
          <dynamics>
            <spring_reference>0</spring_reference>
            <spring_stiffness>0</spring_stiffness>
          </dynamics>
          <use_parent_model_frame>1</use_parent_model_frame>
        </axis>
        <physics>
          <provide_feedback>1</provide_feedback>
          <ode>
            <provide_feedback>1</provide_feedback>
            <implicit_spring_damper>1</implicit_spring_damper>
            <cfm_damping>1</cfm_damping>
            <limit>
              <cfm>0</cfm>
              <erp>0.2</erp>
            </limit>
          </ode>
        </physics>
      </joint>
      <link name='arm1_4'>
        <pose frame=''>0.342823 0.247276 0.091242 0 0 -0.523599</pose>
        <inertial>
          <pose frame=''>-0.007683 -0.040302 -0.043493 0 -0 0</pose>
          <mass>1.31573</mass>
          <inertia>
            <ixx>0.00433039</ixx>
            <ixy>-0.000117374</ixy>
            <ixz>-0.000419232</ixz>
            <iyy>0.00385399</iyy>
            <iyz>-0.00079573</iyz>
            <izz>0.00175947</izz>
          </inertia>
        </inertial>
        <collision name='arm1_4_collision'>
          <pose frame=''>0 0 0 0 -0 0</pose>
          <geometry>
            <mesh>
              <scale>0.001 -0.001 0.001</scale>
              <uri>/home/ioannis/centauro_ws/src/iit-centauro-ros-pkg/centauro_urdf/meshes/simple/Elbow.STL</uri>
            </mesh>
          </geometry>
          <surface>
            <contact>
              <ode/>
            </contact>
            <friction>
              <ode/>
              <torsional>
                <ode/>
              </torsional>
            </friction>
            <bounce/>
          </surface>
          <max_contacts>10</max_contacts>
        </collision>
        <visual name='arm1_4_visual'>
          <pose frame=''>0 0 0 0 -0 0</pose>
          <geometry>
            <mesh>
              <scale>0.001 -0.001 0.001</scale>
              <uri>/home/ioannis/centauro_ws/src/iit-centauro-ros-pkg/centauro_urdf/meshes/Elbow.STL</uri>
            </mesh>
          </geometry>
          <material>
            <script>
              <name>Gazebo/LightBlueLaser</name>
              <uri>file://media/materials/scripts/gazebo.material</uri>
            </script>
          </material>
        </visual>
        <gravity>1</gravity>
        <velocity_decay/>
        <self_collide>0</self_collide>
        <enable_wind>0</enable_wind>
        <kinematic>0</kinematic>
      </link>
      <joint name='j_arm1_4' type='revolute'>
        <child>arm1_4</child>
        <parent>arm1_3</parent>
        <axis>
          <xyz>0.5 0.866025 0</xyz>
          <limit>
            <lower>-2.465</lower>
            <upper>0.28</upper>
            <effort>147</effort>
            <velocity>6.06</velocity>
          </limit>
          <dynamics>
            <spring_reference>0</spring_reference>
            <spring_stiffness>0</spring_stiffness>
          </dynamics>
          <use_parent_model_frame>1</use_parent_model_frame>
        </axis>
        <physics>
          <provide_feedback>1</provide_feedback>
          <ode>
            <provide_feedback>1</provide_feedback>
            <implicit_spring_damper>1</implicit_spring_damper>
            <cfm_damping>1</cfm_damping>
            <limit>
              <cfm>0</cfm>
              <erp>0.2</erp>
            </limit>
          </ode>
        </physics>
      </joint>
      <link name='arm1_5'>
        <pose frame=''>0.302257 0.207015 -0.003758 0 0 -0.523599</pose>
        <inertial>
          <pose frame=''>-0.000111 0.011591 -0.07816 0 -0 0</pose>
          <mass>1.49085</mass>
          <inertia>
            <ixx>0.00856921</ixx>
            <ixy>1.78563e-05</ixy>
            <ixz>1.93794e-05</ixz>
            <iyy>0.00774542</iyy>
            <iyz>-0.000328601</iyz>
            <izz>0.00274419</izz>
          </inertia>
        </inertial>
        <collision name='arm1_5_collision'>
          <pose frame=''>0 0 0 0 -0 0</pose>
          <geometry>
            <mesh>
              <scale>0.001 -0.001 0.001</scale>
              <uri>/home/ioannis/centauro_ws/src/iit-centauro-ros-pkg/centauro_urdf/meshes/simple/Forearm.STL</uri>
            </mesh>
          </geometry>
          <surface>
            <contact>
              <ode/>
            </contact>
            <friction>
              <ode/>
              <torsional>
                <ode/>
              </torsional>
            </friction>
            <bounce/>
          </surface>
          <max_contacts>10</max_contacts>
        </collision>
        <visual name='arm1_5_visual'>
          <pose frame=''>0 0 0 0 -0 0</pose>
          <geometry>
            <mesh>
              <scale>0.001 -0.001 0.001</scale>
              <uri>/home/ioannis/centauro_ws/src/iit-centauro-ros-pkg/centauro_urdf/meshes/Forearm.STL</uri>
            </mesh>
          </geometry>
          <material>
            <script>
              <name>Gazebo/BlackTransparent</name>
              <uri>file://media/materials/scripts/gazebo.material</uri>
            </script>
          </material>
        </visual>
        <gravity>1</gravity>
        <velocity_decay/>
        <self_collide>0</self_collide>
        <enable_wind>0</enable_wind>
        <kinematic>0</kinematic>
      </link>
      <joint name='j_arm1_5' type='revolute'>
        <child>arm1_5</child>
        <parent>arm1_4</parent>
        <axis>
          <xyz>-0 -0 1</xyz>
          <limit>
            <lower>-2.569</lower>
            <upper>2.562</upper>
            <effort>55</effort>
            <velocity>11.72</velocity>
          </limit>
          <dynamics>
            <spring_reference>0</spring_reference>
            <spring_stiffness>0</spring_stiffness>
          </dynamics>
          <use_parent_model_frame>1</use_parent_model_frame>
        </axis>
        <physics>
          <provide_feedback>1</provide_feedback>
          <ode>
            <provide_feedback>1</provide_feedback>
            <implicit_spring_damper>1</implicit_spring_damper>
            <cfm_damping>1</cfm_damping>
            <limit>
              <cfm>0</cfm>
              <erp>0.2</erp>
            </limit>
          </ode>
        </physics>
      </joint>
      <link name='arm1_6'>
        <pose frame=''>0.326757 0.24945 -0.159758 0 0 -0.523599</pose>
        <inertial>
          <pose frame=''>-5e-06 -0.038014 -0.069927 0 -0 0</pose>
          <mass>1.12636</mass>
          <inertia>
            <ixx>0.00518718</ixx>
            <ixy>2.72444e-05</ixy>
            <ixz>2.28335e-06</ixz>
            <iyy>0.00480378</iyy>
            <iyz>-0.000721657</iyz>
            <izz>0.00127714</izz>
          </inertia>
        </inertial>
        <collision name='arm1_6_collision'>
          <pose frame=''>0 0 0 0 -0 0</pose>
          <geometry>
            <mesh>
              <scale>0.001 -0.001 0.001</scale>
              <uri>/home/ioannis/centauro_ws/src/iit-centauro-ros-pkg/centauro_urdf/meshes/simple/ForearmPitch.STL</uri>
            </mesh>
          </geometry>
          <surface>
            <contact>
              <ode/>
            </contact>
            <friction>
              <ode/>
              <torsional>
                <ode/>
              </torsional>
            </friction>
            <bounce/>
          </surface>
          <max_contacts>10</max_contacts>
        </collision>
        <visual name='arm1_6_visual'>
          <pose frame=''>0 0 0 0 -0 0</pose>
          <geometry>
            <mesh>
              <scale>0.001 -0.001 0.001</scale>
              <uri>/home/ioannis/centauro_ws/src/iit-centauro-ros-pkg/centauro_urdf/meshes/ForearmPitch.STL</uri>
            </mesh>
          </geometry>
          <material>
            <script>
              <name>Gazebo/LightBlueLaser</name>
              <uri>file://media/materials/scripts/gazebo.material</uri>
            </script>
          </material>
        </visual>
        <gravity>1</gravity>
        <velocity_decay/>
        <self_collide>0</self_collide>
        <enable_wind>0</enable_wind>
        <kinematic>0</kinematic>
      </link>
      <joint name='j_arm1_6' type='revolute'>
        <child>arm1_6</child>
        <parent>arm1_5</parent>
        <axis>
          <xyz>0.5 0.866025 0</xyz>
          <limit>
            <lower>-1.529</lower>
            <upper>1.509</upper>
            <effort>55</effort>
            <velocity>11.72</velocity>
          </limit>
          <dynamics>
            <spring_reference>0</spring_reference>
            <spring_stiffness>0</spring_stiffness>
          </dynamics>
          <use_parent_model_frame>1</use_parent_model_frame>
        </axis>
        <physics>
          <provide_feedback>1</provide_feedback>
          <ode>
            <provide_feedback>1</provide_feedback>
            <implicit_spring_damper>1</implicit_spring_damper>
            <cfm_damping>1</cfm_damping>
            <limit>
              <cfm>0</cfm>
              <erp>0.2</erp>
            </limit>
          </ode>
        </physics>
      </joint>
      <link name='arm1_7'>
        <pose frame=''>0.302257 0.207015 -0.333758 0 0 -0.523599</pose>
        <inertial>
          <pose frame=''>9e-06 0.000541 0.01433 0 -0 0</pose>
          <mass>1.92794</mass>
          <inertia>
            <ixx>0.00316217</ixx>
            <ixy>2.68715e-06</ixy>
            <ixz>-9.8962e-07</ixz>
            <iyy>0.00313238</iyy>
            <iyz>6.27992e-05</iyz>
            <izz>0.00340412</izz>
          </inertia>
        </inertial>
        <collision name='arm1_7_collision'>
          <pose frame=''>0 0 0 0 -0 0</pose>
          <geometry>
            <mesh>
              <scale>0.001 -0.001 0.001</scale>
              <uri>/home/ioannis/centauro_ws/src/iit-centauro-ros-pkg/centauro_urdf/meshes/simple/ForearmYaw.STL</uri>
            </mesh>
          </geometry>
          <surface>
            <contact>
              <ode/>
            </contact>
            <friction>
              <ode/>
              <torsional>
                <ode/>
              </torsional>
            </friction>
            <bounce/>
          </surface>
          <max_contacts>10</max_contacts>
        </collision>
        <collision name='arm1_7_fixed_joint_lump__ball1_collision_1'>
          <pose frame=''>0 0 0 0 -0 0</pose>
          <geometry>
            <mesh>
              <scale>0.001 0.001 0.001</scale>
              <uri>/home/ioannis/centauro_ws/src/iit-centauro-ros-pkg/centauro_urdf/meshes/simple/BallHand.stl</uri>
            </mesh>
          </geometry>
          <surface>
            <contact>
              <ode/>
            </contact>
            <friction>
              <ode/>
              <torsional>
                <ode/>
              </torsional>
            </friction>
            <bounce/>
          </surface>
          <max_contacts>10</max_contacts>
        </collision>
        <visual name='arm1_7_visual'>
          <pose frame=''>0 0 0 0 -0 0</pose>
          <geometry>
            <mesh>
              <scale>0.001 -0.001 0.001</scale>
              <uri>/home/ioannis/centauro_ws/src/iit-centauro-ros-pkg/centauro_urdf/meshes/ForearmYaw.STL</uri>
            </mesh>
          </geometry>
          <material>
            <script>
              <name>Gazebo/LightBlueLaser</name>
              <uri>file://media/materials/scripts/gazebo.material</uri>
            </script>
          </material>
        </visual>
        <visual name='arm1_7_fixed_joint_lump__ball1_visual_1'>
          <pose frame=''>0 0 0 0 -0 0</pose>
          <geometry>
            <mesh>
              <scale>0.001 0.001 0.001</scale>
              <uri>/home/ioannis/centauro_ws/src/iit-centauro-ros-pkg/centauro_urdf/meshes/BallHand.stl</uri>
            </mesh>
          </geometry>
          <material>
            <script>
              <name>Gazebo/BlackTransparent</name>
              <uri>file://media/materials/scripts/gazebo.material</uri>
            </script>
          </material>
        </visual>
        <velocity_decay/>
        <gravity>1</gravity>
        <velocity_decay/>
        <self_collide>0</self_collide>
        <enable_wind>0</enable_wind>
        <kinematic>0</kinematic>
      </link>
      <joint name='j_arm1_7' type='revolute'>
        <child>arm1_7</child>
        <parent>arm1_6</parent>
        <axis>
          <xyz>-0 -0 1</xyz>
          <limit>
            <lower>-2.565</lower>
            <upper>2.569</upper>
            <effort>28.32</effort>
            <velocity>20.35</velocity>
          </limit>
          <dynamics>
            <spring_reference>0</spring_reference>
            <spring_stiffness>0</spring_stiffness>
          </dynamics>
          <use_parent_model_frame>1</use_parent_model_frame>
        </axis>
        <physics>
          <provide_feedback>1</provide_feedback>
          <ode>
            <provide_feedback>1</provide_feedback>
            <implicit_spring_damper>1</implicit_spring_damper>
            <cfm_damping>1</cfm_damping>
            <limit>
              <cfm>0</cfm>
              <erp>0.2</erp>
            </limit>
          </ode>
        </physics>
      </joint>
      <link name='arm2_1'>
        <pose frame=''>0.245748 -0.169137 0.372626 -0.174533 -0 0.523599</pose>
        <inertial>
          <pose frame=''>-0.007446 -0.034108 0.00011 0 -0 0</pose>
          <mass>1.96287</mass>
          <inertia>
            <ixx>0.00535477</ixx>
            <ixy>-0.000364289</ixy>
            <ixz>1.50896e-05</ixz>
            <iyy>0.00339233</iyy>
            <iyz>-5.56923e-05</iyz>
            <izz>0.00689214</izz>
          </inertia>
        </inertial>
        <collision name='arm2_1_collision'>
          <pose frame=''>0 0 0 0 -0 0</pose>
          <geometry>
            <mesh>
              <scale>0.001 0.001 0.001</scale>
              <uri>/home/ioannis/centauro_ws/src/iit-centauro-ros-pkg/centauro_urdf/meshes/simple/ShoulderPitch.STL</uri>
            </mesh>
          </geometry>
          <surface>
            <contact>
              <ode/>
            </contact>
            <friction>
              <ode/>
              <torsional>
                <ode/>
              </torsional>
            </friction>
            <bounce/>
          </surface>
          <max_contacts>10</max_contacts>
        </collision>
        <visual name='arm2_1_visual'>
          <pose frame=''>0 0 0 0 -0 0</pose>
          <geometry>
            <mesh>
              <scale>0.001 0.001 0.001</scale>
              <uri>/home/ioannis/centauro_ws/src/iit-centauro-ros-pkg/centauro_urdf/meshes/ShoulderPitch.STL</uri>
            </mesh>
          </geometry>
          <material>
            <script>
              <name>Gazebo/BlackTransparent</name>
              <uri>file://media/materials/scripts/gazebo.material</uri>
            </script>
          </material>
        </visual>
        <gravity>1</gravity>
        <velocity_decay/>
        <self_collide>0</self_collide>
        <enable_wind>0</enable_wind>
        <kinematic>0</kinematic>
      </link>
      <joint name='j_arm2_1' type='revolute'>
        <child>arm2_1</child>
        <parent>torso_2</parent>
        <axis>
          <xyz>-0.492404 0.852869 -0.173648</xyz>
          <limit>
            <lower>-3.3458</lower>
            <upper>1.6012</upper>
            <effort>147</effort>
            <velocity>3.86</velocity>
          </limit>
          <dynamics>
            <spring_reference>0</spring_reference>
            <spring_stiffness>0</spring_stiffness>
          </dynamics>
          <use_parent_model_frame>1</use_parent_model_frame>
        </axis>
        <physics>
          <provide_feedback>1</provide_feedback>
          <ode>
            <provide_feedback>1</provide_feedback>
            <implicit_spring_damper>1</implicit_spring_damper>
            <cfm_damping>1</cfm_damping>
            <limit>
              <cfm>0</cfm>
              <erp>0.2</erp>
            </limit>
          </ode>
        </physics>
      </joint>
      <link name='arm2_2'>
        <pose frame=''>0.198204 -0.26709 0.383392 0 -0 0.523599</pose>
        <inertial>
          <pose frame=''>0.058142 -5.7e-05 -0.077478 0 -0 0</pose>
          <mass>1.85958</mass>
          <inertia>
            <ixx>0.0137766</ixx>
            <ixy>-3.77887e-05</ixy>
            <ixz>0.00376902</ixz>
            <iyy>0.0156775</iyy>
            <iyz>9.48935e-06</iyz>
            <izz>0.00463177</izz>
          </inertia>
        </inertial>
        <collision name='arm2_2_collision'>
          <pose frame=''>0 0 0 0 -0 0</pose>
          <geometry>
            <mesh>
              <scale>0.001 0.001 0.001</scale>
              <uri>/home/ioannis/centauro_ws/src/iit-centauro-ros-pkg/centauro_urdf/meshes/simple/ShoulderRoll.STL</uri>
            </mesh>
          </geometry>
          <surface>
            <contact>
              <ode/>
            </contact>
            <friction>
              <ode/>
              <torsional>
                <ode/>
              </torsional>
            </friction>
            <bounce/>
          </surface>
          <max_contacts>10</max_contacts>
        </collision>
        <visual name='arm2_2_visual'>
          <pose frame=''>0 0 0 0 -0 0</pose>
          <geometry>
            <mesh>
              <scale>0.001 0.001 0.001</scale>
              <uri>/home/ioannis/centauro_ws/src/iit-centauro-ros-pkg/centauro_urdf/meshes/ShoulderRoll.STL</uri>
            </mesh>
          </geometry>
          <material>
            <script>
              <name>Gazebo/LightBlueLaser</name>
              <uri>file://media/materials/scripts/gazebo.material</uri>
            </script>
          </material>
        </visual>
        <gravity>1</gravity>
        <velocity_decay/>
        <self_collide>0</self_collide>
        <enable_wind>0</enable_wind>
        <kinematic>0</kinematic>
      </link>
      <joint name='j_arm2_2' type='revolute'>
        <child>arm2_2</child>
        <parent>arm2_1</parent>
        <axis>
          <xyz>0.866025 0.5 -0</xyz>
          <limit>
            <lower>-3.4258</lower>
            <upper>-0.0138</upper>
            <effort>147</effort>
            <velocity>3.86</velocity>
          </limit>
          <dynamics>
            <spring_reference>0</spring_reference>
            <spring_stiffness>0</spring_stiffness>
          </dynamics>
          <use_parent_model_frame>1</use_parent_model_frame>
        </axis>
        <physics>
          <provide_feedback>1</provide_feedback>
          <ode>
            <provide_feedback>1</provide_feedback>
            <implicit_spring_damper>1</implicit_spring_damper>
            <cfm_damping>1</cfm_damping>
            <limit>
              <cfm>0</cfm>
              <erp>0.2</erp>
            </limit>
          </ode>
        </physics>
      </joint>
      <link name='arm2_3'>
        <pose frame=''>0.276277 -0.222015 0.165242 0 -0 0.523599</pose>
        <inertial>
          <pose frame=''>0.014625 -0.000817 -0.028334 0 -0 0</pose>
          <mass>1.66781</mass>
          <inertia>
            <ixx>0.00644804</ixx>
            <ixy>0.000156391</ixy>
            <ixz>0.00122054</ixz>
            <iyy>0.00733721</iyy>
            <iyz>-8.99415e-05</iyz>
            <izz>0.00367384</izz>
          </inertia>
        </inertial>
        <collision name='arm2_3_collision'>
          <pose frame=''>0 0 0 0 -0 0</pose>
          <geometry>
            <mesh>
              <scale>0.001 0.001 0.001</scale>
              <uri>/home/ioannis/centauro_ws/src/iit-centauro-ros-pkg/centauro_urdf/meshes/simple/ShoulderYaw.STL</uri>
            </mesh>
          </geometry>
          <surface>
            <contact>
              <ode/>
            </contact>
            <friction>
              <ode/>
              <torsional>
                <ode/>
              </torsional>
            </friction>
            <bounce/>
          </surface>
          <max_contacts>10</max_contacts>
        </collision>
        <visual name='arm2_3_visual'>
          <pose frame=''>0 0 0 0 -0 0</pose>
          <geometry>
            <mesh>
              <scale>0.001 0.001 0.001</scale>
              <uri>/home/ioannis/centauro_ws/src/iit-centauro-ros-pkg/centauro_urdf/meshes/ShoulderYaw.STL</uri>
            </mesh>
          </geometry>
          <material>
            <script>
              <name>Gazebo/LightBlueLaser</name>
              <uri>file://media/materials/scripts/gazebo.material</uri>
            </script>
          </material>
        </visual>
        <gravity>1</gravity>
        <velocity_decay/>
        <self_collide>0</self_collide>
        <enable_wind>0</enable_wind>
        <kinematic>0</kinematic>
      </link>
      <joint name='j_arm2_3' type='revolute'>
        <child>arm2_3</child>
        <parent>arm2_2</parent>
        <axis>
          <xyz>-0 0 1</xyz>
          <limit>
            <lower>-2.5614</lower>
            <upper>2.5606</upper>
            <effort>147</effort>
            <velocity>6.06</velocity>
          </limit>
          <dynamics>
            <spring_reference>0</spring_reference>
            <spring_stiffness>0</spring_stiffness>
          </dynamics>
          <use_parent_model_frame>1</use_parent_model_frame>
        </axis>
        <physics>
          <provide_feedback>1</provide_feedback>
          <ode>
            <provide_feedback>1</provide_feedback>
            <implicit_spring_damper>1</implicit_spring_damper>
            <cfm_damping>1</cfm_damping>
            <limit>
              <cfm>0</cfm>
              <erp>0.2</erp>
            </limit>
          </ode>
        </physics>
      </joint>
      <link name='arm2_4'>
        <pose frame=''>0.342823 -0.247276 0.091242 0 -0 0.523599</pose>
        <inertial>
          <pose frame=''>-0.007683 0.040302 -0.043493 0 -0 0</pose>
          <mass>1.31573</mass>
          <inertia>
            <ixx>0.00433039</ixx>
            <ixy>0.000117374</ixy>
            <ixz>-0.000419232</ixz>
            <iyy>0.00385399</iyy>
            <iyz>0.00079573</iyz>
            <izz>0.00175947</izz>
          </inertia>
        </inertial>
        <collision name='arm2_4_collision'>
          <pose frame=''>0 0 0 0 -0 0</pose>
          <geometry>
            <mesh>
              <scale>0.001 0.001 0.001</scale>
              <uri>/home/ioannis/centauro_ws/src/iit-centauro-ros-pkg/centauro_urdf/meshes/simple/Elbow.STL</uri>
            </mesh>
          </geometry>
          <surface>
            <contact>
              <ode/>
            </contact>
            <friction>
              <ode/>
              <torsional>
                <ode/>
              </torsional>
            </friction>
            <bounce/>
          </surface>
          <max_contacts>10</max_contacts>
        </collision>
        <visual name='arm2_4_visual'>
          <pose frame=''>0 0 0 0 -0 0</pose>
          <geometry>
            <mesh>
              <scale>0.001 0.001 0.001</scale>
              <uri>/home/ioannis/centauro_ws/src/iit-centauro-ros-pkg/centauro_urdf/meshes/Elbow.STL</uri>
            </mesh>
          </geometry>
          <material>
            <script>
              <name>Gazebo/LightBlueLaser</name>
              <uri>file://media/materials/scripts/gazebo.material</uri>
            </script>
          </material>
        </visual>
        <gravity>1</gravity>
        <velocity_decay/>
        <self_collide>0</self_collide>
        <enable_wind>0</enable_wind>
        <kinematic>0</kinematic>
      </link>
      <joint name='j_arm2_4' type='revolute'>
        <child>arm2_4</child>
        <parent>arm2_3</parent>
        <axis>
          <xyz>-0.5 0.866025 -0</xyz>
          <limit>
            <lower>-2.4794</lower>
            <upper>0.2886</upper>
            <effort>147</effort>
            <velocity>6.06</velocity>
          </limit>
          <dynamics>
            <spring_reference>0</spring_reference>
            <spring_stiffness>0</spring_stiffness>
          </dynamics>
          <use_parent_model_frame>1</use_parent_model_frame>
        </axis>
        <physics>
          <provide_feedback>1</provide_feedback>
          <ode>
            <provide_feedback>1</provide_feedback>
            <implicit_spring_damper>1</implicit_spring_damper>
            <cfm_damping>1</cfm_damping>
            <limit>
              <cfm>0</cfm>
              <erp>0.2</erp>
            </limit>
          </ode>
        </physics>
      </joint>
      <link name='arm2_5'>
        <pose frame=''>0.302257 -0.207015 -0.003758 0 -0 0.523599</pose>
        <inertial>
          <pose frame=''>-0.000111 -0.011591 -0.07816 0 -0 0</pose>
          <mass>1.49085</mass>
          <inertia>
            <ixx>0.00856921</ixx>
            <ixy>-1.78563e-05</ixy>
            <ixz>1.93794e-05</ixz>
            <iyy>0.00774542</iyy>
            <iyz>0.000328601</iyz>
            <izz>0.00274419</izz>
          </inertia>
        </inertial>
        <collision name='arm2_5_collision'>
          <pose frame=''>0 0 0 0 -0 0</pose>
          <geometry>
            <mesh>
              <scale>0.001 0.001 0.001</scale>
              <uri>/home/ioannis/centauro_ws/src/iit-centauro-ros-pkg/centauro_urdf/meshes/simple/Forearm.STL</uri>
            </mesh>
          </geometry>
          <surface>
            <contact>
              <ode/>
            </contact>
            <friction>
              <ode/>
              <torsional>
                <ode/>
              </torsional>
            </friction>
            <bounce/>
          </surface>
          <max_contacts>10</max_contacts>
        </collision>
        <visual name='arm2_5_visual'>
          <pose frame=''>0 0 0 0 -0 0</pose>
          <geometry>
            <mesh>
              <scale>0.001 0.001 0.001</scale>
              <uri>/home/ioannis/centauro_ws/src/iit-centauro-ros-pkg/centauro_urdf/meshes/Forearm.STL</uri>
            </mesh>
          </geometry>
          <material>
            <script>
              <name>Gazebo/BlackTransparent</name>
              <uri>file://media/materials/scripts/gazebo.material</uri>
            </script>
          </material>
        </visual>
        <gravity>1</gravity>
        <velocity_decay/>
        <self_collide>0</self_collide>
        <enable_wind>0</enable_wind>
        <kinematic>0</kinematic>
      </link>
      <joint name='j_arm2_5' type='revolute'>
        <child>arm2_5</child>
        <parent>arm2_4</parent>
        <axis>
          <xyz>-0 0 1</xyz>
          <limit>
            <lower>-2.5394</lower>
            <upper>2.5546</upper>
            <effort>55</effort>
            <velocity>11.72</velocity>
          </limit>
          <dynamics>
            <spring_reference>0</spring_reference>
            <spring_stiffness>0</spring_stiffness>
          </dynamics>
          <use_parent_model_frame>1</use_parent_model_frame>
        </axis>
        <physics>
          <provide_feedback>1</provide_feedback>
          <ode>
            <provide_feedback>1</provide_feedback>
            <implicit_spring_damper>1</implicit_spring_damper>
            <cfm_damping>1</cfm_damping>
            <limit>
              <cfm>0</cfm>
              <erp>0.2</erp>
            </limit>
          </ode>
        </physics>
      </joint>
      <link name='arm2_6'>
        <pose frame=''>0.326757 -0.24945 -0.159758 0 -0 0.523599</pose>
        <inertial>
          <pose frame=''>-5e-06 0.038014 -0.069927 0 -0 0</pose>
          <mass>1.12636</mass>
          <inertia>
            <ixx>0.00518718</ixx>
            <ixy>-2.72444e-05</ixy>
            <ixz>2.28335e-06</ixz>
            <iyy>0.00480378</iyy>
            <iyz>0.000721657</iyz>
            <izz>0.00127714</izz>
          </inertia>
        </inertial>
        <collision name='arm2_6_collision'>
          <pose frame=''>0 0 0 0 -0 0</pose>
          <geometry>
            <mesh>
              <scale>0.001 0.001 0.001</scale>
              <uri>/home/ioannis/centauro_ws/src/iit-centauro-ros-pkg/centauro_urdf/meshes/simple/ForearmPitch.STL</uri>
            </mesh>
          </geometry>
          <surface>
            <contact>
              <ode/>
            </contact>
            <friction>
              <ode/>
              <torsional>
                <ode/>
              </torsional>
            </friction>
            <bounce/>
          </surface>
          <max_contacts>10</max_contacts>
        </collision>
        <visual name='arm2_6_visual'>
          <pose frame=''>0 0 0 0 -0 0</pose>
          <geometry>
            <mesh>
              <scale>0.001 0.001 0.001</scale>
              <uri>/home/ioannis/centauro_ws/src/iit-centauro-ros-pkg/centauro_urdf/meshes/ForearmPitch.STL</uri>
            </mesh>
          </geometry>
          <material>
            <script>
              <name>Gazebo/LightBlueLaser</name>
              <uri>file://media/materials/scripts/gazebo.material</uri>
            </script>
          </material>
        </visual>
        <gravity>1</gravity>
        <velocity_decay/>
        <self_collide>0</self_collide>
        <enable_wind>0</enable_wind>
        <kinematic>0</kinematic>
      </link>
      <joint name='j_arm2_6' type='revolute'>
        <child>arm2_6</child>
        <parent>arm2_5</parent>
        <axis>
          <xyz>-0.5 0.866025 -0</xyz>
          <limit>
            <lower>-1.5154</lower>
            <upper>1.5156</upper>
            <effort>55</effort>
            <velocity>11.72</velocity>
          </limit>
          <dynamics>
            <spring_reference>0</spring_reference>
            <spring_stiffness>0</spring_stiffness>
          </dynamics>
          <use_parent_model_frame>1</use_parent_model_frame>
        </axis>
        <physics>
          <provide_feedback>1</provide_feedback>
          <ode>
            <provide_feedback>1</provide_feedback>
            <implicit_spring_damper>1</implicit_spring_damper>
            <cfm_damping>1</cfm_damping>
            <limit>
              <cfm>0</cfm>
              <erp>0.2</erp>
            </limit>
          </ode>
        </physics>
      </joint>
      <link name='arm2_7'>
        <pose frame=''>0.302257 -0.207015 -0.333758 0 -0 0.523599</pose>
        <inertial>
          <pose frame=''>9e-06 -0.000492 0.01433 0 -0 0</pose>
          <mass>1.92794</mass>
          <inertia>
            <ixx>0.00316227</ixx>
            <ixy>-2.10165e-06</ixy>
            <ixz>-9.8962e-07</ixz>
            <iyy>0.00313238</iyy>
            <iyz>-6.1733e-05</iyz>
            <izz>0.00340422</izz>
          </inertia>
        </inertial>
        <collision name='arm2_7_collision'>
          <pose frame=''>0 0 0 0 -0 0</pose>
          <geometry>
            <mesh>
              <scale>0.001 0.001 0.001</scale>
              <uri>/home/ioannis/centauro_ws/src/iit-centauro-ros-pkg/centauro_urdf/meshes/simple/ForearmYaw.STL</uri>
            </mesh>
          </geometry>
          <surface>
            <contact>
              <ode/>
            </contact>
            <friction>
              <ode/>
              <torsional>
                <ode/>
              </torsional>
            </friction>
            <bounce/>
          </surface>
          <max_contacts>10</max_contacts>
        </collision>
        <collision name='arm2_7_fixed_joint_lump__ball2_collision_1'>
          <pose frame=''>0 0 0 0 -0 0</pose>
          <geometry>
            <mesh>
              <scale>0.001 0.001 0.001</scale>
              <uri>/home/ioannis/centauro_ws/src/iit-centauro-ros-pkg/centauro_urdf/meshes/simple/BallHand.stl</uri>
            </mesh>
          </geometry>
          <surface>
            <contact>
              <ode/>
            </contact>
            <friction>
              <ode/>
              <torsional>
                <ode/>
              </torsional>
            </friction>
            <bounce/>
          </surface>
          <max_contacts>10</max_contacts>
        </collision>
        <visual name='arm2_7_visual'>
          <pose frame=''>0 0 0 0 -0 0</pose>
          <geometry>
            <mesh>
              <scale>0.001 0.001 0.001</scale>
              <uri>/home/ioannis/centauro_ws/src/iit-centauro-ros-pkg/centauro_urdf/meshes/ForearmYaw.STL</uri>
            </mesh>
          </geometry>
          <material>
            <script>
              <name>Gazebo/LightBlueLaser</name>
              <uri>file://media/materials/scripts/gazebo.material</uri>
            </script>
          </material>
        </visual>
        <visual name='arm2_7_fixed_joint_lump__ball2_visual_1'>
          <pose frame=''>0 0 0 0 -0 0</pose>
          <geometry>
            <mesh>
              <scale>0.001 0.001 0.001</scale>
              <uri>/home/ioannis/centauro_ws/src/iit-centauro-ros-pkg/centauro_urdf/meshes/BallHand.stl</uri>
            </mesh>
          </geometry>
          <material>
            <script>
              <name>Gazebo/BlackTransparent</name>
              <uri>file://media/materials/scripts/gazebo.material</uri>
            </script>
          </material>
        </visual>
        <velocity_decay/>
        <gravity>1</gravity>
        <velocity_decay/>
        <self_collide>0</self_collide>
        <enable_wind>0</enable_wind>
        <kinematic>0</kinematic>
      </link>
      <joint name='j_arm2_7' type='revolute'>
        <child>arm2_7</child>
        <parent>arm2_6</parent>
        <axis>
          <xyz>-0 0 1</xyz>
          <limit>
            <lower>-2.5554</lower>
            <upper>2.5686</upper>
            <effort>28.32</effort>
            <velocity>20.35</velocity>
          </limit>
          <dynamics>
            <spring_reference>0</spring_reference>
            <spring_stiffness>0</spring_stiffness>
          </dynamics>
          <use_parent_model_frame>1</use_parent_model_frame>
        </axis>
        <physics>
          <provide_feedback>1</provide_feedback>
          <ode>
            <provide_feedback>1</provide_feedback>
            <implicit_spring_damper>1</implicit_spring_damper>
            <cfm_damping>1</cfm_damping>
            <limit>
              <cfm>0</cfm>
              <erp>0.2</erp>
            </limit>
          </ode>
        </physics>
      </joint>
      <link name='neck_3'>
        <pose frame=''>0.255 0 0.729262 0 0 -1.828</pose>
        <inertial>
          <pose frame=''>0.048467 -0.059852 -0.008531 0 -0 0</pose>
          <mass>0.785269</mass>
          <inertia>
            <ixx>0.000468234</ixx>
            <ixy>-1.05438e-05</ixy>
            <ixz>7.24398e-05</ixz>
            <iyy>0.000263525</iyy>
            <iyz>1.6904e-06</iyz>
            <izz>0.000376335</izz>
          </inertia>
        </inertial>
        <collision name='neck_3_collision'>
          <pose frame=''>0 0 0 0 -0 0</pose>
          <geometry>
            <mesh>
              <scale>0.001 0.001 0.001</scale>
              <uri>/home/ioannis/centauro_ws/src/iit-centauro-ros-pkg/centauro_urdf/meshes/simple/lidar.stl</uri>
            </mesh>
          </geometry>
          <max_contacts>10</max_contacts>
          <surface>
            <contact>
              <ode/>
            </contact>
            <bounce/>
            <friction>
              <torsional>
                <ode/>
              </torsional>
              <ode/>
            </friction>
          </surface>
        </collision>
        <visual name='neck_3_visual'>
          <pose frame=''>0 0 0 0 -0 0</pose>
          <geometry>
            <mesh>
              <scale>0.001 0.001 0.001</scale>
              <uri>/home/ioannis/centauro_ws/src/iit-centauro-ros-pkg/centauro_urdf/meshes/lidar.stl</uri>
            </mesh>
          </geometry>
        </visual>
        <self_collide>0</self_collide>
        <enable_wind>0</enable_wind>
        <kinematic>0</kinematic>
      </link>
      <joint name='neck_velodyne' type='revolute'>
        <child>neck_3</child>
        <parent>torso_2</parent>
        <axis>
          <xyz>0 0 1</xyz>
          <limit>
            <lower>-1e+16</lower>
            <upper>1e+16</upper>
          </limit>
          <dynamics>
            <damping>0.2</damping>
            <friction>10</friction>
            <spring_reference>0</spring_reference>
            <spring_stiffness>0</spring_stiffness>
          </dynamics>
          <use_parent_model_frame>1</use_parent_model_frame>
        </axis>
      </joint>
      <link name='neck_1'>
        <pose frame=''>0.2 0 0.5355 0 -0 0</pose>
        <inertial>
          <pose frame=''>0.04048 0.021378 -0.014595 0 -0 0</pose>
          <mass>0.338787</mass>
          <inertia>
            <ixx>0.000371857</ixx>
            <ixy>-9.42983e-05</ixy>
            <ixz>-2.80644e-05</ixz>
            <iyy>0.000188688</iyy>
            <iyz>-1.54534e-05</iyz>
            <izz>0.000502344</izz>
          </inertia>
        </inertial>
        <collision name='neck_1_collision'>
          <pose frame=''>0 0 0 0 -0 0</pose>
          <geometry>
            <mesh>
              <scale>0.001 0.001 0.001</scale>
              <uri>/home/ioannis/centauro_ws/src/iit-centauro-ros-pkg/centauro_urdf/meshes/simple/neck_yaw.stl</uri>
            </mesh>
          </geometry>
          <max_contacts>10</max_contacts>
          <surface>
            <contact>
              <ode/>
            </contact>
            <bounce/>
            <friction>
              <torsional>
                <ode/>
              </torsional>
              <ode/>
            </friction>
          </surface>
        </collision>
        <visual name='neck_1_visual'>
          <pose frame=''>0 0 0 0 -0 0</pose>
          <geometry>
            <mesh>
              <scale>0.001 0.001 0.001</scale>
              <uri>/home/ioannis/centauro_ws/src/iit-centauro-ros-pkg/centauro_urdf/meshes/neck_yaw.stl</uri>
            </mesh>
          </geometry>
        </visual>
        <self_collide>0</self_collide>
        <enable_wind>0</enable_wind>
        <kinematic>0</kinematic>
      </link>
      <joint name='neck_yaw' type='revolute'>
        <child>neck_1</child>
        <parent>torso_2</parent>
        <axis>
          <xyz>0 0 1</xyz>
          <limit>
            <lower>-0.785398</lower>
            <upper>0.785398</upper>
            <effort>35</effort>
            <velocity>5.7</velocity>
          </limit>
          <dynamics>
            <damping>0</damping>
            <friction>10</friction>
            <spring_reference>0</spring_reference>
            <spring_stiffness>0</spring_stiffness>
          </dynamics>
          <use_parent_model_frame>1</use_parent_model_frame>
        </axis>
      </joint>
      <link name='neck_2'>
        <pose frame=''>0.254 0.0596 0.523003 0 -0 0</pose>
        <inertial>
          <pose frame=''>0.048467 -0.059852 -0.008531 0 -0 0</pose>
          <mass>0.785269</mass>
          <inertia>
            <ixx>0.000468234</ixx>
            <ixy>-1.05438e-05</ixy>
            <ixz>7.24398e-05</ixz>
            <iyy>0.000263525</iyy>
            <iyz>1.6904e-06</iyz>
            <izz>0.000376335</izz>
          </inertia>
        </inertial>
        <collision name='neck_2_collision'>
          <pose frame=''>0 0 0 0 -0 0</pose>
          <geometry>
            <mesh>
              <scale>0.001 0.001 0.001</scale>
              <uri>/home/ioannis/centauro_ws/src/iit-centauro-ros-pkg/centauro_urdf/meshes/simple/neck_pitch.stl</uri>
            </mesh>
          </geometry>
          <max_contacts>10</max_contacts>
          <surface>
            <contact>
              <ode/>
            </contact>
            <bounce/>
            <friction>
              <torsional>
                <ode/>
              </torsional>
              <ode/>
            </friction>
          </surface>
        </collision>
        <visual name='neck_2_visual'>
          <pose frame=''>0 0 0 0 -0 0</pose>
          <geometry>
            <mesh>
              <scale>0.001 0.001 0.001</scale>
              <uri>/home/ioannis/centauro_ws/src/iit-centauro-ros-pkg/centauro_urdf/meshes/neck_pitch.stl</uri>
            </mesh>
          </geometry>
        </visual>
        <self_collide>0</self_collide>
        <enable_wind>0</enable_wind>
        <kinematic>0</kinematic>
      </link>
      <joint name='neck_pitch' type='revolute'>
        <child>neck_2</child>
        <parent>neck_1</parent>
        <axis>
          <xyz>0 1 0</xyz>
          <limit>
            <lower>-0.349066</lower>
            <upper>0.785398</upper>
            <effort>35</effort>
            <velocity>5.7</velocity>
          </limit>
          <dynamics>
            <damping>0</damping>
            <friction>10</friction>
            <spring_reference>0</spring_reference>
            <spring_stiffness>0</spring_stiffness>
          </dynamics>
          <use_parent_model_frame>1</use_parent_model_frame>
        </axis>
      </joint>
      <static>0</static>
      <plugin name='xbot2_link_state_sensor' filename='libxbot2_gz_link_state_sensor.so'>
        <links>
          <link name='pelvis'/>
          <link name='wheel_1'/>
        </links>
        <robotNamespace>/</robotNamespace>
      </plugin>
      <plugin name='xbot2_ft_driver' filename='libxbot2_gz_ft_server.so'>
        <robotNamespace>/</robotNamespace>
      </plugin>
      <plugin name='xbot2_imu_driver' filename='libxbot2_gz_imu_server.so'>
        <robotNamespace>/</robotNamespace>
      </plugin>
      <plugin name='xbot2_joint_driver' filename='libxbot2_gz_joint_server.so'>
        <pid>
          <gain d='5' name='lowpwr_mot' p='50'/>
          <gain d='5' name='small_mot' p='250'/>
          <gain d='10' name='medium_mot' p='1000'/>
          <gain d='10' name='big_mot' p='3000'/>
          <gain d='10' name='wheel_mot' p='0'/>
          <pid name='neck_yaw' profile='lowpwr_mot'/>
          <pid name='neck_pitch' profile='lowpwr_mot'/>
          <pid d='20' name='neck_velodyne' p='0'/>
          <pid name='j_arm1_1' profile='medium_mot'/>
          <pid name='j_arm1_2' profile='medium_mot'/>
          <pid name='j_arm1_3' profile='medium_mot'/>
          <pid name='j_arm1_4' profile='medium_mot'/>
          <pid name='j_arm1_5' profile='small_mot'/>
          <pid name='j_arm1_6' profile='small_mot'/>
          <pid name='j_arm1_7' profile='small_mot'/>
          <pid name='j_arm2_1' profile='medium_mot'/>
          <pid name='j_arm2_2' profile='medium_mot'/>
          <pid name='j_arm2_3' profile='medium_mot'/>
          <pid name='j_arm2_4' profile='medium_mot'/>
          <pid name='j_arm2_5' profile='small_mot'/>
          <pid name='j_arm2_6' profile='small_mot'/>
          <pid name='j_arm2_7' profile='small_mot'/>
          <pid name='torso_yaw' profile='big_mot'/>
          <pid name='hip_yaw_1' profile='big_mot'/>
          <pid name='hip_pitch_1' profile='big_mot'/>
          <pid name='knee_pitch_1' profile='big_mot'/>
          <pid name='ankle_pitch_1' profile='medium_mot'/>
          <pid name='ankle_yaw_1' profile='small_mot'/>
          <pid name='j_wheel_1' profile='wheel_mot'/>
          <pid name='hip_yaw_2' profile='big_mot'/>
          <pid name='hip_pitch_2' profile='big_mot'/>
          <pid name='knee_pitch_2' profile='big_mot'/>
          <pid name='ankle_pitch_2' profile='medium_mot'/>
          <pid name='ankle_yaw_2' profile='small_mot'/>
          <pid name='j_wheel_2' profile='wheel_mot'/>
          <pid name='hip_yaw_3' profile='big_mot'/>
          <pid name='hip_pitch_3' profile='big_mot'/>
          <pid name='knee_pitch_3' profile='big_mot'/>
          <pid name='ankle_pitch_3' profile='medium_mot'/>
          <pid name='ankle_yaw_3' profile='small_mot'/>
          <pid name='j_wheel_3' profile='wheel_mot'/>
          <pid name='hip_yaw_4' profile='big_mot'/>
          <pid name='hip_pitch_4' profile='big_mot'/>
          <pid name='knee_pitch_4' profile='big_mot'/>
          <pid name='ankle_pitch_4' profile='medium_mot'/>
          <pid name='ankle_yaw_4' profile='small_mot'/>
          <pid name='j_wheel_4' profile='wheel_mot'/>
        </pid>
        <robotNamespace>/</robotNamespace>
      </plugin>
      <pose frame=''>0 0 1.2 0 -0 0</pose>
    </model>
    <state world_name='default'>
      <sim_time>55 423500000</sim_time>
      <real_time>342 45823490</real_time>
      <wall_time>1615381858 443858080</wall_time>
      <iterations>221694</iterations>
      <model name='centauro'>
        <pose frame=''>0.16255 -0.017456 0.680455 0.008469 -0.135783 -0.003493</pose>
        <scale>1 1 1</scale>
        <link name='ankle1_1'>
          <pose frame=''>0.582587 0.338843 0.31305 -2.14536 1.41774 0.142519</pose>
          <velocity>0.00514 0.001416 0.000148 -0.000995 0.005527 -0.018171</velocity>
          <acceleration>0.004248 0.002307 0.000154 -2.18537 1.32325 -2.75032</acceleration>
          <wrench>0.005259 0.002856 0.000191 0 -0 0</wrench>
        </link>
        <link name='ankle1_2'>
          <pose frame=''>0.614532 -0.366746 0.511279 2.06845 1.40428 -0.067514</pose>
          <velocity>0.02072 -0.013201 -0.09605 0.064372 0.132945 -0.03215</velocity>
          <acceleration>0.002898 0.002458 0.003574 2.86502 -0.97121 -2.25468</acceleration>
          <wrench>0.003588 0.003043 0.004424 0 -0 0</wrench>
        </link>
        <link name='ankle1_3'>
          <pose frame=''>-0.124132 0.341244 0.312816 -0.77112 1.42529 -0.015687</pose>
          <velocity>0.005349 0.000446 0.00016 -0.00058 -0.000738 -0.006524</velocity>
          <acceleration>0.003075 0.000617 0.000501 -2.71319 1.56729 3.10833</acceleration>
          <wrench>0.003807 0.000764 0.00062 0 -0 0</wrench>
        </link>
        <link name='ankle1_4'>
          <pose frame=''>-0.13088 -0.356528 0.313266 0.878497 1.4339 0.064108</pose>
          <velocity>0.00456 0.001068 0.000131 -0.003987 0.004128 0.009161</velocity>
          <acceleration>0.004741 0.002483 0.002625 2.42943 -0.69591 2.06765</acceleration>
          <wrench>0.00587 0.003075 0.00325 0 -0 0</wrench>
        </link>
        <link name='ankle2_1'>
          <pose frame=''>0.582587 0.338843 0.31305 3.11846 0.151317 3.13187</pose>
          <velocity>0.005359 0.001237 0.000191 -0.003985 0.005346 0.001761</velocity>
          <acceleration>0.003583 0.000953 2e-06 0.245516 -0.731387 1.78128</acceleration>
          <wrench>0.004144 0.001103 2e-06 0 -0 0</wrench>
        </link>
        <link name='ankle2_2'>
          <pose frame=''>0.614532 -0.366745 0.511281 3.13392 -0.166342 -0.021219</pose>
          <velocity>0.020045 -0.01424 -0.098183 0.015563 0.135231 0.25717</velocity>
          <acceleration>0.001869 0.001167 0.003434 2.79397 -1.40832 -0.454027</acceleration>
          <wrench>0.002161 0.00135 0.003972 0 -0 0</wrench>
        </link>
        <link name='ankle2_3'>
          <pose frame=''>-0.124132 0.341244 0.312816 -3.14093 0.145505 3.13043</pose>
          <velocity>0.005316 0.000422 0.000154 -0.001504 -0.000763 -0.000144</velocity>
          <acceleration>0.001486 0.000258 0.000235 2.31559 0.395486 -2.31278</acceleration>
          <wrench>0.001718 0.000298 0.000271 0 -0 0</wrench>
        </link>
        <link name='ankle2_4'>
          <pose frame=''>-0.13088 -0.356528 0.313266 -3.13183 -0.136551 -0.00746</pose>
          <velocity>0.004774 0.000905 0.000158 -0.002816 0.004455 0.000921</velocity>
          <acceleration>0.003574 0.001034 0.002427 -3.03843 -1.42061 1.02203</acceleration>
          <wrench>0.004134 0.001195 0.002807 0 -0 0</wrench>
        </link>
        <link name='arm1_1'>
          <pose frame=''>0.35627 0.147765 1.08436 0.269594 0.392893 -0.39828</pose>
          <velocity>0.004461 0.001033 -0.000193 0.000894 -0.00325 0.000124</velocity>
          <acceleration>0.005003 0.006963 0.000563 -2.77119 1.01342 1.19306</acceleration>
          <wrench>0.00982 0.013668 0.001106 0 -0 0</wrench>
        </link>
        <link name='arm1_2'>
          <pose frame=''>0.308511 0.232695 1.13413 0.392511 0.392893 -0.398281</pose>
          <velocity>0.004296 0.000962 -0.000235 -0.000742 -0.00253 0.000888</velocity>
          <acceleration>0.002245 0.005958 0.000809 -2.91243 1.26275 -1.44303</acceleration>
          <wrench>0.004175 0.011079 0.001504 0 -0 0</wrench>
        </link>
        <link name='arm1_3'>
          <pose frame=''>0.346508 0.307238 0.913414 0.480746 0.274098 -0.130643</pose>
          <velocity>0.004784 0.000825 -0.000194 -0.000876 -0.002145 0.000175</velocity>
          <acceleration>-0.003531 0.004845 -0.000108 1.04669 -1.12755 3.00843</acceleration>
          <wrench>-0.005888 0.00808 -0.00018 0 -0 0</wrench>
        </link>
        <link name='arm1_4'>
          <pose frame=''>0.389523 0.38542 0.862623 2.17501 -0.999225 -2.52899</pose>
          <velocity>0.004882 0.000787 -0.000165 -0.000566 -0.001039 0.00072</velocity>
          <acceleration>-0.004598 0.006204 -0.002537 0.627295 -0.545608 1.36607</acceleration>
          <wrench>-0.00605 0.008163 -0.003338 0 -0 0</wrench>
        </link>
        <link name='arm1_5'>
          <pose frame=''>0.465039 0.30464 0.85465 2.19694 -1.01876 -2.5549</pose>
          <velocity>0.004949 0.000837 -4.1e-05 -0.000151 -0.001238 0.000868</velocity>
          <acceleration>-0.001851 0.009605 -0.006832 1.25638 0.55039 1.8366</acceleration>
          <wrench>-0.00276 0.014319 -0.010186 0 -0 0</wrench>
        </link>
        <link name='arm1_6'>
          <pose frame=''>0.612098 0.285095 0.923415 2.66124 -0.403783 3.06357</pose>
          <velocity>0.004882 0.000975 0.000144 -0.000185 -0.001321 0.000825</velocity>
          <acceleration>0.004558 0.012902 -0.010246 -1.5176 1.44656 -0.768315</acceleration>
          <wrench>0.005134 0.014532 -0.01154 0 -0 0</wrench>
        </link>
        <link name='arm1_7'>
          <pose frame=''>0.654018 0.15758 1.04449 2.64879 -0.388028 3.09584</pose>
          <velocity>0.004828 0.001032 0.000222 -0.000286 -0.001158 0.000558</velocity>
          <acceleration>0.010507 0.014446 -0.011254 0.010719 -0.020106 0.034403</acceleration>
          <wrench>0.020257 0.02785 -0.021697 0 -0 0</wrench>
        </link>
        <link name='arm2_1'>
          <pose frame=''>0.354898 -0.190494 1.08144 -0.252417 0.386366 0.396655</pose>
          <velocity>0.005204 0.001067 -0.001772 0.004043 0.005276 0.001959</velocity>
          <acceleration>0.009435 0.00693 0.003961 2.02181 1.42162 0.81938</acceleration>
          <wrench>0.01852 0.013602 0.007775 0 -0 0</wrench>
        </link>
        <link name='arm2_2'>
          <pose frame=''>0.306452 -0.275875 1.12976 -0.389937 0.386366 0.396655</pose>
          <velocity>0.005629 0.000798 -0.001797 -0.003536 0.002131 0.005283</velocity>
          <acceleration>0.011391 0.006286 0.003878 2.20888 -1.41871 -1.61447</acceleration>
          <wrench>0.021182 0.011688 0.007212 0 -0 0</wrench>
        </link>
        <link name='arm2_3'>
          <pose frame=''>0.345381 -0.349475 0.908887 -0.47404 0.273125 0.138622</pose>
          <velocity>0.005546 0.000238 -0.001602 -0.004472 -0.000507 0.00069</velocity>
          <acceleration>0.014967 0.005912 0.004329 1.87462 -0.843885 -0.139899</acceleration>
          <wrench>0.024962 0.00986 0.007221 0 -0 0</wrench>
        </link>
        <link name='arm2_4'>
          <pose frame=''>0.388881 -0.427057 0.85759 -2.18232 -1.00409 2.54036</pose>
          <velocity>0.005635 4.7e-05 -0.001219 -0.002714 -0.006634 0.003817</velocity>
          <acceleration>0.015731 0.00749 0.004971 2.2814 0.812422 1.89391</acceleration>
          <wrench>0.020697 0.009855 0.006541 0 -0 0</wrench>
        </link>
        <link name='arm2_5'>
          <pose frame=''>0.463961 -0.345838 0.849973 -2.22381 -1.03877 2.589</pose>
          <velocity>0.00538 0.000315 -0.00094 0.002812 -0.00408 0.00579</velocity>
          <acceleration>0.014111 0.010495 0.005831 -2.0282 0.04104 1.67295</acceleration>
          <wrench>0.021038 0.015647 0.008693 0 -0 0</wrench>
        </link>
        <link name='arm2_6'>
          <pose frame=''>0.611443 -0.326194 0.917797 -2.68654 -0.410997 -3.0424</pose>
          <velocity>0.004993 0.000979 -0.000282 -0.000209 0.006056 0.001141</velocity>
          <acceleration>0.010825 0.01326 0.006577 2.3985 0.513443 -1.82818</acceleration>
          <wrench>0.012193 0.014935 0.007408 0 -0 0</wrench>
        </link>
        <link name='arm2_7'>
          <pose frame=''>0.653085 -0.200965 1.04133 -2.6666 -0.387288 -3.09367</pose>
          <velocity>0.0056 0.001053 -0.000561 -0.001127 0.004677 -0.00127</velocity>
          <acceleration>0.00772 0.014445 0.006837 -0.024851 -0.096036 0.035426</acceleration>
          <wrench>0.014884 0.027849 0.013182 0 -0 0</wrench>
        </link>
        <link name='hip1_1'>
          <pose frame=''>0.418204 0.107127 0.659269 3.01908 -0.059291 1.18126</pose>
          <velocity>0.002545 0.003307 -0.000787 0.005891 0.002575 -0.017799</velocity>
          <acceleration>0.005504 0.002666 0.000943 -2.96625 -0.928813 -2.75827</acceleration>
          <wrench>0.010565 0.005117 0.001811 0 -0 0</wrench>
        </link>
        <link name='hip1_2'>
          <pose frame=''>0.417617 -0.142864 0.657171 -3.02117 -0.06347 -1.02898</pose>
          <velocity>0.003426 0.003576 -0.001985 0.003682 0.010029 -0.036723</velocity>
          <acceleration>0.005477 0.002745 0.003078 0.177814 1.22334 2.64159</acceleration>
          <wrench>0.010513 0.005269 0.005908 0 -0 0</wrench>
        </link>
        <link name='hip1_3'>
          <pose frame=''>-0.077191 0.108857 0.591586 3.00927 0.031686 1.86345</pose>
          <velocity>0.002276 0.001417 0.001268 0.005703 0.004455 -0.005725</velocity>
          <acceleration>0.005339 0.002528 0.002559 -0.219927 -0.007515 -2.55127</acceleration>
          <wrench>0.010248 0.004852 0.004912 0 -0 0</wrench>
        </link>
        <link name='hip1_4'>
          <pose frame=''>-0.077778 -0.141133 0.589488 -3.0168 0.054337 -1.92042</pose>
          <velocity>0.003371 0.001438 0.00016 0.002543 0.002458 0.009359</velocity>
          <acceleration>0.005214 0.002433 0.00451 -1.80289 -0.233184 2.63447</acceleration>
          <wrench>0.010008 0.00467 0.008657 0 -0 0</wrench>
        </link>
        <link name='hip2_1'>
          <pose frame=''>0.426665 0.107627 0.597347 -1.87916 -1.29429 1.00907</pose>
          <velocity>0.002366 0.003536 -0.000864 0.005001 0.000521 -0.016987</velocity>
          <acceleration>0.004297 0.002931 0.000338 0.305614 0.137981 -3.1338</acceleration>
          <wrench>0.011714 0.007991 0.000922 0 -0 0</wrench>
        </link>
        <link name='hip2_2'>
          <pose frame=''>0.426079 -0.142364 0.595249 1.76145 1.14014 -0.385725</pose>
          <velocity>0.002696 0.003889 -0.00196 0.172798 0.293241 -0.014724</velocity>
          <acceleration>0.005567 0.002939 0.003675 -1.97232 -1.14763 -2.06425</acceleration>
          <wrench>0.015177 0.008013 0.010021 0 -0 0</wrench>
        </link>
        <link name='hip2_3'>
          <pose frame=''>-0.068729 0.109357 0.529663 -1.00503 1.37559 -0.25293</pose>
          <velocity>0.00203 0.0017 0.001227 -0.004866 -0.005166 -0.007281</velocity>
          <acceleration>0.004632 0.001916 0.001255 2.14042 -0.831765 -1.40763</acceleration>
          <wrench>0.01263 0.005225 0.003422 0 -0 0</wrench>
        </link>
        <link name='hip2_4'>
          <pose frame=''>-0.069316 -0.140633 0.527566 -1.10465 -1.37576 -2.8483</pose>
          <velocity>0.003181 0.001698 0.000183 0.000803 0.001546 0.00891</velocity>
          <acceleration>0.00456 0.00271 0.003369 -0.930208 0.422761 -1.17046</acceleration>
          <wrench>0.012433 0.007388 0.009186 0 -0 0</wrench>
        </link>
        <link name='knee_1'>
          <pose frame=''>0.652542 0.289147 0.519609 -0.889656 1.43883 -1.753</pose>
          <velocity>0.005395 1.8e-05 -0.000307 0.000745 0.005495 -0.018025</velocity>
          <acceleration>0.004501 0.003344 0.00047 -2.41645 -0.938442 -2.60884</acceleration>
          <wrench>0.008712 0.006474 0.000909 0 -0 0</wrench>
        </link>
        <link name='knee_2'>
          <pose frame=''>0.654596 -0.292702 0.718503 -0.323932 1.48724 0.686474</pose>
          <velocity>0.036173 -0.020616 -0.094826 0.028559 0.062081 -0.037718</velocity>
          <acceleration>0.004386 0.002913 0.003034 1.44293 0.975535 -1.17679</acceleration>
          <wrench>0.008491 0.005639 0.005873 0 -0 0</wrench>
        </link>
        <link name='knee_3'>
          <pose frame=''>-0.271618 0.324762 0.480167 1.7997 1.09477 -0.605866</pose>
          <velocity>0.003863 0.002921 -0.000909 -0.008044 -0.008112 -0.007618</velocity>
          <acceleration>0.003926 0.000833 0.001228 0.01299 -0.760823 -1.62734</acceleration>
          <wrench>0.0076 0.001613 0.002377 0 -0 0</wrench>
        </link>
        <link name='knee_4'>
          <pose frame=''>-0.284468 -0.3431 0.475317 -1.73895 1.02339 0.607854</pose>
          <velocity>0.004882 -0.000215 0.00058 -0.000898 0.002649 0.009517</velocity>
          <acceleration>0.00493 0.003175 0.002528 -0.410021 1.53731 1.65888</acceleration>
          <wrench>0.009543 0.006146 0.004894 0 -0 0</wrench>
        </link>
        <link name='neck_1'>
          <pose frame=''>0.288206 -0.02243 1.23808 0.007817 -0.135823 0.001325</pose>
          <velocity>0.005523 8.8e-05 -0.000606 0.004981 0.005249 0.002456</velocity>
          <acceleration>0.007434 0.007806 0.002201 1.50407 -0.619799 1.22894</acceleration>
          <wrench>0.002519 0.002644 0.000746 0 -0 0</wrench>
        </link>
        <link name='neck_2'>
          <pose frame=''>0.343259 0.037339 1.23347 0.007748 0.029066 0.002609</pose>
          <velocity>0.005346 0.000195 -0.000472 0.004661 0.007262 0.001891</velocity>
          <acceleration>0.007677 0.008452 0.002244 -0.18777 -1.20299 0.456064</acceleration>
          <wrench>0.006028 0.006637 0.001762 0 -0 0</wrench>
        </link>
        <link name='neck_3'>
          <pose frame=''>0.316466 -0.024264 1.4375 0.129098 0.043038 -1.83183</pose>
          <velocity>0.006302 -0.00082 -0.000852 0.004827 0.003926 0.002107</velocity>
          <acceleration>0.008663 0.008549 0.002937 -1.96677 -0.575094 -0.364811</acceleration>
          <wrench>0.006803 0.006713 0.002306 0 -0 0</wrench>
        </link>
        <link name='pelvis'>
          <pose frame=''>0.16255 -0.017456 0.680455 0.008469 -0.135783 -0.003493</pose>
          <velocity>0.003164 0.002113 -0.000275 0.004339 0.00415 0.004469</velocity>
          <acceleration>0.00599 0.003785 0.002897 -1.32633 -0.010095 -0.219633</acceleration>
          <wrench>0.096428 0.060921 0.046631 0 -0 0</wrench>
        </link>
        <link name='torso_2'>
          <pose frame=''>0.326048 -0.020195 0.961163 0.008705 -0.135768 -0.005235</pose>
          <velocity>0.004319 0.001568 -0.000897 0.004741 0.004182 0.002253</velocity>
          <acceleration>0.007161 0.006132 0.00245 -0.118685 -0.086568 -1.29433</acceleration>
          <wrench>0.082304 0.070469 0.028153 0 -0 0</wrench>
        </link>
        <link name='wheel_1'>
          <pose frame=''>0.618412 0.344833 0.078495 1.54775 -0.125049 3.13823</pose>
          <velocity>0.004102 0.000349 -1.9e-05 -0.004386 0.053219 0.002963</velocity>
          <acceleration>0.003415 0.0006 -6e-05 3.06799 1.41964 -3.10949</acceleration>
          <wrench>0.005905 0.001038 -0.000104 0 -0 0</wrench>
        </link>
        <link name='wheel_2'>
          <pose frame=''>0.653764 -0.370249 0.277222 -1.56285 -0.311237 3.11667</pose>
          <velocity>-0.010577 -0.000632 -0.105947 0.008546 -0.034682 0.257648</velocity>
          <acceleration>0.001642 0.000839 0.003468 0.834212 0.967665 0.056332</acceleration>
          <wrench>0.002839 0.001451 0.005995 0 -0 0</wrench>
        </link>
        <link name='wheel_3'>
          <pose frame=''>-0.089713 0.341553 0.077974 -1.57148 0.283105 -0.011443</pose>
          <velocity>0.005495 6.3e-05 0.00018 -0.000785 0.070436 -0.000195</velocity>
          <acceleration>0.001073 0.000164 0.000164 2.9624 0.451625 3.13962</acceleration>
          <wrench>0.001855 0.000284 0.000283 0 -0 0</wrench>
        </link>
        <link name='wheel_4'>
          <pose frame=''>-0.098561 -0.355302 0.078129 1.58757 0.956211 0.007578</pose>
          <velocity>0.003732 0.000257 1.2e-05 -0.003224 0.048219 0.001429</velocity>
          <acceleration>0.003256 0.000636 0.002388 3.07424 0.487326 -3.13511</acceleration>
          <wrench>0.005629 0.0011 0.004129 0 -0 0</wrench>
        </link>
      </model>
      <model name='ground_plane'>
        <pose frame=''>0 0 0 0 -0 0</pose>
        <scale>1 1 1</scale>
        <link name='link'>
          <pose frame=''>0 0 0 0 -0 0</pose>
          <velocity>0 0 0 0 -0 0</velocity>
          <acceleration>0 0 0 0 -0 0</acceleration>
          <wrench>0 0 0 0 -0 0</wrench>
        </link>
      </model>
      <model name='unit_box'>
        <pose frame=''>1.09537 -0.49391 0.1 0 -0 0</pose>
        <scale>1 1 1</scale>
        <link name='link'>
          <pose frame=''>1.09537 -0.49391 0.1 0 -0 0</pose>
          <velocity>0 0 0 0 -0 0</velocity>
          <acceleration>0 0 -0.00981 0 -0 0</acceleration>
          <wrench>0 0 -9.81 0 -0 0</wrench>
        </link>
      </model>
      <light name='sun'>
        <pose frame=''>0 0 10 0 -0 0</pose>
      </light>
    </state>
  </world>
</sdf>
